Workbook
Name Company: [1]UEL!$B$18:$B$20
Name Dates: [1]ONT!$N$2:$AN$2
Name DetailedCapShares: '[2]Current Cap'!$T$133
Name FAGroup: [1]UEL!$B$3:$B$15
Name IQ_CH: 110000
Name IQ_CQ: 5000
Name IQ_CY: 10000
Name IQ_DAILY: 500000
Name IQ_FH: 100000
Name IQ_FQ: 500
Name IQ_FY: 1000
Name IQ_LTM: 2000
Name IQ_MONTH: 15000
Name IQ_NTM: 6000
Name IQ_WEEK: 50000
Name IQ_YTD: 3000

Sheet D
C2: Date of NAV | D2: 44834
H3: D A S H B O A R D | L3: figures in USD Millions
D6: # Investments | E6: Committed | F6: Invested | G6: Remaining | H6: Distributions | I6: Residual Value | J6: IRR | K6: TVPI | L6: RPI | M6: DPI | Q6: A T T R I B U T I O N S U M M A R Y
C8: EQUITY | D8: =COUNTIF('Summary | 01 '!C10:C24,"*") -> 15 | E8: ='1. IRR Equity1'!AC28 -> 2063.4981 | F8: ='1. IRR Equity1'!AD28 -> 2050.9949 | G8: ='1. IRR Equity1'!AE28 -> 12.503161 | H8: ='1. IRR Equity1'!AF28 -> 5 | I8: ='1. IRR Equity1'!AG28 -> 2154.3486 | J8: ='1. IRR Equity1'!AH28 -> 0.064125332 | K8: ='1. IRR Equity1'!AI28 -> 1.0528298 | L8: ='1. IRR Equity1'!AJ28 -> 1.050392 | M8: ='1. IRR Equity1'!AK28 -> 0.0024378412 | Q8: TOP GAINERS
Q9: Heygears | R9: Equity | S9: 76.64
Q10: Flyr Inc | R10: Equity | S10: 68.08223
C11: DEBT | D11: =COUNTIF('Summary | 01 '!C28:C30,"*") -> 3 | E11: ='2. IRR Debt'!Q12 -> 10.765747 | F11: ='2. IRR Debt'!R12 -> 10.765747 | G11: ='2. IRR Debt'!S12 -> 0 | H11: ='2. IRR Debt'!T12 -> 0 | I11: ='2. IRR Debt'!U12 -> 2.8104207 | J11: ='2. IRR Debt'!V12 -> -0.40060765 | K11: ='2. IRR Debt'!W12 -> 0.26105208 | L11: ='2. IRR Debt'!X12 -> 0.26105208 | M11: ='2. IRR Debt'!Y12 -> 0 | Q11: Honor Device Co Ltd | R11: Equity | S11: 60.462713
Q12: New Space Capital Fund I | R12: Fund | S12: 10.340849
Q13: ONT plc | R13: Equity | S13: 8.1105485
C14: FUNDS | D14: =COUNTIF('Summary | 01 '!C34:C38,"*") -> 5 | E14: ='3. IRR Funds'!Q15 -> 395.37629 | F14: ='3. IRR Funds'!R15 -> 134.94959 | G14: ='3. IRR Funds'!S15 -> 261.45466 | H14: ='3. IRR Funds'!T15 -> 1.4717893 | I14: ='3. IRR Funds'!U15 -> 140.19737 | J14: ='3. IRR Funds'!V15 -> 0.027224669 | K14: ='3. IRR Funds'!W15 -> 1.0497931 | L14: ='3. IRR Funds'!X15 -> 1.0388869 | M14: ='3. IRR Funds'!Y15 -> 0.010906215 | Q14: Esyasoft Holding | R14: Equity | S14: 2.5
Q15: Beyond Limits | R15: Equity | S15: 1.0015403
C17: TOTAL | D17: =D8+D11+D14 -> 23 | E17: =E8+E11+E14 -> 2469.6401 | F17: =F8+F11+F14 -> 2196.7103 | G17: =G8+G11+G14 -> 273.95782 | H17: =H8+H11+H14 -> 6.4717893 | I17: =I8+I11+I14 -> 2297.3564 | J17: ='4.All'!N9 -> 0.054621205 | K17: =(H17+I17)/F17 -> 1.0487629 | L17: =I17/F17 -> 1.0458168 | M17: =H17/F17 -> 0.0029461279 | Q17: TOP LOSERS
Q18: Jollychic Holding Limited | R18: Equity | S18: -65
E19: =E17='Summary | 01 '!J41 -> TRUE | F19: =F17='Summary | 01 '!K41 -> TRUE | G19: =ROUND(G17,1)=ROUND('Summary | 01 '!L41,1) -> TRUE | H19: =ROUND(H17,1)=ROUND('Summary | 01 '!M41,1) -> TRUE | I19: =ROUND(I17,1)=ROUND('Summary | 01 '!N41,1) -> TRUE | Q19: vTv Therapeutics Inc. | R19: Equity | S19: -13.055785
Q20: Glass Earth Holdings LLC | R20: Debt | S20: -8
Q21: Mena Mobile Inc | R21: Equity | S21: -4.9
C22: Equity Only | D22: # Investments | E22: Committed | F22: Invested | G22: Remaining | H22: Distributions | I22: Residual Value | J22: IRR | K22: TVPI | L22: RPI | M22: DPI | Q22: North Summit Capital Fund | R22: Fund | S22: -2.866692
Q23: Sinovation Disrupt Fund, L.P. | R23: Fund | S23: -0.47118065
C24: Select Portfolio1 IRR | D24: ='1.1(P1)'!O23 -> 9 | E24: ='1.1(P1)'!P23 -> 379.99398 | F24: ='1.1(P1)'!Q23 -> 379.99398 | G24: ='1.1(P1)'!R23 -> 0 | H24: ='1.1(P1)'!S23 -> 5 | I24: ='1.1(P1)'!T23 -> 442.81028 | J24: ='1.1(P1)'!U23 -> 0.076285401 | K24: ='1.1(P1)'!V23 -> 1.1784668 | ... M24: ='1.1(P1)'!X23 -> 0.013158103 | Q24: Acies Investments Fund I, L.P. | R24: Fund | S24: -0.2834155
C26: Vintage 2019 | Equity | D26: 3 | E26: =F26 -> 83 | F26: 83 | G26: 0 | H26: 0 | I26: 81.18223 | J26: -0.0067133114 | K26: 0.97809916 | L26: 0.97809916 | M26: 0 | Q26: TOTAL MOVEMENT | S26: =SUM(S9:S24) -> 132.56081
C28: Vintage 2020 | Equity | D28: 4 | E28: =F28 -> 293.97026 | F28: 293.97026 | G28: 0 | H28: 5 | I28: 377.22235 | J28: 0.12646896 | K28: 1.3002075 | L28: 1.283199 | M28: 0.017008523
C30: Vintage 2021 | Equity | D30: 2 | E30: =F30 -> 8.0237202 | F30: 8.0237202 | G30: 0 | H30: 0 | I30: 8.0237202 | J30: 2.9802322e-09 | K30: 1 | L30: 1 | M30: 0
C34: Includes Equity, Debt, Funds
D35: # Investments | E35: Committed | F35: Invested | G35: Remaining | H35: Distributions | I35: Residual Value | J35: IRR | K35: TVPI | L35: RPI | M35: DPI
C37: Asia-China | D37: 8 | E37: 2578.854 | F37: 1528.8598 | G37: =E37-F37 -> 1049.9941 | H37: 1.4717893 | I37: 1591.9989 | J37: 0.064502594 | K37: 1.0422608 | L37: 1.0412981 | M37: 0.00096267121
C39: Rest of Asia | D39: 3 | E39: 22.911765 | F39: 22.911765 | G39: 0 | H39: 5 | I39: 20.456439 | J39: 0.082198861 | K39: 1.1110641 | L39: 0.89283557 | M39: 0.2182285
C41: Middle East | D41: 1 | E41: 300 | F41: 300 | G41: 0 | H41: 0 | I41: 300 | J41: 2.9802322e-09 | K41: 1 | L41: 1 | M41: 0
C43: USA | D43: 7 | E43: 193.1125 | F43: 174.12686 | G43: 18.985638 | H43: 0 | I43: 221.87142 | J43: 0.12701625 | K43: 1.2503351 | L43: 1.2503351 | M43: 0
C45: Europe | D45: 4 | E45: 174.76187 | F45: 170.81591 | G45: 3.9459573 | H45: 0 | I45: 189.26321 | J45: 0.048084196 | K45: 1.1080218 | L45: 1.1080218 | M45: 0
C48: Notes
C49: Select Portfolio1 includes Jollychic, Mena Mobile, Flyr, Esyasoft, BL, ONT, Heygears, Endless, Instadeep
C50: Vintage 2019 includes Jollychic, Mena Mobile, Flyr
C51: Vintage 2020 includes Esyasoft, BL, ONT, Heygears
C52: Vintage 2021 includes Endless, Instadeep

Sheet Summary | 01 
C2: As of date | D2: =D!D2 -> 44834
C6: Deals | D6: Status | E6: Lead | F6: Investing Entity | G6: Instrument | H6: Vintageἀ | I6: % | J6: Committed | K6: Invested | L6: Remaining Commitment | M6: Distributions | N6: Carrying Value | O6: TVPI | P6: IRR | Q6: Additonal Upside
C9: Direct Investments
C10: Jollychic Holding Limited | D10: Unrealized | E10: Elaine | F10: Mozn | G10: C+ Prefs | H10: 2019 | I10: ='%'!F11 -> 0.056999998 | J10: 65 | K10: =-SUMIF('CF (Equity, Debt)'!$C$3:$K$31,'Summary | 01 '!C10,'CF (Equity, Debt)'!$E$3:$E$31) -> 65 | L10: 0 | M10: =SUMIF('CF (Equity, Debt)'!$C$3:$K$31,'Summary | 01 '!C10,'CF (Equity, Debt)'!$F$3:$F$31) -> 0 | N10: =NAV!D9 -> 0 | O10: =(M10+N10)/K10 -> 0 | P10: =VLOOKUP(C10,'1. IRR Equity1'!AB12:AK26,7,0) -> NM
C11: Mena Mobile Inc | D11: Unrealized | E11: Elaine | F11: Mozn | G11: B Prefs | H11: 2019 | I11: ='%'!F12 -> 0.14 | J11: 8 | K11: =-SUMIF('CF (Equity, Debt)'!$C$3:$K$31,'Summary | 01 '!C11,'CF (Equity, Debt)'!$E$3:$E$31) -> 8 | L11: 0 | M11: =SUMIF('CF (Equity, Debt)'!$C$3:$K$31,'Summary | 01 '!C11,'CF (Equity, Debt)'!$F$3:$F$31) -> 0 | N11: =NAV!D10 -> 3.1 | O11: =(M11+N11)/K11 -> 0.3875 | P11: =VLOOKUP(C11,'1. IRR Equity1'!AB13:AK27,7,0) -> -0.23833896
C12: Flyr Inc | D12: Unrealized | E12: Sushil | F12: Mozn | G12: B-1,2 Prefs | H12: 2019 | I12: ='%'!F13 -> 0.085025485 | J12: 10 | K12: =-SUMIF('CF (Equity, Debt)'!$C$3:$K$31,'Summary | 01 '!C12,'CF (Equity, Debt)'!$E$3:$E$31) -> 10 | L12: 0 | M12: =SUMIF('CF (Equity, Debt)'!$C$3:$K$31,'Summary | 01 '!C12,'CF (Equity, Debt)'!$F$3:$F$31) -> 0 | N12: =NAV!D11 -> 78.08223 | O12: =(M12+N12)/K12 -> 7.808223 | P12: =VLOOKUP(C12,'1. IRR Equity1'!AB14:AK28,7,0) -> 0.95566303 | Q12: Flyr Warrantsa
C13: Esyasoft Holding | D13: Realized | E13: Sushil | F13: Mozn | G13: Convertible Note | H13: 2020 | I13: ='%'!F14 -> n/a | J13: 2.5 | K13: =-SUMIF('CF (Equity, Debt)'!$C$3:$K$31,'Summary | 01 '!C13,'CF (Equity, Debt)'!$E$3:$E$31) -> 2.5 | L13: 0 | M13: =SUMIF('CF (Equity, Debt)'!$C$3:$K$31,'Summary | 01 '!C13,'CF (Equity, Debt)'!$F$3:$F$31) -> 5 | N13: =NAV!D12 -> 0 | O13: =(M13+N13)/K13 -> 2 | P13: =VLOOKUP(C13,'1. IRR Equity1'!AB15:AK29,7,0) -> 0.36091766
C14: Beyond Limits | D14: Unrealized | E14: Divyesh | F14: Mozn | G14: C Prefs | H14: 2020 | I14: ='%'!F15 -> 0.09739482 | J14: 90 | K14: =-SUMIF('CF (Equity, Debt)'!$C$3:$K$31,'Summary | 01 '!C14,'CF (Equity, Debt)'!$E$3:$E$31) -> 90 | L14: 0 | M14: =SUMIF('CF (Equity, Debt)'!$C$3:$K$31,'Summary | 01 '!C14,'CF (Equity, Debt)'!$F$3:$F$31) -> 0 | N14: =NAV!D13 -> 91.00154 | O14: =(M14+N14)/K14 -> 1.0111282 | P14: =VLOOKUP(C14,'1. IRR Equity1'!AB16:AK30,7,0) -> 0.0046035081
C15: ONT plc | D15: Unrealized | E15: Divyesh | F15: Mozn | G15: Ordinary Shares | H15: 2020 | I15: ='%'!F16 -> 0.053819975 | J15: 141.47026 | K15: =-SUMIF('CF (Equity, Debt)'!$C$3:$K$31,'Summary | 01 '!C15,'CF (Equity, Debt)'!$E$3:$E$31) -> 141.47026 | L15: 0 | M15: =SUMIF('CF (Equity, Debt)'!$C$3:$K$31,'Summary | 01 '!C15,'CF (Equity, Debt)'!$F$3:$F$31) -> 0 | N15: =NAV!D14 -> 125.96279 | O15: =(M15+N15)/K15 -> 0.89038351 | P15: =VLOOKUP(C15,'1. IRR Equity1'!AB17:AK31,7,0) -> -0.049104276
C16: Heygears | D16: Unrealized | E16: Elaine | F16: Mozn | G16: Registered Capital | H16: 2020 | I16: ='%'!F17 -> 0.1438 | J16: 60 | K16: =-SUMIF('CF (Equity, Debt)'!$C$3:$K$31,'Summary | 01 '!C16,'CF (Equity, Debt)'!$E$3:$E$31) -> 60 | L16: 0 | M16: =SUMIF('CF (Equity, Debt)'!$C$3:$K$31,'Summary | 01 '!C16,'CF (Equity, Debt)'!$F$3:$F$31) -> 0 | N16: =NAV!D15 -> 136.64 | O16: =(M16+N16)/K16 -> 2.2773333 | P16: =VLOOKUP(C16,'1. IRR Equity1'!AB18:AK32,7,0) -> 0.5678354
C17: Jysan Technologies | D17: To be Exited | E17: Sushil | F17: QAZ42 | G17: A (Ordinary Shares) | H17: 2021 | I17: ='%'!F18 -> 0.03 | J17: 20 | K17: =-SUMIF('CF (Equity, Debt)'!$C$3:$K$31,'Summary | 01 '!C17,'CF (Equity, Debt)'!$E$3:$E$31) -> 20 | L17: 0 | M17: =SUMIF('CF (Equity, Debt)'!$C$3:$K$31,'Summary | 01 '!C17,'CF (Equity, Debt)'!$F$3:$F$31) -> 0 | N17: =NAV!D16 -> 20 | O17: =(M17+N17)/K17 -> 1 | P17: =VLOOKUP(C17,'1. IRR Equity1'!AB19:AK33,7,0) -> 2.9802322e-09
C18: Cerebras Systems Inc | D18: Unrealized | E18: Ignasi | F18: Mozn | G18: F Prefs | H18: 2021 | I18: ='%'!F19 -> 0.01 | J18: 40 | K18: =-SUMIF('CF (Equity, Debt)'!$C$3:$K$31,'Summary | 01 '!C18,'CF (Equity, Debt)'!$E$3:$E$31) -> 39.999983 | L18: 0 | M18: =SUMIF('CF (Equity, Debt)'!$C$3:$K$31,'Summary | 01 '!C18,'CF (Equity, Debt)'!$F$3:$F$31) -> 0 | N18: =NAV!D17 -> 39.999983 | O18: =(M18+N18)/K18 -> 1 | P18: =VLOOKUP(C18,'1. IRR Equity1'!AB20:AK34,7,0) -> 2.9802322e-09
C19: Endless Studios LLC | D19: Unrealized | E19: Sushil | F19: Mozn | G19: A Pref Units | H19: 2021 | I19: ='%'!F20 -> 0.068571429 | J19: 3 | K19: =-SUMIF('CF (Equity, Debt)'!$C$3:$K$31,'Summary | 01 '!C19,'CF (Equity, Debt)'!$E$3:$E$31) -> 3 | L19: 0 | M19: =SUMIF('CF (Equity, Debt)'!$C$3:$K$31,'Summary | 01 '!C19,'CF (Equity, Debt)'!$F$3:$F$31) -> 0 | N19: =NAV!D18 -> 3 | O19: =(M19+N19)/K19 -> 1 | P19: =VLOOKUP(C19,'1. IRR Equity1'!AB21:AK35,7,0) -> 2.9802322e-09
C20: Instadeep Limited | D20: Unrealized | E20: Ignasi | F20: Mozn | G20: B Prefs | H20: 2021 | I20: ='%'!F21 -> 0.011489406 | J20: 5.0278212 | K20: =-SUMIF('CF (Equity, Debt)'!$C$3:$K$31,'Summary | 01 '!C20,'CF (Equity, Debt)'!$E$3:$E$31) -> 5.0237202 | L20: 0 | M20: =SUMIF('CF (Equity, Debt)'!$C$3:$K$31,'Summary | 01 '!C20,'CF (Equity, Debt)'!$F$3:$F$31) -> 0 | N20: =NAV!D19 -> 5.0237202 | O20: =(M20+N20)/K20 -> 1 | P20: =VLOOKUP(C20,'1. IRR Equity1'!AB22:AK36,7,0) -> 2.9802322e-09
C21: X-fusion | D21: Unrealized | E21: Elaine | F21: Enterprise Connection | G21: Equity-TBC | H21: 2022 | I21: ='%'!F22 -> 0.05 | J21: 493.5 | K21: =-SUMIF('CF (Equity, Debt)'!$C$3:$K$31,'Summary | 01 '!C21,'CF (Equity, Debt)'!$E$3:$E$31) -> 493.50096 | L21: 0 | M21: =SUMIF('CF (Equity, Debt)'!$C$3:$K$31,'Summary | 01 '!C21,'CF (Equity, Debt)'!$F$3:$F$31) -> 0 | N21: 493.5 | O21: =(M21+N21)/K21 -> 0.99999806 | P21: =VLOOKUP(C21,'1. IRR Equity1'!AB23:AK37,7,0) -> 2.9802322e-09
C22: DriveNets | D22: Unrealized | E22: Anton | F22: G42 | G22: Equity-TBC | H22: 2022 | I22: ='%'!F23 -> 0.0943 | J22: 300 | K22: =-SUMIF('CF (Equity, Debt)'!$C$3:$K$31,'Summary | 01 '!C22,'CF (Equity, Debt)'!$E$3:$E$31) -> 300 | L22: =0 -> 0 | M22: =SUMIF('CF (Equity, Debt)'!$C$3:$K$31,'Summary | 01 '!C22,'CF (Equity, Debt)'!$F$3:$F$31) -> 0 | N22: =NAV!D21 -> 300 | O22: =(M22+N22)/K22 -> 1 | P22: =VLOOKUP(C22,'1. IRR Equity1'!AB24:AK38,7,0) -> 2.9802322e-09 | Q22: DN Warrants b
C23: vTv Therapeutics Inc. | D23: Unrealized | E23: Divyesh | F23: G42 | G23: Ordinary Shares | H23: 2022 | I23: ='%'!F24 -> 0.099316564 | J23: 25 | K23: =-SUMIF('CF (Equity, Debt)'!$C$3:$K$31,'Summary | 01 '!C23,'CF (Equity, Debt)'!$E$3:$E$31) -> 12.5 | L23: =J23-K23 -> 12.5 | M23: =SUMIF('CF (Equity, Debt)'!$C$3:$K$31,'Summary | 01 '!C23,'CF (Equity, Debt)'!$F$3:$F$31) -> 0 | N23: =NAV!D22 -> -2.4253142 | O23: =(M23+N23)/K23 -> -0.19402514 | P23: =VLOOKUP(C23,'1. IRR Equity1'!AB25:AK39,7,0) -> NM | Q23: vTv $30m milestn payment c
C24: Honor Device Co Ltd | D24: Unrealized | E24: Elaine | F24: Smart Interaction | G24: Equity-TBC | H24: 2022 | I24: ='%'!F25 -> 0.0188 | J24: =K24 -> 800 | K24: =-SUMIF('CF (Equity, Debt)'!$C$3:$K$31,'Summary | 01 '!C24,'CF (Equity, Debt)'!$E$3:$E$31) -> 800 | L24: =J24-K24 -> 0 | M24: =SUMIF('CF (Equity, Debt)'!$C$3:$K$31,'Summary | 01 '!C24,'CF (Equity, Debt)'!$F$3:$F$31) -> 0 | N24: =NAV!D23 -> 860.46271 | O24: =(M24+N24)/K24 -> 1.0755784 | P24: =VLOOKUP(C24,'1. IRR Equity1'!AB26:AK40,7,0) -> NM
J25: =SUM(J10:J24) -> 2063.4981 | K25: =SUM(K10:K24) -> 2050.9949 | L25: =SUM(L10:L24) -> 12.5 | M25: =SUM(M10:M24) -> 5 | N25: =SUM(N10:N24) -> 2154.3477 | O25: =(M25+N25)/K25 -> 1.0528294
C27: Debt Investments
C28: Glass Earth Holdings LLC | D28: In default | F28: Mozn | G28: Promissory Note | H28: 2019 | I28: NA | J28: 8 | K28: 8 | L28: 0 | M28: 0 | N28: 0 | O28: =(M28+N28)/K28 -> 0 | P28: =VLOOKUP(C28,'2. IRR Debt'!P9:Y11,7,0) -> NM
C29: Mena Mobile Inc | D29: In default | E29: Elaine | F29: Mozn | G29: Loan | H29: 2021 | I29: NA | J29: 2.353982 | K29: =J29 -> 2.353982 | L29: 0 | M29: 0 | N29: =K29 -> 2.353982 | O29: =(M29+N29)/K29 -> 1 | P29: =VLOOKUP(C29,'2. IRR Debt'!P10:Y12,7,0) -> 2.9802322e-09
C30: Esyasoft Holding | D30: Unrealized | E30: Sushil | F30: Mozn | G30: Loan | H30: 2021 | I30: NA | J30: 0.411765 | K30: 0.411765 | L30: 0 | M30: 0 | N30: =456438.682191781/1000000 -> 0.45643868 | O30: =(M30+N30)/K30 -> 1.1084932 | P30: =VLOOKUP(C30,'2. IRR Debt'!P11:Y13,7,0) -> 0.087134919
J31: =SUM(J28:J30) -> 10.765747 | K31: =SUM(K28:K30) -> 10.765747 | L31: =SUM(L28:L30) -> 0 | M31: =SUM(M28:M30) -> 0 | N31: =SUM(N28:N30) -> 2.8104207 | O31: =(M31+N31)/K31 -> 0.26105208
C33: Funds Investments
C34: New Space Capital Fund I | D34: Unrealized | E34: Sushil | F34: G42 | G34: LP | H34: 2020 | I34: NA | J34: =23.2344618712304*1.1 -> 25.557908 | K34: 21.611951 | L34: 3.9459573 | M34: 0 | N34: 31.952799 | O34: 1.4784783 | P34: 0.21877305
C35: New Space Capital SCSp | D35: Unrealized | E35: Sushil | F35: G42 | G35: GP | H35: 2020 | I35: NA | J35: =2.3/0.85 -> 2.7058824 | K35: 2.7058824 | L35: 0 | M35: 0 | N35: 2.7058824 | O35: 1 | P35: 0
C36: North Summit Capital Fund | D36: Unrealized | E36: Elaine | F36: G42 | G36: LP | H36: 2020 | I36: NA | J36: 300 | K36: 83.214653 | L36: 217.81331 | M36: 1.027961 | N36: 79.32 | O36: 0.96555063 | P36: -0.018566843
C37: Sinovation Disrupt Fund, L.P. | D37: Unrealized | E37: Elaine | F37: G42 | G37: LP | H37: 2020 | I37: NA | J37: 50 | K37: 16.790246 | L37: 33.209754 | M37: 0.44382835 | N37: 15.875237 | O37: 0.97193724 | P37: -0.01726273
C38: Acies Investments Fund I, L.P. | D38: Unrealized | E38: Divyesh | F38: G42 | G38: LP | H38: 2021 | I38: 0.33 | J38: 17.1125 | K38: 10.626862 | L38: 6.4856375 | M38: 0 | N38: 10.343447 | O38: 0.97333028 | P38: -0.050154206 | Q38: 9.9% GP | Anchor
J39: =SUM(J34:J38) -> 395.37629 | K39: =SUM(K34:K38) -> 134.94959 | L39: =SUM(L34:L38) -> 261.45466 | M39: =SUM(M34:M38) -> 1.4717893 | N39: =SUM(N34:N38) -> 140.19737 | O39: =(M39+N39)/K39 -> 1.0497931
C41: Total | J41: =J25+J31+J39 -> 2469.6401 | K41: =K25+K31+K39 -> 2196.7103 | L41: =L25+L31+L39 -> 273.95466 | M41: =M25+M31+M39 -> 6.4717893 | N41: =N25+N31+N39 -> 2297.3554 | O41: =(M41+N41)/K41 -> 1.0487624
C46: Notes: | G46: Additional Upside Section:
C47: NA = Not applicable or Not available | G47: a) Flyr: For every $1m of revenue, 194,477 shares, capped at 1,264,1000 (B-1) shares shall be issued to Mozn
C48: NM = Not meaningful | G48: b) DriveNets: Share warrants exercisable upon the achievement of target revenue of clients referred by G42, and corresponding milestones
C49: TBC = to be confirmed | G49: c) vTv Therapeutics: Potential issuance of $30m in additional shares, if FDA approval received for the drug TTP399
C50: G42 = G42 Investments AI Holding RSC Ltd | G50: d) Acies Investments Fund I LP: Being the Anchor investor, entitled to 9.9% of the aggregate carried interest earned by the GP
C51: Mozn = Mozn Holding RSC Ltd
C52: QAZ42 = QAZ42 Investment SPV RSC Ltd
C53: Smart Interaction = Smart Interaction1 Holding SPV RSC LTD
...

Sheet Summary | 02
C2: As of date | D2: ='Summary | 01 '!D2 -> 44834
I4: Changes during the Period
I5: 1a | J5: 1b | K5: 1c | L5: 1d | N5: 3 | O5: 4
C6: Deals | D6: Status | E6: Lead | F6: Investing Entity | G6: Instrument | H6: Listed / Unlisted | I6: No. of securities held (Movement during the Period) | N6: Dividend / Interest | O6: For Comments Refer to Note
I7: Opening | J7: Acquired | K7: Re-organisation | L7: Sale / Transfer | M7: Closing
C9: Direct Investments
C10: Jollychic Holding Limited | D10: Unrealized | E10: Elaine | F10: Mozn | G10: C+ Prefs | I10: ='%'!D11 -> 13458655 | J10: 0 | K10: 0 | L10: 0 | M10: =I10 -> 13458655 | N10: 0 | O10: 1
C11: Mena Mobile Inc | D11: Unrealized | E11: Elaine | F11: Mozn | G11: B Prefs | I11: ='%'!D12 -> 21419829 | J11: 0 | K11: 0 | L11: 0 | M11: =I11 -> 21419829 | N11: 0 | O11: 2
C12: Flyr Inc | D12: Unrealized | E12: Sushil | F12: Mozn | G12: B-1,2 Prefs | I12: ='%'!D13 -> 5205482 | J12: 0 | K12: 0 | L12: 0 | N12: 0 | O12: 3
C13: Esyasoft Holding | D13: Realized | E13: Sushil | F13: Mozn | G13: Convertible Note | J13: 0 | K13: 0 | L13: 0 | N13: 0 | O13: 4
C14: Beyond Limits | D14: Unrealized | E14: Divyesh | F14: Mozn | G14: C Prefs | I14: ='%'!D15 -> 17670202 | J14: 0 | K14: 0 | L14: 0 | M14: =I14 -> 17670202 | N14: 0 | O14: 5
C15: ONT plc | D15: Unrealized | E15: Divyesh | F15: Mozn | G15: Ordinary Shares | H15: Listed | I15: ='%'!D16 -> 44328120 | J15: 0 | K15: 0 | L15: 0 | M15: =I15 -> 44328120 | N15: 0 | O15: 6
C16: Heygears | D16: Unrealized | E16: Elaine | F16: Mozn | G16: Registered Capital | I16: ='%'!D17 -> 3565017.2 | J16: 0 | K16: 0 | L16: 0 | M16: =I16 -> 3565017.2 | N16: 0 | O16: 7
C17: Jysan Technologies | D17: To be Exited | E17: Sushil | F17: QAZ42 | G17: A (Ordinary Shares) | I17: =NAV!F16 -> 7959497 | J17: 0 | K17: 0 | L17: 0 | M17: =I17 -> 7959497 | N17: 0 | O17: 8
C18: Cerebras Systems Inc | D18: Unrealized | E18: Ignasi | F18: Mozn | G18: F Prefs | I18: =NAV!F17 -> 1441711 | J18: 0 | K18: 0 | L18: 0 | M18: =I18 -> 1441711 | N18: 0 | O18: 9
C19: Endless Studios LLC | D19: Unrealized | E19: Sushil | F19: Mozn | G19: A Pref Units | I19: =NAV!F18 -> 3000000 | J19: 0 | K19: 0 | L19: 0 | M19: =I19 -> 3000000 | N19: 0 | O19: 10
C20: Instadeep Limited | D20: Unrealized | E20: Ignasi | F20: Mozn | G20: B Prefs | I20: =NAV!F19 -> 33267 | J20: 0 | K20: 0 | L20: 0 | M20: =I20 -> 33267 | N20: 0 | O20: 11
C21: X-fusion | D21: Unrealized | E21: Elaine | F21: Enterprise Connection | G21: Equity-TBC | O21: 12
C22: DriveNets | D22: Unrealized | E22: Anton | F22: G42 | G22: Equity-TBC | O22: 13
C23: vTv Therapeutics Inc. | D23: Unrealized | E23: Divyesh | F23: G42 | G23: Ordinary Shares | H23: Listed | I23: 10386274 | J23: 0 | K23: 0 | L23: 0 | M23: 10386274 | N23: 0 | O23: 14
C24: Honor Device Co Ltd | D24: Unrealized | E24: Elaine | F24: Smart Interaction | G24: Equity-TBC | O24: 15
C27: Debt Investments
C28: Glass Earth Holdings LLC | D28: In default | F28: Mozn | G28: Promissory Note | O28: 16
C29: Mena Mobile Inc | D29: In default | E29: Elaine | F29: Mozn | G29: Loan | O29: 17
C30: Esyasoft Holding | D30: Unrealized | E30: Sushil | F30: Mozn | G30: Loan | O30: 18
C33: Funds Investments
C34: New Space Capital Fund I | D34: Unrealized | E34: Sushil | F34: G42 | G34: LP | O34: 19
C35: New Space Capital SCSp | D35: Unrealized | E35: Sushil | F35: G42 | G35: GP | O35: 20
C36: North Summit Capital Fund | D36: Unrealized | E36: Elaine | F36: G42 | G36: LP | O36: 21
C37: Sinovation Disrupt Fund, L.P. | D37: Unrealized | E37: Elaine | F37: G42 | G37: LP | O37: 22
C38: Acies Investments Fund I, L.P. | D38: Unrealized | E38: Divyesh | F38: G42 | G38: LP | O38: 23
B45: Notes:
B46: 1 | C46: Jollychic | D46: During 2021, Jollychic Holding Ltd has filed for its liquidation. Therefore, investment is considered to be fully impaired in Dec 21.
B47: 2 | C47: Mena Mobile | D47: Investment is marked down based on the inputs received from 3rd party.
B48: 3 | C48: Flyr | D48: Within five years of the Initial Closing, for every USD 1mn of Qualifying Revenue generated, Flyr will issue, at no additional charge, 194,477 B-1 Prefs in the name of G42, up to a maximum of 1,264,100 B-1 Prefs.
B49: 4 | C49: Esyasoft Holding | D49: Investment in Esyasoft is in the form of Convertible Note which will convert to 21% interest on conversion on a fully diluted basis. As per Dec 2020 FS of Esyasoft, the CN was reflected as Debt - Exit of US$ 2.5 Mn Convertible Note @ 2.0x (MoC) i.e. US$ 5 Mn in May 22 - US$ 0.4 Mn represents Working Capital Loan
B50: 5 | C50: Beyond Limits | D50: Business targeting raising funds by the end of FY2022
B51: 6 | C51: ONT plc
B52: 7 | C52: Heygears | D52: Mozn's holding is RMB 4,753,356.29 of the Registered Capital.
B53: 8 | C53: Jysan Technologies | D53: - 50% of the investment has been financed by profit sharing loan. - Further, in case of exit of G42’s investment, 50% of the sale proceeds shall be paid to the lender as full and final settlement of the outstanding liability - Exit for this investment is under process. Buyback agreement is pending for signature internally. (Relevant documents to be perused by the consolidation / reporting team for details and corresponding implications, if any) - Dividend receivable amounting to US$ 3.2 m will be waived upon exit of this investment
...

Sheet NAV
B2: NAV Date | C2: =D!D2 -> 44834
B5: Investments | C5: Instrument | D5: Carrying Value | E5: Carrying Value | F5: Current Shares/Units | G5: PPS | 30 Sep 2022 | H5: Comment
D6: USD, Million | E6: USD, Million | F6: # | G6: USD
D7: ="NAV | "& TEXT(C2,"dd")&" "&TEXT(C2,"mmm")&" "&TEXT(C2,"yyyy") -> NAV | 30 Sep 2022 | E7: NAV | 30 Jun 2022
B8: Direct Investments
B9: Jollychic Holding Limited | C9: ='Summary | 01 '!G10 -> C+ Prefs | D9: =F9*G9*10^-6 -> 0 | E9: 0 | F9: =SUM('CF (Equity, Debt)'!J4:J6) -> 13458655 | G9: 0 | H9: In Liquidation
B10: Mena Mobile Inc | C10: ='Summary | 01 '!G11 -> B Prefs | D10: 3.1 | E10: =D10 -> 3.1 | F10: ='CF (Equity, Debt)'!J7 -> 21419829 | H10: As per 3rd Party | Ardent Estimates
B11: Flyr Inc | C11: ='Summary | 01 '!G12 -> B-1,2 Prefs | D11: =F11*G11*10^-6*(1-20%) -> 78.08223 | E11: =D11 -> 78.08223 | F11: 5205482 | G11: 18.75 | H11: At Series C PPS $18.75/share with 20% discount
B12: Esyasoft Holding | C12: ='Summary | 01 '!G13 -> Convertible Note | D12: 0 | E12: =D12 -> 0 | F12: N/A | H12: Exit at $5m (10th May) | Residual value = 0
B13: Beyond Limits | C13: ='Summary | 01 '!G14 -> C Prefs | D13: =F13*G13*10^-6 -> 91.00154 | E13: =D13 -> 91.00154 | F13: =SUM('CF (Equity, Debt)'!J11:J14) -> 17670202 | G13: 5.15 | H13: Held at cost (as per revised management guidance)
B14: ONT plc | C14: ='Summary | 01 '!G15 -> Ordinary Shares | D14: =F14*G14*10^-6 -> 125.96279 | E14: =2.66*1.22*F14*10^-6 -> 143.85362 | F14: 44328120 | G14: =2.56*1.11 -> 2.8416 | H14: Listed & marked to market
B15: Heygears | C15: ='Summary | 01 '!G16 -> Registered Capital | D15: 136.64 | E15: =D15 -> 136.64 | F15: ='CF (Equity, Debt)'!J20 -> 4753356.3 | H15: Negotiating final terms of a new round at $1.5Bn
B16: Jysan Technologies | C16: ='Summary | 01 '!G17 -> A (Ordinary Shares) | D16: =-'CF (Equity, Debt)'!E21 -> 20 | E16: =D16 -> 20 | F16: ='CF (Equity, Debt)'!J21 -> 7959497 | G16: =D16*10^6/F16 -> 2.5127216 | H16: Held at cost. To be exited
B17: Cerebras Systems Inc | C17: ='Summary | 01 '!G18 -> F Prefs | D17: =-'CF (Equity, Debt)'!E22 -> 39.999983 | E17: =D17 -> 39.999983 | F17: ='CF (Equity, Debt)'!J22 -> 1441711 | H17: Held at cost. To be exited
B18: Endless Studios LLC | C18: ='Summary | 01 '!G19 -> A Pref Units | D18: =-'CF (Equity, Debt)'!E23 -> 3 | E18: =D18 -> 3 | F18: ='CF (Equity, Debt)'!J23 -> 3000000 | H18: Held at cost.
B19: Instadeep Limited | C19: ='Summary | 01 '!G20 -> B Prefs | D19: =-'CF (Equity, Debt)'!E24 -> 5.0237202 | E19: =D19 -> 5.0237202 | F19: ='CF (Equity, Debt)'!J24 -> 33267 | H19: Held at cost.
B20: X-fusion | C20: ='Summary | 01 '!G21 -> Equity-TBC | D20: =-'CF (Equity, Debt)'!E25 -> 493.50096 | E20: =D20 -> 493.50096 | H20: Held at cost.
B21: DriveNets | C21: ='Summary | 01 '!G22 -> Equity-TBC | D21: =-SUM('CF (Equity, Debt)'!E26:E27) -> 300 | E21: =D21 -> 300 | H21: Held at cost.
B22: vTv Therapeutics Inc. | C22: ='Summary | 01 '!G23 -> Ordinary Shares | D22: =(F22*G22)*10^-6-12.5 -> -2.4253142 | E22: =(0.75*G22)*10^-6-12.5 -> -12.499999 | F22: ='CF (Equity, Debt)'!J29 -> 10386274 | G22: 0.97 | H22: Listed & marked to market
B23: Honor Device Co Ltd | C23: ='Summary | 01 '!G24 -> Equity-TBC | D23: =310000000000/6.7731/1000000*4.7%*50%*0.8 -> 860.46271 | E23: n/a | H23: Honor is closing a new round at RMB 310B
B27: Debt Investments
B28: Glass Earth Holdings LLC | C28: Promissory Note | D28: 0
B29: Mena Mobile Inc | C29: Loan | D29: 2.353982
B30: Esyasoft Holding | C30: Loan | D30: 0.45643868
B34: Funds Investments
B35: New Space Capital Fund I | C35: LP | D35: 31.952799 | H35: Q1'22 report
B36: New Space Capital SCSp | C36: GP | D36: 2.7058824 | H36: Q1'22 report
B37: North Summit Capital Fund | C37: LP | D37: 79.32 | H37: Q1'22 report
B38: Sinovation Disrupt Fund, L.P. | C38: LP | D38: 15.875237 | H38: Q1'22 report
B39: Acies Investments Fund I, L.P. | C39: LP | D39: 10.343447 | H39: Q1'22 report
B42: Note:
B43: • For estimating the NAV the share price for ONT and vTv Therapeutics is taken as of 15/09 (the latest available as of the date)

Sheet %
C2: % OWNERSHIP
C3: As of date | D3: ='Summary | 01 '!D2 -> 44834
C8: Deals | D8: Shares | E8: Total | F8: % Ownership | G8: Source
C10: Direct Investments
C11: Jollychic Holding Limited | D11: 13458655 | E11: 236116762 | F11: =D11/E11 -> 0.056999998 | G11: Dan Kong
C12: Mena Mobile Inc | D12: 21419829 | E12: 152998776 | F12: =D12/E12 -> 0.14 | G12: Dan Kong
C13: Flyr Inc | D13: 5205482 | E13: 61222609 | F13: =D13/E13 -> 0.085025485 | G13: Cap Table
C14: Esyasoft Holding | D14: n/a | E14: n/a | F14: n/a | G14: n/a
C15: Beyond Limits | D15: 17670202 | E15: 1.8142856e+08 | F15: =D15/E15 -> 0.09739482 | G15: Cap Table
C16: ONT plc | D16: 44328120 | E16: 823636945 | F16: =D16/E16 -> 0.053819975 | G16: LSE Announcement
C17: Heygears | D17: 3565017.2 | E17: =D17/F17 -> 24791497 | F17: 0.1438 | G17: Dan Kong
C18: Jysan Technologies | D18: 7959497 | E18: 2.6531657e+08 | F18: 0.03 | G18: Txn docs
C19: Cerebras Systems Inc | D19: 1441711 | E19: n/a | F19: 0.01 | G19: Pitchbook triangulation
C20: Endless Studios LLC | D20: 3000000 | E20: 43750000 | F20: =D20/E20 -> 0.068571429 | G20: Txn docs
C21: Instadeep Limited | D21: 33267 | E21: 2895450 | F21: =D21/E21 -> 0.011489406 | G21: Txn docs
C22: X-fusion | F22: =10% * 1/2 -> 0.05 | G22: Dan Kong
C23: DriveNets | F23: 0.0943 | G23: Finance team
C24: vTv Therapeutics Inc. | D24: 10386274 | E24: =81483600+23093860 -> 104577460 | F24: =D24/E24 -> 0.099316564 | G24: 10Q report 15Aug
C25: Honor Device Co Ltd | F25: =4.7%* 0.8/2 -> 0.0188 | G25: Dan Kong
C27: Debt Investments
C28: Glass Earth Holdings LLC
C29: Mena Mobile Inc
C30: Esyasoft Holding
C33: Funds Investments
C34: New Space Capital Fund I
C35: New Space Capital SCSp
C36: North Summit Capital Fund
C37: Sinovation Disrupt Fund, L.P.
C38: Acies Investments Fund I, L.P. | F38: =1/3 -> 0.33333333

Sheet CF (Equity, Debt)
B2: E QU I T Y
B3: Accounting entity | C3: Investment | D3: Payment date | E3: Contributions (in USD, Mn) | F3: Distributions (in USD, Mn) | G3: Currency | H3: Investment Amount | I3: Investment Amount | J3: Consideration (shares) | K3: Comment
B4: Mozn | C4: Jollychic Holding Limited | D4: 43470 | E4: =-I4*10^-6 -> -30 | G4: USD | H4: 30000000 | I4: =H4 -> 30000000 | J4: 6100312 | N4: NOTES
B5: Mozn | C5: Jollychic Holding Limited | D5: 43724 | E5: =-I5*10^-6 -> -20 | G5: USD | H5: 20000000 | I5: =H5 -> 20000000 | J5: 4204767.4 | N5: USD AED | O5: 3.678
B6: Mozn | C6: Jollychic Holding Limited | D6: 43724 | E6: =-I6*10^-6 -> -15 | G6: USD | H6: 15000000 | I6: =H6 -> 15000000 | J6: 3153575.6
B7: Mozn | C7: Mena Mobile Inc | D7: 43563 | E7: =-I7*10^-6 -> -8 | G7: USD | H7: 8000000 | I7: =H7 -> 8000000 | J7: 21419829
B8: Mozn | C8: Flyr Inc | D8: 43570 | E8: =-I8*10^-6 -> -4.9999981 | G8: USD | H8: 4999998.1 | I8: =H8 -> 4999998.1 | J8: 2625467
B9: Mozn | C9: Flyr Inc | D9: 43915 | E9: =-I9*10^-6 -> -5.0000019 | G9: USD | H9: =10000000-H8 -> 5000001.9 | I9: =H9 -> 5000001.9 | J9: 2580015
B10: Mozn | C10: Esyasoft Holding | D10: 43870 | E10: =-I10*10^-6 -> -2.5 | G10: USD | H10: 2500000 | I10: =H10 -> 2500000 | J10: N/A
B11: Mozn | C11: Beyond Limits | D11: 43879 | E11: =-I11*10^-6 -> -20 | G11: USD | H11: 20000000 | I11: =H11 -> 20000000 | J11: 4084038
B12: Mozn | C12: Beyond Limits | D12: 43921 | E12: =-I12*10^-6 -> -30 | G12: USD | H12: 30000000 | I12: =H12 -> 30000000 | J12: 5822642
B13: Mozn | C13: Beyond Limits | D13: 43989 | E13: =-I13*10^-6 -> -30 | G13: USD | H13: 30000000 | I13: =H13 -> 30000000 | J13: 5822642
B14: Mozn | C14: Beyond Limits | D14: 44103 | E14: =-I14*10^-6 -> -10 | G14: USD | H14: 10000000 | I14: =H14 -> 10000000 | J14: 1940880
B15: G42 | C15: ONT plc | D15: 43968 | E15: =-I15*10^-6 -> -50 | G15: USD | H15: 50000000 | I15: 50000000 | J15: 15277680
B16: G42 | C16: ONT plc | D16: 44006 | E16: =-I16*10^-6 -> -27.268351 | G16: GBP | H16: 21029625 | I16: 27268351 | J16: 9000000
B17: G42 | C17: ONT plc | D17: 43837 | E17: =-I17*10^-6 -> -18.109441 | G17: GBP | H17: 14386480 | I17: 18109441 | J17: 6362180
B18: G42 | C18: ONT plc | D18: 43990 | E18: =-I18*10^-6 -> -34.851687 | G18: GBP | H18: 26085573 | I18: 34851687 | J18: 11381140
B19: G42 | C19: ONT plc | D19: 44315 | E19: =-I19*10^-6 -> -11.24078 | G19: GBP | H19: 8074920 | I19: 11240780 | J19: 2307120
B20: Mozn | C20: Heygears | D20: 44166 | E20: =-I20*10^-6 -> -60 | G20: USD | H20: 60000000 | I20: =H20 -> 60000000 | J20: 4753356.3
B21: QAZ42 | C21: Jysan Technologies | D21: 44363 | E21: =-I21*10^-6 -> -20 | G21: USD | H21: 20000000 | I21: =H21 -> 20000000 | J21: 7959497
B22: Mozn | C22: Cerebras Systems Inc | D22: 44488 | E22: =-I22*10^-6 -> -39.999983 | G22: USD | H22: 39999983 | I22: =H22 -> 39999983 | J22: 1441711
B23: Mozn | C23: Endless Studios LLC | D23: 44494 | E23: =-I23*10^-6 -> -3 | G23: USD | H23: 3000000 | I23: =H23 -> 3000000 | J23: 3000000
B24: Mozn | C24: Instadeep Limited | D24: 44550 | E24: =-I24*10^-6 -> -5.0237202 | G24: GBP | H24: 3679995.5 | I24: 5023720.2 | J24: 33267
B25: Enterprise Connection | C25: X-fusion | D25: 44574 | E25: =-I25*10^-6 -> -493.50096 | G25: USD | H25: 8.9350096e+08 | I25: 4.9350096e+08
B26: G42 | C26: DriveNets | D26: 44643 | E26: =-I26*10^-6 -> -200 | G26: USD | H26: 200000000 | I26: =H26 -> 200000000
B27: G42 | C27: DriveNets | D27: 44680 | E27: =-I27*10^-6 -> -100 | G27: USD | H27: 100000000 | I27: =H27 -> 100000000
B28: Mozn | C28: Esyasoft Holding | D28: 44691 | F28: 5 | G28: USD
B29: G42 | C29: vTv Therapeutics Inc. | D29: 44712 | E29: =-I29*10^-6 -> -12.5 | G29: USD | H29: 12500000 | I29: =H29 -> 12500000 | J29: 10386274
B30: Smart Interaction | C30: Honor Device Co Ltd | D30: 44769 | E30: =-I30*10^-6 -> -800 | G30: USD | H30: 800000000 | I30: =H30 -> 800000000
B32: L O AN | P R O M I S S O R Y N O T E S | D E B T
B33: Mozn | C33: Glass Earth Holdings LLC | D33: 43635 | E33: -8 | H33: 8000000
B34: Mozn | C34: Mena Mobile Inc | D34: 44293 | E34: -2.353982
B35: Mozn | C35: Esyasoft Holding | D35: 44384 | E35: =-I35*10^-6 -> -0.411765 | G35: USD | H35: 2500000 | I35: 411765 | J35: N/A

Sheet CF (Funds)
A2: Entity | B2: Investment | C2: Payment date | D2: Contributions (USD, Mn) | E2: Distributions (USD, Mn) | F2: Currency | G2: Cashflows | H2: Description
A3: G42 | B3: Sinovation Disrupt Fund, L.P. | C3: 44153 | D3: =G3 -> -10.5 | F3: USD | G3: -10.5 | H3: 1st Capital Call
A4: G42 | B4: Sinovation Disrupt Fund, L.P. | C4: 44238 | D4: =G4 -> 4.214027 | F4: USD | G4: 4.214027 | H4: Partial return of the 1st Capital Call
A5: G42 | B5: Sinovation Disrupt Fund, L.P. | C5: 44238 | E5: =G5 -> 0.05044835 | F5: USD | G5: 0.05044835 | H5: Interest Catchup
A6: G42 | B6: Sinovation Disrupt Fund, L.P. | C6: 44285 | D6: =G6 -> -6.433746 | F6: USD | G6: -6.433746 | H6: 2nd Capital Calll
A7: G42 | B7: Sinovation Disrupt Fund, L.P. | C7: 44269 | D7: =G7 -> 1.1352074 | F7: USD | G7: 1.1352074 | H7: Return of Capital fund
A8: G42 | B8: Sinovation Disrupt Fund, L.P. | C8: 44269 | E8: =G8 -> 0.0259 | F8: USD | G8: 0.0259 | H8: Interest Catchup
A9: G42 | B9: Sinovation Disrupt Fund, L.P. | C9: 44483 | D9: =G9 -> -7.567138 | F9: USD | G9: -7.567138 | H9: 3rd Capital Call
A10: G42 | B10: Sinovation Disrupt Fund, L.P. | C10: 44554 | D10: =G10 -> -7.385016 | F10: USD | G10: -7.385016 | H10: 4th Capital Call
A11: G42 | B11: Sinovation Disrupt Fund, L.P. | C11: 44554 | D11: =G11 -> 4.0733456 | F11: USD | G11: 4.0733456 | H11: Return of Capital fund
A12: G42 | B12: Sinovation Disrupt Fund, L.P. | C12: 44554 | E12: =G12 -> 0.139694 | F12: USD | G12: 0.139694 | H12: Interest Catchup
A13: G42 | B13: Sinovation Disrupt Fund, L.P. | C13: 44703 | D13: =G13 -> 5.673074 | F13: USD | G13: 5.673074 | H13: Return of Capital fund
A14: G42 | B14: Sinovation Disrupt Fund, L.P. | C14: 44703 | E14: =G14 -> 0.227786 | F14: USD | G14: 0.227786 | H14: Interest Catchup
A15: Mozn | B15: North Summit Capital Fund | C15: 43665 | D15: =G15 -> -3 | F15: USD | G15: -3 | H15: 1st Capital Call
A16: Mozn | B16: North Summit Capital Fund | C16: 43983 | D16: =G16 -> -4.485 | F16: USD | G16: -4.485 | H16: 2nd Capital Calll
A17: Mozn | B17: North Summit Capital Fund | C17: 43879 | D17: =G17 -> -9.50975 | F17: USD | G17: -9.50975 | H17: 3rd Capital Call
A18: Mozn | B18: North Summit Capital Fund | C18: 43934 | D18: =G18 -> -41.3 | F18: USD | G18: -41.3 | H18: 4th Capital Call
A19: Mozn | B19: North Summit Capital Fund | C19: 44151 | D19: =G19 -> 9.95 | F19: USD | G19: 9.95 | H19: 5th Capital Call-Partial return of the 4th Capital Call
A20: Mozn | B20: North Summit Capital Fund | C20: 44151 | D20: =G20 -> -10.455 | F20: USD | G20: -10.455 | H20: 5th Capital Call
A21: Mozn | B21: North Summit Capital Fund | C21: 44196 | D21: =G21 -> 4.975 | F21: USD | G21: 4.975 | H21: 6th Capital Call-Partial return of the 4th Capital Call
A22: Mozn | B22: North Summit Capital Fund | C22: 44196 | D22: =G22 -> -3.452293 | F22: USD | G22: -3.452293 | H22: 6th Capital Call
A23: Mozn | B23: North Summit Capital Fund | C23: 44196 | E23: =G23 -> 0.582902 | F23: USD | G23: 0.582902 | H23: 6th Capital Call-Dividends from Project Topscore
A24: Mozn | B24: North Summit Capital Fund | C24: 44370 | D24: =G24 -> -5.97 | F24: USD | G24: -5.97 | H24: 7th Capital Call
A25: Mozn | B25: North Summit Capital Fund | C25: 44400 | D25: =G25 -> -0.75 | F25: USD | G25: -0.75 | H25: 8th Capital Call
A26: Mozn | B26: North Summit Capital Fund | C26: 44400 | E26: =G26 -> 0.445059 | F26: USD | G26: 0.445059 | H26: 8th Capital Call-Dividends from Project Topscore
A27: Mozn | B27: North Summit Capital Fund | C27: 44554 | D27: =G27 -> 1.78239 | F27: USD | G27: 1.78239 | H27: 9th Capital Call-Return of Capital Fund
A28: Mozn | B28: North Summit Capital Fund | C28: 44676 | D28: =G28 -> -21 | F28: USD | G28: -21 | H28: 12th Capital Call
A29: G42 | B29: New Space Capital Fund I | C29: 44087 | D29: =G29*1.1 -> -20.917553 | F29: EUR | G29: -19.015957 | H29: Drawdown1
A30: G42 | B30: New Space Capital Fund I | C30: 44287 | D30: -0.21103182 | F30: EUR | G30: -0.21103182 | H30: Drawdown2
A31: G42 | B31: New Space Capital Fund I | C31: 44442 | D31: =1.18*G31 -> -0.23965473 | F31: EUR | G31: =-203097.23*10^-6 -> -0.20309723 | H31: Drawdown3
A32: G42 | B32: New Space Capital Fund I | C32: 44623 | D32: =1.11*G32 -> -0.25893585 | F32: EUR | G32: =-233275.54*10^-6 -> -0.23327554 | H32: Drawdown4
A33: G42 | B33: New Space Capital Fund I | C33: 44784 | D33: =1.03*G33 -> 0.015224657 | F33: EUR | G33: =14781.22*10^-6 -> 0.01478122 | H33: Return of Capital
A34: G42 | B34: New Space Capital SCSp | C34: 44087 | D34: =-'Summary | 01 '!K35 -> -2.7058824 | F34: EUR | G34: -2.125 | H34: Drawdown1
A35: G42 | B35: Acies Investments Fund I, L.P. | C35: 44540 | D35: =G35 -> -2.8053125 | F35: USD | G35: -2.8053125 | H35: 1st Capital Call
A36: G42 | B36: Acies Investments Fund I, L.P. | C36: 44602 | D36: =G36 -> -3.4075 | F36: USD | G36: -3.4075 | H36: 2nd Capital Call
A37: G42 | B37: Acies Investments Fund I, L.P. | C37: 44683 | D37: =G37 -> -1.025775 | F37: USD | G37: -1.025775 | H37: 3rd Capital Call
A38: G42 | B38: Acies Investments Fund I, L.P. | C38: 44707 | D38: =G38 -> -3.388275 | F38: USD | G38: -3.388275 | H38: 4th Capital Call

Sheet 1. IRR Equity1
B2: IRR - Equity (Individual Investments)
B4: Date of NAV | C4: =D!D2 -> 44834 | J4: Investtment Level Summary | AA4: Overall Summary
B6: (in USD, Mn)
B7: Investment | C7: Payment date | D7: Contribution | E7: Distributions | F7: Remaining Value | G7: Combined | J7: Jollychic Holding Limited | K7: Mena Mobile Inc | L7: Flyr Inc | M7: Esyasoft Holding | N7: Beyond Limits | O7: ONT plc | P7: Heygears | Q7: Jysan Technologies | R7: Cerebras Systems Inc | S7: Endless Studios LLC | T7: Instadeep Limited | U7: X-fusion | V7: DriveNets | W7: vTv Therapeutics Inc. | X7: Honor Device Co Ltd | AC7: Committed | AD7: Invested | AE7: Remaining Commitment | AF7: Distributions | AG7: Residual Value | AH7: IRR | AI7: TVPI | AJ7: RPI | AK7: DPI
B10: ='CF (Equity, Debt)'!C4 -> Jollychic Holding Limited | C10: ='CF (Equity, Debt)'!D4 -> 43470 | D10: ='CF (Equity, Debt)'!E4 -> -30 | G10: =SUM(D10:F10) -> -30 | H10: =IF(D10='CF (Equity, Debt)'!E4," ", "xxx") | J10: =D10 -> -30
B11: ='CF (Equity, Debt)'!C5 -> Jollychic Holding Limited | C11: ='CF (Equity, Debt)'!D5 -> 43724 | D11: ='CF (Equity, Debt)'!E5 -> -20 | G11: =SUM(D11:F11) -> -20 | H11: =IF(D11='CF (Equity, Debt)'!E5," ", "xxx") | J11: =D11 -> -20
B12: ='CF (Equity, Debt)'!C6 -> Jollychic Holding Limited | C12: ='CF (Equity, Debt)'!D6 -> 43724 | D12: ='CF (Equity, Debt)'!E6 -> -15 | G12: =SUM(D12:F12) -> -15 | H12: =IF(D12='CF (Equity, Debt)'!E6," ", "xxx") | J12: =D12 -> -15 | AB12: Jollychic Holding Limited | AC12: ='Summary | 01 '!J10 -> 65 | AD12: =-SUMIF($B$7:$F$103,$AB12,$D$7:$D$103) -> 65 | AE12: =AC12-AD12 -> 0 | AF12: =SUMIF($B$7:$F$103,$AB12,$E$7:$E$103) -> 0 | AG12: =SUMIF($B$7:$F$103,$AB12,$F$7:$F$103) -> 0 | AH12: =HLOOKUP(AB12,$J$7:$X$59,48,0) -> NM | AI12: =(AF12+AG12)/AD12 -> 0 | AJ12: =AG12/AD12 -> 0 | AK12: =AF12/AD12 -> 0
B13: ='CF (Equity, Debt)'!C7 -> Mena Mobile Inc | C13: ='CF (Equity, Debt)'!D7 -> 43563 | D13: ='CF (Equity, Debt)'!E7 -> -8 | G13: =SUM(D13:F13) -> -8 | H13: =IF(D13='CF (Equity, Debt)'!E7," ", "xxx") | K13: =D13 -> -8 | AB13: Mena Mobile Inc | AC13: ='Summary | 01 '!J11 -> 8 | AD13: =-SUMIF($B$7:$F$103,$AB13,$D$7:$D$103) -> 8 | AE13: =AC13-AD13 -> 0 | AF13: =SUMIF($B$7:$F$103,$AB13,$E$7:$E$103) -> 0 | AG13: =SUMIF($B$7:$F$103,$AB13,$F$7:$F$103) -> 3.1 | AH13: =HLOOKUP(AB13,$J$7:$X$59,48,0) -> -0.23833896 | AI13: =(AF13+AG13)/AD13 -> 0.3875 | AJ13: =AG13/AD13 -> 0.3875 | AK13: =AF13/AD13 -> 0
B14: ='CF (Equity, Debt)'!C8 -> Flyr Inc | C14: ='CF (Equity, Debt)'!D8 -> 43570 | D14: ='CF (Equity, Debt)'!E8 -> -4.9999981 | G14: =SUM(D14:F14) -> -4.9999981 | H14: =IF(D14='CF (Equity, Debt)'!E8," ", "xxx") | L14: =D14 -> -4.9999981 | AB14: Flyr Inc | AC14: ='Summary | 01 '!J12 -> 10 | AD14: =-SUMIF($B$7:$F$103,$AB14,$D$7:$D$103) -> 10 | AE14: =AC14-AD14 -> 0 | AF14: =SUMIF($B$7:$F$103,$AB14,$E$7:$E$103) -> 0 | AG14: =SUMIF($B$7:$F$103,$AB14,$F$7:$F$103) -> 78.08223 | AH14: =HLOOKUP(AB14,$J$7:$X$59,48,0) -> 0.95566303 | AI14: =(AF14+AG14)/AD14 -> 7.808223 | AJ14: =AG14/AD14 -> 7.808223 | AK14: =AF14/AD14 -> 0
B15: ='CF (Equity, Debt)'!C9 -> Flyr Inc | C15: ='CF (Equity, Debt)'!D9 -> 43915 | D15: ='CF (Equity, Debt)'!E9 -> -5.0000019 | G15: =SUM(D15:F15) -> -5.0000019 | H15: =IF(D15='CF (Equity, Debt)'!E9," ", "xxx") | L15: =D15 -> -5.0000019 | AB15: Esyasoft Holding | AC15: ='Summary | 01 '!J13 -> 2.5 | AD15: =-SUMIF($B$7:$F$103,$AB15,$D$7:$D$103) -> 2.5 | AE15: =AC15-AD15 -> 0 | AF15: =SUMIF($B$7:$F$103,$AB15,$E$7:$E$103) -> 5 | AG15: =SUMIF($B$7:$F$103,$AB15,$F$7:$F$103) -> 0 | AH15: =HLOOKUP(AB15,$J$7:$X$59,48,0) -> 0.36091766 | AI15: =(AF15+AG15)/AD15 -> 2 | AJ15: =AG15/AD15 -> 0 | AK15: =AF15/AD15 -> 2
B16: ='CF (Equity, Debt)'!C10 -> Esyasoft Holding | C16: ='CF (Equity, Debt)'!D10 -> 43870 | D16: ='CF (Equity, Debt)'!E10 -> -2.5 | G16: =SUM(D16:F16) -> -2.5 | H16: =IF(D16='CF (Equity, Debt)'!E10," ", "xxx") | M16: =D16 -> -2.5 | AB16: Beyond Limits | AC16: ='Summary | 01 '!J14 -> 90 | AD16: =-SUMIF($B$7:$F$103,$AB16,$D$7:$D$103) -> 90 | AE16: =AC16-AD16 -> 0 | AF16: =SUMIF($B$7:$F$103,$AB16,$E$7:$E$103) -> 0 | AG16: =SUMIF($B$7:$F$103,$AB16,$F$7:$F$103) -> 91.00154 | AH16: =HLOOKUP(AB16,$J$7:$X$59,48,0) -> 0.0046035081 | AI16: =(AF16+AG16)/AD16 -> 1.0111282 | AJ16: =AG16/AD16 -> 1.0111282 | AK16: =AF16/AD16 -> 0
B17: ='CF (Equity, Debt)'!C11 -> Beyond Limits | C17: ='CF (Equity, Debt)'!D11 -> 43879 | D17: ='CF (Equity, Debt)'!E11 -> -20 | G17: =SUM(D17:F17) -> -20 | H17: =IF(D17='CF (Equity, Debt)'!E11," ", "xxx") | N17: =D17 -> -20 | AB17: ONT plc | AC17: ='Summary | 01 '!J15 -> 141.47026 | AD17: =-SUMIF($B$7:$F$103,$AB17,$D$7:$D$103) -> 141.47026 | AE17: =AC17-AD17 -> 0 | AF17: =SUMIF($B$7:$F$103,$AB17,$E$7:$E$103) -> 0 | AG17: =SUMIF($B$7:$F$103,$AB17,$F$7:$F$103) -> 125.96279 | AH17: =HLOOKUP(AB17,$J$7:$X$59,48,0) -> -0.049104276 | AI17: =(AF17+AG17)/AD17 -> 0.89038351 | AJ17: =AG17/AD17 -> 0.89038351 | AK17: =AF17/AD17 -> 0
B18: ='CF (Equity, Debt)'!C12 -> Beyond Limits | C18: ='CF (Equity, Debt)'!D12 -> 43921 | D18: ='CF (Equity, Debt)'!E12 -> -30 | G18: =SUM(D18:F18) -> -30 | H18: =IF(D18='CF (Equity, Debt)'!E12," ", "xxx") | N18: =D18 -> -30 | AB18: Heygears | AC18: ='Summary | 01 '!J16 -> 60 | AD18: =-SUMIF($B$7:$F$103,$AB18,$D$7:$D$103) -> 60 | AE18: =AC18-AD18 -> 0 | AF18: =SUMIF($B$7:$F$103,$AB18,$E$7:$E$103) -> 0 | AG18: =SUMIF($B$7:$F$103,$AB18,$F$7:$F$103) -> 136.64 | AH18: =HLOOKUP(AB18,$J$7:$X$59,48,0) -> 0.5678354 | AI18: =(AF18+AG18)/AD18 -> 2.2773333 | AJ18: =AG18/AD18 -> 2.2773333 | AK18: =AF18/AD18 -> 0
B19: ='CF (Equity, Debt)'!C13 -> Beyond Limits | C19: ='CF (Equity, Debt)'!D13 -> 43989 | D19: ='CF (Equity, Debt)'!E13 -> -30 | G19: =SUM(D19:F19) -> -30 | H19: =IF(D19='CF (Equity, Debt)'!E13," ", "xxx") | N19: =D19 -> -30 | AB19: Jysan Technologies | AC19: ='Summary | 01 '!J17 -> 20 | AD19: =-SUMIF($B$7:$F$103,$AB19,$D$7:$D$103) -> 20 | AE19: =AC19-AD19 -> 0 | AF19: =SUMIF($B$7:$F$103,$AB19,$E$7:$E$103) -> 0 | AG19: =SUMIF($B$7:$F$103,$AB19,$F$7:$F$103) -> 20 | AH19: =HLOOKUP(AB19,$J$7:$X$59,48,0) -> 2.9802322e-09 | AI19: =(AF19+AG19)/AD19 -> 1 | AJ19: =AG19/AD19 -> 1 | AK19: =AF19/AD19 -> 0
B20: ='CF (Equity, Debt)'!C14 -> Beyond Limits | C20: ='CF (Equity, Debt)'!D14 -> 44103 | D20: ='CF (Equity, Debt)'!E14 -> -10 | G20: =SUM(D20:F20) -> -10 | H20: =IF(D20='CF (Equity, Debt)'!E14," ", "xxx") | N20: =D20 -> -10 | AB20: Cerebras Systems Inc | AC20: ='Summary | 01 '!J18 -> 40 | AD20: =-SUMIF($B$7:$F$103,$AB20,$D$7:$D$103) -> 39.999983 | AE20: =AC20-AD20 -> 1.664e-05 | AF20: =SUMIF($B$7:$F$103,$AB20,$E$7:$E$103) -> 0 | AG20: =SUMIF($B$7:$F$103,$AB20,$F$7:$F$103) -> 39.999983 | AH20: =HLOOKUP(AB20,$J$7:$X$59,48,0) -> 2.9802322e-09 | AI20: =(AF20+AG20)/AD20 -> 1 | AJ20: =AG20/AD20 -> 1 | AK20: =AF20/AD20 -> 0
B21: ='CF (Equity, Debt)'!C15 -> ONT plc | C21: ='CF (Equity, Debt)'!D15 -> 43968 | D21: ='CF (Equity, Debt)'!E15 -> -50 | G21: =SUM(D21:F21) -> -50 | H21: =IF(D21='CF (Equity, Debt)'!E15," ", "xxx") | O21: =D21 -> -50 | AB21: Endless Studios LLC | AC21: ='Summary | 01 '!J19 -> 3 | AD21: =-SUMIF($B$7:$F$103,$AB21,$D$7:$D$103) -> 3 | AE21: =AC21-AD21 -> 0 | AF21: =SUMIF($B$7:$F$103,$AB21,$E$7:$E$103) -> 0 | AG21: =SUMIF($B$7:$F$103,$AB21,$F$7:$F$103) -> 3 | AH21: =HLOOKUP(AB21,$J$7:$X$59,48,0) -> 2.9802322e-09 | AI21: =(AF21+AG21)/AD21 -> 1 | AJ21: =AG21/AD21 -> 1 | AK21: =AF21/AD21 -> 0
B22: ='CF (Equity, Debt)'!C16 -> ONT plc | C22: ='CF (Equity, Debt)'!D16 -> 44006 | D22: ='CF (Equity, Debt)'!E16 -> -27.268351 | G22: =SUM(D22:F22) -> -27.268351 | H22: =IF(D22='CF (Equity, Debt)'!E16," ", "xxx") | O22: =D22 -> -27.268351 | AB22: Instadeep Limited | AC22: ='Summary | 01 '!J20 -> 5.0278212 | AD22: =-SUMIF($B$7:$F$103,$AB22,$D$7:$D$103) -> 5.0237202 | AE22: =AC22-AD22 -> 0.0041009961 | AF22: =SUMIF($B$7:$F$103,$AB22,$E$7:$E$103) -> 0 | AG22: =SUMIF($B$7:$F$103,$AB22,$F$7:$F$103) -> 5.0237202 | AH22: =HLOOKUP(AB22,$J$7:$X$59,48,0) -> 2.9802322e-09 | AI22: =(AF22+AG22)/AD22 -> 1 | AJ22: =AG22/AD22 -> 1 | AK22: =AF22/AD22 -> 0
B23: ='CF (Equity, Debt)'!C17 -> ONT plc | C23: ='CF (Equity, Debt)'!D17 -> 43837 | D23: ='CF (Equity, Debt)'!E17 -> -18.109441 | G23: =SUM(D23:F23) -> -18.109441 | H23: =IF(D23='CF (Equity, Debt)'!E17," ", "xxx") | O23: =D23 -> -18.109441 | AB23: X-fusion | AC23: ='Summary | 01 '!J21 -> 493.5 | AD23: =-SUMIF($B$7:$F$103,$AB23,$D$7:$D$103) -> 493.50096 | AE23: =AC23-AD23 -> -0.0009562 | AF23: =SUMIF($B$7:$F$103,$AB23,$E$7:$E$103) -> 0 | AG23: =SUMIF($B$7:$F$103,$AB23,$F$7:$F$103) -> 493.50096 | AH23: =HLOOKUP(AB23,$J$7:$X$59,48,0) -> 2.9802322e-09 | AI23: =(AF23+AG23)/AD23 -> 1 | AJ23: =AG23/AD23 -> 1 | AK23: =AF23/AD23 -> 0
B24: ='CF (Equity, Debt)'!C18 -> ONT plc | C24: ='CF (Equity, Debt)'!D18 -> 43990 | D24: ='CF (Equity, Debt)'!E18 -> -34.851687 | G24: =SUM(D24:F24) -> -34.851687 | H24: =IF(D24='CF (Equity, Debt)'!E18," ", "xxx") | O24: =D24 -> -34.851687 | AB24: DriveNets | AC24: ='Summary | 01 '!J22 -> 300 | AD24: =-SUMIF($B$7:$F$103,$AB24,$D$7:$D$103) -> 300 | AE24: =AC24-AD24 -> 0 | AF24: =SUMIF($B$7:$F$103,$AB24,$E$7:$E$103) -> 0 | AG24: =SUMIF($B$7:$F$103,$AB24,$F$7:$F$103) -> 300 | AH24: =HLOOKUP(AB24,$J$7:$X$59,48,0) -> 2.9802322e-09 | AI24: =(AF24+AG24)/AD24 -> 1 | AJ24: =AG24/AD24 -> 1 | AK24: =AF24/AD24 -> 0
B25: ='CF (Equity, Debt)'!C19 -> ONT plc | C25: ='CF (Equity, Debt)'!D19 -> 44315 | D25: ='CF (Equity, Debt)'!E19 -> -11.24078 | G25: =SUM(D25:F25) -> -11.24078 | H25: =IF(D25='CF (Equity, Debt)'!E19," ", "xxx") | O25: =D25 -> -11.24078 | AB25: vTv Therapeutics Inc. | AC25: ='Summary | 01 '!J23 -> 25 | AD25: =-SUMIF($B$7:$F$103,$AB25,$D$7:$D$103) -> 12.5 | AE25: =AC25-AD25 -> 12.5 | AF25: =SUMIF($B$7:$F$103,$AB25,$E$7:$E$103) -> 0 | AG25: =SUMIF($B$7:$F$103,$AB25,$F$7:$F$103) -> -2.4253142 | AH25: =HLOOKUP(AB25,$J$7:$X$59,48,0) -> NM | AI25: =(AF25+AG25)/AD25 -> -0.19402514 | AJ25: =AG25/AD25 -> -0.19402514 | AK25: =AF25/AD25 -> 0
B26: ='CF (Equity, Debt)'!C20 -> Heygears | C26: ='CF (Equity, Debt)'!D20 -> 44166 | D26: ='CF (Equity, Debt)'!E20 -> -60 | G26: =SUM(D26:F26) -> -60 | H26: =IF(D26='CF (Equity, Debt)'!E20," ", "xxx") | P26: =D26 -> -60 | AB26: Honor Device Co Ltd | AC26: ='Summary | 01 '!J24 -> 800 | AD26: =-SUMIF($B$7:$F$103,$AB26,$D$7:$D$103) -> 800 | AE26: =AC26-AD26 -> 0 | AF26: =SUMIF($B$7:$F$103,$AB26,$E$7:$E$103) -> 0 | AG26: =SUMIF($B$7:$F$103,$AB26,$F$7:$F$103) -> 860.46271 | AH26: =HLOOKUP(AB26,$J$7:$X$59,48,0) -> NM | AI26: =(AF26+AG26)/AD26 -> 1.0755784 | AJ26: =AG26/AD26 -> 1.0755784 | AK26: =AF26/AD26 -> 0
B27: ='CF (Equity, Debt)'!C21 -> Jysan Technologies | C27: ='CF (Equity, Debt)'!D21 -> 44363 | D27: ='CF (Equity, Debt)'!E21 -> -20 | G27: =SUM(D27:F27) -> -20 | H27: =IF(D27='CF (Equity, Debt)'!E21," ", "xxx") | Q27: =D27 -> -20
B28: ='CF (Equity, Debt)'!C22 -> Cerebras Systems Inc | C28: ='CF (Equity, Debt)'!D22 -> 44488 | D28: ='CF (Equity, Debt)'!E22 -> -39.999983 | G28: =SUM(D28:F28) -> -39.999983 | H28: =IF(D28='CF (Equity, Debt)'!E22," ", "xxx") | R28: =D28 -> -39.999983 | AC28: =SUM(AC12:AC27) -> 2063.4981 | AD28: =SUM(AD12:AD27) -> 2050.9949 | AE28: =SUM(AE12:AE27) -> 12.503161 | AF28: =SUM(AF12:AF27) -> 5 | AG28: =SUM(AG12:AG27) -> 2154.3486 | AH28: =AC35 -> 0.064125332 | AI28: =(AF28+AG28)/AD28 -> 1.0528298 | AJ28: =AG28/AD28 -> 1.050392 | AK28: =AF28/AD28 -> 0.0024378412
B29: ='CF (Equity, Debt)'!C23 -> Endless Studios LLC | C29: ='CF (Equity, Debt)'!D23 -> 44494 | D29: ='CF (Equity, Debt)'!E23 -> -3 | G29: =SUM(D29:F29) -> -3 | H29: =IF(D29='CF (Equity, Debt)'!E23," ", "xxx") | S29: =D29 -> -3
B30: ='CF (Equity, Debt)'!C24 -> Instadeep Limited | C30: ='CF (Equity, Debt)'!D24 -> 44550 | D30: ='CF (Equity, Debt)'!E24 -> -5.0237202 | G30: =SUM(D30:F30) -> -5.0237202 | H30: =IF(D30='CF (Equity, Debt)'!E24," ", "xxx") | T30: =D30 -> -5.0237202
B31: ='CF (Equity, Debt)'!C25 -> X-fusion | C31: ='CF (Equity, Debt)'!D25 -> 44574 | D31: ='CF (Equity, Debt)'!E25 -> -493.50096 | G31: =SUM(D31:F31) -> -493.50096 | H31: =IF(D31='CF (Equity, Debt)'!E25," ", "xxx") | U31: =D31 -> -493.50096
B32: ='CF (Equity, Debt)'!C26 -> DriveNets | C32: ='CF (Equity, Debt)'!D26 -> 44643 | D32: ='CF (Equity, Debt)'!E26 -> -200 | G32: =SUM(D32:F32) -> -200 | H32: =IF(D32='CF (Equity, Debt)'!E26," ", "xxx") | V32: =D32 -> -200
B33: ='CF (Equity, Debt)'!C27 -> DriveNets | C33: ='CF (Equity, Debt)'!D27 -> 44680 | D33: ='CF (Equity, Debt)'!E27 -> -100 | G33: =SUM(D33:F33) -> -100 | H33: =IF(D33='CF (Equity, Debt)'!E27," ", "xxx") | V33: =D33 -> -100
B34: ='CF (Equity, Debt)'!C28 -> Esyasoft Holding | C34: ='CF (Equity, Debt)'!D28 -> 44691 | D34: ='CF (Equity, Debt)'!E28 -> 0 | E34: 5 | G34: =SUM(D34:F34) -> 5 | H34: =IF(D34='CF (Equity, Debt)'!E28," ", "xxx") | M34: =E34 -> 5
B35: ='CF (Equity, Debt)'!C29 -> vTv Therapeutics Inc. | C35: ='CF (Equity, Debt)'!D29 -> 44712 | D35: ='CF (Equity, Debt)'!E29 -> -12.5 | G35: =SUM(D35:F35) -> -12.5 | H35: =IF(D35='CF (Equity, Debt)'!E29," ", "xxx") | W35: =D35 -> -12.5 | AB35: XIRR | AC35: =XIRR(G10:G52,C10:C52) -> 0.064125332
B36: ='CF (Equity, Debt)'!C30 -> Honor Device Co Ltd | C36: ='CF (Equity, Debt)'!D30 -> 44769 | D36: ='CF (Equity, Debt)'!E30 -> -800 | G36: =SUM(D36:F36) -> -800 | H36: =IF(D36='CF (Equity, Debt)'!E30," ", "xxx") | X36: =D36 -> -800 | AB36: TVPI | AC36: =SUM(AF12:AG26)/SUM(AD12:AD26) -> 1.0528298
AB37: RPI | AC37: =SUM(AG12:AG26)/SUM(AD12:AD26) -> 1.050392
B38: Jollychic Holding Limited | C38: =$C$4 -> 44834 | F38: =NAV!D9 -> 0 | G38: =SUM(D38:F38) -> 0 | J38: =F38 -> 0 | AB38: DPI | AC38: =SUM(AF12:AF26)/SUM(AD12:AD26) -> 0.0024378412
B39: Mena Mobile Inc | C39: =$C$4 -> 44834 | F39: =NAV!D10 -> 3.1 | G39: =SUM(D39:F39) -> 3.1 | K39: =F39 -> 3.1
B40: Flyr Inc | C40: =$C$4 -> 44834 | F40: =NAV!D11 -> 78.08223 | G40: =SUM(D40:F40) -> 78.08223 | L40: =F40 -> 78.08223
B41: Esyasoft Holding | C41: =$C$4 -> 44834 | F41: =NAV!D12 -> 0 | G41: =SUM(D41:F41) -> 0
B42: Beyond Limits | C42: =$C$4 -> 44834 | F42: =NAV!D13 -> 91.00154 | G42: =SUM(D42:F42) -> 91.00154 | N42: =F42 -> 91.00154
B43: ONT plc | C43: =$C$4 -> 44834 | F43: =NAV!D14 -> 125.96279 | G43: =SUM(D43:F43) -> 125.96279 | O43: =F43 -> 125.96279
B44: Heygears | C44: =$C$4 -> 44834 | F44: =NAV!D15 -> 136.64 | G44: =SUM(D44:F44) -> 136.64 | P44: =F44 -> 136.64
B45: Jysan Technologies | C45: =$C$4 -> 44834 | F45: =NAV!D16 -> 20 | G45: =SUM(D45:F45) -> 20 | Q45: =F45 -> 20
...

Sheet 1.1(P1)
B2: IRR - Equity (Select Investments)
C3: KEY PORTFOLIO IRR
C8: (in USD, Mn) | H8: Eliminated | I8: Portfolio 1
C9: Investment | D9: Payment date | E9: Contribution | F9: Distributions | G9: Remaining Value | H9: Jysan Technologies | I9: Jollychic Holding Limited
H10: Cerebras Systems Inc | I10: Mena Mobile Inc
H11: X-fusion | I11: Flyr Inc
H12: DriveNets | I12: Esyasoft Holding
H13: vTv Therapeutics Inc. | I13: Beyond Limits
H14: Honor Device Co Ltd | I14: ONT plc
I15: Heygears
I16: Endless Studios LLC
I17: Instadeep Limited
I21: Contribution | J21: Distribution | K21: Remaining Value | L21: Combined | O21: # Investments | P21: Committed | Q21: Invested | R21: Remaining Commitment | S21: Distributions | T21: Residual Value | U21: IRR | V21: TVPI | W21: RPI | X21: DPI
C22: ='CF (Equity, Debt)'!C4 -> Jollychic Holding Limited | D22: ='CF (Equity, Debt)'!D4 -> 43470 | E22: ='CF (Equity, Debt)'!E4 -> -30 | I22: =IF(ISERROR(VLOOKUP($C22,$I$9:$I$18,1,0)),0,1)*E22 -> -30 | J22: =IF(ISERROR(VLOOKUP($C22,$I$9:$I$18,1,0)),0,1)*F22 -> 0 | K22: =IF(ISERROR(VLOOKUP($C22,$I$9:$I$18,1,0)),0,1)*G22 -> 0 | L22: =SUM(I22:K22) -> -30
C23: ='CF (Equity, Debt)'!C5 -> Jollychic Holding Limited | D23: ='CF (Equity, Debt)'!D5 -> 43724 | E23: ='CF (Equity, Debt)'!E5 -> -20 | I23: =IF(ISERROR(VLOOKUP($C23,$I$9:$I$18,1,0)),0,1)*E23 -> -20 | J23: =IF(ISERROR(VLOOKUP($C23,$I$9:$I$18,1,0)),0,1)*F23 -> 0 | K23: =IF(ISERROR(VLOOKUP($C23,$I$9:$I$18,1,0)),0,1)*G23 -> 0 | L23: =SUM(I23:K23) -> -20 | O23: =COUNTIF(I9:I17,"*") -> 9 | P23: =Q23 -> 379.99398 | Q23: =-SUM(I22:I64) -> 379.99398 | R23: =P23-Q23 -> 0 | S23: =SUM(J22:J64) -> 5 | T23: =SUM(K22:K64) -> 442.81028 | U23: =J70 -> 0.076285401 | V23: =J71 -> 1.1784668 | W23: =J72 -> 1.1653087 | X23: =J73 -> 0.013158103
C24: ='CF (Equity, Debt)'!C6 -> Jollychic Holding Limited | D24: ='CF (Equity, Debt)'!D6 -> 43724 | E24: ='CF (Equity, Debt)'!E6 -> -15 | I24: =IF(ISERROR(VLOOKUP($C24,$I$9:$I$18,1,0)),0,1)*E24 -> -15 | J24: =IF(ISERROR(VLOOKUP($C24,$I$9:$I$18,1,0)),0,1)*F24 -> 0 | K24: =IF(ISERROR(VLOOKUP($C24,$I$9:$I$18,1,0)),0,1)*G24 -> 0 | L24: =SUM(I24:K24) -> -15
C25: ='CF (Equity, Debt)'!C7 -> Mena Mobile Inc | D25: ='CF (Equity, Debt)'!D7 -> 43563 | E25: ='CF (Equity, Debt)'!E7 -> -8 | I25: =IF(ISERROR(VLOOKUP($C25,$I$9:$I$18,1,0)),0,1)*E25 -> -8 | J25: =IF(ISERROR(VLOOKUP($C25,$I$9:$I$18,1,0)),0,1)*F25 -> 0 | K25: =IF(ISERROR(VLOOKUP($C25,$I$9:$I$18,1,0)),0,1)*G25 -> 0 | L25: =SUM(I25:K25) -> -8
C26: ='CF (Equity, Debt)'!C8 -> Flyr Inc | D26: ='CF (Equity, Debt)'!D8 -> 43570 | E26: ='CF (Equity, Debt)'!E8 -> -4.9999981 | I26: =IF(ISERROR(VLOOKUP($C26,$I$9:$I$18,1,0)),0,1)*E26 -> -4.9999981 | J26: =IF(ISERROR(VLOOKUP($C26,$I$9:$I$18,1,0)),0,1)*F26 -> 0 | K26: =IF(ISERROR(VLOOKUP($C26,$I$9:$I$18,1,0)),0,1)*G26 -> 0 | L26: =SUM(I26:K26) -> -4.9999981
C27: ='CF (Equity, Debt)'!C9 -> Flyr Inc | D27: ='CF (Equity, Debt)'!D9 -> 43915 | E27: ='CF (Equity, Debt)'!E9 -> -5.0000019 | I27: =IF(ISERROR(VLOOKUP($C27,$I$9:$I$18,1,0)),0,1)*E27 -> -5.0000019 | J27: =IF(ISERROR(VLOOKUP($C27,$I$9:$I$18,1,0)),0,1)*F27 -> 0 | K27: =IF(ISERROR(VLOOKUP($C27,$I$9:$I$18,1,0)),0,1)*G27 -> 0 | L27: =SUM(I27:K27) -> -5.0000019
C28: ='CF (Equity, Debt)'!C10 -> Esyasoft Holding | D28: ='CF (Equity, Debt)'!D10 -> 43870 | E28: ='CF (Equity, Debt)'!E10 -> -2.5 | I28: =IF(ISERROR(VLOOKUP($C28,$I$9:$I$18,1,0)),0,1)*E28 -> -2.5 | J28: =IF(ISERROR(VLOOKUP($C28,$I$9:$I$18,1,0)),0,1)*F28 -> 0 | K28: =IF(ISERROR(VLOOKUP($C28,$I$9:$I$18,1,0)),0,1)*G28 -> 0 | L28: =SUM(I28:K28) -> -2.5
C29: ='CF (Equity, Debt)'!C11 -> Beyond Limits | D29: ='CF (Equity, Debt)'!D11 -> 43879 | E29: ='CF (Equity, Debt)'!E11 -> -20 | I29: =IF(ISERROR(VLOOKUP($C29,$I$9:$I$18,1,0)),0,1)*E29 -> -20 | J29: =IF(ISERROR(VLOOKUP($C29,$I$9:$I$18,1,0)),0,1)*F29 -> 0 | K29: =IF(ISERROR(VLOOKUP($C29,$I$9:$I$18,1,0)),0,1)*G29 -> 0 | L29: =SUM(I29:K29) -> -20
C30: ='CF (Equity, Debt)'!C12 -> Beyond Limits | D30: ='CF (Equity, Debt)'!D12 -> 43921 | E30: ='CF (Equity, Debt)'!E12 -> -30 | I30: =IF(ISERROR(VLOOKUP($C30,$I$9:$I$18,1,0)),0,1)*E30 -> -30 | J30: =IF(ISERROR(VLOOKUP($C30,$I$9:$I$18,1,0)),0,1)*F30 -> 0 | K30: =IF(ISERROR(VLOOKUP($C30,$I$9:$I$18,1,0)),0,1)*G30 -> 0 | L30: =SUM(I30:K30) -> -30
C31: ='CF (Equity, Debt)'!C13 -> Beyond Limits | D31: ='CF (Equity, Debt)'!D13 -> 43989 | E31: ='CF (Equity, Debt)'!E13 -> -30 | I31: =IF(ISERROR(VLOOKUP($C31,$I$9:$I$18,1,0)),0,1)*E31 -> -30 | J31: =IF(ISERROR(VLOOKUP($C31,$I$9:$I$18,1,0)),0,1)*F31 -> 0 | K31: =IF(ISERROR(VLOOKUP($C31,$I$9:$I$18,1,0)),0,1)*G31 -> 0 | L31: =SUM(I31:K31) -> -30
C32: ='CF (Equity, Debt)'!C14 -> Beyond Limits | D32: ='CF (Equity, Debt)'!D14 -> 44103 | E32: ='CF (Equity, Debt)'!E14 -> -10 | I32: =IF(ISERROR(VLOOKUP($C32,$I$9:$I$18,1,0)),0,1)*E32 -> -10 | J32: =IF(ISERROR(VLOOKUP($C32,$I$9:$I$18,1,0)),0,1)*F32 -> 0 | K32: =IF(ISERROR(VLOOKUP($C32,$I$9:$I$18,1,0)),0,1)*G32 -> 0 | L32: =SUM(I32:K32) -> -10
C33: ='CF (Equity, Debt)'!C15 -> ONT plc | D33: ='CF (Equity, Debt)'!D15 -> 43968 | E33: ='CF (Equity, Debt)'!E15 -> -50 | I33: =IF(ISERROR(VLOOKUP($C33,$I$9:$I$18,1,0)),0,1)*E33 -> -50 | J33: =IF(ISERROR(VLOOKUP($C33,$I$9:$I$18,1,0)),0,1)*F33 -> 0 | K33: =IF(ISERROR(VLOOKUP($C33,$I$9:$I$18,1,0)),0,1)*G33 -> 0 | L33: =SUM(I33:K33) -> -50
C34: ='CF (Equity, Debt)'!C16 -> ONT plc | D34: ='CF (Equity, Debt)'!D16 -> 44006 | E34: ='CF (Equity, Debt)'!E16 -> -27.268351 | I34: =IF(ISERROR(VLOOKUP($C34,$I$9:$I$18,1,0)),0,1)*E34 -> -27.268351 | J34: =IF(ISERROR(VLOOKUP($C34,$I$9:$I$18,1,0)),0,1)*F34 -> 0 | K34: =IF(ISERROR(VLOOKUP($C34,$I$9:$I$18,1,0)),0,1)*G34 -> 0 | L34: =SUM(I34:K34) -> -27.268351
C35: ='CF (Equity, Debt)'!C17 -> ONT plc | D35: ='CF (Equity, Debt)'!D17 -> 43837 | E35: ='CF (Equity, Debt)'!E17 -> -18.109441 | I35: =IF(ISERROR(VLOOKUP($C35,$I$9:$I$18,1,0)),0,1)*E35 -> -18.109441 | J35: =IF(ISERROR(VLOOKUP($C35,$I$9:$I$18,1,0)),0,1)*F35 -> 0 | K35: =IF(ISERROR(VLOOKUP($C35,$I$9:$I$18,1,0)),0,1)*G35 -> 0 | L35: =SUM(I35:K35) -> -18.109441
... C38: ='CF (Equity, Debt)'!C20 -> Heygears | D38: ='CF (Equity, Debt)'!D20 -> 44166 | E38: ='CF (Equity, Debt)'!E20 -> -60 | I38: =IF(ISERROR(VLOOKUP($C38,$I$9:$I$18,1,0)),0,1)*E38 -> -60 | J38: =IF(ISERROR(VLOOKUP($C38,$I$9:$I$18,1,0)),0,1)*F38 -> 0 | K38: =IF(ISERROR(VLOOKUP($C38,$I$9:$I$18,1,0)),0,1)*G38 -> 0 | L38: =SUM(I38:K38) -> -60
C39: ='CF (Equity, Debt)'!C21 -> Jysan Technologies | D39: ='CF (Equity, Debt)'!D21 -> 44363 | E39: ='CF (Equity, Debt)'!E21 -> -20 | H39: =E39 -> -20 | I39: =IF(ISERROR(VLOOKUP($C39,$I$9:$I$18,1,0)),0,1)*E39 -> 0 | J39: =IF(ISERROR(VLOOKUP($C39,$I$9:$I$18,1,0)),0,1)*F39 -> 0 | K39: =IF(ISERROR(VLOOKUP($C39,$I$9:$I$18,1,0)),0,1)*G39 -> 0 | L39: =SUM(I39:K39) -> 0
C40: ='CF (Equity, Debt)'!C22 -> Cerebras Systems Inc | D40: ='CF (Equity, Debt)'!D22 -> 44488 | E40: ='CF (Equity, Debt)'!E22 -> -39.999983 | H40: =E40 -> -39.999983 | I40: =IF(ISERROR(VLOOKUP($C40,$I$9:$I$18,1,0)),0,1)*E40 -> 0 | J40: =IF(ISERROR(VLOOKUP($C40,$I$9:$I$18,1,0)),0,1)*F40 -> 0 | K40: =IF(ISERROR(VLOOKUP($C40,$I$9:$I$18,1,0)),0,1)*G40 -> 0 | L40: =SUM(I40:K40) -> 0
C41: ='CF (Equity, Debt)'!C23 -> Endless Studios LLC | D41: ='CF (Equity, Debt)'!D23 -> 44494 | E41: ='CF (Equity, Debt)'!E23 -> -3 | I41: =IF(ISERROR(VLOOKUP($C41,$I$9:$I$18,1,0)),0,1)*E41 -> -3 | J41: =IF(ISERROR(VLOOKUP($C41,$I$9:$I$18,1,0)),0,1)*F41 -> 0 | K41: =IF(ISERROR(VLOOKUP($C41,$I$9:$I$18,1,0)),0,1)*G41 -> 0 | L41: =SUM(I41:K41) -> -3
C42: ='CF (Equity, Debt)'!C24 -> Instadeep Limited | D42: ='CF (Equity, Debt)'!D24 -> 44550 | E42: ='CF (Equity, Debt)'!E24 -> -5.0237202 | I42: =IF(ISERROR(VLOOKUP($C42,$I$9:$I$18,1,0)),0,1)*E42 -> -5.0237202 | J42: =IF(ISERROR(VLOOKUP($C42,$I$9:$I$18,1,0)),0,1)*F42 -> 0 | K42: =IF(ISERROR(VLOOKUP($C42,$I$9:$I$18,1,0)),0,1)*G42 -> 0 | L42: =SUM(I42:K42) -> -5.0237202
C43: ='CF (Equity, Debt)'!C25 -> X-fusion | D43: ='CF (Equity, Debt)'!D25 -> 44574 | E43: ='CF (Equity, Debt)'!E25 -> -493.50096 | H43: =E43 -> -493.50096 | I43: =IF(ISERROR(VLOOKUP($C43,$I$9:$I$18,1,0)),0,1)*E43 -> 0 | J43: =IF(ISERROR(VLOOKUP($C43,$I$9:$I$18,1,0)),0,1)*F43 -> 0 | K43: =IF(ISERROR(VLOOKUP($C43,$I$9:$I$18,1,0)),0,1)*G43 -> 0 | L43: =SUM(I43:K43) -> 0
