Workbook
Name Company: [1]UEL!$B$18:$B$20
Name Dates: [1]ONT!$N$2:$AN$2
Name DetailedCapShares: '[2]Current Cap'!$T$133
Name FAGroup: [1]UEL!$B$3:$B$15
Name IQ_CH: 110000
Name IQ_CQ: 5000
Name IQ_CY: 10000
Name IQ_DAILY: 500000
Name IQ_FH: 100000
Name IQ_FQ: 500
Name IQ_FY: 1000
Name IQ_LTM: 2000
Name IQ_MONTH: 15000
Name IQ_NTM: 6000
Name IQ_WEEK: 50000
Name IQ_YTD: 3000

Sheet D
C2: Date of NAV | D2: 45016
H3: D A S H B O A R D | L3: figures in USD Millions
D6: # Investments | E6: Committed | F6: Invested | G6: Remaining | H6: Distributions | I6: Residual Value | J6: IRR | K6: TVPI | L6: RPI | M6: DPI
C8: EQUITY | D8: =COUNTIF('Summary | 01 '!C10:C27,"*") -> 17 | E8: ='1. IRR Equity'!AD29 -> 2093.0293 | F8: ='1. IRR Equity'!AE29 -> 2082.7762 | G8: ='1. IRR Equity'!AF29 -> 10.253161 | H8: ='1. IRR Equity'!AG29 -> 5 | I8: ='1. IRR Equity'!AH29 -> 2082.8141 | J8: ='1. IRR Equity'!AI29 -> 0.0019109696 | K8: ='1. IRR Equity'!AJ29 -> 1.0024189 | L8: ='1. IRR Equity'!AK29 -> 1.0000182 | M8: ='1. IRR Equity'!AL29 -> 0.002400642
C11: DEBT | D11: =COUNTIF('Summary | 01 '!C30:C32,"*") -> 3 | E11: ='2. IRR Debt'!Q12 -> 10.765747 | F11: ='2. IRR Debt'!R12 -> 10.765747 | G11: ='2. IRR Debt'!S12 -> 0 | H11: ='2. IRR Debt'!T12 -> 0.47078465 | I11: ='2. IRR Debt'!U12 -> 2.353982 | J11: ='2. IRR Debt'!V12 -> -0.35001702 | K11: ='2. IRR Debt'!W12 -> 0.26238464 | L11: ='2. IRR Debt'!X12 -> 0.21865478 | M11: ='2. IRR Debt'!Y12 -> 0.043729864
C14: FUNDS | D14: =COUNTIF('Summary | 01 '!C36:C40,"*") -> 5 | E14: ='3. IRR Funds'!Q15 -> 395.37629 | F14: ='3. IRR Funds'!R15 -> 133.65097 | G14: ='3. IRR Funds'!S15 -> 262.75328 | H14: ='3. IRR Funds'!T15 -> 4.4275637 | I14: ='3. IRR Funds'!U15 -> 122.28936 | J14: ='3. IRR Funds'!V15 -> -0.02269576 | K14: ='3. IRR Funds'!W15 -> 0.94811825 | L14: ='3. IRR Funds'!X15 -> 0.91499044 | M14: ='3. IRR Funds'!Y15 -> 0.033127807
C17: TOTAL | D17: =D8+D11+D14 -> 25 | E17: =E8+E11+E14 -> 2499.1714 | F17: =F8+F11+F14 -> 2227.1929 | G17: =G8+G11+G14 -> 273.00644 | H17: =H8+H11+H14 -> 9.8983484 | I17: =I8+I11+I14 -> 2207.4575 | J17: ='4.All'!N9 -> -0.0033056326 | K17: =(H17+I17)/F17 -> 0.99558319 | L17: =I17/F17 -> 0.99113887 | M17: =H17/F17 -> 0.0044443157
E19: =E17='Summary | 01 '!J43 -> FALSE | F19: =F17='Summary | 01 '!K43 -> TRUE | G19: =ROUND(G17,1)=ROUND('Summary | 01 '!L43,1) -> FALSE | H19: =ROUND(H17,1)=ROUND('Summary | 01 '!M43,1) -> TRUE | I19: =ROUND(I17,1)=ROUND('Summary | 01 '!N43,1) -> TRUE

Sheet Summary | 01 
C2: As of date | D2: =D!D2 -> 45016
C6: Deals | D6: Status | E6: Lead | F6: Investing Entity | G6: Vintageἀ | H6: Instrument | I6: % | J6: Committed | K6: Invested | L6: Remaining Commitment | M6: Distributions | N6: Carrying Value | O6: Gain | P6: TVPI | Q6: IRRβ | R6: Additonal Upside
G7: # | I7: % | J7: $,m | K7: $,m | L7: $,m | M7: $,m | N7: $,m | O7: $,m | P7: X | Q7: %
C9: Direct Investments
C10: Jollychic Holding Limited | D10: In Liquidation | E10: Elaine | F10: Mozn | G10: 2019 | H10: C+ Prefs | I10: ='7. %'!F10 -> 0.056999998 | J10: 65 | K10: =-SUMIF('CF (Equity, Debt)'!$C$3:$K$35,'Summary | 01 '!C10,'CF (Equity, Debt)'!$E$3:$E$35) -> 65 | L10: 0 | M10: =SUMIF('CF (Equity, Debt)'!$C$3:$K$35,'Summary | 01 '!C10,'CF (Equity, Debt)'!$F$3:$F$35) -> 0 | N10: =VLOOKUP(C10,NAV!$B$4:$E$42,4,0) -> 0 | O10: =N10+M10-K10 -> -65 | P10: =(M10+N10)/K10 -> 0 | Q10: =VLOOKUP(C10,'1. IRR Equity'!$AC$12:$AL$28,7,0) -> NM
C11: Mena Mobile Inc | D11: Unrealized | E11: Elaine | F11: Mozn | G11: 2019 | H11: B Prefs | I11: ='7. %'!F11 -> 0.14 | J11: 8 | K11: =-SUMIF('CF (Equity, Debt)'!$C$3:$K$35,'Summary | 01 '!C11,'CF (Equity, Debt)'!$E$3:$E$35) -> 8 | L11: 0 | M11: =SUMIF('CF (Equity, Debt)'!$C$3:$K$35,'Summary | 01 '!C11,'CF (Equity, Debt)'!$F$3:$F$35) -> 0 | N11: =VLOOKUP(C11,NAV!$B$4:$E$42,4,0) -> 3.1 | O11: =N11+M11-K11 -> -4.9 | P11: =(M11+N11)/K11 -> 0.3875 | Q11: =VLOOKUP(C11,'1. IRR Equity'!$AC$12:$AL$28,7,0) -> -0.21191685
C12: Flyr Inc | D12: Unrealized | E12: Sushil | F12: Mozn | G12: 2019 | H12: B-1,2 Prefs | I12: ='7. %'!F12 -> 0.085025485 | J12: 10 | K12: =-SUMIF('CF (Equity, Debt)'!$C$3:$K$35,'Summary | 01 '!C12,'CF (Equity, Debt)'!$E$3:$E$35) -> 10 | L12: 0 | M12: =SUMIF('CF (Equity, Debt)'!$C$3:$K$35,'Summary | 01 '!C12,'CF (Equity, Debt)'!$F$3:$F$35) -> 0 | N12: =VLOOKUP(C12,NAV!$B$4:$E$42,4,0) -> 78.08223 | O12: =N12+M12-K12 -> 68.08223 | P12: =(M12+N12)/K12 -> 7.808223 | Q12: =VLOOKUP(C12,'1. IRR Equity'!$AC$12:$AL$28,7,0) -> 0.7832873 | R12: Flyr Warrantsa
C13: Esyasoft Holding | D13: Realized | E13: Sushil | F13: Mozn | G13: 2020 | H13: Convertible Note | I13: ='7. %'!F13 -> n/a | J13: 2.5 | K13: =-SUMIF('CF (Equity, Debt)'!$C$3:$K$35,'Summary | 01 '!C13,'CF (Equity, Debt)'!$E$3:$E$35) -> 2.5 | L13: 0 | M13: =SUMIF('CF (Equity, Debt)'!$C$3:$K$35,'Summary | 01 '!C13,'CF (Equity, Debt)'!$F$3:$F$35) -> 5 | N13: =VLOOKUP(C13,NAV!$B$4:$E$42,4,0) -> 0 | O13: =N13+M13-K13 -> 2.5 | P13: =(M13+N13)/K13 -> 2 | Q13: =VLOOKUP(C13,'1. IRR Equity'!$AC$12:$AL$28,7,0) -> 0.36091766
C14: Beyond Limits | D14: Unrealized | E14: Divyesh | F14: Mozn | G14: 2020 | H14: C Prefs | I14: ='7. %'!F14 -> 0.09739482 | J14: 90 | K14: =-SUMIF('CF (Equity, Debt)'!$C$3:$K$35,'Summary | 01 '!C14,'CF (Equity, Debt)'!$E$3:$E$35) -> 90 | L14: 0 | M14: =SUMIF('CF (Equity, Debt)'!$C$3:$K$35,'Summary | 01 '!C14,'CF (Equity, Debt)'!$F$3:$F$35) -> 0 | N14: =VLOOKUP(C14,NAV!$B$4:$E$42,4,0) -> 91.00154 | O14: =N14+M14-K14 -> 1.0015403 | P14: =(M14+N14)/K14 -> 1.0111282 | Q14: =VLOOKUP(C14,'1. IRR Equity'!$AC$12:$AL$28,7,0) -> 0.0038127035
C15: ONT plc | D15: Unrealized | E15: Divyesh | F15: Mozn | G15: 2020 | H15: Ordinary Shares | I15: ='7. %'!F15 -> 0.053819975 | J15: 141.47026 | K15: =-SUMIF('CF (Equity, Debt)'!$C$3:$K$35,'Summary | 01 '!C15,'CF (Equity, Debt)'!$E$3:$E$35) -> 141.47026 | L15: 0 | M15: =SUMIF('CF (Equity, Debt)'!$C$3:$K$35,'Summary | 01 '!C15,'CF (Equity, Debt)'!$F$3:$F$35) -> 0 | N15: =VLOOKUP(C15,NAV!$B$4:$E$42,4,0) -> 122.38019 | O15: =N15+M15-K15 -> -19.090073 | P15: =(M15+N15)/K15 -> 0.86505946 | Q15: =VLOOKUP(C15,'1. IRR Equity'!$AC$12:$AL$28,7,0) -> -0.050375113
C16: Heygears | D16: Unrealized | E16: Elaine | F16: Mozn | G16: 2020 | H16: Registered Capital | I16: ='7. %'!F16 -> 0.1438 | J16: 60 | K16: =-SUMIF('CF (Equity, Debt)'!$C$3:$K$35,'Summary | 01 '!C16,'CF (Equity, Debt)'!$E$3:$E$35) -> 60 | L16: 0 | M16: =SUMIF('CF (Equity, Debt)'!$C$3:$K$35,'Summary | 01 '!C16,'CF (Equity, Debt)'!$F$3:$F$35) -> 0 | N16: =VLOOKUP(C16,NAV!$B$4:$E$42,4,0) -> 119.2498 | O16: =N16+M16-K16 -> 59.249804 | P16: =(M16+N16)/K16 -> 1.9874967 | Q16: =VLOOKUP(C16,'1. IRR Equity'!$AC$12:$AL$28,7,0) -> 0.34306269
C17: Jysan Technologies | D17: Unrealized | E17: Sushil | F17: Mozn 1 | G17: 2021 | H17: A (Ordinary Shares) | I17: ='7. %'!F17 -> 0.03 | J17: 20 | K17: =-SUMIF('CF (Equity, Debt)'!$C$3:$K$35,'Summary | 01 '!C17,'CF (Equity, Debt)'!$E$3:$E$35) -> 20 | L17: 0 | M17: =SUMIF('CF (Equity, Debt)'!$C$3:$K$35,'Summary | 01 '!C17,'CF (Equity, Debt)'!$F$3:$F$35) -> 0 | N17: =VLOOKUP(C17,NAV!$B$4:$E$42,4,0) -> 20 | O17: =N17+M17-K17 -> 0 | P17: =(M17+N17)/K17 -> 1 | Q17: =VLOOKUP(C17,'1. IRR Equity'!$AC$12:$AL$28,7,0) -> 2.9802322e-09
C18: Cerebras Systems Inc | D18: Unrealized | E18: Ignasi | F18: Mozn | G18: 2021 | H18: F Prefs | I18: ='7. %'!F18 -> 0.01 | J18: 40 | K18: =-SUMIF('CF (Equity, Debt)'!$C$3:$K$35,'Summary | 01 '!C18,'CF (Equity, Debt)'!$E$3:$E$35) -> 39.999983 | L18: 0 | M18: =SUMIF('CF (Equity, Debt)'!$C$3:$K$35,'Summary | 01 '!C18,'CF (Equity, Debt)'!$F$3:$F$35) -> 0 | N18: =VLOOKUP(C18,NAV!$B$4:$E$42,4,0) -> 39.999983 | O18: =N18+M18-K18 -> 0 | P18: =(M18+N18)/K18 -> 1 | Q18: =VLOOKUP(C18,'1. IRR Equity'!$AC$12:$AL$28,7,0) -> 2.9802322e-09
C19: Endless Studios LLC | D19: Unrealized | E19: Sushil | F19: Mozn | G19: 2021 | H19: A Pref Units | I19: ='7. %'!F19 -> 0.068571429 | J19: 3 | K19: =-SUMIF('CF (Equity, Debt)'!$C$3:$K$35,'Summary | 01 '!C19,'CF (Equity, Debt)'!$E$3:$E$35) -> 3 | L19: 0 | M19: =SUMIF('CF (Equity, Debt)'!$C$3:$K$35,'Summary | 01 '!C19,'CF (Equity, Debt)'!$F$3:$F$35) -> 0 | N19: =VLOOKUP(C19,NAV!$B$4:$E$42,4,0) -> 3 | O19: =N19+M19-K19 -> 0 | P19: =(M19+N19)/K19 -> 1 | Q19: =VLOOKUP(C19,'1. IRR Equity'!$AC$12:$AL$28,7,0) -> 2.9802322e-09
C20: Instadeep Limited | D20: To be Exited | E20: Ignasi | F20: Mozn | G20: 2021 | H20: B Prefs | I20: ='7. %'!F20 -> 0.011489406 | J20: 5.0278212 | K20: =-SUMIF('CF (Equity, Debt)'!$C$3:$K$35,'Summary | 01 '!C20,'CF (Equity, Debt)'!$E$3:$E$35) -> 5.0237202 | L20: 0 | M20: =SUMIF('CF (Equity, Debt)'!$C$3:$K$35,'Summary | 01 '!C20,'CF (Equity, Debt)'!$F$3:$F$35) -> 0 | N20: =VLOOKUP(C20,NAV!$B$4:$E$42,4,0) -> 5.0237202 | O20: =N20+M20-K20 -> 0 | P20: =(M20+N20)/K20 -> 1 | Q20: =VLOOKUP(C20,'1. IRR Equity'!$AC$12:$AL$28,7,0) -> 2.9802322e-09
C21: X-fusion | D21: Unrealized | E21: Elaine | F21: Mozn 2 | G21: 2022 | H21: Equity-TBC | I21: ='7. %'!F21 -> 0.05 | J21: 493.5 | K21: =-SUMIF('CF (Equity, Debt)'!$C$3:$K$35,'Summary | 01 '!C21,'CF (Equity, Debt)'!$E$3:$E$35) -> 493.50096 | L21: 0 | M21: =SUMIF('CF (Equity, Debt)'!$C$3:$K$35,'Summary | 01 '!C21,'CF (Equity, Debt)'!$F$3:$F$35) -> 0 | N21: =VLOOKUP(C21,NAV!$B$4:$E$42,4,0) -> 424.06662 | O21: =N21+M21-K21 -> -69.434338 | P21: =(M21+N21)/K21 -> 0.85930253 | Q21: =VLOOKUP(C21,'1. IRR Equity'!$AC$12:$AL$28,7,0) -> NM
C22: DriveNets | D22: Unrealized | E22: Anton | F22: G42 | G22: 2022 | H22: Equity-TBC | I22: ='7. %'!F22 -> 0.0943 | J22: 300 | K22: =-SUMIF('CF (Equity, Debt)'!$C$3:$K$35,'Summary | 01 '!C22,'CF (Equity, Debt)'!$E$3:$E$35) -> 300 | L22: =0 -> 0 | M22: =SUMIF('CF (Equity, Debt)'!$C$3:$K$35,'Summary | 01 '!C22,'CF (Equity, Debt)'!$F$3:$F$35) -> 0 | N22: =VLOOKUP(C22,NAV!$B$4:$E$42,4,0) -> 300 | O22: =N22+M22-K22 -> 0 | P22: =(M22+N22)/K22 -> 1 | Q22: =VLOOKUP(C22,'1. IRR Equity'!$AC$12:$AL$28,7,0) -> NM | R22: DN Warrants b
C23: vTv Therapeutics Inc. | D23: Unrealized | E23: Divyesh | F23: G42 | G23: 2022 | H23: Ordinary Shares | I23: ='7. %'!F23 -> 0.099316564 | J23: =K23 -> 24.53125 | K23: =-SUMIF('CF (Equity, Debt)'!$C$3:$K$35,'Summary | 01 '!C23,'CF (Equity, Debt)'!$E$3:$E$35) -> 24.53125 | L23: =J23-K23 -> 0 | M23: =SUMIF('CF (Equity, Debt)'!$C$3:$K$35,'Summary | 01 '!C23,'CF (Equity, Debt)'!$F$3:$F$35) -> 0 | N23: =VLOOKUP(C23,NAV!$B$4:$E$42,4,0) -> 8.3900321 | O23: =N23+M23-K23 -> -16.141218 | P23: =(M23+N23)/K23 -> 0.34201405 | Q23: =VLOOKUP(C23,'1. IRR Equity'!$AC$12:$AL$28,7,0) -> NM | R23: vTv $30m milestn payment c
C24: Honor Device Co Ltd | D24: Unrealized | E24: Elaine | F24: G42 3 | G24: 2022 | H24: Equity-TBC | I24: ='7. %'!F24 -> 0.018823528 | J24: =K24 -> 800 | K24: =-SUMIF('CF (Equity, Debt)'!$C$3:$K$35,'Summary | 01 '!C24,'CF (Equity, Debt)'!$E$3:$E$35) -> 800 | L24: =J24-K24 -> 0 | M24: =SUMIF('CF (Equity, Debt)'!$C$3:$K$35,'Summary | 01 '!C24,'CF (Equity, Debt)'!$F$3:$F$35) -> 0 | N24: =VLOOKUP(C24,NAV!$B$4:$E$42,4,0) -> 848.76999 | O24: =N24+M24-K24 -> 48.76999 | P24: =(M24+N24)/K24 -> 1.0609625 | Q24: =VLOOKUP(C24,'1. IRR Equity'!$AC$12:$AL$28,7,0) -> NM
C25: Applied AI Corporation Limited | D25: Unrealized | E25: Anton | F25: Mozn | G25: 2022 | H25: Convertible Note | I25: n/a | J25: 15 | K25: 4.75 | L25: =J25-K25 -> 10.25 | M25: 0 | N25: =VLOOKUP(C25,NAV!$B$4:$E$42,4,0) -> 4.75 | O25: =N25+M25-K25 -> 0 | P25: =(M25+N25)/K25 -> 1 | Q25: =VLOOKUP(C25,'1. IRR Equity'!$AC$12:$AL$28,7,0) -> NM
C26: eSpace | D26: Unrealized | E26: Anton | F26: Mozn 4 | G26: 2022 | H26: SAFE note | I26: n/a | J26: 15 | K26: 15 | L26: =J26-K26 -> 0 | M26: 0 | N26: =VLOOKUP(C26,NAV!$B$4:$E$42,4,0) -> 15 | O26: =N26+M26-K26 -> 0 | P26: =(M26+N26)/K26 -> 1 | Q26: =VLOOKUP(C26,'1. IRR Equity'!$AC$12:$AL$28,7,0) -> NM
J27: =SUM(J10:J26) -> 2093.0293 | K27: =SUM(K10:K26) -> 2082.7762 | L27: =SUM(L10:L26) -> 10.25 | M27: =SUM(M10:M26) -> 5 | N27: =SUM(N10:N26) -> 2082.8141 | O27: =SUM(O10:O26) -> 5.0379353 | P27: =(M27+N27)/K27 -> 1.0024189 | Q27: ='1. IRR Equity'!AD35 -> 0.0019109696
C29: Debt Investments
C30: Glass Earth Holdings LLC | D30: In default | E30: Marty | F30: Mozn | G30: 2019 | H30: Promissory Note | I30: n/a | J30: 8 | K30: 8 | L30: 0 | M30: 0 | N30: 0 | O30: =N30+M30-K30 -> -8 | P30: =(M30+N30)/K30 -> 0 | Q30: =VLOOKUP(C30,'2. IRR Debt'!$P$9:$Y$11,7,0) -> NM
C31: Mena Mobile Inc (Debt) | D31: Unrealized | E31: Elaine | F31: Mozn | G31: 2021 | H31: Loan | I31: n/a | J31: 2.353982 | K31: =J31 -> 2.353982 | L31: 0 | M31: 0 | N31: =K31 -> 2.353982 | O31: =N31+M31-K31 -> 0 | P31: =(M31+N31)/K31 -> 1 | Q31: =VLOOKUP(C31,'2. IRR Debt'!$P$9:$Y$11,7,0) -> 2.9802322e-09
C32: Esyasoft Holding (Debt) | D32: Realized | E32: Sushil | F32: Mozn | G32: 2021 | H32: Loan | I32: n/a | J32: 0.411765 | K32: 0.411765 | L32: 0 | M32: ='CF (Equity, Debt)'!F40 -> 0.47078465 | N32: 0 | O32: =N32+M32-K32 -> 0.05901965 | P32: =(M32+N32)/K32 -> 1.1433333 | Q32: =VLOOKUP(C32,'2. IRR Debt'!$P$9:$Y$11,7,0) -> 0.075277027
J33: =SUM(J30:J32) -> 10.765747 | K33: =SUM(K30:K32) -> 10.765747 | L33: =SUM(L30:L32) -> 0 | M33: =SUM(M30:M32) -> 0.47078465 | N33: =SUM(N30:N32) -> 2.353982 | O33: =N33+M33-K33 -> -7.9409804 | P33: =(M33+N33)/K33 -> 0.26238464 | Q33: ='2. IRR Debt'!Q15 -> -0.35001702
C35: Funds Investments
C36: New Space Capital Fund I | D36: Unrealized | E36: Sushil | F36: G42 | G36: 2020 | H36: LP | I36: n/a | J36: =K36+L36 -> 28.098225 | K36: =-SUM('CF (Funds)'!D31:D37) -> 11.058035 | L36: =NAV!P33 -> 17.040191 | M36: =SUM('CF (Funds)'!E31:E37) -> 2.9557744 | N36: =VLOOKUP(C36,NAV!$B$4:$E$42,4,0) -> 14.294891 | O36: =N36+M36-K36 -> 6.1926309 | P36: 1.4784783 | Q36: =VLOOKUP(C36,'3. IRR Funds'!$P$7:$Y$15,7,0) -> 0.1090443
C37: New Space Capital SCSp | D37: Unrealized | E37: Sushil | F37: G42 | G37: 2020 | H37: GP | I37: n/a | J37: =2.3/0.85 -> 2.7058824 | K37: 2.7058824 | L37: 0 | M37: 0 | N37: =VLOOKUP(C37,NAV!$B$4:$E$42,4,0) -> 2.7058824 | O37: =N37+M37-K37 -> 0 | P37: 1 | Q37: =VLOOKUP(C37,'3. IRR Funds'!$P$7:$Y$15,7,0) -> 0
C38: North Summit Capital Fund | D38: Unrealized | E38: Elaine | F38: G42 | G38: 2020 | H38: LP | I38: n/a | J38: 300 | K38: 83.214653 | L38: 217.81331 | M38: 1.027961 | N38: =VLOOKUP(C38,NAV!$B$4:$E$42,4,0) -> 70.03 | O38: =N38+M38-K38 -> -12.156692 | P38: 0.96555063 | Q38: =VLOOKUP(C38,'3. IRR Funds'!$P$7:$Y$15,7,0) -> -0.064168629
C39: Sinovation Disrupt Fund, L.P. | D39: Unrealized | E39: Elaine | F39: G42 | G39: 2020 | H39: LP | I39: n/a | J39: 50 | K39: =-SUM('CF (Funds)'!D3:D16) -> 22.657267 | L39: =J39-K39 -> 27.342733 | M39: 0.44382835 | N39: =VLOOKUP(C39,NAV!$B$4:$E$42,4,0) -> 21.51575 | O39: =N39+M39-K39 -> -0.69768865 | P39: 0.97193724 | Q39: =VLOOKUP(C39,'3. IRR Funds'!$P$7:$Y$15,7,0) -> -0.018159524
C40: Acies Investments Fund I, L.P. | D40: Unrealized | E40: Divyesh | F40: G42 | G40: 2021 | H40: LP | I40: 0.33 | J40: 17.1125 | K40: 14.015137 | L40: =J40-K40 -> 3.0973625 | M40: 0 | N40: =VLOOKUP(C40,NAV!$B$4:$E$42,4,0) -> 13.742841 | O40: =N40+M40-K40 -> -0.2722965 | P40: 0.97333028 | Q40: =VLOOKUP(C40,'3. IRR Funds'!$P$7:$Y$15,7,0) -> -0.021553859 | R40: 9.9% GP | Anchor
J41: =SUM(J36:J40) -> 397.91661 | K41: =SUM(K36:K40) -> 133.65097 | L41: =SUM(L36:L40) -> 265.29359 | M41: =SUM(M36:M40) -> 4.4275637 | N41: =SUM(N36:N40) -> 122.28936 | O41: =N41+M41-K41 -> -6.9340462 | P41: =(M41+N41)/K41 -> 0.94811825 | Q41: ='3. IRR Funds'!Q18 -> -0.02269576
C43: Total | J43: =J27+J33+J41 -> 2501.7117 | K43: =K27+K33+K41 -> 2227.1929 | L43: =L27+L33+L41 -> 275.54359 | M43: =M27+M33+M41 -> 9.8983484 | N43: =N27+N33+N41 -> 2207.4575 | O43: =N43+M43-K43 -> -9.8370913 | P43: =(M43+N43)/K43 -> 0.99558319 | Q43: ='4.All'!N9 -> -0.0033056326
K44: =ROUND(K43,2)=ROUND('4.All'!J9,2) -> TRUE | M44: =ROUND(M43,2)=ROUND('4.All'!L9,2) -> TRUE | N44: =ROUND(N43,2)=ROUND('4.All'!M9,2) -> TRUE
C46: Additional Upside Section:
C47: a) Flyr: For every $1m of revenue, 194,477 shares, capped at 1,264,1000 (B-1) shares shall be issued to Mozn
C48: b) DriveNets: Share warrants exercisable upon the achievement of target revenue of clients referred by G42, and corresponding milestones
C49: c) vTv Therapeutics: Potential issuance of $30m in additional shares, if FDA approval received for the drug TTP399
...

Sheet S | 02
C2: As of date | E2: =D!D2 -> 45016
E5: 2 | F5: 3 | G5: 4 | H5: 5 | I5: 6 | J5: 7 | K5: 8 | L5: 9 | M5: 11 | N5: 12 | O5: 13 | Q5: 15 | R5: 14 | S5: 10
C6: Deals | D6: Type | E6: Status | F6: Lead | G6: Investing Entity | H6: Vintageἀ | I6: Instrument | J6: % | K6: Committed | L6: Invested | M6: Distributions | N6: Carrying Value | O6: Gain | P6: Gain FY21 | Q6: IRRβ | R6: TVPI | S6: Remaining Commitment | T6: Additonal Upside
I7: # | J7: % | K7: $,m | L7: $,m | M7: $,m | N7: $,m | O7: $,m | Q7: % | R7: X | S7: $,m | W7: MOZN
C9: eSpace | D9: Direct Investment | E9: =VLOOKUP($C9,'Summary | 01 '!$C$6:$R$43,E$5,0) -> Unrealized | F9: =VLOOKUP($C9,'Summary | 01 '!$C$6:$R$43,F$5,0) -> Anton | G9: =VLOOKUP($C9,'Summary | 01 '!$C$6:$R$43,G$5,0) -> Mozn 4 | H9: =VLOOKUP($C9,'Summary | 01 '!$C$6:$R$43,H$5,0) -> 2022 | I9: =VLOOKUP($C9,'Summary | 01 '!$C$6:$R$43,I$5,0) -> SAFE note | J9: =VLOOKUP($C9,'Summary | 01 '!$C$6:$R$43,J$5,0) -> n/a | K9: =VLOOKUP($C9,'Summary | 01 '!$C$6:$R$43,K$5,0) -> 15 | L9: =VLOOKUP($C9,'Summary | 01 '!$C$6:$R$43,L$5,0) -> 15 | ... O9: =VLOOKUP($C9,'Summary | 01 '!$C$6:$R$43,O$5,0) -> 0 | P9: n/a | Q9: =VLOOKUP($C9,'Summary | 01 '!$C$6:$R$43,Q$5,0) -> NM | R9: =VLOOKUP($C9,'Summary | 01 '!$C$6:$R$43,R$5,0) -> 1 | S9: =VLOOKUP($C9,'Summary | 01 '!$C$6:$R$43,S$5,0) -> 0 | W9: Invested | X9: =L27 -> 969.01067
C10: Applied AI Corporation Limited | D10: Direct Investment | E10: =VLOOKUP($C10,'Summary | 01 '!$C$6:$R$43,E$5,0) -> Unrealized | F10: =VLOOKUP($C10,'Summary | 01 '!$C$6:$R$43,F$5,0) -> Anton | G10: =VLOOKUP($C10,'Summary | 01 '!$C$6:$R$43,G$5,0) -> Mozn | H10: =VLOOKUP($C10,'Summary | 01 '!$C$6:$R$43,H$5,0) -> 2022 | I10: =VLOOKUP($C10,'Summary | 01 '!$C$6:$R$43,I$5,0) -> Convertible Note | J10: =VLOOKUP($C10,'Summary | 01 '!$C$6:$R$43,J$5,0) -> n/a | K10: =VLOOKUP($C10,'Summary | 01 '!$C$6:$R$43,K$5,0) -> 15 | L10: =VLOOKUP($C10,'Summary | 01 '!$C$6:$R$43,L$5,0) -> 4.75 | ... O10: =VLOOKUP($C10,'Summary | 01 '!$C$6:$R$43,O$5,0) -> 0 | P10: n/a | Q10: =VLOOKUP($C10,'Summary | 01 '!$C$6:$R$43,Q$5,0) -> NM | R10: =VLOOKUP($C10,'Summary | 01 '!$C$6:$R$43,R$5,0) -> 1 | S10: =VLOOKUP($C10,'Summary | 01 '!$C$6:$R$43,S$5,0) -> 10.25 | W10: NAV | X10: =N27 -> 928.00806
C11: X-fusion | D11: Direct Investment | E11: =VLOOKUP($C11,'Summary | 01 '!$C$6:$R$43,E$5,0) -> Unrealized | F11: =VLOOKUP($C11,'Summary | 01 '!$C$6:$R$43,F$5,0) -> Elaine | G11: =VLOOKUP($C11,'Summary | 01 '!$C$6:$R$43,G$5,0) -> Mozn 2 | H11: =VLOOKUP($C11,'Summary | 01 '!$C$6:$R$43,H$5,0) -> 2022 | I11: =VLOOKUP($C11,'Summary | 01 '!$C$6:$R$43,I$5,0) -> Equity-TBC | J11: =VLOOKUP($C11,'Summary | 01 '!$C$6:$R$43,J$5,0) -> 0.05 | K11: =VLOOKUP($C11,'Summary | 01 '!$C$6:$R$43,K$5,0) -> 493.5 | L11: =VLOOKUP($C11,'Summary | 01 '!$C$6:$R$43,L$5,0) -> 493.50096 | ... O11: =VLOOKUP($C11,'Summary | 01 '!$C$6:$R$43,O$5,0) -> -69.434338 | P11: n/a | Q11: =VLOOKUP($C11,'Summary | 01 '!$C$6:$R$43,Q$5,0) -> NM | R11: =VLOOKUP($C11,'Summary | 01 '!$C$6:$R$43,R$5,0) -> 0.85930253 | S11: =VLOOKUP($C11,'Summary | 01 '!$C$6:$R$43,S$5,0) -> 0 | W11: Gain | X11: =O27 -> -35.531817
C12: Mena Mobile Inc (Debt) | D12: Debt Investment | E12: =VLOOKUP($C12,'Summary | 01 '!$C$6:$R$43,E$5,0) -> Unrealized | F12: =VLOOKUP($C12,'Summary | 01 '!$C$6:$R$43,F$5,0) -> Elaine | G12: =VLOOKUP($C12,'Summary | 01 '!$C$6:$R$43,G$5,0) -> Mozn | H12: =VLOOKUP($C12,'Summary | 01 '!$C$6:$R$43,H$5,0) -> 2021 | I12: =VLOOKUP($C12,'Summary | 01 '!$C$6:$R$43,I$5,0) -> Loan | J12: =VLOOKUP($C12,'Summary | 01 '!$C$6:$R$43,J$5,0) -> n/a | K12: =VLOOKUP($C12,'Summary | 01 '!$C$6:$R$43,K$5,0) -> 2.353982 | L12: =VLOOKUP($C12,'Summary | 01 '!$C$6:$R$43,L$5,0) -> 2.353982 | ... O12: =VLOOKUP($C12,'Summary | 01 '!$C$6:$R$43,O$5,0) -> 0 | P12: 0 | Q12: =VLOOKUP($C12,'Summary | 01 '!$C$6:$R$43,Q$5,0) -> 2.9802322e-09 | R12: =VLOOKUP($C12,'Summary | 01 '!$C$6:$R$43,R$5,0) -> 1 | S12: =VLOOKUP($C12,'Summary | 01 '!$C$6:$R$43,S$5,0) -> 0 | W12: YTD Gains | X12: =X11-227.4 -> -262.93182
C13: Esyasoft Holding (Debt) | D13: Debt Investment | E13: =VLOOKUP($C13,'Summary | 01 '!$C$6:$R$43,E$5,0) -> Realized | F13: =VLOOKUP($C13,'Summary | 01 '!$C$6:$R$43,F$5,0) -> Sushil | G13: =VLOOKUP($C13,'Summary | 01 '!$C$6:$R$43,G$5,0) -> Mozn | H13: =VLOOKUP($C13,'Summary | 01 '!$C$6:$R$43,H$5,0) -> 2021 | I13: =VLOOKUP($C13,'Summary | 01 '!$C$6:$R$43,I$5,0) -> Loan | J13: =VLOOKUP($C13,'Summary | 01 '!$C$6:$R$43,J$5,0) -> n/a | K13: =VLOOKUP($C13,'Summary | 01 '!$C$6:$R$43,K$5,0) -> 0.411765 | L13: =VLOOKUP($C13,'Summary | 01 '!$C$6:$R$43,L$5,0) -> 0.411765 | ... O13: =VLOOKUP($C13,'Summary | 01 '!$C$6:$R$43,O$5,0) -> 0.05901965 | P13: 0 | Q13: =VLOOKUP($C13,'Summary | 01 '!$C$6:$R$43,Q$5,0) -> 0.075277027 | R13: =VLOOKUP($C13,'Summary | 01 '!$C$6:$R$43,R$5,0) -> 1.1433333 | S13: =VLOOKUP($C13,'Summary | 01 '!$C$6:$R$43,S$5,0) -> 0 | W13: IRR | X13: =Q27 -> -0.019320041
C14: Jysan Technologies | D14: Direct Investment | E14: =VLOOKUP($C14,'Summary | 01 '!$C$6:$R$43,E$5,0) -> Unrealized | F14: =VLOOKUP($C14,'Summary | 01 '!$C$6:$R$43,F$5,0) -> Sushil | G14: =VLOOKUP($C14,'Summary | 01 '!$C$6:$R$43,G$5,0) -> Mozn 1 | H14: =VLOOKUP($C14,'Summary | 01 '!$C$6:$R$43,H$5,0) -> 2021 | I14: =VLOOKUP($C14,'Summary | 01 '!$C$6:$R$43,I$5,0) -> A (Ordinary Shares) | J14: =VLOOKUP($C14,'Summary | 01 '!$C$6:$R$43,J$5,0) -> 0.03 | K14: =VLOOKUP($C14,'Summary | 01 '!$C$6:$R$43,K$5,0) -> 20 | L14: =VLOOKUP($C14,'Summary | 01 '!$C$6:$R$43,L$5,0) -> 20 | ... O14: =VLOOKUP($C14,'Summary | 01 '!$C$6:$R$43,O$5,0) -> 0 | P14: 0 | Q14: =VLOOKUP($C14,'Summary | 01 '!$C$6:$R$43,Q$5,0) -> 2.9802322e-09 | R14: =VLOOKUP($C14,'Summary | 01 '!$C$6:$R$43,R$5,0) -> 1 | S14: =VLOOKUP($C14,'Summary | 01 '!$C$6:$R$43,S$5,0) -> 0
C15: Instadeep Limited | D15: Direct Investment | E15: =VLOOKUP($C15,'Summary | 01 '!$C$6:$R$43,E$5,0) -> To be Exited | F15: =VLOOKUP($C15,'Summary | 01 '!$C$6:$R$43,F$5,0) -> Ignasi | G15: =VLOOKUP($C15,'Summary | 01 '!$C$6:$R$43,G$5,0) -> Mozn | H15: =VLOOKUP($C15,'Summary | 01 '!$C$6:$R$43,H$5,0) -> 2021 | I15: =VLOOKUP($C15,'Summary | 01 '!$C$6:$R$43,I$5,0) -> B Prefs | J15: =VLOOKUP($C15,'Summary | 01 '!$C$6:$R$43,J$5,0) -> 0.011489406 | K15: =VLOOKUP($C15,'Summary | 01 '!$C$6:$R$43,K$5,0) -> 5.0278212 | L15: =VLOOKUP($C15,'Summary | 01 '!$C$6:$R$43,L$5,0) -> 5.0237202 | ... O15: =VLOOKUP($C15,'Summary | 01 '!$C$6:$R$43,O$5,0) -> 0 | P15: 0 | Q15: =VLOOKUP($C15,'Summary | 01 '!$C$6:$R$43,Q$5,0) -> 2.9802322e-09 | R15: =VLOOKUP($C15,'Summary | 01 '!$C$6:$R$43,R$5,0) -> 1 | S15: =VLOOKUP($C15,'Summary | 01 '!$C$6:$R$43,S$5,0) -> 0
C16: Cerebras Systems Inc | D16: Direct Investment | E16: =VLOOKUP($C16,'Summary | 01 '!$C$6:$R$43,E$5,0) -> Unrealized | F16: =VLOOKUP($C16,'Summary | 01 '!$C$6:$R$43,F$5,0) -> Ignasi | G16: =VLOOKUP($C16,'Summary | 01 '!$C$6:$R$43,G$5,0) -> Mozn | H16: =VLOOKUP($C16,'Summary | 01 '!$C$6:$R$43,H$5,0) -> 2021 | I16: =VLOOKUP($C16,'Summary | 01 '!$C$6:$R$43,I$5,0) -> F Prefs | J16: =VLOOKUP($C16,'Summary | 01 '!$C$6:$R$43,J$5,0) -> 0.01 | K16: =VLOOKUP($C16,'Summary | 01 '!$C$6:$R$43,K$5,0) -> 40 | L16: =VLOOKUP($C16,'Summary | 01 '!$C$6:$R$43,L$5,0) -> 39.999983 | ... O16: =VLOOKUP($C16,'Summary | 01 '!$C$6:$R$43,O$5,0) -> 0 | P16: 0 | Q16: =VLOOKUP($C16,'Summary | 01 '!$C$6:$R$43,Q$5,0) -> 2.9802322e-09 | R16: =VLOOKUP($C16,'Summary | 01 '!$C$6:$R$43,R$5,0) -> 1 | S16: =VLOOKUP($C16,'Summary | 01 '!$C$6:$R$43,S$5,0) -> 0
C17: Endless Studios LLC | D17: Direct Investment | E17: =VLOOKUP($C17,'Summary | 01 '!$C$6:$R$43,E$5,0) -> Unrealized | F17: =VLOOKUP($C17,'Summary | 01 '!$C$6:$R$43,F$5,0) -> Sushil | G17: =VLOOKUP($C17,'Summary | 01 '!$C$6:$R$43,G$5,0) -> Mozn | H17: =VLOOKUP($C17,'Summary | 01 '!$C$6:$R$43,H$5,0) -> 2021 | I17: =VLOOKUP($C17,'Summary | 01 '!$C$6:$R$43,I$5,0) -> A Pref Units | J17: =VLOOKUP($C17,'Summary | 01 '!$C$6:$R$43,J$5,0) -> 0.068571429 | K17: =VLOOKUP($C17,'Summary | 01 '!$C$6:$R$43,K$5,0) -> 3 | L17: =VLOOKUP($C17,'Summary | 01 '!$C$6:$R$43,L$5,0) -> 3 | ... O17: =VLOOKUP($C17,'Summary | 01 '!$C$6:$R$43,O$5,0) -> 0 | P17: 0 | Q17: =VLOOKUP($C17,'Summary | 01 '!$C$6:$R$43,Q$5,0) -> 2.9802322e-09 | R17: =VLOOKUP($C17,'Summary | 01 '!$C$6:$R$43,R$5,0) -> 1 | S17: =VLOOKUP($C17,'Summary | 01 '!$C$6:$R$43,S$5,0) -> 0
C18: Esyasoft Holding | D18: Direct Investment | E18: =VLOOKUP($C18,'Summary | 01 '!$C$6:$R$43,E$5,0) -> Realized | F18: =VLOOKUP($C18,'Summary | 01 '!$C$6:$R$43,F$5,0) -> Sushil | G18: =VLOOKUP($C18,'Summary | 01 '!$C$6:$R$43,G$5,0) -> Mozn | H18: =VLOOKUP($C18,'Summary | 01 '!$C$6:$R$43,H$5,0) -> 2020 | I18: =VLOOKUP($C18,'Summary | 01 '!$C$6:$R$43,I$5,0) -> Convertible Note | J18: =VLOOKUP($C18,'Summary | 01 '!$C$6:$R$43,J$5,0) -> n/a | K18: =VLOOKUP($C18,'Summary | 01 '!$C$6:$R$43,K$5,0) -> 2.5 | L18: =VLOOKUP($C18,'Summary | 01 '!$C$6:$R$43,L$5,0) -> 2.5 | ... O18: =VLOOKUP($C18,'Summary | 01 '!$C$6:$R$43,O$5,0) -> 2.5 | P18: 2.5 | Q18: =VLOOKUP($C18,'Summary | 01 '!$C$6:$R$43,Q$5,0) -> 0.36091766 | R18: =VLOOKUP($C18,'Summary | 01 '!$C$6:$R$43,R$5,0) -> 2 | S18: =VLOOKUP($C18,'Summary | 01 '!$C$6:$R$43,S$5,0) -> 0
C19: Heygears | D19: Direct Investment | E19: =VLOOKUP($C19,'Summary | 01 '!$C$6:$R$43,E$5,0) -> Unrealized | F19: =VLOOKUP($C19,'Summary | 01 '!$C$6:$R$43,F$5,0) -> Elaine | G19: =VLOOKUP($C19,'Summary | 01 '!$C$6:$R$43,G$5,0) -> Mozn | H19: =VLOOKUP($C19,'Summary | 01 '!$C$6:$R$43,H$5,0) -> 2020 | I19: =VLOOKUP($C19,'Summary | 01 '!$C$6:$R$43,I$5,0) -> Registered Capital | J19: =VLOOKUP($C19,'Summary | 01 '!$C$6:$R$43,J$5,0) -> 0.1438 | K19: =VLOOKUP($C19,'Summary | 01 '!$C$6:$R$43,K$5,0) -> 60 | L19: =VLOOKUP($C19,'Summary | 01 '!$C$6:$R$43,L$5,0) -> 60 | ... O19: =VLOOKUP($C19,'Summary | 01 '!$C$6:$R$43,O$5,0) -> 59.249804 | P19: -39.7 | Q19: =VLOOKUP($C19,'Summary | 01 '!$C$6:$R$43,Q$5,0) -> 0.34306269 | R19: =VLOOKUP($C19,'Summary | 01 '!$C$6:$R$43,R$5,0) -> 1.9874967 | S19: =VLOOKUP($C19,'Summary | 01 '!$C$6:$R$43,S$5,0) -> 0
C20: Beyond Limits | D20: Direct Investment | E20: =VLOOKUP($C20,'Summary | 01 '!$C$6:$R$43,E$5,0) -> Unrealized | F20: =VLOOKUP($C20,'Summary | 01 '!$C$6:$R$43,F$5,0) -> Divyesh | G20: =VLOOKUP($C20,'Summary | 01 '!$C$6:$R$43,G$5,0) -> Mozn | H20: =VLOOKUP($C20,'Summary | 01 '!$C$6:$R$43,H$5,0) -> 2020 | I20: =VLOOKUP($C20,'Summary | 01 '!$C$6:$R$43,I$5,0) -> C Prefs | J20: =VLOOKUP($C20,'Summary | 01 '!$C$6:$R$43,J$5,0) -> 0.09739482 | K20: =VLOOKUP($C20,'Summary | 01 '!$C$6:$R$43,K$5,0) -> 90 | L20: =VLOOKUP($C20,'Summary | 01 '!$C$6:$R$43,L$5,0) -> 90 | ... O20: =VLOOKUP($C20,'Summary | 01 '!$C$6:$R$43,O$5,0) -> 1.0015403 | P20: 0 | Q20: =VLOOKUP($C20,'Summary | 01 '!$C$6:$R$43,Q$5,0) -> 0.0038127035 | R20: =VLOOKUP($C20,'Summary | 01 '!$C$6:$R$43,R$5,0) -> 1.0111282 | S20: =VLOOKUP($C20,'Summary | 01 '!$C$6:$R$43,S$5,0) -> 0
C21: ONT plc | D21: Direct Investment | E21: =VLOOKUP($C21,'Summary | 01 '!$C$6:$R$43,E$5,0) -> Unrealized | F21: =VLOOKUP($C21,'Summary | 01 '!$C$6:$R$43,F$5,0) -> Divyesh | G21: =VLOOKUP($C21,'Summary | 01 '!$C$6:$R$43,G$5,0) -> Mozn | H21: =VLOOKUP($C21,'Summary | 01 '!$C$6:$R$43,H$5,0) -> 2020 | I21: =VLOOKUP($C21,'Summary | 01 '!$C$6:$R$43,I$5,0) -> Ordinary Shares | J21: =VLOOKUP($C21,'Summary | 01 '!$C$6:$R$43,J$5,0) -> 0.053819975 | K21: =VLOOKUP($C21,'Summary | 01 '!$C$6:$R$43,K$5,0) -> 141.47026 | L21: =VLOOKUP($C21,'Summary | 01 '!$C$6:$R$43,L$5,0) -> 141.47026 | ... O21: =VLOOKUP($C21,'Summary | 01 '!$C$6:$R$43,O$5,0) -> -19.090073 | P21: 275.8 | Q21: =VLOOKUP($C21,'Summary | 01 '!$C$6:$R$43,Q$5,0) -> -0.050375113 | R21: =VLOOKUP($C21,'Summary | 01 '!$C$6:$R$43,R$5,0) -> 0.86505946 | S21: =VLOOKUP($C21,'Summary | 01 '!$C$6:$R$43,S$5,0) -> 0
C22: Flyr Inc | D22: Direct Investment | E22: =VLOOKUP($C22,'Summary | 01 '!$C$6:$R$43,E$5,0) -> Unrealized | F22: =VLOOKUP($C22,'Summary | 01 '!$C$6:$R$43,F$5,0) -> Sushil | G22: =VLOOKUP($C22,'Summary | 01 '!$C$6:$R$43,G$5,0) -> Mozn | H22: =VLOOKUP($C22,'Summary | 01 '!$C$6:$R$43,H$5,0) -> 2019 | I22: =VLOOKUP($C22,'Summary | 01 '!$C$6:$R$43,I$5,0) -> B-1,2 Prefs | J22: =VLOOKUP($C22,'Summary | 01 '!$C$6:$R$43,J$5,0) -> 0.085025485 | K22: =VLOOKUP($C22,'Summary | 01 '!$C$6:$R$43,K$5,0) -> 10 | L22: =VLOOKUP($C22,'Summary | 01 '!$C$6:$R$43,L$5,0) -> 10 | ... O22: =VLOOKUP($C22,'Summary | 01 '!$C$6:$R$43,O$5,0) -> 68.08223 | P22: 68.1 | Q22: =VLOOKUP($C22,'Summary | 01 '!$C$6:$R$43,Q$5,0) -> 0.7832873 | R22: =VLOOKUP($C22,'Summary | 01 '!$C$6:$R$43,R$5,0) -> 7.808223 | S22: =VLOOKUP($C22,'Summary | 01 '!$C$6:$R$43,S$5,0) -> 0 | T22: Flyr Warrantsa
C23: Mena Mobile Inc | D23: Direct Investment | E23: =VLOOKUP($C23,'Summary | 01 '!$C$6:$R$43,E$5,0) -> Unrealized | F23: =VLOOKUP($C23,'Summary | 01 '!$C$6:$R$43,F$5,0) -> Elaine | G23: =VLOOKUP($C23,'Summary | 01 '!$C$6:$R$43,G$5,0) -> Mozn | H23: =VLOOKUP($C23,'Summary | 01 '!$C$6:$R$43,H$5,0) -> 2019 | I23: =VLOOKUP($C23,'Summary | 01 '!$C$6:$R$43,I$5,0) -> B Prefs | J23: =VLOOKUP($C23,'Summary | 01 '!$C$6:$R$43,J$5,0) -> 0.14 | K23: =VLOOKUP($C23,'Summary | 01 '!$C$6:$R$43,K$5,0) -> 8 | L23: =VLOOKUP($C23,'Summary | 01 '!$C$6:$R$43,L$5,0) -> 8 | ... O23: =VLOOKUP($C23,'Summary | 01 '!$C$6:$R$43,O$5,0) -> -4.9 | P23: -6.3 | Q23: =VLOOKUP($C23,'Summary | 01 '!$C$6:$R$43,Q$5,0) -> -0.21191685 | R23: =VLOOKUP($C23,'Summary | 01 '!$C$6:$R$43,R$5,0) -> 0.3875 | S23: =VLOOKUP($C23,'Summary | 01 '!$C$6:$R$43,S$5,0) -> 0
C24: Glass Earth Holdings LLC | D24: Debt Investment | E24: =VLOOKUP($C24,'Summary | 01 '!$C$6:$R$43,E$5,0) -> In default | F24: =VLOOKUP($C24,'Summary | 01 '!$C$6:$R$43,F$5,0) -> Marty | G24: =VLOOKUP($C24,'Summary | 01 '!$C$6:$R$43,G$5,0) -> Mozn | H24: =VLOOKUP($C24,'Summary | 01 '!$C$6:$R$43,H$5,0) -> 2019 | I24: =VLOOKUP($C24,'Summary | 01 '!$C$6:$R$43,I$5,0) -> Promissory Note | J24: =VLOOKUP($C24,'Summary | 01 '!$C$6:$R$43,J$5,0) -> n/a | K24: =VLOOKUP($C24,'Summary | 01 '!$C$6:$R$43,K$5,0) -> 8 | L24: =VLOOKUP($C24,'Summary | 01 '!$C$6:$R$43,L$5,0) -> 8 | ... O24: =VLOOKUP($C24,'Summary | 01 '!$C$6:$R$43,O$5,0) -> -8 | P24: -8 | Q24: =VLOOKUP($C24,'Summary | 01 '!$C$6:$R$43,Q$5,0) -> NM | R24: =VLOOKUP($C24,'Summary | 01 '!$C$6:$R$43,R$5,0) -> 0 | S24: =VLOOKUP($C24,'Summary | 01 '!$C$6:$R$43,S$5,0) -> 0
C25: Jollychic Holding Limited | D25: Direct Investment | E25: =VLOOKUP($C25,'Summary | 01 '!$C$6:$R$43,E$5,0) -> In Liquidation | F25: =VLOOKUP($C25,'Summary | 01 '!$C$6:$R$43,F$5,0) -> Elaine | G25: =VLOOKUP($C25,'Summary | 01 '!$C$6:$R$43,G$5,0) -> Mozn | H25: =VLOOKUP($C25,'Summary | 01 '!$C$6:$R$43,H$5,0) -> 2019 | I25: =VLOOKUP($C25,'Summary | 01 '!$C$6:$R$43,I$5,0) -> C+ Prefs | J25: =VLOOKUP($C25,'Summary | 01 '!$C$6:$R$43,J$5,0) -> 0.056999998 | K25: =VLOOKUP($C25,'Summary | 01 '!$C$6:$R$43,K$5,0) -> 65 | L25: =VLOOKUP($C25,'Summary | 01 '!$C$6:$R$43,L$5,0) -> 65 | ... O25: =VLOOKUP($C25,'Summary | 01 '!$C$6:$R$43,O$5,0) -> -65 | P25: -65 | Q25: =VLOOKUP($C25,'Summary | 01 '!$C$6:$R$43,Q$5,0) -> NM | R25: =VLOOKUP($C25,'Summary | 01 '!$C$6:$R$43,R$5,0) -> 0 | S25: =VLOOKUP($C25,'Summary | 01 '!$C$6:$R$43,S$5,0) -> 0
K27: =SUM(K9:K25) -> 979.26383 | L27: =SUM(L9:L25) -> 969.01067 | M27: =SUM(M9:M25) -> 5.4707846 | N27: =SUM(N9:N25) -> 928.00806 | O27: =SUM(O9:O25) -> -35.531817 | P27: =SUM(P9:P26) -> 227.4 | Q27: ='4. Mozn-IRR'!L16 -> -0.019320041 | R27: =(M27+N27)/L27 -> 0.96333186 | S27: =SUM(S9:S25) -> 10.25 | T27: =N27+M27-L27 -> -35.531817
C29: Honor Device Co Ltd | D29: Direct Investment | E29: =VLOOKUP($C29,'Summary | 01 '!$C$6:$R$43,E$5,0) -> Unrealized | F29: =VLOOKUP($C29,'Summary | 01 '!$C$6:$R$43,F$5,0) -> Elaine | G29: =VLOOKUP($C29,'Summary | 01 '!$C$6:$R$43,G$5,0) -> G42 3 | H29: =VLOOKUP($C29,'Summary | 01 '!$C$6:$R$43,H$5,0) -> 2022 | I29: =VLOOKUP($C29,'Summary | 01 '!$C$6:$R$43,I$5,0) -> Equity-TBC | J29: =VLOOKUP($C29,'Summary | 01 '!$C$6:$R$43,J$5,0) -> 0.018823528 | K29: =VLOOKUP($C29,'Summary | 01 '!$C$6:$R$43,K$5,0) -> 800 | L29: =VLOOKUP($C29,'Summary | 01 '!$C$6:$R$43,L$5,0) -> 800 | ... O29: =VLOOKUP($C29,'Summary | 01 '!$C$6:$R$43,O$5,0) -> 48.76999 | P29: n/a | Q29: =VLOOKUP($C29,'Summary | 01 '!$C$6:$R$43,Q$5,0) -> NM | R29: =VLOOKUP($C29,'Summary | 01 '!$C$6:$R$43,R$5,0) -> 1.0609625 | S29: =VLOOKUP($C29,'Summary | 01 '!$C$6:$R$43,S$5,0) -> 0 | W29: G42
C30: DriveNets | D30: Direct Investment | E30: =VLOOKUP($C30,'Summary | 01 '!$C$6:$R$43,E$5,0) -> Unrealized | F30: =VLOOKUP($C30,'Summary | 01 '!$C$6:$R$43,F$5,0) -> Anton | G30: =VLOOKUP($C30,'Summary | 01 '!$C$6:$R$43,G$5,0) -> G42 | H30: =VLOOKUP($C30,'Summary | 01 '!$C$6:$R$43,H$5,0) -> 2022 | I30: =VLOOKUP($C30,'Summary | 01 '!$C$6:$R$43,I$5,0) -> Equity-TBC | J30: =VLOOKUP($C30,'Summary | 01 '!$C$6:$R$43,J$5,0) -> 0.0943 | K30: =VLOOKUP($C30,'Summary | 01 '!$C$6:$R$43,K$5,0) -> 300 | L30: =VLOOKUP($C30,'Summary | 01 '!$C$6:$R$43,L$5,0) -> 300 | ... O30: =VLOOKUP($C30,'Summary | 01 '!$C$6:$R$43,O$5,0) -> 0 | P30: n/a | Q30: =VLOOKUP($C30,'Summary | 01 '!$C$6:$R$43,Q$5,0) -> NM | R30: =VLOOKUP($C30,'Summary | 01 '!$C$6:$R$43,R$5,0) -> 1 | S30: =VLOOKUP($C30,'Summary | 01 '!$C$6:$R$43,S$5,0) -> 0 | T30: DN Warrants b
C31: vTv Therapeutics Inc. | D31: Direct Investment | E31: =VLOOKUP($C31,'Summary | 01 '!$C$6:$R$43,E$5,0) -> Unrealized | F31: =VLOOKUP($C31,'Summary | 01 '!$C$6:$R$43,F$5,0) -> Divyesh | G31: =VLOOKUP($C31,'Summary | 01 '!$C$6:$R$43,G$5,0) -> G42 | H31: =VLOOKUP($C31,'Summary | 01 '!$C$6:$R$43,H$5,0) -> 2022 | I31: =VLOOKUP($C31,'Summary | 01 '!$C$6:$R$43,I$5,0) -> Ordinary Shares | J31: =VLOOKUP($C31,'Summary | 01 '!$C$6:$R$43,J$5,0) -> 0.099316564 | K31: =VLOOKUP($C31,'Summary | 01 '!$C$6:$R$43,K$5,0) -> 24.53125 | L31: =VLOOKUP($C31,'Summary | 01 '!$C$6:$R$43,L$5,0) -> 24.53125 | ... O31: =VLOOKUP($C31,'Summary | 01 '!$C$6:$R$43,O$5,0) -> -16.141218 | P31: n/a | Q31: =VLOOKUP($C31,'Summary | 01 '!$C$6:$R$43,Q$5,0) -> NM | R31: =VLOOKUP($C31,'Summary | 01 '!$C$6:$R$43,R$5,0) -> 0.34201405 | S31: =VLOOKUP($C31,'Summary | 01 '!$C$6:$R$43,S$5,0) -> 0 | T31: vTv $30m milestn payment c | W31: Invested | X31: =K38 -> 1522.4479
C32: North Summit Capital Fund | D32: Fund Investment | E32: =VLOOKUP($C32,'Summary | 01 '!$C$6:$R$43,E$5,0) -> Unrealized | F32: =VLOOKUP($C32,'Summary | 01 '!$C$6:$R$43,F$5,0) -> Elaine | G32: =VLOOKUP($C32,'Summary | 01 '!$C$6:$R$43,G$5,0) -> G42 | H32: =VLOOKUP($C32,'Summary | 01 '!$C$6:$R$43,H$5,0) -> 2020 | I32: =VLOOKUP($C32,'Summary | 01 '!$C$6:$R$43,I$5,0) -> LP | J32: =VLOOKUP($C32,'Summary | 01 '!$C$6:$R$43,J$5,0) -> n/a | K32: =VLOOKUP($C32,'Summary | 01 '!$C$6:$R$43,K$5,0) -> 300 | L32: =VLOOKUP($C32,'Summary | 01 '!$C$6:$R$43,L$5,0) -> 83.214653 | ... O32: =VLOOKUP($C32,'Summary | 01 '!$C$6:$R$43,O$5,0) -> -12.156692 | P32: 6.6 | Q32: =VLOOKUP($C32,'Summary | 01 '!$C$6:$R$43,Q$5,0) -> -0.064168629 | R32: =VLOOKUP($C32,'Summary | 01 '!$C$6:$R$43,R$5,0) -> 0.96555063 | S32: =VLOOKUP($C32,'Summary | 01 '!$C$6:$R$43,S$5,0) -> 217.81331 | W32: NAV | X32: =N38 -> 1279.4494
C33: New Space Capital Fund I | D33: Fund Investment | E33: =VLOOKUP($C33,'Summary | 01 '!$C$6:$R$43,E$5,0) -> Unrealized | F33: =VLOOKUP($C33,'Summary | 01 '!$C$6:$R$43,F$5,0) -> Sushil | G33: =VLOOKUP($C33,'Summary | 01 '!$C$6:$R$43,G$5,0) -> G42 | H33: =VLOOKUP($C33,'Summary | 01 '!$C$6:$R$43,H$5,0) -> 2020 | I33: =VLOOKUP($C33,'Summary | 01 '!$C$6:$R$43,I$5,0) -> LP | J33: =VLOOKUP($C33,'Summary | 01 '!$C$6:$R$43,J$5,0) -> n/a | K33: =VLOOKUP($C33,'Summary | 01 '!$C$6:$R$43,K$5,0) -> 28.098225 | L33: =VLOOKUP($C33,'Summary | 01 '!$C$6:$R$43,L$5,0) -> 11.058035 | ... O33: =VLOOKUP($C33,'Summary | 01 '!$C$6:$R$43,O$5,0) -> 6.1926309 | P33: 1 | Q33: =VLOOKUP($C33,'Summary | 01 '!$C$6:$R$43,Q$5,0) -> 0.1090443 | R33: =VLOOKUP($C33,'Summary | 01 '!$C$6:$R$43,R$5,0) -> 1.4784783 | S33: =VLOOKUP($C33,'Summary | 01 '!$C$6:$R$43,S$5,0) -> 17.040191 | W33: Gain | X33: =O38 -> 25.694726
C34: New Space Capital SCSp | D34: Fund Investment | E34: =VLOOKUP($C34,'Summary | 01 '!$C$6:$R$43,E$5,0) -> Unrealized | F34: =VLOOKUP($C34,'Summary | 01 '!$C$6:$R$43,F$5,0) -> Sushil | G34: =VLOOKUP($C34,'Summary | 01 '!$C$6:$R$43,G$5,0) -> G42 | H34: =VLOOKUP($C34,'Summary | 01 '!$C$6:$R$43,H$5,0) -> 2020 | I34: =VLOOKUP($C34,'Summary | 01 '!$C$6:$R$43,I$5,0) -> GP | J34: =VLOOKUP($C34,'Summary | 01 '!$C$6:$R$43,J$5,0) -> n/a | K34: =VLOOKUP($C34,'Summary | 01 '!$C$6:$R$43,K$5,0) -> 2.7058824 | L34: =VLOOKUP($C34,'Summary | 01 '!$C$6:$R$43,L$5,0) -> 2.7058824 | ... O34: =VLOOKUP($C34,'Summary | 01 '!$C$6:$R$43,O$5,0) -> 0 | P34: 0 | Q34: =VLOOKUP($C34,'Summary | 01 '!$C$6:$R$43,Q$5,0) -> 0 | R34: =VLOOKUP($C34,'Summary | 01 '!$C$6:$R$43,R$5,0) -> 1 | S34: =VLOOKUP($C34,'Summary | 01 '!$C$6:$R$43,S$5,0) -> 0 | W34: YTD Gains | X34: =X33-11.1 -> 14.594726
C35: Sinovation Disrupt Fund, L.P. | D35: Fund Investment | E35: =VLOOKUP($C35,'Summary | 01 '!$C$6:$R$43,E$5,0) -> Unrealized | F35: =VLOOKUP($C35,'Summary | 01 '!$C$6:$R$43,F$5,0) -> Elaine | G35: =VLOOKUP($C35,'Summary | 01 '!$C$6:$R$43,G$5,0) -> G42 | H35: =VLOOKUP($C35,'Summary | 01 '!$C$6:$R$43,H$5,0) -> 2020 | I35: =VLOOKUP($C35,'Summary | 01 '!$C$6:$R$43,I$5,0) -> LP | J35: =VLOOKUP($C35,'Summary | 01 '!$C$6:$R$43,J$5,0) -> n/a | K35: =VLOOKUP($C35,'Summary | 01 '!$C$6:$R$43,K$5,0) -> 50 | L35: =VLOOKUP($C35,'Summary | 01 '!$C$6:$R$43,L$5,0) -> 22.657267 | ... O35: =VLOOKUP($C35,'Summary | 01 '!$C$6:$R$43,O$5,0) -> -0.69768865 | P35: 3.5 | Q35: =VLOOKUP($C35,'Summary | 01 '!$C$6:$R$43,Q$5,0) -> -0.018159524 | R35: =VLOOKUP($C35,'Summary | 01 '!$C$6:$R$43,R$5,0) -> 0.97193724 | S35: =VLOOKUP($C35,'Summary | 01 '!$C$6:$R$43,S$5,0) -> 27.342733 | W35: IRR | X35: =Q38 -> 0.022939894
C36: Acies Investments Fund I, L.P. | D36: Fund Investment | E36: =VLOOKUP($C36,'Summary | 01 '!$C$6:$R$43,E$5,0) -> Unrealized | F36: =VLOOKUP($C36,'Summary | 01 '!$C$6:$R$43,F$5,0) -> Divyesh | G36: =VLOOKUP($C36,'Summary | 01 '!$C$6:$R$43,G$5,0) -> G42 | H36: =VLOOKUP($C36,'Summary | 01 '!$C$6:$R$43,H$5,0) -> 2021 | I36: =VLOOKUP($C36,'Summary | 01 '!$C$6:$R$43,I$5,0) -> LP | J36: =VLOOKUP($C36,'Summary | 01 '!$C$6:$R$43,J$5,0) -> 0.33 | K36: =VLOOKUP($C36,'Summary | 01 '!$C$6:$R$43,K$5,0) -> 17.1125 | L36: =VLOOKUP($C36,'Summary | 01 '!$C$6:$R$43,L$5,0) -> 14.015137 | ... O36: =VLOOKUP($C36,'Summary | 01 '!$C$6:$R$43,O$5,0) -> -0.2722965 | P36: 0 | Q36: =VLOOKUP($C36,'Summary | 01 '!$C$6:$R$43,Q$5,0) -> -0.021553859 | R36: =VLOOKUP($C36,'Summary | 01 '!$C$6:$R$43,R$5,0) -> 0.97333028 | S36: =VLOOKUP($C36,'Summary | 01 '!$C$6:$R$43,S$5,0) -> 3.0973625 | T36: 9.9% GP | Anchor
K38: =SUM(K29:K36) -> 1522.4479 | L38: =SUM(L29:L36) -> 1258.1822 | M38: =SUM(M29:M36) -> 4.4275637 | N38: =SUM(N29:N36) -> 1279.4494 | O38: =N38+M38-L38 -> 25.694726 | P38: =SUM(P29:P36) -> 11.1 | Q38: ='4. G42-IRR'!L16 -> 0.022939894 | R38: =(M38+N38)/L38 -> 1.0204221 | S38: =SUM(S29:S36) -> 265.29359 | T38: =N38+M38-L38 -> 25.694726
K40: =K27+K38 -> 2501.7117 | L40: =L27+L38 -> 2227.1929 | M40: =M27+M38 -> 9.8983484 | N40: =N27+N38 -> 2207.4575 | O40: =O27+O38 -> -9.8370913 | R40: =(M40+N40)/L40 -> 0.99558319 | S40: =S27+S38 -> 275.54359
I43: Checks: | K43: =K40='Summary | 01 '!J43 -> TRUE | L43: =ROUND(L40,3)=ROUND('Summary | 01 '!K43,3) -> TRUE | M43: =M40='Summary | 01 '!M43 -> TRUE | N43: =N40='Summary | 01 '!N43 -> TRUE | O43: =ROUND(O40,3)=ROUND('Summary | 01 '!O43,3) -> TRUE | S43: =S40='Summary | 01 '!L43 -> TRUE
B44: For Notes, refer to Summary | 01
O45: =P27-O27 -> 262.93182
O46: =K38-L38 -> 264.26563
O47: =O38-P38 -> 14.594726
O48: =SUM(M29:N31)-SUM(L29:L31) -> 32.628772
O49: =SUM(M32:N36)-SUM(L32:L36) -> -6.9340462
O50: =K38-L38 -> 264.26563

Sheet S | 03
C2: As of date | D2: ='Summary | 01 '!D2 -> 45016
I4: Changes during the Period
I5: 1a | J5: 1b | K5: 1c | L5: 1d | N5: 3 | O5: 4
C6: Deals | D6: Status | E6: Lead | F6: Investing Entity | G6: Instrument | H6: Listed / Unlisted | I6: No. of securities held (Movement during the Period) | N6: Dividend / Interest | O6: For Comments Refer to Note
I7: Opening | J7: Acquired | K7: Re-organisation | L7: Sale / Transfer | M7: Closing
C9: Direct Investments
C10: ='Summary | 01 '!C10 -> Jollychic Holding Limited | D10: ='Summary | 01 '!D10 -> In Liquidation | E10: ='Summary | 01 '!E10 -> Elaine | F10: ='Summary | 01 '!F10 -> Mozn | G10: ='Summary | 01 '!H10 -> C+ Prefs | I10: ='7. %'!D10 -> 13458655 | J10: 0 | K10: 0 | L10: 0 | M10: =I10 -> 13458655 | N10: 0 | O10: 1
C11: ='Summary | 01 '!C11 -> Mena Mobile Inc | D11: ='Summary | 01 '!D11 -> Unrealized | E11: ='Summary | 01 '!E11 -> Elaine | F11: ='Summary | 01 '!F11 -> Mozn | G11: ='Summary | 01 '!H11 -> B Prefs | I11: ='7. %'!D11 -> 21419829 | J11: 0 | K11: 0 | L11: 0 | M11: =I11 -> 21419829 | N11: 0 | O11: 2
C12: ='Summary | 01 '!C12 -> Flyr Inc | D12: ='Summary | 01 '!D12 -> Unrealized | E12: ='Summary | 01 '!E12 -> Sushil | F12: ='Summary | 01 '!F12 -> Mozn | G12: ='Summary | 01 '!H12 -> B-1,2 Prefs | I12: ='7. %'!D12 -> 5205482 | J12: 0 | K12: 0 | L12: 0 | N12: 0 | O12: 3
C13: ='Summary | 01 '!C13 -> Esyasoft Holding | D13: ='Summary | 01 '!D13 -> Realized | E13: ='Summary | 01 '!E13 -> Sushil | F13: ='Summary | 01 '!F13 -> Mozn | G13: ='Summary | 01 '!H13 -> Convertible Note | J13: 0 | K13: 0 | L13: 0 | N13: 0 | O13: 4
C14: ='Summary | 01 '!C14 -> Beyond Limits | D14: ='Summary | 01 '!D14 -> Unrealized | E14: ='Summary | 01 '!E14 -> Divyesh | F14: ='Summary | 01 '!F14 -> Mozn | G14: ='Summary | 01 '!H14 -> C Prefs | I14: ='7. %'!D14 -> 17670202 | J14: 0 | K14: 0 | L14: 0 | M14: =I14 -> 17670202 | N14: 0 | O14: 5
C15: ='Summary | 01 '!C15 -> ONT plc | D15: ='Summary | 01 '!D15 -> Unrealized | E15: ='Summary | 01 '!E15 -> Divyesh | F15: ='Summary | 01 '!F15 -> Mozn | G15: ='Summary | 01 '!H15 -> Ordinary Shares | H15: Listed | I15: ='7. %'!D15 -> 44328120 | J15: 0 | K15: 0 | L15: 0 | M15: =I15 -> 44328120 | N15: 0 | O15: 6
C16: ='Summary | 01 '!C16 -> Heygears | D16: ='Summary | 01 '!D16 -> Unrealized | E16: ='Summary | 01 '!E16 -> Elaine | F16: ='Summary | 01 '!F16 -> Mozn | G16: ='Summary | 01 '!H16 -> Registered Capital | I16: ='7. %'!D16 -> 3565017.2 | J16: 0 | K16: 0 | L16: 0 | M16: =I16 -> 3565017.2 | N16: 0 | O16: 7
C17: ='Summary | 01 '!C17 -> Jysan Technologies | D17: ='Summary | 01 '!D17 -> Unrealized | E17: ='Summary | 01 '!E17 -> Sushil | F17: ='Summary | 01 '!F17 -> Mozn 1 | G17: ='Summary | 01 '!H17 -> A (Ordinary Shares) | I17: =NAV!F16 -> 7959497 | J17: 0 | K17: 0 | L17: 0 | M17: =I17 -> 7959497 | N17: 0 | O17: 8
C18: ='Summary | 01 '!C18 -> Cerebras Systems Inc | D18: ='Summary | 01 '!D18 -> Unrealized | E18: ='Summary | 01 '!E18 -> Ignasi | F18: ='Summary | 01 '!F18 -> Mozn | G18: ='Summary | 01 '!H18 -> F Prefs | I18: =NAV!F17 -> 1441711 | J18: 0 | K18: 0 | L18: 0 | M18: =I18 -> 1441711 | N18: 0 | O18: 9
C19: ='Summary | 01 '!C19 -> Endless Studios LLC | D19: ='Summary | 01 '!D19 -> Unrealized | E19: ='Summary | 01 '!E19 -> Sushil | F19: ='Summary | 01 '!F19 -> Mozn | G19: ='Summary | 01 '!H19 -> A Pref Units | I19: =NAV!F18 -> 3000000 | J19: 0 | K19: 0 | L19: 0 | M19: =I19 -> 3000000 | N19: 0 | O19: 10
C20: ='Summary | 01 '!C20 -> Instadeep Limited | D20: ='Summary | 01 '!D20 -> To be Exited | E20: ='Summary | 01 '!E20 -> Ignasi | F20: ='Summary | 01 '!F20 -> Mozn | G20: ='Summary | 01 '!H20 -> B Prefs | I20: =NAV!F19 -> 33267 | J20: 0 | K20: 0 | L20: 0 | M20: =I20 -> 33267 | N20: 0 | O20: 11
C21: ='Summary | 01 '!C21 -> X-fusion | D21: ='Summary | 01 '!D21 -> Unrealized | E21: ='Summary | 01 '!E21 -> Elaine | F21: ='Summary | 01 '!F21 -> Mozn 2 | G21: ='Summary | 01 '!H21 -> Equity-TBC | O21: 12
C22: ='Summary | 01 '!C22 -> DriveNets | D22: ='Summary | 01 '!D22 -> Unrealized | E22: ='Summary | 01 '!E22 -> Anton | F22: ='Summary | 01 '!F22 -> G42 | G22: ='Summary | 01 '!H22 -> Equity-TBC | O22: 13
C23: ='Summary | 01 '!C23 -> vTv Therapeutics Inc. | D23: ='Summary | 01 '!D23 -> Unrealized | E23: ='Summary | 01 '!E23 -> Divyesh | F23: ='Summary | 01 '!F23 -> G42 | G23: ='Summary | 01 '!H23 -> Ordinary Shares | H23: Listed | I23: 10386274 | J23: 0 | K23: 0 | L23: 0 | M23: 10386274 | N23: 0 | O23: 14
C24: ='Summary | 01 '!C24 -> Honor Device Co Ltd | D24: ='Summary | 01 '!D24 -> Unrealized | E24: ='Summary | 01 '!E24 -> Elaine | F24: ='Summary | 01 '!F24 -> G42 3 | G24: ='Summary | 01 '!H24 -> Equity-TBC | O24: 15
C25: ='Summary | 01 '!C25 -> Applied AI Corporation Limited | D25: ='Summary | 01 '!D25 -> Unrealized | E25: ='Summary | 01 '!E25 -> Anton | F25: ='Summary | 01 '!F25 -> Mozn | G25: ='Summary | 01 '!H25 -> Convertible Note | J25: 0 | K25: 0 | L25: 0 | N25: 0 | O25: 16
C26: ='Summary | 01 '!C26 -> eSpace | D26: ='Summary | 01 '!D26 -> Unrealized | E26: ='Summary | 01 '!E26 -> Anton | F26: ='Summary | 01 '!F26 -> Mozn 4 | G26: ='Summary | 01 '!H26 -> SAFE note | O26: 17
C29: Debt Investments
C30: Glass Earth Holdings LLC | D30: In default | F30: Mozn | G30: Promissory Note | O30: 16
C31: Mena Mobile Inc (Debt) | D31: In default | E31: Elaine | F31: Mozn | G31: Loan | O31: 17
C32: Esyasoft Holding (Debt) | D32: Unrealized | E32: Sushil | F32: Mozn | G32: Loan | O32: 18
C35: Funds Investments
C36: New Space Capital Fund I | D36: Unrealized | E36: Sushil | F36: G42 | G36: LP | O36: 19
C37: New Space Capital SCSp | D37: Unrealized | E37: Sushil | F37: G42 | G37: GP | O37: 20
C38: North Summit Capital Fund | D38: Unrealized | E38: Elaine | F38: G42 | G38: LP | O38: 21
C39: Sinovation Disrupt Fund, L.P. | D39: Unrealized | E39: Elaine | F39: G42 | G39: LP | O39: 22
C40: Acies Investments Fund I, L.P. | D40: Unrealized | E40: Divyesh | F40: G42 | G40: LP | O40: 23
B47: Notes:
B48: 1 | C48: Jollychic | D48: During 2021, Jollychic Holding Ltd has filed for its liquidation. Therefore, investment is considered to be fully impaired in Dec 21.
B49: 2 | C49: Mena Mobile | D49: Investment is marked down based on the inputs received from 3rd party.
B50: 3 | C50: Flyr | D50: Within five years of the Initial Closing, for every USD 1mn of Qualifying Revenue generated, Flyr will issue, at no additional charge, 194,477 B-1 Prefs in the name of G42, up to a maximum of 1,264,100 B-1 Prefs.
B51: 4 | C51: Esyasoft Holding | D51: Investment in Esyasoft is in the form of Convertible Note which will convert to 21% interest on conversion on a fully diluted basis. As per Dec 2020 FS of Esyasoft, the CN was reflected as Debt - Exit of US$ 2.5 Mn Convertible Note @ 2.0x (MoC) i.e. US$ 5 Mn in May 22 - US$ 0.4 Mn represents Working Capital Loan - fully exited in Dec 22
B52: 5 | C52: Beyond Limits | D52: Business targeting raising funds by the end of FY2022
B53: 6 | C53: ONT plc
...

Sheet NAV
B2: NAV Date | C2: ='Summary | 01 '!D2 -> 45016
B5: Investments | C5: Investing Entity | D5: Instrument | E5: Carrying Value | F5: Current Shares/Units | H5: Comment
E6: USD, Million | F6: # | G6: USD | J6: Updated as on: | K6: =C2 -> 45016
E7: ="NAV | "& TEXT(C2,"dd")&" "&TEXT(C2,"mmm")&" "&TEXT(C2,"yyyy") -> NAV | 31 Mar 2023 | G7: ="PPS |" & TEXT(C2,"dd")&" "&TEXT(C2,"mmm")&" "&TEXT(C2,"yyyy") -> PPS |31 Mar 2023 | L7: source
B8: Direct Investments | J8: ONT Share price | K8: 2.225 | L8: link
B9: ='Summary | 01 '!C10 -> Jollychic Holding Limited | C9: ='Summary | 01 '!F10 -> Mozn | D9: ='Summary | 01 '!H10 -> C+ Prefs | E9: =F9*G9*10^-6 -> 0 | F9: =SUM('CF (Equity, Debt)'!J4:J6) -> 13458655 | H9: In Liquidation | J9: VTVT Share price | K9: 0.8078 | L9: link
B10: ='Summary | 01 '!C11 -> Mena Mobile Inc | C10: ='Summary | 01 '!F11 -> Mozn | D10: ='Summary | 01 '!H11 -> B Prefs | E10: 3.1 | F10: ='CF (Equity, Debt)'!J7 -> 21419829 | H10: As per 3rd Party | Ardent Estimates | J10: GBP USD | K10: 1.2408 | L10: xe.com
B11: ='Summary | 01 '!C12 -> Flyr Inc | C11: ='Summary | 01 '!F12 -> Mozn | D11: ='Summary | 01 '!H12 -> B-1,2 Prefs | E11: =F11*G11*10^-6*(1-20%) -> 78.08223 | F11: 5205482 | G11: 18.75 | H11: At Series C PPS $18.75/share with 20% discount | J11: USD RMB | K11: 6.875 | L11: xe.com
B12: ='Summary | 01 '!C13 -> Esyasoft Holding | C12: ='Summary | 01 '!F13 -> Mozn | D12: ='Summary | 01 '!H13 -> Convertible Note | E12: 0 | F12: n/a | H12: Exited at $5m (10th May) | Residual value = 0 | J12: EURUSD | K12: 1.08705 | L12: xe.com
B13: ='Summary | 01 '!C14 -> Beyond Limits | C13: ='Summary | 01 '!F14 -> Mozn | D13: ='Summary | 01 '!H14 -> C Prefs | E13: =F13*G13*10^-6 -> 91.00154 | F13: =SUM('CF (Equity, Debt)'!J11:J14) -> 17670202 | G13: 5.15 | H13: Held at cost (as per revised management guidance)
B14: ='Summary | 01 '!C15 -> ONT plc | C14: ='Summary | 01 '!F15 -> Mozn | D14: ='Summary | 01 '!H15 -> Ordinary Shares | E14: =F14*G14*10^-6 -> 122.38019 | F14: 44328120 | G14: =K8*K10 -> 2.76078 | H14: Listed & marked to market
B15: ='Summary | 01 '!C16 -> Heygears | C15: ='Summary | 01 '!F16 -> Mozn | D15: ='Summary | 01 '!H16 -> Registered Capital | E15: =K25/1000000 -> 119.2498 | F15: ='CF (Equity, Debt)'!J20 -> 4753356.3 | H15: Adjusted for currency. Negotiating final terms of a new round at $1.5Bn pre
B16: ='Summary | 01 '!C17 -> Jysan Technologies | C16: ='Summary | 01 '!F17 -> Mozn 1 | D16: ='Summary | 01 '!H17 -> A (Ordinary Shares) | E16: =-'CF (Equity, Debt)'!E21 -> 20 | F16: ='CF (Equity, Debt)'!J21 -> 7959497 | G16: =E16*10^6/F16 -> 2.5127216 | H16: Held at cost. | J16: Heygears Oct 22 | O16: New Space Capital
B17: ='Summary | 01 '!C18 -> Cerebras Systems Inc | C17: ='Summary | 01 '!F18 -> Mozn | D17: ='Summary | 01 '!H18 -> F Prefs | E17: =-'CF (Equity, Debt)'!E22 -> 39.999983 | F17: ='CF (Equity, Debt)'!J22 -> 1441711 | H17: Held at cost.
B18: ='Summary | 01 '!C19 -> Endless Studios LLC | C18: ='Summary | 01 '!F19 -> Mozn | D18: ='Summary | 01 '!H19 -> A Pref Units | E18: =-'CF (Equity, Debt)'!E23 -> 3 | F18: ='CF (Equity, Debt)'!J23 -> 3000000 | H18: Held at cost. | J18: Post Valuation closed in June 2021 (RMB) | K18: 7500000000 | O18: EUR | P18: 3Q22 | Q18: 4Q22
B19: ='Summary | 01 '!C20 -> Instadeep Limited | C19: ='Summary | 01 '!F20 -> Mozn | D19: ='Summary | 01 '!H20 -> B Prefs | E19: =-'CF (Equity, Debt)'!E24 -> 5.0237202 | F19: ='CF (Equity, Debt)'!J24 -> 33267 | H19: Held at cost. | J19: G42 Stake | K19: 0.143832 | O19: Commitment | P19: 23234462 | Q19: 23234462 | R19: source: distribution letter
B20: ='Summary | 01 '!C21 -> X-fusion | C20: ='Summary | 01 '!F21 -> Mozn 2 | D20: ='Summary | 01 '!H21 -> Equity-TBC | E20: =5810000000/K11/1000000*(1-49.82%) -> 424.06662 | H20: Held at original cost, adjusted for currency, and ownership | J20: G42 Valuation before Discount (RMB) | K20: 1078740000 | O20: Capital Contribution | P20: 19178323 | Q20: 9436936
B21: ='Summary | 01 '!C22 -> DriveNets | C21: ='Summary | 01 '!F22 -> G42 | D21: ='Summary | 01 '!H22 -> Equity-TBC | E21: =-SUM('CF (Equity, Debt)'!E26:E27) -> 300 | H21: Held at cost. | J21: Liquidity Discount | K21: 0.2 | O21: Unfunded | P21: =P19-P20 -> 4056139 | Q21: =Q19-Q20 -> 13797526
B22: ='Summary | 01 '!C23 -> vTv Therapeutics Inc. | C22: ='Summary | 01 '!F23 -> G42 | D22: ='Summary | 01 '!H23 -> Ordinary Shares | E22: =(F22*G22)*10^-6 -> 8.3900321 | F22: ='CF (Equity, Debt)'!J29 -> 10386274 | G22: =K9 -> 0.8078 | H22: Listed & marked to market | J22: Minority Holding Discount | K22: 0.05 | O22: Unrealized Gain | P22: 13103567 | Q22: 3803379
B23: ='Summary | 01 '!C24 -> Honor Device Co Ltd | C23: ='Summary | 01 '!F24 -> G42 3 | D23: ='Summary | 01 '!H24 -> Equity-TBC | E23: =310000000000/K11/1000000*4.705882%*0.8/2 -> 848.76999 | F23: n/a | H23: Closing a new round at RMB 310B. Adjusted for currency. | J23: G42 Valuation (RMB) | K23: =K20*(1-K21)*(1-K22) -> 819842400 | O23: NAV | P23: 32325017 | Q23: 13150169 | R23: source: distribution letter
B24: ='Summary | 01 '!C25 -> Applied AI Corporation Limited | C24: ='Summary | 01 '!F25 -> Mozn | D24: ='Summary | 01 '!H25 -> Convertible Note | E24: 4.75 | F24: n/a | H24: Held at cost. | J24: Exchange Rate (RMB/USD) | K24: =K11 -> 6.875 | O24: Capital Return | Q24: =P20-Q20 -> 9741387 | R24: estimated
B25: eSpace | C25: ='Summary | 01 '!F26 -> Mozn 4 | D25: ='Summary | 01 '!H26 -> SAFE note | E25: 15 | F25: n/a | H25: Held at cost. | J25: G42 Valuation (USD) | K25: =K23/K24 -> 1.192498e+08 | O25: Interest Capitalization | Q25: =Q26-Q24 -> 2728214 | R25: estimated
J26: Investment Cost of G42 (USD) | K26: 60000000 | O26: Total Distribution Received | Q26: 12469601 | R26: source: distribution letters, Gino
J27: Investment Multiple | K27: 1.9039182 | O27: Remaining Commitment | Q27: =15675627.21 -> 15675627 | R27: source: distribution letter
B29: Debt Investments
B30: Glass Earth Holdings LLC | C30: Mozn | D30: Promissory Note | E30: ='Summary | 01 '!N30 -> 0 | H30: In default | O30: in USD, Mn
B31: Mena Mobile Inc (Debt) | C31: Mozn | D31: Loan | E31: ='Summary | 01 '!N31 -> 2.353982 | H31: Held at cost. | O31: Capital Committed | P31: =P32+P33 -> 28.098225
B32: Esyasoft Holding (Debt) | C32: Mozn | D32: Loan | E32: 0 | H32: Received payment of $470,784.65 ($411K+$59K) | O32: Capital Called | P32: =-SUM('CF (Funds)'!D31:D35)-Q24*1.08341*10^-6 -> 11.058035 | Q32: =Q20*10^-6*K12 -> 10.258421
O33: Remaining | P33: =Q27*10^-6*K12 -> 17.040191
O34: NAV | P34: =Q23*10^-6*K12 -> 14.294891
J35: CHECKS
B36: Funds Investments
B37: New Space Capital Fund I | C37: G42 | D37: LP | E37: =Q23*10^-6*K12 -> 14.294891 | H37: Q3'22 reported | J37: Equity | K37: =SUM(E9:E25) -> 2082.8141
B38: New Space Capital SCSp | C38: G42 | D38: GP | E38: 2.7058824 | H38: Q3'22 at cost | J38: Debt | K38: =SUM(E30:E32) -> 2.353982
B39: North Summit Capital Fund | C39: G42 | D39: LP | E39: 70.03 | H39: Q3'22 reported | J39: Funds | K39: =SUM(E37:E41) -> 122.28936
B40: Sinovation Disrupt Fund, L.P. | C40: G42 | D40: LP | E40: =18.884222-'CF (Funds)'!D16 -> 21.51575 | H40: Q3'22 reported | J40: Total | K40: =SUM(K37:K39) -> 2207.4575
B41: Acies Investments Fund I, L.P. | C41: G42 | D41: LP | E41: =10.354566-'CF (Funds)'!D43 -> 13.742841 | H41: Q3'22 reported | K41: =K40='Summary | 01 '!N43 -> TRUE
K42: =K40='4.All'!M9 -> TRUE
B44: Note:
B45: • For estimating the NAV their listed share price for ONT and vTv Therapeutics is taken

Sheet CF (Equity, Debt)
B2: E Q U I T Y
B3: Accounting entity | C3: Investment | D3: Payment date | E3: Contributions (in USD, Mn) | F3: Distributions (in USD, Mn) | G3: Currency | H3: Investment Amt (investee currency) | I3: Investment Amount (USD) | J3: Consideration (shares) | K3: Comment
B4: =VLOOKUP(C4,'Summary | 01 '!$C$10:$F$40,4,0) -> Mozn | C4: Jollychic Holding Limited | D4: 43470 | E4: =-I4*10^-6 -> -30 | G4: USD | H4: 30000000 | I4: =H4 -> 30000000 | J4: 6100312 | N4: NOTES
B5: =VLOOKUP(C5,'Summary | 01 '!$C$10:$F$40,4,0) -> Mozn | C5: Jollychic Holding Limited | D5: 43724 | E5: =-I5*10^-6 -> -20 | G5: USD | H5: 20000000 | I5: =H5 -> 20000000 | J5: 4204767.4 | N5: USD AED | O5: 3.678
B6: =VLOOKUP(C6,'Summary | 01 '!$C$10:$F$40,4,0) -> Mozn | C6: Jollychic Holding Limited | D6: 43724 | E6: =-I6*10^-6 -> -15 | G6: USD | H6: 15000000 | I6: =H6 -> 15000000 | J6: 3153575.6
B7: =VLOOKUP(C7,'Summary | 01 '!$C$10:$F$40,4,0) -> Mozn | C7: Mena Mobile Inc | D7: 43563 | E7: =-I7*10^-6 -> -8 | G7: USD | H7: 8000000 | I7: =H7 -> 8000000 | J7: 21419829
B8: =VLOOKUP(C8,'Summary | 01 '!$C$10:$F$40,4,0) -> Mozn | C8: Flyr Inc | D8: 43570 | E8: =-I8*10^-6 -> -4.9999981 | G8: USD | H8: 4999998.1 | I8: =H8 -> 4999998.1 | J8: 2625467
B9: =VLOOKUP(C9,'Summary | 01 '!$C$10:$F$40,4,0) -> Mozn | C9: Flyr Inc | D9: 43915 | E9: =-I9*10^-6 -> -5.0000019 | G9: USD | H9: =10000000-H8 -> 5000001.9 | I9: =H9 -> 5000001.9 | J9: 2580015
B10: =VLOOKUP(C10,'Summary | 01 '!$C$10:$F$40,4,0) -> Mozn | C10: Esyasoft Holding | D10: 43870 | E10: =-I10*10^-6 -> -2.5 | G10: USD | H10: 2500000 | I10: =H10 -> 2500000 | J10: N/A
B11: =VLOOKUP(C11,'Summary | 01 '!$C$10:$F$40,4,0) -> Mozn | C11: Beyond Limits | D11: 43879 | E11: =-I11*10^-6 -> -20 | G11: USD | H11: 20000000 | I11: =H11 -> 20000000 | J11: 4084038
B12: =VLOOKUP(C12,'Summary | 01 '!$C$10:$F$40,4,0) -> Mozn | C12: Beyond Limits | D12: 43921 | E12: =-I12*10^-6 -> -30 | G12: USD | H12: 30000000 | I12: =H12 -> 30000000 | J12: 5822642
B13: =VLOOKUP(C13,'Summary | 01 '!$C$10:$F$40,4,0) -> Mozn | C13: Beyond Limits | D13: 43989 | E13: =-I13*10^-6 -> -30 | G13: USD | H13: 30000000 | I13: =H13 -> 30000000 | J13: 5822642
B14: =VLOOKUP(C14,'Summary | 01 '!$C$10:$F$40,4,0) -> Mozn | C14: Beyond Limits | D14: 44103 | E14: =-I14*10^-6 -> -10 | G14: USD | H14: 10000000 | I14: =H14 -> 10000000 | J14: 1940880
B15: =VLOOKUP(C15,'Summary | 01 '!$C$10:$F$40,4,0) -> Mozn | C15: ONT plc | D15: 43968 | E15: =-I15*10^-6 -> -50 | G15: USD | H15: 50000000 | I15: 50000000 | J15: 15277680
B16: =VLOOKUP(C16,'Summary | 01 '!$C$10:$F$40,4,0) -> Mozn | C16: ONT plc | D16: 44006 | E16: =-I16*10^-6 -> -27.268351 | G16: GBP | H16: 21029625 | I16: 27268351 | J16: 9000000
B17: =VLOOKUP(C17,'Summary | 01 '!$C$10:$F$40,4,0) -> Mozn | C17: ONT plc | D17: 43837 | E17: =-I17*10^-6 -> -18.109441 | G17: GBP | H17: 14386480 | I17: 18109441 | J17: 6362180
B18: =VLOOKUP(C18,'Summary | 01 '!$C$10:$F$40,4,0) -> Mozn | C18: ONT plc | D18: 43990 | E18: =-I18*10^-6 -> -34.851687 | G18: GBP | H18: 26085573 | I18: 34851687 | J18: 11381140
B19: =VLOOKUP(C19,'Summary | 01 '!$C$10:$F$40,4,0) -> Mozn | C19: ONT plc | D19: 44315 | E19: =-I19*10^-6 -> -11.24078 | G19: GBP | H19: 8074920 | I19: 11240780 | J19: 2307120
B20: =VLOOKUP(C20,'Summary | 01 '!$C$10:$F$40,4,0) -> Mozn | C20: Heygears | D20: 44166 | E20: =-I20*10^-6 -> -60 | G20: USD | H20: 60000000 | I20: =H20 -> 60000000 | J20: 4753356.3
B21: =VLOOKUP(C21,'Summary | 01 '!$C$10:$F$40,4,0) -> Mozn 1 | C21: Jysan Technologies | D21: 44363 | E21: =-I21*10^-6 -> -20 | G21: USD | H21: 20000000 | I21: =H21 -> 20000000 | J21: 7959497
B22: =VLOOKUP(C22,'Summary | 01 '!$C$10:$F$40,4,0) -> Mozn | C22: Cerebras Systems Inc | D22: 44488 | E22: =-I22*10^-6 -> -39.999983 | G22: USD | H22: 39999983 | I22: =H22 -> 39999983 | J22: 1441711
B23: =VLOOKUP(C23,'Summary | 01 '!$C$10:$F$40,4,0) -> Mozn | C23: Endless Studios LLC | D23: 44494 | E23: =-I23*10^-6 -> -3 | G23: USD | H23: 3000000 | I23: =H23 -> 3000000 | J23: 3000000
B24: =VLOOKUP(C24,'Summary | 01 '!$C$10:$F$40,4,0) -> Mozn | C24: Instadeep Limited | D24: 44550 | E24: =-I24*10^-6 -> -5.0237202 | G24: GBP | H24: 3679995.5 | I24: 5023720.2 | J24: 33267
B25: =VLOOKUP(C25,'Summary | 01 '!$C$10:$F$40,4,0) -> Mozn 2 | C25: X-fusion | D25: 44574 | E25: =-I25*10^-6 -> -493.50096 | G25: USD | H25: 8.9350096e+08 | I25: 4.9350096e+08
B26: =VLOOKUP(C26,'Summary | 01 '!$C$10:$F$40,4,0) -> G42 | C26: DriveNets | D26: 44643 | E26: =-I26*10^-6 -> -200 | G26: USD | H26: 200000000 | I26: =H26 -> 200000000
B27: =VLOOKUP(C27,'Summary | 01 '!$C$10:$F$40,4,0) -> G42 | C27: DriveNets | D27: 44680 | E27: =-I27*10^-6 -> -100 | G27: USD | H27: 100000000 | I27: =H27 -> 100000000
B28: =VLOOKUP(C28,'Summary | 01 '!$C$10:$F$40,4,0) -> Mozn | C28: Esyasoft Holding | D28: 44691 | F28: 5 | G28: USD
B29: =VLOOKUP(C29,'Summary | 01 '!$C$10:$F$40,4,0) -> G42 | C29: vTv Therapeutics Inc. | D29: 44712 | E29: =-I29*10^-6 -> -12.5 | G29: USD | H29: 12500000 | I29: =H29 -> 12500000 | J29: 10386274
B30: =VLOOKUP(C30,'Summary | 01 '!$C$10:$F$40,4,0) -> G42 3 | C30: Honor Device Co Ltd | D30: 44769 | E30: =-I30*10^-6 -> -600 | G30: USD | H30: 600000000 | I30: =H30 -> 600000000
B31: =VLOOKUP(C31,'Summary | 01 '!$C$10:$F$40,4,0) -> G42 3 | C31: Honor Device Co Ltd | D31: 44849 | E31: =-I31*10^-6 -> -200 | G31: USD | H31: 200000000 | I31: =H31 -> 200000000
B32: =VLOOKUP(C32,'Summary | 01 '!$C$10:$F$40,4,0) -> Mozn | C32: Applied AI Corporation Limited | D32: 44861 | E32: =-I32*10^-6 -> -4.75 | G32: USD | H32: 4750000 | I32: =H32 -> 4750000
B33: =VLOOKUP(C33,'Summary | 01 '!$C$10:$F$40,4,0) -> Mozn 4 | C33: eSpace | D33: 44892 | E33: =-I33*10^-6 -> -15 | G33: USD | H33: 15000000 | I33: =H33 -> 15000000
B34: =VLOOKUP(C34,'Summary | 01 '!$C$10:$F$40,4,0) -> G42 | C34: vTv Therapeutics Inc. | D34: 44985 | E34: =-I34*10^-6 -> -12.03125 | G34: USD | H34: 12031250 | I34: =H34 -> 12031250
B36: L O AN | P R O M I S S O R Y N O T E S | D E B T
