Workbook
Name Company: [1]UEL!$B$18:$B$20
Name Dates: [1]ONT!$N$2:$AN$2
Name DetailedCapShares: '[2]Current Cap'!$T$133
Name FAGroup: [1]UEL!$B$3:$B$15
Name IQ_CH: 110000
Name IQ_CQ: 5000
Name IQ_CY: 10000
Name IQ_DAILY: 500000
Name IQ_FH: 100000
Name IQ_FQ: 500
Name IQ_FY: 1000
Name IQ_LTM: 2000
Name IQ_MONTH: 15000
Name IQ_NTM: 6000
Name IQ_WEEK: 50000
Name IQ_YTD: 3000

Sheet D
C2: Date of NAV | D2: 45138
H3: D A S H B O A R D | L3: figures in USD Millions
D6: # Investments | E6: Committed | F6: Invested | G6: Remaining | H6: Distributions | I6: Residual Value | J6: IRR | K6: TVPI | L6: RPI | M6: DPI
C8: EQUITY | D8: =COUNTIF('S | 01 '!C10:C30,"*") -> 19 | E8: ='1. IRR Equity'!AE33 -> 2108.0362 | F8: ='1. IRR Equity'!AF33 -> 2100.533 | G8: ='1. IRR Equity'!AG33 -> 7.5031614 | H8: ='1. IRR Equity'!AH33 -> 12.820776 | I8: ='1. IRR Equity'!AI33 -> 2118.5933 | J8: ='1. IRR Equity'!AJ33 -> 0.0092234105 | K8: ='1. IRR Equity'!AK33 -> 1.0147015 | L8: ='1. IRR Equity'!AL33 -> 1.008598 | M8: ='1. IRR Equity'!AM33 -> 0.0061035822
C11: DEBT | D11: =COUNTIF('S | 01 '!C33:C35,"*") -> 3 | E11: ='2. IRR Debt'!Q12 -> 10.765747 | F11: ='2. IRR Debt'!R12 -> 10.765747 | G11: ='2. IRR Debt'!S12 -> 0 | H11: ='2. IRR Debt'!T12 -> 0.47078465 | I11: ='2. IRR Debt'!U12 -> 2.353982 | J11: ='2. IRR Debt'!V12 -> -0.32476586 | K11: ='2. IRR Debt'!W12 -> 0.26238464 | L11: ='2. IRR Debt'!X12 -> 0.21865478 | M11: ='2. IRR Debt'!Y12 -> 0.043729864
C14: FUNDS | D14: =COUNTIF('S | 01 '!C39:C43,"*") -> 5 | E14: ='3. IRR Funds'!Q15 -> 398.15519 | F14: ='3. IRR Funds'!R15 -> 131.73842 | G14: ='3. IRR Funds'!S15 -> 267.44473 | H14: ='3. IRR Funds'!T15 -> 4.4275637 | I14: ='3. IRR Funds'!U15 -> 130.91493 | J14: ='3. IRR Funds'!V15 -> 0.010083666 | K14: ='3. IRR Funds'!W15 -> 1.0273578 | L14: ='3. IRR Funds'!X15 -> 0.99374909 | M14: ='3. IRR Funds'!Y15 -> 0.033608751
C17: TOTAL | D17: =D8+D11+D14 -> 27 | E17: =E8+E11+E14 -> 2516.9571 | F17: =F8+F11+F14 -> 2243.0372 | G17: =G8+G11+G14 -> 274.9479 | H17: =H8+H11+H14 -> 17.719124 | I17: =I8+I11+I14 -> 2251.8623 | J17: ='4.All'!N9 -> 0.007097432 | K17: =(H17+I17)/F17 -> 1.011834 | L17: =I17/F17 -> 1.0039344 | M17: =H17/F17 -> 0.0078996124
E19: =E17='S | 01 '!J46 -> TRUE | F19: =F17='S | 01 '!K46 -> TRUE | G19: =ROUND(G17,1)=ROUND('S | 01 '!L46,1) -> TRUE | H19: =ROUND(H17,1)=ROUND('S | 01 '!M46,1) -> TRUE | I19: =ROUND(I17,1)=ROUND('S | 01 '!N46,1) -> TRUE

Sheet S | 01 
C2: As of date | D2: =D!D2 -> 45138
C6: Deals | D6: Status | E6: Lead | F6: Investing Entity | G6: Vintageἀ | H6: Instrument | I6: % | J6: Committed | K6: Invested | L6: Remaining Commitment | M6: Distributions | N6: Carrying Value | O6: Gain | P6: TVPI | Q6: IRRβ | R6: Additonal Upside
G7: # | I7: % | J7: $,m | K7: $,m | L7: $,m | M7: $,m | N7: $,m | O7: $,m | P7: X | Q7: %
C9: Direct Investments
C10: Jollychic Holding Limited | D10: In Liquidation | E10: Elaine | F10: Mozn | G10: 2019 | H10: C+ Prefs | I10: ='6. %'!F9 -> 0.056999998 | J10: 65 | K10: =-SUMIF('CF (Equity, Debt)'!$C$3:$K$40,'S | 01 '!C10,'CF (Equity, Debt)'!$E$3:$E$40) -> 65 | L10: 0 | M10: =SUMIF('CF (Equity, Debt)'!$C$3:$K$40,'S | 01 '!C10,'CF (Equity, Debt)'!$F$3:$F$40) -> 0 | N10: =VLOOKUP(C10,NAV!$B$4:$E$44,4,0) -> 0 | O10: =N10+M10-K10 -> -65 | P10: =(M10+N10)/K10 -> 0 | Q10: =VLOOKUP(C10,'1. IRR Equity'!$AD$12:$AM$30,7,0) -> NM
C11: Mena Mobile Inc | D11: Unrealized | E11: Elaine | F11: Mozn | G11: 2019 | H11: B Prefs | I11: ='6. %'!F10 -> 0.14 | J11: 8 | K11: =-SUMIF('CF (Equity, Debt)'!$C$3:$K$40,'S | 01 '!C11,'CF (Equity, Debt)'!$E$3:$E$40) -> 8 | L11: 0 | M11: =SUMIF('CF (Equity, Debt)'!$C$3:$K$40,'S | 01 '!C11,'CF (Equity, Debt)'!$F$3:$F$40) -> 0 | N11: =VLOOKUP(C11,NAV!$B$4:$E$44,4,0) -> 0 | O11: =N11+M11-K11 -> -8 | P11: =(M11+N11)/K11 -> 0 | Q11: =VLOOKUP(C11,'1. IRR Equity'!$AD$12:$AM$30,7,0) -> NM
C12: Flyr Inc | D12: Unrealized | E12: Sushil | F12: Mozn | G12: 2019 | H12: B-1,2 Prefs | I12: ='6. %'!F11 -> 0.085025485 | J12: 10 | K12: =-SUMIF('CF (Equity, Debt)'!$C$3:$K$40,'S | 01 '!C12,'CF (Equity, Debt)'!$E$3:$E$40) -> 10 | L12: 0 | M12: =SUMIF('CF (Equity, Debt)'!$C$3:$K$40,'S | 01 '!C12,'CF (Equity, Debt)'!$F$3:$F$40) -> 0 | N12: =VLOOKUP(C12,NAV!$B$4:$E$44,4,0) -> 78.08223 | O12: =N12+M12-K12 -> 68.08223 | P12: =(M12+N12)/K12 -> 7.808223 | Q12: =VLOOKUP(C12,'1. IRR Equity'!$AD$12:$AM$30,7,0) -> 0.69797844 | R12: Flyr Warrantsa
C13: Esyasoft Holding | D13: Realized | E13: Sushil | F13: Mozn | G13: 2020 | H13: Convertible Note | I13: ='6. %'!F12 -> n/a | J13: 2.5 | K13: =-SUMIF('CF (Equity, Debt)'!$C$3:$K$40,'S | 01 '!C13,'CF (Equity, Debt)'!$E$3:$E$40) -> 2.5 | L13: 0 | M13: =SUMIF('CF (Equity, Debt)'!$C$3:$K$40,'S | 01 '!C13,'CF (Equity, Debt)'!$F$3:$F$40) -> 5 | N13: =VLOOKUP(C13,NAV!$B$4:$E$44,4,0) -> 0 | O13: =N13+M13-K13 -> 2.5 | P13: =(M13+N13)/K13 -> 2 | Q13: =VLOOKUP(C13,'1. IRR Equity'!$AD$12:$AM$30,7,0) -> 0.36091766
C14: Beyond Limits | D14: Unrealized | E14: Divyesh | F14: Mozn | G14: 2020 | H14: C Prefs | I14: ='6. %'!F13 -> 0.097965107 | J14: 90 | K14: =-SUMIF('CF (Equity, Debt)'!$C$3:$K$40,'S | 01 '!C14,'CF (Equity, Debt)'!$E$3:$E$40) -> 90 | L14: 0 | M14: =SUMIF('CF (Equity, Debt)'!$C$3:$K$40,'S | 01 '!C14,'CF (Equity, Debt)'!$F$3:$F$40) -> 0 | N14: =VLOOKUP(C14,NAV!$B$4:$E$44,4,0) -> 91.00154 | O14: =N14+M14-K14 -> 1.0015403 | P14: =(M14+N14)/K14 -> 1.0111282 | Q14: =VLOOKUP(C14,'1. IRR Equity'!$AD$12:$AM$30,7,0) -> 0.0034190029
C15: ONT plc | D15: Unrealized | E15: Divyesh | F15: Mozn | G15: 2020 | H15: Ordinary Shares | I15: ='6. %'!F14 -> 0.053583931 | J15: 141.47026 | K15: =-SUMIF('CF (Equity, Debt)'!$C$3:$K$40,'S | 01 '!C15,'CF (Equity, Debt)'!$E$3:$E$40) -> 141.47026 | L15: 0 | M15: =SUMIF('CF (Equity, Debt)'!$C$3:$K$40,'S | 01 '!C15,'CF (Equity, Debt)'!$F$3:$F$40) -> 0 | N15: =VLOOKUP(C15,NAV!$B$4:$E$44,4,0) -> 150.40044 | O15: =N15+M15-K15 -> 8.9301789 | P15: =(M15+N15)/K15 -> 1.0631241 | Q15: =VLOOKUP(C15,'1. IRR Equity'!$AD$12:$AM$30,7,0) -> 0.019673982
C16: Heygears | D16: Unrealized | E16: Elaine | F16: Mozn | G16: 2020 | H16: Registered Capital | I16: ='6. %'!F15 -> 0.1438 | J16: 60 | K16: =-SUMIF('CF (Equity, Debt)'!$C$3:$K$40,'S | 01 '!C16,'CF (Equity, Debt)'!$E$3:$E$40) -> 60 | L16: 0 | M16: =SUMIF('CF (Equity, Debt)'!$C$3:$K$40,'S | 01 '!C16,'CF (Equity, Debt)'!$F$3:$F$40) -> 0 | N16: =VLOOKUP(C16,NAV!$B$4:$E$44,4,0) -> 151.06943 | O16: =N16+M16-K16 -> 91.069434 | P16: =(M16+N16)/K16 -> 2.5178239 | Q16: =VLOOKUP(C16,'1. IRR Equity'!$AD$12:$AM$30,7,0) -> 0.41446041
C17: Jysan Technologies | D17: Unrealized | E17: Sushil | F17: Mozn 1 | G17: 2021 | H17: A (Ordinary Shares) | I17: ='6. %'!F16 -> 0.03 | J17: 20 | K17: =-SUMIF('CF (Equity, Debt)'!$C$3:$K$40,'S | 01 '!C17,'CF (Equity, Debt)'!$E$3:$E$40) -> 20 | L17: 0 | M17: =SUMIF('CF (Equity, Debt)'!$C$3:$K$40,'S | 01 '!C17,'CF (Equity, Debt)'!$F$3:$F$40) -> 0 | N17: =VLOOKUP(C17,NAV!$B$4:$E$44,4,0) -> 20 | O17: =N17+M17-K17 -> 0 | P17: =(M17+N17)/K17 -> 1 | Q17: =VLOOKUP(C17,'1. IRR Equity'!$AD$12:$AM$30,7,0) -> 2.9802322e-09
C18: Cerebras Systems Inc | D18: Unrealized | E18: Ignasi | F18: Mozn | G18: 2021 | H18: F Prefs | I18: ='6. %'!F17 -> 0.0094767871 | J18: 40 | K18: =-SUMIF('CF (Equity, Debt)'!$C$3:$K$40,'S | 01 '!C18,'CF (Equity, Debt)'!$E$3:$E$40) -> 39.999983 | L18: 0 | M18: =SUMIF('CF (Equity, Debt)'!$C$3:$K$40,'S | 01 '!C18,'CF (Equity, Debt)'!$F$3:$F$40) -> 0 | N18: =VLOOKUP(C18,NAV!$B$4:$E$44,4,0) -> 39.999983 | O18: =N18+M18-K18 -> 0 | P18: =(M18+N18)/K18 -> 1 | Q18: =VLOOKUP(C18,'1. IRR Equity'!$AD$12:$AM$30,7,0) -> 2.9802322e-09
C19: Endless Studios LLC | D19: Unrealized | E19: Sushil | F19: Mozn | G19: 2021 | H19: A Pref Units | I19: ='6. %'!F18 -> 0.077419355 | J19: 3 | K19: =-SUMIF('CF (Equity, Debt)'!$C$3:$K$40,'S | 01 '!C19,'CF (Equity, Debt)'!$E$3:$E$40) -> 3 | L19: 0 | M19: =SUMIF('CF (Equity, Debt)'!$C$3:$K$40,'S | 01 '!C19,'CF (Equity, Debt)'!$F$3:$F$40) -> 0 | N19: =VLOOKUP(C19,NAV!$B$4:$E$44,4,0) -> 3 | O19: =N19+M19-K19 -> 0 | P19: =(M19+N19)/K19 -> 1 | Q19: =VLOOKUP(C19,'1. IRR Equity'!$AD$12:$AM$30,7,0) -> 2.9802322e-09
C20: Instadeep Limited | D20: Realized | E20: Ignasi | F20: Mozn | G20: 2021 | H20: B Prefs | I20: ='6. %'!F19 -> 0.011489406 | J20: 5.0278212 | K20: =-SUMIF('CF (Equity, Debt)'!$C$3:$K$40,'S | 01 '!C20,'CF (Equity, Debt)'!$E$3:$E$40) -> 5.0237202 | L20: 0 | M20: =SUMIF('CF (Equity, Debt)'!$C$3:$K$40,'S | 01 '!C20,'CF (Equity, Debt)'!$F$3:$F$40) -> 7.8207761 | N20: =VLOOKUP(C20,NAV!$B$4:$E$44,4,0) -> 0 | O20: =N20+M20-K20 -> 2.7970559 | P20: =(M20+N20)/K20 -> 1.5567698 | Q20: =VLOOKUP(C20,'1. IRR Equity'!$AD$12:$AM$30,7,0) -> 0.3162033
C21: X-fusion | D21: Unrealized | E21: Elaine | F21: Mozn 2 | G21: 2022 | H21: Equity-TBC | I21: ='6. %'!F20 -> 0.051 | J21: 493.5 | K21: =-SUMIF('CF (Equity, Debt)'!$C$3:$K$40,'S | 01 '!C21,'CF (Equity, Debt)'!$E$3:$E$40) -> 493.50096 | L21: 0 | M21: =SUMIF('CF (Equity, Debt)'!$C$3:$K$40,'S | 01 '!C21,'CF (Equity, Debt)'!$F$3:$F$40) -> 0 | N21: =VLOOKUP(C21,NAV!$B$4:$E$44,4,0) -> 408.28799 | O21: =N21+M21-K21 -> -85.212962 | P21: =(M21+N21)/K21 -> 0.82732969 | Q21: =VLOOKUP(C21,'1. IRR Equity'!$AD$12:$AM$30,7,0) -> -0.11544542
C22: DriveNets | D22: Unrealized | E22: Anton | F22: G42 | G22: 2022 | H22: Equity-TBC | I22: ='6. %'!F21 -> 0.11141914 | J22: 300 | K22: =-SUMIF('CF (Equity, Debt)'!$C$3:$K$40,'S | 01 '!C22,'CF (Equity, Debt)'!$E$3:$E$40) -> 300 | L22: =0 -> 0 | M22: =SUMIF('CF (Equity, Debt)'!$C$3:$K$40,'S | 01 '!C22,'CF (Equity, Debt)'!$F$3:$F$40) -> 0 | N22: =VLOOKUP(C22,NAV!$B$4:$E$44,4,0) -> 300 | O22: =N22+M22-K22 -> 0 | P22: =(M22+N22)/K22 -> 1 | Q22: =VLOOKUP(C22,'1. IRR Equity'!$AD$12:$AM$30,7,0) -> 2.9802322e-09 | R22: DN Warrants b
C23: vTv Therapeutics Inc. | D23: Unrealized | E23: Divyesh | F23: G42 | G23: 2022 | H23: Ordinary Shares | I23: ='6. %'!F22 -> 0.099316564 | J23: =K23 -> 24.53125 | K23: =-SUMIF('CF (Equity, Debt)'!$C$3:$K$40,'S | 01 '!C23,'CF (Equity, Debt)'!$E$3:$E$40) -> 24.53125 | L23: =J23-K23 -> 0 | M23: =SUMIF('CF (Equity, Debt)'!$C$3:$K$40,'S | 01 '!C23,'CF (Equity, Debt)'!$F$3:$F$40) -> 0 | N23: =VLOOKUP(C23,NAV!$B$4:$E$44,4,0) -> 7.0626663 | O23: =N23+M23-K23 -> -17.468584 | P23: =(M23+N23)/K23 -> 0.28790487 | Q23: =VLOOKUP(C23,'1. IRR Equity'!$AD$12:$AM$30,7,0) -> NM | R23: vTv $30m milestn payment c
C24: Honor Device Co Ltd | D24: Unrealized | E24: Elaine | F24: G42 3 | G24: 2022 | H24: Equity-TBC | I24: ='6. %'!F23 -> 0.018823528 | J24: =K24 -> 800 | K24: =-SUMIF('CF (Equity, Debt)'!$C$3:$K$40,'S | 01 '!C24,'CF (Equity, Debt)'!$E$3:$E$40) -> 800 | L24: =J24-K24 -> 0 | M24: =SUMIF('CF (Equity, Debt)'!$C$3:$K$40,'S | 01 '!C24,'CF (Equity, Debt)'!$F$3:$F$40) -> 0 | N24: =VLOOKUP(C24,NAV!$B$4:$E$44,4,0) -> 817.18905 | O24: =N24+M24-K24 -> 17.18905 | P24: =(M24+N24)/K24 -> 1.0214863 | Q24: =VLOOKUP(C24,'1. IRR Equity'!$AD$12:$AM$30,7,0) -> 0.022479972
C25: Applied AI Corporation Limited | D25: Unrealized | E25: Divyesh | F25: Mozn | G25: 2022 | H25: Convertible Note | I25: ='6. %'!F24 -> n/a | J25: 15 | K25: =-SUMIF('CF (Equity, Debt)'!$C$3:$K$40,'S | 01 '!C25,'CF (Equity, Debt)'!$E$3:$E$40) -> 7.5 | L25: =J25-K25 -> 7.5 | M25: 0 | N25: =VLOOKUP(C25,NAV!$B$4:$E$44,4,0) -> 7.5 | O25: =N25+M25-K25 -> 0 | P25: =(M25+N25)/K25 -> 1 | Q25: =VLOOKUP(C25,'1. IRR Equity'!$AD$12:$AM$30,7,0) -> NM
C26: eSpace | D26: Unrealized | E26: Anton | F26: Mozn 4 | G26: 2022 | H26: SAFE note | I26: ='6. %'!F25 -> n/a | J26: 15 | K26: =-SUMIF('CF (Equity, Debt)'!$C$3:$K$40,'S | 01 '!C26,'CF (Equity, Debt)'!$E$3:$E$40) -> 15 | L26: =J26-K26 -> 0 | M26: 0 | N26: =VLOOKUP(C26,NAV!$B$4:$E$44,4,0) -> 15 | O26: =N26+M26-K26 -> 0 | P26: =(M26+N26)/K26 -> 1 | Q26: =VLOOKUP(C26,'1. IRR Equity'!$AD$12:$AM$30,7,0) -> NM
C27: Tools for Humanity Corporation | D27: Unrealized | E27: Divyesh | F27: Mozn | G27: 2023 | H27: C Prefs | I27: ='6. %'!F26 -> 0.0062621983 | J27: =K27 -> 14.999999 | K27: =-SUMIF('CF (Equity, Debt)'!$C$3:$K$40,'S | 01 '!C27,'CF (Equity, Debt)'!$E$3:$E$40) -> 14.999999 | L27: =J27-K27 -> 0 | M27: =M26 -> 0 | N27: =VLOOKUP(C27,NAV!$B$4:$E$44,4,0) -> 14.999999 | O27: =N27+M27-K27 -> 0 | P27: =(M27+N27)/K27 -> 1 | Q27: =VLOOKUP(C27,'1. IRR Equity'!$AD$12:$AM$30,7,0) -> NM | R27: Token Warrants d
C28: WLD Tokens | D28: Unrealized | E28: Divyesh | F28: Mozn | G28: 2023 | H28: Tokens | I28: ='6. %'!F27 -> 0.00625 | J28: =K28 -> 0.006875 | K28: =-SUMIF('CF (Equity, Debt)'!$C$3:$K$40,'S | 01 '!C28,'CF (Equity, Debt)'!$E$3:$E$40) -> 0.006875 | L28: =J28-K28 -> 0 | M28: =M27 -> 0 | N28: =VLOOKUP(C28,NAV!$B$4:$E$44,4,0) -> 15 | O28: =N28+M28-K28 -> 14.993125 | P28: NM | Q28: =VLOOKUP(C28,'1. IRR Equity'!$AD$12:$AM$30,7,0) -> NM
J30: =SUM(J10:J28) -> 2108.0362 | K30: =SUM(K10:K28) -> 2100.533 | L30: =SUM(L10:L28) -> 7.5 | M30: =SUM(M10:M28) -> 12.820776 | N30: =SUM(N10:N28) -> 2118.5933 | O30: =SUM(O10:O28) -> 30.88107 | P30: =(M30+N30)/K30 -> 1.0147015 | Q30: ='1. IRR Equity'!AE38 -> 0.0092234105
C32: Debt Investments
C33: Glass Earth Holdings LLC | D33: In default | E33: Marty | F33: Mozn | G33: 2019 | H33: Promissory Note | I33: n/a | J33: 8 | K33: 8 | L33: 0 | M33: 0 | N33: 0 | O33: =N33+M33-K33 -> -8 | P33: =(M33+N33)/K33 -> 0 | Q33: =VLOOKUP(C33,'2. IRR Debt'!$P$9:$Y$11,7,0) -> NM
C34: Mena Mobile Inc (Debt) | D34: Unrealized | E34: Elaine | F34: Mozn | G34: 2021 | H34: Loan | I34: n/a | J34: 2.353982 | K34: =J34 -> 2.353982 | L34: 0 | M34: 0 | N34: =K34 -> 2.353982 | O34: =N34+M34-K34 -> 0 | P34: =(M34+N34)/K34 -> 1 | Q34: =VLOOKUP(C34,'2. IRR Debt'!$P$9:$Y$11,7,0) -> 2.9802322e-09
C35: Esyasoft Holding (Debt) | D35: Realized | E35: Sushil | F35: Mozn | G35: 2021 | H35: Loan | I35: n/a | J35: 0.411765 | K35: 0.411765 | L35: 0 | M35: ='CF (Equity, Debt)'!F45 -> 0.47078465 | N35: 0 | O35: =N35+M35-K35 -> 0.05901965 | P35: =(M35+N35)/K35 -> 1.1433333 | Q35: =VLOOKUP(C35,'2. IRR Debt'!$P$9:$Y$11,7,0) -> 0.075277027
J36: =SUM(J33:J35) -> 10.765747 | K36: =SUM(K33:K35) -> 10.765747 | L36: =SUM(L33:L35) -> 0 | M36: =SUM(M33:M35) -> 0.47078465 | N36: =SUM(N33:N35) -> 2.353982 | O36: =N36+M36-K36 -> -7.9409804 | P36: =(M36+N36)/K36 -> 0.26238464 | Q36: ='2. IRR Debt'!Q15 -> -0.32476586
C38: Funds Investments
C39: New Space Capital Fund I | D39: Unrealized | E39: Sushil | F39: G42 | G39: 2020 | H39: LP | I39: n/a | J39: =K39+L39 -> 28.336808 | K39: =-SUM('CF (Funds)'!D32:D38) -> 11.058035 | L39: =NAV!K49 -> 17.278774 | M39: =SUM('CF (Funds)'!E32:E38) -> 2.9557744 | N39: =VLOOKUP(C39,NAV!$B$4:$E$44,4,0) -> 13.390399 | O39: =N39+M39-K39 -> 5.2881388 | P39: 1.4784783 | Q39: =VLOOKUP(C39,'3. IRR Funds'!$P$7:$Y$15,7,0) -> 0.08799049
C40: New Space Capital GP Com SCSp | D40: Unrealized | E40: Sushil | F40: G42 | G40: 2023 | H40: LP | I40: n/a | J40: =2.3/0.85 -> 2.7058824 | K40: 2.7058824 | L40: 0 | M40: 0 | N40: =VLOOKUP(C40,NAV!$B$4:$E$44,4,0) -> 3.276608 | O40: =N40+M40-K40 -> 0.57072563 | P40: 1 | Q40: =VLOOKUP(C40,'3. IRR Funds'!$P$7:$Y$15,7,0) -> 0
C41: North Summit Capital Fund | D41: Unrealized | E41: Elaine | F41: G42 | G41: 2020 | H41: LP | I41: n/a | J41: 300 | K41: 83.214653 | L41: 217.81331 | M41: 1.027961 | N41: =VLOOKUP(C41,NAV!$B$4:$E$44,4,0) -> 81.695786 | O41: =N41+M41-K41 -> -0.490906 | P41: 0.96555063 | Q41: =VLOOKUP(C41,'3. IRR Funds'!$P$7:$Y$15,7,0) -> -0.0021562932
C42: Sinovation Disrupt Fund, L.P. | D42: Unrealized | E42: Elaine | F42: G42 | G42: 2020 | H42: LP | I42: n/a | J42: 50 | K42: =-SUM('CF (Funds)'!D3:D17) -> 20.74471 | L42: =J42-K42 -> 29.25529 | M42: 0.44382835 | N42: =VLOOKUP(C42,NAV!$B$4:$E$44,4,0) -> 19.244515 | O42: =N42+M42-K42 -> -1.0563667 | P42: 0.97193724 | Q42: =VLOOKUP(C42,'3. IRR Funds'!$P$7:$Y$15,7,0) -> -0.023361704
C43: Acies Investments Fund I, L.P. | D43: Unrealized | E43: Divyesh | F43: G42 | G43: 2021 | H43: LP | I43: 0.33 | J43: 17.1125 | K43: 14.015137 | L43: =J43-K43 -> 3.0973625 | M43: 0 | N43: =VLOOKUP(C43,NAV!$B$4:$E$44,4,0) -> 13.307625 | O43: =N43+M43-K43 -> -0.7075125 | P43: 0.97333028 | Q43: =VLOOKUP(C43,'3. IRR Funds'!$P$7:$Y$15,7,0) -> -0.04112356 | R43: 9.9% GP | Anchor e
J44: =SUM(J39:J43) -> 398.15519 | K44: =SUM(K39:K43) -> 131.73842 | L44: =SUM(L39:L43) -> 267.44473 | M44: =SUM(M39:M43) -> 4.4275637 | N44: =SUM(N39:N43) -> 130.91493 | O44: =N44+M44-K44 -> 3.6040793 | P44: =(M44+N44)/K44 -> 1.0273578 | Q44: ='3. IRR Funds'!Q18 -> 0.010083666
C46: Total | J46: =J30+J36+J44 -> 2516.9571 | K46: =K30+K36+K44 -> 2243.0372 | L46: =L30+L36+L44 -> 274.94473 | M46: =M30+M36+M44 -> 17.719124 | N46: =N30+N36+N44 -> 2251.8623 | O46: =N46+M46-K46 -> 26.544169 | P46: =(M46+N46)/K46 -> 1.011834 | Q46: ='4.All'!N9 -> 0.007097432
K47: =ROUND(K46,2)=ROUND('4.All'!J9,2) -> TRUE | M47: =ROUND(M46,2)=ROUND('4.All'!L9,2) -> TRUE | N47: =ROUND(N46,2)=ROUND('4.All'!M9,2) -> TRUE
C49: Additional Upside Section:
C50: a) Flyr: For every $1m of revenue, 194,477 shares, capped at 1,264,1000 (B-1) shares shall be issued to Mozn
...

Sheet S | 02
C2: As of date | E2: =D!D2 -> 45138
E5: 2 | F5: 3 | G5: 4 | H5: 5 | I5: 6 | J5: 7 | K5: 8 | L5: 9 | M5: 11 | N5: 12 | O5: 13 | Q5: 15 | R5: 14 | S5: 10 | T5: 16
C6: Deals | D6: Type | E6: Status | F6: Lead | G6: Investing Entity | H6: Vintageἀ | I6: Instrument | J6: % | K6: Committed | L6: Invested | M6: Distributions | N6: Carrying Value | O6: Gain | P6: Gain till FY22 | Q6: IRRβ | R6: TVPI | S6: Remaining Commitment | T6: Additonal Upside
I7: # | J7: % | K7: $,m | L7: $,m | M7: $,m | N7: $,m | O7: $,m | Q7: % | R7: X | S7: $,m | W7: MOZN
C9: WLD Tokens | D9: Direct Investment | E9: =VLOOKUP($C9,'S | 01 '!$C$6:$R$46,E$5,0) -> Unrealized | F9: =VLOOKUP($C9,'S | 01 '!$C$6:$R$46,F$5,0) -> Divyesh | G9: =VLOOKUP($C9,'S | 01 '!$C$6:$R$46,G$5,0) -> Mozn | H9: =VLOOKUP($C9,'S | 01 '!$C$6:$R$46,H$5,0) -> 2023 | I9: =VLOOKUP($C9,'S | 01 '!$C$6:$R$46,I$5,0) -> Tokens | J9: =VLOOKUP($C9,'S | 01 '!$C$6:$R$46,J$5,0) -> 0.00625 | K9: =VLOOKUP($C9,'S | 01 '!$C$6:$R$46,K$5,0) -> 0.006875 | L9: =VLOOKUP($C9,'S | 01 '!$C$6:$R$46,L$5,0) -> 0.006875 | ... O9: =VLOOKUP($C9,'S | 01 '!$C$6:$R$46,O$5,0) -> 14.993125 | P9: n/a | Q9: =VLOOKUP($C9,'S | 01 '!$C$6:$R$46,Q$5,0) -> NM | R9: =VLOOKUP($C9,'S | 01 '!$C$6:$R$46,R$5,0) -> NM | S9: =VLOOKUP($C9,'S | 01 '!$C$6:$R$46,S$5,0) -> 0
C10: Tools for Humanity Corporation | D10: Direct Investment | E10: =VLOOKUP($C10,'S | 01 '!$C$6:$R$46,E$5,0) -> Unrealized | F10: =VLOOKUP($C10,'S | 01 '!$C$6:$R$46,F$5,0) -> Divyesh | G10: =VLOOKUP($C10,'S | 01 '!$C$6:$R$46,G$5,0) -> Mozn | H10: =VLOOKUP($C10,'S | 01 '!$C$6:$R$46,H$5,0) -> 2023 | I10: =VLOOKUP($C10,'S | 01 '!$C$6:$R$46,I$5,0) -> C Prefs | J10: =VLOOKUP($C10,'S | 01 '!$C$6:$R$46,J$5,0) -> 0.0062621983 | K10: =VLOOKUP($C10,'S | 01 '!$C$6:$R$46,K$5,0) -> 14.999999 | L10: =VLOOKUP($C10,'S | 01 '!$C$6:$R$46,L$5,0) -> 14.999999 | ... O10: =VLOOKUP($C10,'S | 01 '!$C$6:$R$46,O$5,0) -> 0 | P10: n/a | Q10: =VLOOKUP($C10,'S | 01 '!$C$6:$R$46,Q$5,0) -> NM | R10: =VLOOKUP($C10,'S | 01 '!$C$6:$R$46,R$5,0) -> 1 | S10: =VLOOKUP($C10,'S | 01 '!$C$6:$R$46,S$5,0) -> 0 | T10: Token Warrants d
C11: eSpace | D11: Direct Investment | E11: =VLOOKUP($C11,'S | 01 '!$C$6:$R$46,E$5,0) -> Unrealized | F11: =VLOOKUP($C11,'S | 01 '!$C$6:$R$46,F$5,0) -> Anton | G11: =VLOOKUP($C11,'S | 01 '!$C$6:$R$46,G$5,0) -> Mozn 4 | H11: =VLOOKUP($C11,'S | 01 '!$C$6:$R$46,H$5,0) -> 2022 | I11: =VLOOKUP($C11,'S | 01 '!$C$6:$R$46,I$5,0) -> SAFE note | J11: =VLOOKUP($C11,'S | 01 '!$C$6:$R$46,J$5,0) -> n/a | K11: =VLOOKUP($C11,'S | 01 '!$C$6:$R$46,K$5,0) -> 15 | L11: =VLOOKUP($C11,'S | 01 '!$C$6:$R$46,L$5,0) -> 15 | ... O11: =VLOOKUP($C11,'S | 01 '!$C$6:$R$46,O$5,0) -> 0 | P11: 0 | Q11: =VLOOKUP($C11,'S | 01 '!$C$6:$R$46,Q$5,0) -> NM | R11: =VLOOKUP($C11,'S | 01 '!$C$6:$R$46,R$5,0) -> 1 | S11: =VLOOKUP($C11,'S | 01 '!$C$6:$R$46,S$5,0) -> 0 | W11: Invested | X11: =L29 -> 986.76754
C12: Applied AI Corporation Limited | D12: Direct Investment | E12: =VLOOKUP($C12,'S | 01 '!$C$6:$R$46,E$5,0) -> Unrealized | F12: =VLOOKUP($C12,'S | 01 '!$C$6:$R$46,F$5,0) -> Divyesh | G12: =VLOOKUP($C12,'S | 01 '!$C$6:$R$46,G$5,0) -> Mozn | H12: =VLOOKUP($C12,'S | 01 '!$C$6:$R$46,H$5,0) -> 2022 | I12: =VLOOKUP($C12,'S | 01 '!$C$6:$R$46,I$5,0) -> Convertible Note | J12: =VLOOKUP($C12,'S | 01 '!$C$6:$R$46,J$5,0) -> n/a | K12: =VLOOKUP($C12,'S | 01 '!$C$6:$R$46,K$5,0) -> 15 | L12: =VLOOKUP($C12,'S | 01 '!$C$6:$R$46,L$5,0) -> 7.5 | ... O12: =VLOOKUP($C12,'S | 01 '!$C$6:$R$46,O$5,0) -> 0 | P12: 0 | Q12: =VLOOKUP($C12,'S | 01 '!$C$6:$R$46,Q$5,0) -> NM | R12: =VLOOKUP($C12,'S | 01 '!$C$6:$R$46,R$5,0) -> 1 | S12: =VLOOKUP($C12,'S | 01 '!$C$6:$R$46,S$5,0) -> 7.5 | W12: NAV | X12: =N29 -> 996.6956
C13: X-fusion | D13: Direct Investment | E13: =VLOOKUP($C13,'S | 01 '!$C$6:$R$46,E$5,0) -> Unrealized | F13: =VLOOKUP($C13,'S | 01 '!$C$6:$R$46,F$5,0) -> Elaine | G13: =VLOOKUP($C13,'S | 01 '!$C$6:$R$46,G$5,0) -> Mozn 2 | H13: =VLOOKUP($C13,'S | 01 '!$C$6:$R$46,H$5,0) -> 2022 | I13: =VLOOKUP($C13,'S | 01 '!$C$6:$R$46,I$5,0) -> Equity-TBC | J13: =VLOOKUP($C13,'S | 01 '!$C$6:$R$46,J$5,0) -> 0.051 | K13: =VLOOKUP($C13,'S | 01 '!$C$6:$R$46,K$5,0) -> 493.5 | L13: =VLOOKUP($C13,'S | 01 '!$C$6:$R$46,L$5,0) -> 493.50096 | ... O13: =VLOOKUP($C13,'S | 01 '!$C$6:$R$46,O$5,0) -> -85.212962 | P13: -64.391 | Q13: =VLOOKUP($C13,'S | 01 '!$C$6:$R$46,Q$5,0) -> -0.11544542 | R13: =VLOOKUP($C13,'S | 01 '!$C$6:$R$46,R$5,0) -> 0.82732969 | S13: =VLOOKUP($C13,'S | 01 '!$C$6:$R$46,S$5,0) -> 0 | W13: Gain | X13: =O29 -> 23.219623
C14: Mena Mobile Inc (Debt) | D14: Debt Investment | E14: =VLOOKUP($C14,'S | 01 '!$C$6:$R$46,E$5,0) -> Unrealized | F14: =VLOOKUP($C14,'S | 01 '!$C$6:$R$46,F$5,0) -> Elaine | G14: =VLOOKUP($C14,'S | 01 '!$C$6:$R$46,G$5,0) -> Mozn | H14: =VLOOKUP($C14,'S | 01 '!$C$6:$R$46,H$5,0) -> 2021 | I14: =VLOOKUP($C14,'S | 01 '!$C$6:$R$46,I$5,0) -> Loan | J14: =VLOOKUP($C14,'S | 01 '!$C$6:$R$46,J$5,0) -> n/a | K14: =VLOOKUP($C14,'S | 01 '!$C$6:$R$46,K$5,0) -> 2.353982 | L14: =VLOOKUP($C14,'S | 01 '!$C$6:$R$46,L$5,0) -> 2.353982 | ... O14: =VLOOKUP($C14,'S | 01 '!$C$6:$R$46,O$5,0) -> 0 | P14: 0 | Q14: =VLOOKUP($C14,'S | 01 '!$C$6:$R$46,Q$5,0) -> 2.9802322e-09 | R14: =VLOOKUP($C14,'S | 01 '!$C$6:$R$46,R$5,0) -> 1 | S14: =VLOOKUP($C14,'S | 01 '!$C$6:$R$46,S$5,0) -> 0 | W14: YTD Gains | X14: =X13-P29 -> 8.6824242
C15: Esyasoft Holding (Debt) | D15: Debt Investment | E15: =VLOOKUP($C15,'S | 01 '!$C$6:$R$46,E$5,0) -> Realized | F15: =VLOOKUP($C15,'S | 01 '!$C$6:$R$46,F$5,0) -> Sushil | G15: =VLOOKUP($C15,'S | 01 '!$C$6:$R$46,G$5,0) -> Mozn | H15: =VLOOKUP($C15,'S | 01 '!$C$6:$R$46,H$5,0) -> 2021 | I15: =VLOOKUP($C15,'S | 01 '!$C$6:$R$46,I$5,0) -> Loan | J15: =VLOOKUP($C15,'S | 01 '!$C$6:$R$46,J$5,0) -> n/a | K15: =VLOOKUP($C15,'S | 01 '!$C$6:$R$46,K$5,0) -> 0.411765 | L15: =VLOOKUP($C15,'S | 01 '!$C$6:$R$46,L$5,0) -> 0.411765 | ... O15: =VLOOKUP($C15,'S | 01 '!$C$6:$R$46,O$5,0) -> 0.05901965 | P15: 0.05901965 | Q15: =VLOOKUP($C15,'S | 01 '!$C$6:$R$46,Q$5,0) -> 0.075277027 | R15: =VLOOKUP($C15,'S | 01 '!$C$6:$R$46,R$5,0) -> 1.1433333 | S15: =VLOOKUP($C15,'S | 01 '!$C$6:$R$46,S$5,0) -> 0 | W15: IRR | X15: =Q29 -> 0.010515186
C16: Jysan Technologies | D16: Direct Investment | E16: =VLOOKUP($C16,'S | 01 '!$C$6:$R$46,E$5,0) -> Unrealized | F16: =VLOOKUP($C16,'S | 01 '!$C$6:$R$46,F$5,0) -> Sushil | G16: =VLOOKUP($C16,'S | 01 '!$C$6:$R$46,G$5,0) -> Mozn 1 | H16: =VLOOKUP($C16,'S | 01 '!$C$6:$R$46,H$5,0) -> 2021 | I16: =VLOOKUP($C16,'S | 01 '!$C$6:$R$46,I$5,0) -> A (Ordinary Shares) | J16: =VLOOKUP($C16,'S | 01 '!$C$6:$R$46,J$5,0) -> 0.03 | K16: =VLOOKUP($C16,'S | 01 '!$C$6:$R$46,K$5,0) -> 20 | L16: =VLOOKUP($C16,'S | 01 '!$C$6:$R$46,L$5,0) -> 20 | ... O16: =VLOOKUP($C16,'S | 01 '!$C$6:$R$46,O$5,0) -> 0 | P16: 0 | Q16: =VLOOKUP($C16,'S | 01 '!$C$6:$R$46,Q$5,0) -> 2.9802322e-09 | R16: =VLOOKUP($C16,'S | 01 '!$C$6:$R$46,R$5,0) -> 1 | S16: =VLOOKUP($C16,'S | 01 '!$C$6:$R$46,S$5,0) -> 0
C17: Instadeep Limited | D17: Direct Investment | E17: =VLOOKUP($C17,'S | 01 '!$C$6:$R$46,E$5,0) -> Realized | F17: =VLOOKUP($C17,'S | 01 '!$C$6:$R$46,F$5,0) -> Ignasi | G17: =VLOOKUP($C17,'S | 01 '!$C$6:$R$46,G$5,0) -> Mozn | H17: =VLOOKUP($C17,'S | 01 '!$C$6:$R$46,H$5,0) -> 2021 | I17: =VLOOKUP($C17,'S | 01 '!$C$6:$R$46,I$5,0) -> B Prefs | J17: =VLOOKUP($C17,'S | 01 '!$C$6:$R$46,J$5,0) -> 0.011489406 | K17: =VLOOKUP($C17,'S | 01 '!$C$6:$R$46,K$5,0) -> 5.0278212 | L17: =VLOOKUP($C17,'S | 01 '!$C$6:$R$46,L$5,0) -> 5.0237202 | ... O17: =VLOOKUP($C17,'S | 01 '!$C$6:$R$46,O$5,0) -> 2.7970559 | P17: 1.6721788 | Q17: =VLOOKUP($C17,'S | 01 '!$C$6:$R$46,Q$5,0) -> 0.3162033 | R17: =VLOOKUP($C17,'S | 01 '!$C$6:$R$46,R$5,0) -> 1.5567698 | S17: =VLOOKUP($C17,'S | 01 '!$C$6:$R$46,S$5,0) -> 0
C18: Cerebras Systems Inc | D18: Direct Investment | E18: =VLOOKUP($C18,'S | 01 '!$C$6:$R$46,E$5,0) -> Unrealized | F18: =VLOOKUP($C18,'S | 01 '!$C$6:$R$46,F$5,0) -> Ignasi | G18: =VLOOKUP($C18,'S | 01 '!$C$6:$R$46,G$5,0) -> Mozn | H18: =VLOOKUP($C18,'S | 01 '!$C$6:$R$46,H$5,0) -> 2021 | I18: =VLOOKUP($C18,'S | 01 '!$C$6:$R$46,I$5,0) -> F Prefs | J18: =VLOOKUP($C18,'S | 01 '!$C$6:$R$46,J$5,0) -> 0.0094767871 | K18: =VLOOKUP($C18,'S | 01 '!$C$6:$R$46,K$5,0) -> 40 | L18: =VLOOKUP($C18,'S | 01 '!$C$6:$R$46,L$5,0) -> 39.999983 | ... O18: =VLOOKUP($C18,'S | 01 '!$C$6:$R$46,O$5,0) -> 0 | P18: 0 | Q18: =VLOOKUP($C18,'S | 01 '!$C$6:$R$46,Q$5,0) -> 2.9802322e-09 | R18: =VLOOKUP($C18,'S | 01 '!$C$6:$R$46,R$5,0) -> 1 | S18: =VLOOKUP($C18,'S | 01 '!$C$6:$R$46,S$5,0) -> 0
C19: Endless Studios LLC | D19: Direct Investment | E19: =VLOOKUP($C19,'S | 01 '!$C$6:$R$46,E$5,0) -> Unrealized | F19: =VLOOKUP($C19,'S | 01 '!$C$6:$R$46,F$5,0) -> Sushil | G19: =VLOOKUP($C19,'S | 01 '!$C$6:$R$46,G$5,0) -> Mozn | H19: =VLOOKUP($C19,'S | 01 '!$C$6:$R$46,H$5,0) -> 2021 | I19: =VLOOKUP($C19,'S | 01 '!$C$6:$R$46,I$5,0) -> A Pref Units | J19: =VLOOKUP($C19,'S | 01 '!$C$6:$R$46,J$5,0) -> 0.077419355 | K19: =VLOOKUP($C19,'S | 01 '!$C$6:$R$46,K$5,0) -> 3 | L19: =VLOOKUP($C19,'S | 01 '!$C$6:$R$46,L$5,0) -> 3 | ... O19: =VLOOKUP($C19,'S | 01 '!$C$6:$R$46,O$5,0) -> 0 | P19: 0 | Q19: =VLOOKUP($C19,'S | 01 '!$C$6:$R$46,Q$5,0) -> 2.9802322e-09 | R19: =VLOOKUP($C19,'S | 01 '!$C$6:$R$46,R$5,0) -> 1 | S19: =VLOOKUP($C19,'S | 01 '!$C$6:$R$46,S$5,0) -> 0
C20: Esyasoft Holding | D20: Direct Investment | E20: =VLOOKUP($C20,'S | 01 '!$C$6:$R$46,E$5,0) -> Realized | F20: =VLOOKUP($C20,'S | 01 '!$C$6:$R$46,F$5,0) -> Sushil | G20: =VLOOKUP($C20,'S | 01 '!$C$6:$R$46,G$5,0) -> Mozn | H20: =VLOOKUP($C20,'S | 01 '!$C$6:$R$46,H$5,0) -> 2020 | I20: =VLOOKUP($C20,'S | 01 '!$C$6:$R$46,I$5,0) -> Convertible Note | J20: =VLOOKUP($C20,'S | 01 '!$C$6:$R$46,J$5,0) -> n/a | K20: =VLOOKUP($C20,'S | 01 '!$C$6:$R$46,K$5,0) -> 2.5 | L20: =VLOOKUP($C20,'S | 01 '!$C$6:$R$46,L$5,0) -> 2.5 | ... O20: =VLOOKUP($C20,'S | 01 '!$C$6:$R$46,O$5,0) -> 2.5 | P20: 2.5 | Q20: =VLOOKUP($C20,'S | 01 '!$C$6:$R$46,Q$5,0) -> 0.36091766 | R20: =VLOOKUP($C20,'S | 01 '!$C$6:$R$46,R$5,0) -> 2 | S20: =VLOOKUP($C20,'S | 01 '!$C$6:$R$46,S$5,0) -> 0
C21: Heygears | D21: Direct Investment | E21: =VLOOKUP($C21,'S | 01 '!$C$6:$R$46,E$5,0) -> Unrealized | F21: =VLOOKUP($C21,'S | 01 '!$C$6:$R$46,F$5,0) -> Elaine | G21: =VLOOKUP($C21,'S | 01 '!$C$6:$R$46,G$5,0) -> Mozn | H21: =VLOOKUP($C21,'S | 01 '!$C$6:$R$46,H$5,0) -> 2020 | I21: =VLOOKUP($C21,'S | 01 '!$C$6:$R$46,I$5,0) -> Registered Capital | J21: =VLOOKUP($C21,'S | 01 '!$C$6:$R$46,J$5,0) -> 0.1438 | K21: =VLOOKUP($C21,'S | 01 '!$C$6:$R$46,K$5,0) -> 60 | L21: =VLOOKUP($C21,'S | 01 '!$C$6:$R$46,L$5,0) -> 60 | ... O21: =VLOOKUP($C21,'S | 01 '!$C$6:$R$46,O$5,0) -> 91.069434 | P21: 96.4 | Q21: =VLOOKUP($C21,'S | 01 '!$C$6:$R$46,Q$5,0) -> 0.41446041 | R21: =VLOOKUP($C21,'S | 01 '!$C$6:$R$46,R$5,0) -> 2.5178239 | S21: =VLOOKUP($C21,'S | 01 '!$C$6:$R$46,S$5,0) -> 0
C22: Beyond Limits | D22: Direct Investment | E22: =VLOOKUP($C22,'S | 01 '!$C$6:$R$46,E$5,0) -> Unrealized | F22: =VLOOKUP($C22,'S | 01 '!$C$6:$R$46,F$5,0) -> Divyesh | G22: =VLOOKUP($C22,'S | 01 '!$C$6:$R$46,G$5,0) -> Mozn | H22: =VLOOKUP($C22,'S | 01 '!$C$6:$R$46,H$5,0) -> 2020 | I22: =VLOOKUP($C22,'S | 01 '!$C$6:$R$46,I$5,0) -> C Prefs | J22: =VLOOKUP($C22,'S | 01 '!$C$6:$R$46,J$5,0) -> 0.097965107 | K22: =VLOOKUP($C22,'S | 01 '!$C$6:$R$46,K$5,0) -> 90 | L22: =VLOOKUP($C22,'S | 01 '!$C$6:$R$46,L$5,0) -> 90 | ... O22: =VLOOKUP($C22,'S | 01 '!$C$6:$R$46,O$5,0) -> 1.0015403 | P22: 1.042 | Q22: =VLOOKUP($C22,'S | 01 '!$C$6:$R$46,Q$5,0) -> 0.0034190029 | R22: =VLOOKUP($C22,'S | 01 '!$C$6:$R$46,R$5,0) -> 1.0111282 | S22: =VLOOKUP($C22,'S | 01 '!$C$6:$R$46,S$5,0) -> 0
C23: ONT plc | D23: Direct Investment | E23: =VLOOKUP($C23,'S | 01 '!$C$6:$R$46,E$5,0) -> Unrealized | F23: =VLOOKUP($C23,'S | 01 '!$C$6:$R$46,F$5,0) -> Divyesh | G23: =VLOOKUP($C23,'S | 01 '!$C$6:$R$46,G$5,0) -> Mozn | H23: =VLOOKUP($C23,'S | 01 '!$C$6:$R$46,H$5,0) -> 2020 | I23: =VLOOKUP($C23,'S | 01 '!$C$6:$R$46,I$5,0) -> Ordinary Shares | J23: =VLOOKUP($C23,'S | 01 '!$C$6:$R$46,J$5,0) -> 0.053583931 | K23: =VLOOKUP($C23,'S | 01 '!$C$6:$R$46,K$5,0) -> 141.47026 | L23: =VLOOKUP($C23,'S | 01 '!$C$6:$R$46,L$5,0) -> 141.47026 | ... O23: =VLOOKUP($C23,'S | 01 '!$C$6:$R$46,O$5,0) -> 8.9301789 | P23: -9.845 | Q23: =VLOOKUP($C23,'S | 01 '!$C$6:$R$46,Q$5,0) -> 0.019673982 | R23: =VLOOKUP($C23,'S | 01 '!$C$6:$R$46,R$5,0) -> 1.0631241 | S23: =VLOOKUP($C23,'S | 01 '!$C$6:$R$46,S$5,0) -> 0
C24: Flyr Inc | D24: Direct Investment | E24: =VLOOKUP($C24,'S | 01 '!$C$6:$R$46,E$5,0) -> Unrealized | F24: =VLOOKUP($C24,'S | 01 '!$C$6:$R$46,F$5,0) -> Sushil | G24: =VLOOKUP($C24,'S | 01 '!$C$6:$R$46,G$5,0) -> Mozn | H24: =VLOOKUP($C24,'S | 01 '!$C$6:$R$46,H$5,0) -> 2019 | I24: =VLOOKUP($C24,'S | 01 '!$C$6:$R$46,I$5,0) -> B-1,2 Prefs | J24: =VLOOKUP($C24,'S | 01 '!$C$6:$R$46,J$5,0) -> 0.085025485 | K24: =VLOOKUP($C24,'S | 01 '!$C$6:$R$46,K$5,0) -> 10 | L24: =VLOOKUP($C24,'S | 01 '!$C$6:$R$46,L$5,0) -> 10 | ... O24: =VLOOKUP($C24,'S | 01 '!$C$6:$R$46,O$5,0) -> 68.08223 | P24: 68.1 | Q24: =VLOOKUP($C24,'S | 01 '!$C$6:$R$46,Q$5,0) -> 0.69797844 | R24: =VLOOKUP($C24,'S | 01 '!$C$6:$R$46,R$5,0) -> 7.808223 | S24: =VLOOKUP($C24,'S | 01 '!$C$6:$R$46,S$5,0) -> 0 | T24: Flyr Warrantsa
C25: Mena Mobile Inc | D25: Direct Investment | E25: =VLOOKUP($C25,'S | 01 '!$C$6:$R$46,E$5,0) -> Unrealized | F25: =VLOOKUP($C25,'S | 01 '!$C$6:$R$46,F$5,0) -> Elaine | G25: =VLOOKUP($C25,'S | 01 '!$C$6:$R$46,G$5,0) -> Mozn | H25: =VLOOKUP($C25,'S | 01 '!$C$6:$R$46,H$5,0) -> 2019 | I25: =VLOOKUP($C25,'S | 01 '!$C$6:$R$46,I$5,0) -> B Prefs | J25: =VLOOKUP($C25,'S | 01 '!$C$6:$R$46,J$5,0) -> 0.14 | K25: =VLOOKUP($C25,'S | 01 '!$C$6:$R$46,K$5,0) -> 8 | L25: =VLOOKUP($C25,'S | 01 '!$C$6:$R$46,L$5,0) -> 8 | ... O25: =VLOOKUP($C25,'S | 01 '!$C$6:$R$46,O$5,0) -> -8 | P25: -8 | Q25: =VLOOKUP($C25,'S | 01 '!$C$6:$R$46,Q$5,0) -> NM | R25: =VLOOKUP($C25,'S | 01 '!$C$6:$R$46,R$5,0) -> 0 | S25: =VLOOKUP($C25,'S | 01 '!$C$6:$R$46,S$5,0) -> 0
C26: Glass Earth Holdings LLC | D26: Debt Investment | E26: =VLOOKUP($C26,'S | 01 '!$C$6:$R$46,E$5,0) -> In default | F26: =VLOOKUP($C26,'S | 01 '!$C$6:$R$46,F$5,0) -> Marty | G26: =VLOOKUP($C26,'S | 01 '!$C$6:$R$46,G$5,0) -> Mozn | H26: =VLOOKUP($C26,'S | 01 '!$C$6:$R$46,H$5,0) -> 2019 | I26: =VLOOKUP($C26,'S | 01 '!$C$6:$R$46,I$5,0) -> Promissory Note | J26: =VLOOKUP($C26,'S | 01 '!$C$6:$R$46,J$5,0) -> n/a | K26: =VLOOKUP($C26,'S | 01 '!$C$6:$R$46,K$5,0) -> 8 | L26: =VLOOKUP($C26,'S | 01 '!$C$6:$R$46,L$5,0) -> 8 | ... O26: =VLOOKUP($C26,'S | 01 '!$C$6:$R$46,O$5,0) -> -8 | P26: -8 | Q26: =VLOOKUP($C26,'S | 01 '!$C$6:$R$46,Q$5,0) -> NM | R26: =VLOOKUP($C26,'S | 01 '!$C$6:$R$46,R$5,0) -> 0 | S26: =VLOOKUP($C26,'S | 01 '!$C$6:$R$46,S$5,0) -> 0
C27: Jollychic Holding Limited | D27: Direct Investment | E27: =VLOOKUP($C27,'S | 01 '!$C$6:$R$46,E$5,0) -> In Liquidation | F27: =VLOOKUP($C27,'S | 01 '!$C$6:$R$46,F$5,0) -> Elaine | G27: =VLOOKUP($C27,'S | 01 '!$C$6:$R$46,G$5,0) -> Mozn | H27: =VLOOKUP($C27,'S | 01 '!$C$6:$R$46,H$5,0) -> 2019 | I27: =VLOOKUP($C27,'S | 01 '!$C$6:$R$46,I$5,0) -> C+ Prefs | J27: =VLOOKUP($C27,'S | 01 '!$C$6:$R$46,J$5,0) -> 0.056999998 | K27: =VLOOKUP($C27,'S | 01 '!$C$6:$R$46,K$5,0) -> 65 | L27: =VLOOKUP($C27,'S | 01 '!$C$6:$R$46,L$5,0) -> 65 | ... O27: =VLOOKUP($C27,'S | 01 '!$C$6:$R$46,O$5,0) -> -65 | P27: -65 | Q27: =VLOOKUP($C27,'S | 01 '!$C$6:$R$46,Q$5,0) -> NM | R27: =VLOOKUP($C27,'S | 01 '!$C$6:$R$46,R$5,0) -> 0 | S27: =VLOOKUP($C27,'S | 01 '!$C$6:$R$46,S$5,0) -> 0
K29: =SUM(K9:K27) -> 994.2707 | L29: =SUM(L9:L27) -> 986.76754 | M29: =SUM(M9:M27) -> 13.291561 | N29: =SUM(N9:N27) -> 996.6956 | O29: =SUM(O9:O27) -> 23.219623 | P29: =SUM(P9:P27) -> 14.537198 | Q29: ='4. Mozn-IRR'!L16 -> 0.010515186 | R29: =(M29+N29)/L29 -> 1.023531 | S29: =SUM(S9:S27) -> 7.5
C31: Honor Device Co Ltd | D31: Direct Investment | E31: =VLOOKUP($C31,'S | 01 '!$C$6:$R$46,E$5,0) -> Unrealized | F31: =VLOOKUP($C31,'S | 01 '!$C$6:$R$46,F$5,0) -> Elaine | G31: =VLOOKUP($C31,'S | 01 '!$C$6:$R$46,G$5,0) -> G42 3 | H31: =VLOOKUP($C31,'S | 01 '!$C$6:$R$46,H$5,0) -> 2022 | I31: =VLOOKUP($C31,'S | 01 '!$C$6:$R$46,I$5,0) -> Equity-TBC | J31: =VLOOKUP($C31,'S | 01 '!$C$6:$R$46,J$5,0) -> 0.018823528 | K31: =VLOOKUP($C31,'S | 01 '!$C$6:$R$46,K$5,0) -> 800 | L31: =VLOOKUP($C31,'S | 01 '!$C$6:$R$46,L$5,0) -> 800 | ... O31: =VLOOKUP($C31,'S | 01 '!$C$6:$R$46,O$5,0) -> 17.18905 | P31: 54.67 | Q31: =VLOOKUP($C31,'S | 01 '!$C$6:$R$46,Q$5,0) -> 0.022479972 | R31: =VLOOKUP($C31,'S | 01 '!$C$6:$R$46,R$5,0) -> 1.0214863 | S31: =VLOOKUP($C31,'S | 01 '!$C$6:$R$46,S$5,0) -> 0 | W31: G42
C32: DriveNets | D32: Direct Investment | E32: =VLOOKUP($C32,'S | 01 '!$C$6:$R$46,E$5,0) -> Unrealized | F32: =VLOOKUP($C32,'S | 01 '!$C$6:$R$46,F$5,0) -> Anton | G32: =VLOOKUP($C32,'S | 01 '!$C$6:$R$46,G$5,0) -> G42 | H32: =VLOOKUP($C32,'S | 01 '!$C$6:$R$46,H$5,0) -> 2022 | I32: =VLOOKUP($C32,'S | 01 '!$C$6:$R$46,I$5,0) -> Equity-TBC | J32: =VLOOKUP($C32,'S | 01 '!$C$6:$R$46,J$5,0) -> 0.11141914 | K32: =VLOOKUP($C32,'S | 01 '!$C$6:$R$46,K$5,0) -> 300 | L32: =VLOOKUP($C32,'S | 01 '!$C$6:$R$46,L$5,0) -> 300 | ... O32: =VLOOKUP($C32,'S | 01 '!$C$6:$R$46,O$5,0) -> 0 | P32: 0 | Q32: =VLOOKUP($C32,'S | 01 '!$C$6:$R$46,Q$5,0) -> 2.9802322e-09 | R32: =VLOOKUP($C32,'S | 01 '!$C$6:$R$46,R$5,0) -> 1 | S32: =VLOOKUP($C32,'S | 01 '!$C$6:$R$46,S$5,0) -> 0 | T32: DN Warrants b
C33: vTv Therapeutics Inc. | D33: Direct Investment | E33: =VLOOKUP($C33,'S | 01 '!$C$6:$R$46,E$5,0) -> Unrealized | F33: =VLOOKUP($C33,'S | 01 '!$C$6:$R$46,F$5,0) -> Divyesh | G33: =VLOOKUP($C33,'S | 01 '!$C$6:$R$46,G$5,0) -> G42 | H33: =VLOOKUP($C33,'S | 01 '!$C$6:$R$46,H$5,0) -> 2022 | I33: =VLOOKUP($C33,'S | 01 '!$C$6:$R$46,I$5,0) -> Ordinary Shares | J33: =VLOOKUP($C33,'S | 01 '!$C$6:$R$46,J$5,0) -> 0.099316564 | K33: =VLOOKUP($C33,'S | 01 '!$C$6:$R$46,K$5,0) -> 24.53125 | L33: =VLOOKUP($C33,'S | 01 '!$C$6:$R$46,L$5,0) -> 24.53125 | ... O33: =VLOOKUP($C33,'S | 01 '!$C$6:$R$46,O$5,0) -> -17.468584 | P33: -1.348 | Q33: =VLOOKUP($C33,'S | 01 '!$C$6:$R$46,Q$5,0) -> NM | R33: =VLOOKUP($C33,'S | 01 '!$C$6:$R$46,R$5,0) -> 0.28790487 | S33: =VLOOKUP($C33,'S | 01 '!$C$6:$R$46,S$5,0) -> 0 | T33: vTv $30m milestn payment c | W33: Invested | X33: =L40 -> 1256.2697
C34: North Summit Capital Fund | D34: Fund Investment | E34: =VLOOKUP($C34,'S | 01 '!$C$6:$R$46,E$5,0) -> Unrealized | F34: =VLOOKUP($C34,'S | 01 '!$C$6:$R$46,F$5,0) -> Elaine | G34: =VLOOKUP($C34,'S | 01 '!$C$6:$R$46,G$5,0) -> G42 | H34: =VLOOKUP($C34,'S | 01 '!$C$6:$R$46,H$5,0) -> 2020 | I34: =VLOOKUP($C34,'S | 01 '!$C$6:$R$46,I$5,0) -> LP | J34: =VLOOKUP($C34,'S | 01 '!$C$6:$R$46,J$5,0) -> n/a | K34: =VLOOKUP($C34,'S | 01 '!$C$6:$R$46,K$5,0) -> 300 | L34: =VLOOKUP($C34,'S | 01 '!$C$6:$R$46,L$5,0) -> 83.214653 | ... O34: =VLOOKUP($C34,'S | 01 '!$C$6:$R$46,O$5,0) -> -0.490906 | P34: -0.306 | Q34: =VLOOKUP($C34,'S | 01 '!$C$6:$R$46,Q$5,0) -> -0.0021562932 | R34: =VLOOKUP($C34,'S | 01 '!$C$6:$R$46,R$5,0) -> 0.96555063 | S34: =VLOOKUP($C34,'S | 01 '!$C$6:$R$46,S$5,0) -> 217.81331 | W34: NAV | X34: =N40 -> 1255.1666
C35: New Space Capital Fund I | D35: Fund Investment | E35: =VLOOKUP($C35,'S | 01 '!$C$6:$R$46,E$5,0) -> Unrealized | F35: =VLOOKUP($C35,'S | 01 '!$C$6:$R$46,F$5,0) -> Sushil | G35: =VLOOKUP($C35,'S | 01 '!$C$6:$R$46,G$5,0) -> G42 | H35: =VLOOKUP($C35,'S | 01 '!$C$6:$R$46,H$5,0) -> 2020 | I35: =VLOOKUP($C35,'S | 01 '!$C$6:$R$46,I$5,0) -> LP | J35: =VLOOKUP($C35,'S | 01 '!$C$6:$R$46,J$5,0) -> n/a | K35: =VLOOKUP($C35,'S | 01 '!$C$6:$R$46,K$5,0) -> 28.336808 | L35: =VLOOKUP($C35,'S | 01 '!$C$6:$R$46,L$5,0) -> 11.058035 | ... O35: =VLOOKUP($C35,'S | 01 '!$C$6:$R$46,O$5,0) -> 5.2881388 | P35: 5.445 | Q35: =VLOOKUP($C35,'S | 01 '!$C$6:$R$46,Q$5,0) -> 0.08799049 | R35: =VLOOKUP($C35,'S | 01 '!$C$6:$R$46,R$5,0) -> 1.4784783 | S35: =VLOOKUP($C35,'S | 01 '!$C$6:$R$46,S$5,0) -> 17.278774 | W35: Gain | X35: =O40 -> 3.324546
C36: New Space Capital GP Com SCSp | D36: Fund Investment | E36: =VLOOKUP($C36,'S | 01 '!$C$6:$R$46,E$5,0) -> Unrealized | F36: =VLOOKUP($C36,'S | 01 '!$C$6:$R$46,F$5,0) -> Sushil | G36: =VLOOKUP($C36,'S | 01 '!$C$6:$R$46,G$5,0) -> G42 | H36: =VLOOKUP($C36,'S | 01 '!$C$6:$R$46,H$5,0) -> 2023 | I36: =VLOOKUP($C36,'S | 01 '!$C$6:$R$46,I$5,0) -> LP | J36: =VLOOKUP($C36,'S | 01 '!$C$6:$R$46,J$5,0) -> n/a | K36: =VLOOKUP($C36,'S | 01 '!$C$6:$R$46,K$5,0) -> 2.7058824 | L36: =VLOOKUP($C36,'S | 01 '!$C$6:$R$46,L$5,0) -> 2.7058824 | ... O36: =VLOOKUP($C36,'S | 01 '!$C$6:$R$46,O$5,0) -> 0.57072563 | P36: 0 | Q36: =VLOOKUP($C36,'S | 01 '!$C$6:$R$46,Q$5,0) -> 0 | R36: =VLOOKUP($C36,'S | 01 '!$C$6:$R$46,R$5,0) -> 1 | S36: =VLOOKUP($C36,'S | 01 '!$C$6:$R$46,S$5,0) -> 0 | W36: YTD Gains | X36: =O40-P40 -> -53.565454
C37: Sinovation Disrupt Fund, L.P. | D37: Fund Investment | E37: =VLOOKUP($C37,'S | 01 '!$C$6:$R$46,E$5,0) -> Unrealized | F37: =VLOOKUP($C37,'S | 01 '!$C$6:$R$46,F$5,0) -> Elaine | G37: =VLOOKUP($C37,'S | 01 '!$C$6:$R$46,G$5,0) -> G42 | H37: =VLOOKUP($C37,'S | 01 '!$C$6:$R$46,H$5,0) -> 2020 | I37: =VLOOKUP($C37,'S | 01 '!$C$6:$R$46,I$5,0) -> LP | J37: =VLOOKUP($C37,'S | 01 '!$C$6:$R$46,J$5,0) -> n/a | K37: =VLOOKUP($C37,'S | 01 '!$C$6:$R$46,K$5,0) -> 50 | L37: =VLOOKUP($C37,'S | 01 '!$C$6:$R$46,L$5,0) -> 20.74471 | ... O37: =VLOOKUP($C37,'S | 01 '!$C$6:$R$46,O$5,0) -> -1.0563667 | P37: -1.265 | Q37: =VLOOKUP($C37,'S | 01 '!$C$6:$R$46,Q$5,0) -> -0.023361704 | R37: =VLOOKUP($C37,'S | 01 '!$C$6:$R$46,R$5,0) -> 0.97193724 | S37: =VLOOKUP($C37,'S | 01 '!$C$6:$R$46,S$5,0) -> 29.25529 | W37: IRR | X37: =Q40 -> 0.0021642417
C38: Acies Investments Fund I, L.P. | D38: Fund Investment | E38: =VLOOKUP($C38,'S | 01 '!$C$6:$R$46,E$5,0) -> Unrealized | F38: =VLOOKUP($C38,'S | 01 '!$C$6:$R$46,F$5,0) -> Divyesh | G38: =VLOOKUP($C38,'S | 01 '!$C$6:$R$46,G$5,0) -> G42 | H38: =VLOOKUP($C38,'S | 01 '!$C$6:$R$46,H$5,0) -> 2021 | I38: =VLOOKUP($C38,'S | 01 '!$C$6:$R$46,I$5,0) -> LP | J38: =VLOOKUP($C38,'S | 01 '!$C$6:$R$46,J$5,0) -> 0.33 | K38: =VLOOKUP($C38,'S | 01 '!$C$6:$R$46,K$5,0) -> 17.1125 | L38: =VLOOKUP($C38,'S | 01 '!$C$6:$R$46,L$5,0) -> 14.015137 | ... O38: =VLOOKUP($C38,'S | 01 '!$C$6:$R$46,O$5,0) -> -0.7075125 | P38: -0.306 | Q38: =VLOOKUP($C38,'S | 01 '!$C$6:$R$46,Q$5,0) -> -0.04112356 | R38: =VLOOKUP($C38,'S | 01 '!$C$6:$R$46,R$5,0) -> 0.97333028 | S38: =VLOOKUP($C38,'S | 01 '!$C$6:$R$46,S$5,0) -> 3.0973625 | T38: 9.9% GP | Anchor
W39: =O29-P29 -> 8.6824242
K40: =SUM(K31:K38) -> 1522.6864 | L40: =SUM(L31:L38) -> 1256.2697 | M40: =SUM(M31:M38) -> 4.4275637 | N40: =SUM(N31:N38) -> 1255.1666 | O40: =N40+M40-L40 -> 3.324546 | P40: =SUM(P31:P38) -> 56.89 | Q40: ='4. G42-IRR'!L16 -> 0.0021642417 | R40: =(M40+N40)/L40 -> 1.0026464 | S40: =SUM(S31:S38) -> 267.44473 | T40: =N40+M40-L40 -> 3.324546 | W40: =K40-L40 -> 266.41677
W41: =O40-P40 -> -53.565454
K42: =K29+K40 -> 2516.9571 | L42: =L29+L40 -> 2243.0372 | M42: =M29+M40 -> 17.719124 | N42: =N29+N40 -> 2251.8623 | O42: =O29+O40 -> 26.544169 | P42: =P29+P40 -> 71.427198 | Q42: ='4.All'!N9 -> 0.007097432 | R42: =(M42+N42)/L42 -> 1.011834 | S42: =S29+S40 -> 274.94473 | W42: =SUM(M31:N33)-SUM(L31:L33) -> -0.27953332
W43: =SUM(M34:N38)-SUM(L34:L38) -> 3.6040793
W44: =K40-L40 -> 266.41677
I45: Checks: | K45: =K42='S | 01 '!J46 -> TRUE | L45: =ROUND(L42,3)=ROUND('S | 01 '!K46,3) -> TRUE | M45: =M42='S | 01 '!M46 -> TRUE | N45: =N42='S | 01 '!N46 -> TRUE | O45: =ROUND(O42,3)=ROUND('S | 01 '!O46,3) -> TRUE | S45: =S29='S | 01 '!L30 -> TRUE
B46: For Notes, refer to Summary | 01
...

Sheet S | 03
C2: As of date | D2: ='S | 01 '!D2 -> 45138
M3: n/a refers to information not available
C6: Deals | D6: Status | E6: Lead | F6: Investing Entity | G6: Instrument | H6: Listed / Unlisted | I6: Website link | J6: Pitchbook link | K6: Jurisdiction | L6: % | M6: Upside (Warrants, Milestone payments, ) | N6: For Comments Refer to Note
C8: Direct Investments
C9: ='S | 01 '!C10 -> Jollychic Holding Limited | D9: ='S | 01 '!D10 -> In Liquidation | E9: ='S | 01 '!E10 -> Elaine | F9: ='S | 01 '!F10 -> Mozn | G9: ='S | 01 '!H10 -> C+ Prefs | I9: link | J9: link | K9: =VLOOKUP(C9,'6. %'!$C$6:$J$35,6,0) -> Cayman Islands | L9: =VLOOKUP(C9,'6. %'!$C$6:$J$35,4,0) -> 0.056999998 | N9: 1
C10: ='S | 01 '!C11 -> Mena Mobile Inc | D10: ='S | 01 '!D11 -> Unrealized | E10: ='S | 01 '!E11 -> Elaine | F10: ='S | 01 '!F11 -> Mozn | G10: ='S | 01 '!H11 -> B Prefs | I10: link | J10: link | K10: =VLOOKUP(C10,'6. %'!$C$6:$J$35,6,0) -> Cayman Islands | L10: =VLOOKUP(C10,'6. %'!$C$6:$J$35,4,0) -> 0.14 | N10: 2
C11: ='S | 01 '!C12 -> Flyr Inc | D11: ='S | 01 '!D12 -> Unrealized | E11: ='S | 01 '!E12 -> Sushil | F11: ='S | 01 '!F12 -> Mozn | G11: ='S | 01 '!H12 -> B-1,2 Prefs | I11: link | J11: link | K11: =VLOOKUP(C11,'6. %'!$C$6:$J$35,6,0) -> Delaware Corporation | L11: =VLOOKUP(C11,'6. %'!$C$6:$J$35,4,0) -> 0.085025485 | M11: Flyr Warrantsa | N11: 3
C12: ='S | 01 '!C13 -> Esyasoft Holding | D12: ='S | 01 '!D13 -> Realized | E12: ='S | 01 '!E13 -> Sushil | F12: ='S | 01 '!F13 -> Mozn | G12: ='S | 01 '!H13 -> Convertible Note | I12: link | J12: n/a | K12: =VLOOKUP(C12,'6. %'!$C$6:$J$35,6,0) -> DIFC | L12: =VLOOKUP(C12,'6. %'!$C$6:$J$35,4,0) -> n/a | N12: 4
C13: ='S | 01 '!C14 -> Beyond Limits | D13: ='S | 01 '!D14 -> Unrealized | E13: ='S | 01 '!E14 -> Divyesh | F13: ='S | 01 '!F14 -> Mozn | G13: ='S | 01 '!H14 -> C Prefs | I13: link | J13: link | K13: =VLOOKUP(C13,'6. %'!$C$6:$J$35,6,0) -> Delaware Corporation | L13: =VLOOKUP(C13,'6. %'!$C$6:$J$35,4,0) -> 0.097965107 | N13: 5
C14: ='S | 01 '!C15 -> ONT plc | D14: ='S | 01 '!D15 -> Unrealized | E14: ='S | 01 '!E15 -> Divyesh | F14: ='S | 01 '!F15 -> Mozn | G14: ='S | 01 '!H15 -> Ordinary Shares | H14: Listed | I14: link | J14: link | K14: =VLOOKUP(C14,'6. %'!$C$6:$J$35,6,0) -> UK | L14: =VLOOKUP(C14,'6. %'!$C$6:$J$35,4,0) -> 0.053583931 | N14: 6
C15: ='S | 01 '!C16 -> Heygears | D15: ='S | 01 '!D16 -> Unrealized | E15: ='S | 01 '!E16 -> Elaine | F15: ='S | 01 '!F16 -> Mozn | G15: ='S | 01 '!H16 -> Registered Capital | I15: link | J15: link | K15: =VLOOKUP(C15,'6. %'!$C$6:$J$35,6,0) -> PRC | L15: =VLOOKUP(C15,'6. %'!$C$6:$J$35,4,0) -> 0.1438 | N15: 7
C16: ='S | 01 '!C17 -> Jysan Technologies | D16: ='S | 01 '!D17 -> Unrealized | E16: ='S | 01 '!E17 -> Sushil | F16: Mozn aa | G16: ='S | 01 '!H17 -> A (Ordinary Shares) | I16: link | J16: n/a | K16: =VLOOKUP(C16,'6. %'!$C$6:$J$35,6,0) -> UK | L16: =VLOOKUP(C16,'6. %'!$C$6:$J$35,4,0) -> 0.03 | N16: 8
C17: ='S | 01 '!C18 -> Cerebras Systems Inc | D17: ='S | 01 '!D18 -> Unrealized | E17: ='S | 01 '!E18 -> Ignasi | F17: ='S | 01 '!F18 -> Mozn | G17: ='S | 01 '!H18 -> F Prefs | I17: link | J17: link | K17: =VLOOKUP(C17,'6. %'!$C$6:$J$35,6,0) -> Delaware Corporation | L17: =VLOOKUP(C17,'6. %'!$C$6:$J$35,4,0) -> 0.0094767871 | N17: 9
C18: ='S | 01 '!C19 -> Endless Studios LLC | D18: ='S | 01 '!D19 -> Unrealized | E18: ='S | 01 '!E19 -> Sushil | F18: ='S | 01 '!F19 -> Mozn | G18: ='S | 01 '!H19 -> A Pref Units | I18: link | J18: link | K18: =VLOOKUP(C18,'6. %'!$C$6:$J$35,6,0) -> Delaware Corporation | L18: =VLOOKUP(C18,'6. %'!$C$6:$J$35,4,0) -> 0.077419355 | N18: 10
C19: ='S | 01 '!C20 -> Instadeep Limited | D19: ='S | 01 '!D20 -> Realized | E19: ='S | 01 '!E20 -> Ignasi | F19: ='S | 01 '!F20 -> Mozn | G19: ='S | 01 '!H20 -> B Prefs | I19: link | J19: link | K19: =VLOOKUP(C19,'6. %'!$C$6:$J$35,6,0) -> UK | L19: =VLOOKUP(C19,'6. %'!$C$6:$J$35,4,0) -> 0.011489406 | N19: 11
C20: ='S | 01 '!C21 -> X-fusion | D20: ='S | 01 '!D21 -> Unrealized | E20: ='S | 01 '!E21 -> Elaine | F20: Mozn bb | G20: ='S | 01 '!H21 -> Equity-TBC | I20: link | J20: link | K20: =VLOOKUP(C20,'6. %'!$C$6:$J$35,6,0) -> PRC | L20: =VLOOKUP(C20,'6. %'!$C$6:$J$35,4,0) -> 0.051 | N20: 12
C21: ='S | 01 '!C22 -> DriveNets | D21: ='S | 01 '!D22 -> Unrealized | E21: ='S | 01 '!E22 -> Anton | F21: ='S | 01 '!F22 -> G42 | G21: ='S | 01 '!H22 -> Equity-TBC | I21: link | J21: link | K21: =VLOOKUP(C21,'6. %'!$C$6:$J$35,6,0) -> Israeli Pvt Company | L21: =VLOOKUP(C21,'6. %'!$C$6:$J$35,4,0) -> 0.11141914 | M21: DN Warrants b | N21: 13
C22: ='S | 01 '!C23 -> vTv Therapeutics Inc. | D22: ='S | 01 '!D23 -> Unrealized | E22: ='S | 01 '!E23 -> Divyesh | F22: ='S | 01 '!F23 -> G42 | G22: ='S | 01 '!H23 -> Ordinary Shares | H22: Listed | I22: link | J22: link | K22: =VLOOKUP(C22,'6. %'!$C$6:$J$35,6,0) -> Delaware Corporation | L22: =VLOOKUP(C22,'6. %'!$C$6:$J$35,4,0) -> 0.099316564 | M22: vTv $30m milestn payment c | N22: 14
C23: ='S | 01 '!C24 -> Honor Device Co Ltd | D23: ='S | 01 '!D24 -> Unrealized | E23: ='S | 01 '!E24 -> Elaine | F23: G42 cc | G23: ='S | 01 '!H24 -> Equity-TBC | I23: link | J23: link | K23: =VLOOKUP(C23,'6. %'!$C$6:$J$35,6,0) -> PRC | L23: =VLOOKUP(C23,'6. %'!$C$6:$J$35,4,0) -> 0.018823528 | N23: 15
C24: ='S | 01 '!C25 -> Applied AI Corporation Limited | D24: ='S | 01 '!D25 -> Unrealized | E24: ='S | 01 '!E25 -> Divyesh | F24: ='S | 01 '!F25 -> Mozn | G24: ='S | 01 '!H25 -> Convertible Note | I24: link | J24: link | K24: =VLOOKUP(C24,'6. %'!$C$6:$J$35,6,0) -> ADGM | L24: =VLOOKUP(C24,'6. %'!$C$6:$J$35,4,0) -> n/a | N24: 16
C25: ='S | 01 '!C26 -> eSpace | D25: ='S | 01 '!D26 -> Unrealized | E25: ='S | 01 '!E26 -> Anton | F25: Mozn dd | G25: ='S | 01 '!H26 -> SAFE note | I25: link | J25: link | K25: =VLOOKUP(C25,'6. %'!$C$6:$J$35,6,0) -> Delaware Corporation | L25: =VLOOKUP(C25,'6. %'!$C$6:$J$35,4,0) -> n/a | N25: 17
C26: ='S | 01 '!C27 -> Tools for Humanity Corporation | D26: ='S | 01 '!D27 -> Unrealized | E26: ='S | 01 '!E27 -> Divyesh | F26: ='S | 01 '!F27 -> Mozn | G26: ='S | 01 '!H27 -> C Prefs | I26: link | J26: link | K26: =VLOOKUP(C26,'6. %'!$C$6:$J$35,6,0) -> Delaware Corporation | L26: =VLOOKUP(C26,'6. %'!$C$6:$J$35,4,0) -> 0.0062621983 | N26: 24
C27: ='S | 01 '!C28 -> WLD Tokens | D27: ='S | 01 '!D28 -> Unrealized | E27: ='S | 01 '!E28 -> Divyesh | F27: ='S | 01 '!F28 -> Mozn | G27: ='S | 01 '!H28 -> Tokens | I27: link | J27: Coinbase | K27: =VLOOKUP(C27,'6. %'!$C$6:$J$35,6,0) -> DAO | Cayman Islands | L27: =VLOOKUP(C27,'6. %'!$C$6:$J$35,4,0) -> 0.00625 | N27: 25
C30: Debt Investments
C31: Glass Earth Holdings LLC | D31: In default | F31: Mozn | G31: Promissory Note | I31: n/a | J31: n/a | K31: n/a | N31: 16
C32: Mena Mobile Inc (Debt) | D32: In default | E32: Elaine | F32: Mozn | G32: Loan | I32: link | J32: link | K32: =K10 -> Cayman Islands | N32: 17
C33: Esyasoft Holding (Debt) | D33: Unrealized | E33: Sushil | F33: Mozn | G33: Loan | I33: link | J33: n/a | K33: =K12 -> DIFC | N33: 18
C36: Funds Investments
C37: New Space Capital Fund I | D37: Unrealized | E37: Sushil | F37: G42 | G37: LP | I37: link | J37: link | K37: =VLOOKUP(C37,'6. %'!$C$6:$J$35,6,0) -> Luxembourg | L37: =VLOOKUP(C37,'6. %'!$C$6:$J$35,4,0) -> 0.22044082 | N37: 19
C38: New Space Capital GP Com SCSp | D38: Unrealized | E38: Sushil | F38: G42 | G38: GP | I38: link | J38: link | K38: =VLOOKUP(C38,'6. %'!$C$6:$J$35,6,0) -> Luxembourg | L38: =VLOOKUP(C38,'6. %'!$C$6:$J$35,4,0) -> 0.02016129 | N38: 20
C39: North Summit Capital Fund | D39: Unrealized | E39: Elaine | F39: G42 | G39: LP | I39: n/a | J39: link | K39: =VLOOKUP(C39,'6. %'!$C$6:$J$35,6,0) -> Cayman Islands | L39: =VLOOKUP(C39,'6. %'!$C$6:$J$35,4,0) -> 0.995 | N39: 21
C40: Sinovation Disrupt Fund, L.P. | D40: Unrealized | E40: Elaine | F40: G42 | G40: LP | I40: link | J40: link | K40: =VLOOKUP(C40,'6. %'!$C$6:$J$35,6,0) -> Cayman Islands | L40: =VLOOKUP(C40,'6. %'!$C$6:$J$35,4,0) -> 0.1006609 | N40: 22
C41: Acies Investments Fund I, L.P. | D41: Unrealized | E41: Divyesh | F41: G42 | G41: LP | I41: link | J41: link | K41: =VLOOKUP(C41,'6. %'!$C$6:$J$35,6,0) -> Delaware LLC | L41: =VLOOKUP(C41,'6. %'!$C$6:$J$35,4,0) -> 0.33333333 | M41: 9.9% GP | Anchor e | N41: 23
B45: Notes:
B46: 1 | C46: Jollychic | D46: During 2021, Jollychic Holding Ltd has filed for its liquidation. Therefore, investment is considered to be fully impaired in Dec 21.
B47: 2 | C47: Mena Mobile | D47: Investment is written off based on the 3rd party valuation report
B48: 3 | C48: Flyr | D48: Within five years of the Initial Closing, for every USD 1mn of Qualifying Revenue generated, Flyr will issue, at no additional charge, 194,477 B-1 Prefs in the name of G42, up to a maximum of 1,264,100 B-1 Prefs.
B49: 4 | C49: Esyasoft Holding | D49: Investment in Esyasoft is in the form of Convertible Note which will convert to 21% interest on conversion on a fully diluted basis. As per Dec 2020 FS of Esyasoft, the CN was reflected as Debt - Exit of US$ 2.5 Mn Convertible Note @ 2.0x (MoC) i.e. US$ 5 Mn in May 22 - US$ 0.4 Mn represents Working Capital Loan - fully exited in Dec 22
B50: 5 | C50: Beyond Limits | D50: Business targeting raising funds by the end of FY2022
B51: 6 | C51: ONT plc | D51: Listed
...

Sheet NAV
B2: NAV Date | C2: ='S | 01 '!D2 -> 45138
B5: Investments | C5: Investing Entity | D5: Instrument | E5: Carrying Value | F5: Current Shares/Units | H5: Comment | N5: CHECKS
E6: USD, Million | F6: # | G6: USD | J6: Updated as on: | K6: =C2 -> 45138
E7: ="NAV | "& TEXT(C2,"dd")&" "&TEXT(C2,"mmm")&" "&TEXT(C2,"yyyy") -> NAV | 31 Jul 2023 | G7: ="PPS |" & TEXT(C2,"dd")&" "&TEXT(C2,"mmm")&" "&TEXT(C2,"yyyy") -> PPS |31 Jul 2023 | L7: source | N7: Equity | O7: =SUM(E9:E26) -> 2103.5933
B8: Direct Investments | J8: ONT Share price | K8: 2.638 | L8: link | N8: Debt | O8: =SUM(E32:E34) -> 2.353982
B9: ='S | 01 '!C10 -> Jollychic Holding Limited | C9: ='S | 01 '!F10 -> Mozn | D9: ='S | 01 '!H10 -> C+ Prefs | E9: =F9*G9*10^-6 -> 0 | F9: =SUM('CF (Equity, Debt)'!J4:J6) -> 13458655 | H9: In Liquidation | J9: VTVT Share price | K9: 0.68 | L9: link | N9: Funds | O9: =SUM(E39:E43) -> 130.91493
B10: ='S | 01 '!C11 -> Mena Mobile Inc | C10: ='S | 01 '!F11 -> Mozn | D10: ='S | 01 '!H11 -> B Prefs | E10: 0 | F10: ='CF (Equity, Debt)'!J7 -> 21419829 | H10: As per 3rd Party | Ardent Estimates | Equity written off | J10: GBP USD | K10: 1.28616 | L10: xe.com | N10: Total | O10: =SUM(O7:O9) -> 2236.8623
B11: ='S | 01 '!C12 -> Flyr Inc | C11: ='S | 01 '!F12 -> Mozn | D11: ='S | 01 '!H12 -> B-1,2 Prefs | E11: =F11*G11*10^-6*(1-20%) -> 78.08223 | F11: 5205482 | G11: 18.75 | H11: At Series C PPS $18.75/share with 20% discount | J11: USD RMB | K11: 7.14069 | L11: xe.com | N11: =E23/800 -> 1.0214863 | O11: =O10='S | 01 '!N46 -> FALSE
B12: ='S | 01 '!C13 -> Esyasoft Holding | C12: ='S | 01 '!F13 -> Mozn | D12: ='S | 01 '!H13 -> Convertible Note | E12: 0 | F12: n/a | H12: Exited at $5m (10th May) | Residual value = 0 | J12: EURUSD | K12: 1.10227 | L12: xe.com | O12: =O10='4.All'!M9 -> FALSE
B13: ='S | 01 '!C14 -> Beyond Limits | C13: ='S | 01 '!F14 -> Mozn | D13: ='S | 01 '!H14 -> C Prefs | E13: =F13*G13*10^-6 -> 91.00154 | F13: =SUM('CF (Equity, Debt)'!J11:J14) -> 17670202 | G13: 5.15 | H13: Held at cost (as per revised management guidance)
B14: ='S | 01 '!C15 -> ONT plc | C14: ='S | 01 '!F15 -> Mozn | D14: ='S | 01 '!H15 -> Ordinary Shares | E14: =F14*G14*10^-6 -> 150.40044 | F14: 44328120 | G14: =K8*K10 -> 3.3928901 | H14: Listed & marked to market
B15: ='S | 01 '!C16 -> Heygears | C15: ='S | 01 '!F16 -> Mozn | D15: ='S | 01 '!H16 -> Registered Capital | E15: =K25/1000000 -> 151.06943 | F15: ='CF (Equity, Debt)'!J20 -> 4753356.3 | H15: Adjusted for currency. Valued at the recent round
B16: ='S | 01 '!C17 -> Jysan Technologies | C16: ='S | 01 '!F17 -> Mozn 1 | D16: ='S | 01 '!H17 -> A (Ordinary Shares) | E16: =-'CF (Equity, Debt)'!E21 -> 20 | F16: ='CF (Equity, Debt)'!J21 -> 7959497 | G16: =E16*10^6/F16 -> 2.5127216 | H16: Held at cost. | J16: Heygears Oct 22
B17: ='S | 01 '!C18 -> Cerebras Systems Inc | C17: ='S | 01 '!F18 -> Mozn | D17: ='S | 01 '!H18 -> F Prefs | E17: =-'CF (Equity, Debt)'!E22 -> 39.999983 | F17: ='6. %'!D17 -> 1441711 | H17: Held at cost.
B18: ='S | 01 '!C19 -> Endless Studios LLC | C18: ='S | 01 '!F19 -> Mozn | D18: ='S | 01 '!H19 -> A Pref Units | E18: =-'CF (Equity, Debt)'!E23 -> 3 | F18: ='CF (Equity, Debt)'!J23 -> 3000000 | H18: Held at cost. | J18: Post Valuation closed in June 2021 (RMB) | K18: 7500000000
B19: ='S | 01 '!C20 -> Instadeep Limited | C19: ='S | 01 '!F20 -> Mozn | D19: ='S | 01 '!H20 -> B Prefs | E19: =-'CF (Equity, Debt)'!E24*G19 -> 0 | F19: ='CF (Equity, Debt)'!J24 -> 33267 | G19: 0 | H19: Exited at 1.56X | Residual Value = 0 | J19: G42 Stake | K19: 0.143832
B20: ='S | 01 '!C21 -> X-fusion | C20: ='S | 01 '!F21 -> Mozn 2 | D20: ='S | 01 '!H21 -> Equity-TBC | E20: =5810000000/K11/1000000*(1-49.82%) -> 408.28799 | F20: n/a | H20: Held at original cost, adjusted for currency, and ownership | J20: G42 Valuation before Discount (RMB) | K20: 1078740000
B21: ='S | 01 '!C22 -> DriveNets | C21: ='S | 01 '!F22 -> G42 | D21: ='S | 01 '!H22 -> Equity-TBC | E21: =-SUM('CF (Equity, Debt)'!E26:E27) -> 300 | F21: ='6. %'!D21 -> 86882669 | H21: Held at cost. | J21: Liquidity Discount | K21: 0
B22: ='S | 01 '!C23 -> vTv Therapeutics Inc. | C22: ='S | 01 '!F23 -> G42 | D22: ='S | 01 '!H23 -> Ordinary Shares | E22: =(F22*G22)*10^-6 -> 7.0626663 | F22: ='CF (Equity, Debt)'!J29 -> 10386274 | G22: =K9 -> 0.68 | H22: Listed & marked to market | J22: Minority Holding Discount | K22: 0
B23: ='S | 01 '!C24 -> Honor Device Co Ltd | C23: ='S | 01 '!F24 -> G42 3 | D23: ='S | 01 '!H24 -> Equity-TBC | E23: =310000000000/K11/1000000*4.705882%*0.8/2 -> 817.18905 | F23: n/a | H23: Closing a new round at RMB 310B. Adjusted for currency. | J23: G42 Valuation (RMB) | K23: =K20*(1-K21)*(1-K22) -> 1078740000
B24: ='S | 01 '!C25 -> Applied AI Corporation Limited | C24: ='S | 01 '!F25 -> Mozn | D24: ='S | 01 '!H25 -> Convertible Note | E24: =-'CF (Equity, Debt)'!E32-'CF (Equity, Debt)'!E38 -> 7.5 | F24: n/a | H24: Held at cost. | J24: Exchange Rate (RMB/USD) | K24: =K11 -> 7.14069
B25: ='S | 01 '!C26 -> eSpace | C25: ='S | 01 '!F26 -> Mozn 4 | D25: ='S | 01 '!H26 -> SAFE note | E25: 15 | F25: n/a | H25: Held at cost. | J25: G42 Valuation (USD) | K25: =K23/K24 -> 1.5106943e+08
B26: ='S | 01 '!C27 -> Tools for Humanity Corporation | C26: ='S | 01 '!F27 -> Mozn | D26: ='S | 01 '!H27 -> C Prefs | E26: ='S | 01 '!K27 -> 14.999999 | F26: ='6. %'!D26 -> 65413 | H26: Equity value held at cost. | J26: Investment Cost of G42 (USD) | K26: 60000000
B27: ='S | 01 '!C28 -> WLD Tokens | C27: ='S | 01 '!F28 -> Mozn | D27: ='S | 01 '!H28 -> Tokens | E27: =MAX('S | 01 '!K28,F27*G27*10^-6) -> 15 | F27: ='6. %'!D27 -> 62500000 | G27: =0.24 -> 0.24 | H27: Tokens valued at $0.3 per token taking into account the liquidity discount | J27: Investment Multiple | K27: 1.9039182
B31: Debt Investments | J31: New Space Capital
B32: Glass Earth Holdings LLC | C32: Mozn | D32: Promissory Note | E32: ='S | 01 '!N33 -> 0 | H32: In default
B33: Mena Mobile Inc (Debt) | C33: Mozn | D33: Loan | E33: ='S | 01 '!N34 -> 2.353982 | H33: Held at cost. | J33: EUR | K33: 3Q22 | L33: 4Q22 | M33: 1Q23
B34: Esyasoft Holding (Debt) | C34: Mozn | D34: Loan | E34: 0 | H34: Received payment of $470,784.65 ($411K+$59K) | J34: Commitment | K34: 23234462 | L34: 23234462 | M34: 23234462 | N34: source: distribution letter
J35: Capital Contribution | K35: 19178323 | L35: 9436936 | M35: 9626402
J36: Unfunded | K36: =K34-K35 -> 4056139 | L36: =L34-L35 -> 13797526 | M36: =M34-M35 -> 13608060
J37: Unrealized Gain | K37: 13103567 | L37: 3803379
B38: Funds Investments | J38: NAV | K38: 32325017 | L38: 12031777 | M38: 12148021 | N38: source: distribution letter
B39: New Space Capital Fund I | C39: G42 | D39: LP | E39: =M38*10^-6*K12 -> 13.390399 | H39: Q1'23 capital account statement | J39: Capital Return | L39: =K35-L35 -> 9741387 | N39: estimated
B40: New Space Capital GP Com SCSp | C40: G42 | D40: GP | E40: =E39*'S | 02'!L36/'S | 02'!L35 -> 3.276608 | H40: Q4'22 pro-rated | J40: Interest Capitalization | L40: =L42-L39 -> 2728214 | N40: estimated
B41: North Summit Capital Fund | C41: G42 | D41: LP | E41: 81.695786 | H41: Q1'23 capital account statement
B42: Sinovation Disrupt Fund, L.P. | C42: G42 | D42: LP | E42: =21.157072-'CF (Funds)'!D17 -> 19.244515 | H42: Q1'23 capital account statement | J42: Total Distribution Received | L42: 12469601 | N42: source: distribution letters, Gino
B43: Acies Investments Fund I, L.P. | C43: G42 | D43: LP | E43: 13.307625 | H43: Q1'23 capital account statement | J43: Remaining Commitment | L43: =15675627.21 -> 15675627 | N43: source: distribution letter
B46: Note: | F46: IRR | J46: in USD, Mn
B47: • For estimating the NAV their listed share price for ONT and vTv Therapeutics is taken | F47: Mozn | G47: ='S | 02'!Q29 -> 0.010515186 | J47: Capital Committed | K47: =K48+K49 -> 28.336808
F48: G42 | G48: ='S | 02'!Q40 -> 0.0021642417 | J48: Capital Called | K48: =-SUM('CF (Funds)'!D32:D36)-L39*1.08341*10^-6 -> 11.058035 | L48: =L35*10^-6*K12 -> 10.402051
...

Sheet CF (Equity, Debt)
B2: E Q U I T Y
B3: Accounting entity | C3: Investment | D3: Payment date | E3: Contributions (in USD, Mn) | F3: Distributions (in USD, Mn) | G3: Currency | H3: Investment / Exit Amt (investee currency) | I3: Investment / Exit Amount (USD) | J3: Consideration (shares) | K3: Comment
B4: =VLOOKUP(C4,'S | 01 '!$C$10:$F$43,4,0) -> Mozn | C4: Jollychic Holding Limited | D4: 43470 | E4: =-I4*10^-6 -> -30 | G4: USD | H4: 30000000 | I4: =H4 -> 30000000 | J4: 6100312 | N4: NOTES
B5: =VLOOKUP(C5,'S | 01 '!$C$10:$F$43,4,0) -> Mozn | C5: Jollychic Holding Limited | D5: 43724 | E5: =-I5*10^-6 -> -20 | G5: USD | H5: 20000000 | I5: =H5 -> 20000000 | J5: 4204767.4 | N5: USD AED | O5: 3.678
B6: =VLOOKUP(C6,'S | 01 '!$C$10:$F$43,4,0) -> Mozn | C6: Jollychic Holding Limited | D6: 43724 | E6: =-I6*10^-6 -> -15 | G6: USD | H6: 15000000 | I6: =H6 -> 15000000 | J6: 3153575.6
B7: =VLOOKUP(C7,'S | 01 '!$C$10:$F$43,4,0) -> Mozn | C7: Mena Mobile Inc | D7: 43563 | E7: =-I7*10^-6 -> -8 | G7: USD | H7: 8000000 | I7: =H7 -> 8000000 | J7: 21419829
B8: =VLOOKUP(C8,'S | 01 '!$C$10:$F$43,4,0) -> Mozn | C8: Flyr Inc | D8: 43570 | E8: =-I8*10^-6 -> -4.9999981 | G8: USD | H8: 4999998.1 | I8: =H8 -> 4999998.1 | J8: 2625467
B9: =VLOOKUP(C9,'S | 01 '!$C$10:$F$43,4,0) -> Mozn | C9: Flyr Inc | D9: 43915 | E9: =-I9*10^-6 -> -5.0000019 | G9: USD | H9: =10000000-H8 -> 5000001.9 | I9: =H9 -> 5000001.9 | J9: 2580015
B10: =VLOOKUP(C10,'S | 01 '!$C$10:$F$43,4,0) -> Mozn | C10: Esyasoft Holding | D10: 43870 | E10: =-I10*10^-6 -> -2.5 | G10: USD | H10: 2500000 | I10: =H10 -> 2500000 | J10: N/A
B11: =VLOOKUP(C11,'S | 01 '!$C$10:$F$43,4,0) -> Mozn | C11: Beyond Limits | D11: 43879 | E11: =-I11*10^-6 -> -20 | G11: USD | H11: 20000000 | I11: =H11 -> 20000000 | J11: 4084038
B12: =VLOOKUP(C12,'S | 01 '!$C$10:$F$43,4,0) -> Mozn | C12: Beyond Limits | D12: 43921 | E12: =-I12*10^-6 -> -30 | G12: USD | H12: 30000000 | I12: =H12 -> 30000000 | J12: 5822642
B13: =VLOOKUP(C13,'S | 01 '!$C$10:$F$43,4,0) -> Mozn | C13: Beyond Limits | D13: 43989 | E13: =-I13*10^-6 -> -30 | G13: USD | H13: 30000000 | I13: =H13 -> 30000000 | J13: 5822642
B14: =VLOOKUP(C14,'S | 01 '!$C$10:$F$43,4,0) -> Mozn | C14: Beyond Limits | D14: 44103 | E14: =-I14*10^-6 -> -10 | G14: USD | H14: 10000000 | I14: =H14 -> 10000000 | J14: 1940880
B15: =VLOOKUP(C15,'S | 01 '!$C$10:$F$43,4,0) -> Mozn | C15: ONT plc | D15: 43968 | E15: =-I15*10^-6 -> -50 | G15: USD | H15: 50000000 | I15: 50000000 | J15: 15277680
B16: =VLOOKUP(C16,'S | 01 '!$C$10:$F$43,4,0) -> Mozn | C16: ONT plc | D16: 44006 | E16: =-I16*10^-6 -> -27.268351 | G16: GBP | H16: 21029625 | I16: 27268351 | J16: 9000000
