Workbook
Name Company: #REF!
Name Dates: #REF!
Name DetailedCapShares: #REF!
Name FAGroup: #REF!
Name IQ_CH: 110000
Name IQ_CQ: 5000
Name IQ_CY: 10000
Name IQ_DAILY: 500000
Name IQ_FH: 100000
Name IQ_FQ: 500
Name IQ_FY: 1000
Name IQ_LTM: 2000
Name IQ_MONTH: 15000
Name IQ_NTM: 6000
Name IQ_WEEK: 50000
Name IQ_YTD: 3000
Name UNLOCKED_PERCENT_FAST: _xludf.LAMBDA(start_date, date, IF(start_date="",0,MIN(1,MAX(0,(date-EDATE(start_date,12)+1)/(EDATE(start_date,36)-EDATE(start_date,12))))))
Name UNLOCKED_PERCENT_SLOW: _xludf.LAMBDA(start_date, date, IF(start_date="",0, MIN(1,MAX(0,(date-EDATE(start_date,12)+1)/(EDATE(start_date,60)-EDATE(start_date,12))))))

Sheet D1
B2: Date of NAV | D2: 45565 | E2: =TEXT(D2,"dddddd") -> Monday
H4: D A S H B O A R D
B6: L I V E D E A L S (includes unrealized or partially realized investments)
E8: # Investments | F8: Committed | G8: Invested | H8: Remaining | I8: Distributions | J8: Residual Value | K8: Gain | L8: TVPI | M8: DPI
E9: # | F9: USD, Mn | G9: USD, Mn | H9: USD, Mn | I9: USD, Mn | J9: USD, Mn | K9: USD, Mn | L9: X | M9: X
C11: EQUITY* | D11: Direct Investment | E11: =COUNTIF('1. Live'!$D$1:D26,$D11) -> 13 | F11: =SUMIF('1. Live'!$D$1:$D$100,$D11,'1. Live'!K$1:K$100) -> 757.75837 | G11: =SUMIF('1. Live'!$D$1:$D$100,$D11,'1. Live'!L$1:L$100) -> 754.00837 | H11: =SUMIF('1. Live'!$D$1:$D$100,$D11,'1. Live'!M$1:M$100) -> 3.75 | I11: =SUMIF('1. Live'!$D$1:$D$100,$D11,'1. Live'!N$1:N$100) -> 0 | J11: =SUMIF('1. Live'!$D$1:$D$100,$D11,'1. Live'!O$1:O$100) -> 772.04324 | K11: =SUMIF('1. Live'!$D$1:$D$100,$D11,'1. Live'!P$1:P$100) -> 18.034877 | L11: =IFERROR((I11+J11)/G11,"") -> 1.0239187 | M11: =IFERROR(I11/G11,"") -> 0
C13: DEBT | D13: Debt Investment | E13: =COUNTIF('1. Live'!$D$1:D28,$D13) -> 0 | F13: =SUMIF('1. Live'!$D$1:$D$100,$D13,'1. Live'!K$1:K$100) -> 0 | G13: =SUMIF('1. Live'!$D$1:$D$100,$D13,'1. Live'!L$1:L$100) -> 0 | H13: =SUMIF('1. Live'!$D$1:$D$100,$D13,'1. Live'!M$1:M$100) -> 0 | I13: =SUMIF('1. Live'!$D$1:$D$100,$D13,'1. Live'!N$1:N$100) -> 0 | J13: =SUMIF('1. Live'!$D$1:$D$100,$D13,'1. Live'!O$1:O$100) -> 0 | K13: =SUMIF('1. Live'!$D$1:$D$100,$D13,'1. Live'!P$1:P$100) -> 0 | L13: =IFERROR((I13+J13)/G13,"") | M13: =IFERROR(I13/G13,"")
C15: FUNDS | D15: Fund Investment | E15: =COUNTIF('1. Live'!$D$1:D30,$D15) -> 4 | F15: =SUMIF('1. Live'!$D$1:$D$100,$D15,'1. Live'!K$1:K$100) -> 129.32658 | G15: =SUMIF('1. Live'!$D$1:$D$100,$D15,'1. Live'!L$1:L$100) -> 115.91381 | H15: =SUMIF('1. Live'!$D$1:$D$100,$D15,'1. Live'!M$1:M$100) -> 15.826355 | I15: =SUMIF('1. Live'!$D$1:$D$100,$D15,'1. Live'!N$1:N$100) -> 11.23534 | J15: =SUMIF('1. Live'!$D$1:$D$100,$D15,'1. Live'!O$1:O$100) -> 127.48674 | K15: =SUMIF('1. Live'!$D$1:$D$100,$D15,'1. Live'!P$1:P$100) -> 22.80827 | L15: =IFERROR((I15+J15)/G15,"") -> 1.1967692 | M15: =IFERROR(I15/G15,"") -> 0.0969284
C17: TOTAL | E17: =E11+E13+E15 -> 17 | F17: =F11+F13+F15 -> 887.08495 | G17: =G11+G13+G15 -> 869.92218 | H17: =H11+H13+H15 -> 19.576355 | I17: =I11+I13+I15 -> 11.23534 | J17: =J11+J13+J15 -> 899.52998 | K17: =I17+J17-G17 -> 40.843147 | L17: =IFERROR((I17+J17)/G17,"") -> 1.0469503 | M17: =IFERROR(I17/G17,"") -> 0.012915339
B20: E X I T E D D E A L S (includes liquidated, written-off or completely exited investments)
E22: # Investments | F22: Committed | G22: Invested | H22: Remaining | I22: Distributions | J22: Residual Value | K22: Gain | L22: TVPI | M22: DPI
E23: # | F23: USD, Mn | G23: USD, Mn | H23: USD, Mn | I23: USD, Mn | J23: USD, Mn | K23: USD, Mn | L23: X | M23: X
C25: EQUITY* | D25: Direct Investment | E25: =COUNTIF('2. Exited'!$D$1:D40,$D25) -> 7 | F25: =SUMIF('2. Exited'!$D$1:$D$40,$D25,'2. Exited'!K$1:K$40) -> 1394.0247 | G25: =SUMIF('2. Exited'!$D$1:$D$40,$D25,'2. Exited'!L$1:L$40) -> 1394.0247 | H25: =SUMIF('2. Exited'!$D$1:$D$40,$D25,'2. Exited'!M$1:M$40) -> 0 | I25: =SUMIF('2. Exited'!$D$1:$D$40,$D25,'2. Exited'!N$1:N$40) -> 1243.2422 | J25: =SUMIF('2. Exited'!$D$1:$D$40,$D25,'2. Exited'!O$1:O$40) -> 0 | K25: =SUMIF('2. Exited'!$D$1:$D$40,$D25,'2. Exited'!P$1:P$40) -> -150.78248 | L25: =IFERROR((I25+J25)/G25,"") -> 0.89183657 | M25: =IFERROR(I25/G25,"") -> 0.89183657
C27: DEBT | D27: Debt Investment | E27: =COUNTIF('2. Exited'!$D$1:D42,$D27) -> 3 | F27: =SUMIF('2. Exited'!$D$1:$D$40,$D27,'2. Exited'!K$1:K$40) -> 10.765747 | G27: =SUMIF('2. Exited'!$D$1:$D$40,$D27,'2. Exited'!L$1:L$40) -> 10.765747 | H27: =SUMIF('2. Exited'!$D$1:$D$40,$D27,'2. Exited'!M$1:M$40) -> 0 | I27: =SUMIF('2. Exited'!$D$1:$D$40,$D27,'2. Exited'!N$1:N$40) -> 0.47078465 | J27: =SUMIF('2. Exited'!$D$1:$D$40,$D27,'2. Exited'!O$1:O$40) -> 0 | K27: =SUMIF('2. Exited'!$D$1:$D$40,$D27,'2. Exited'!P$1:P$40) -> -10.294962 | L27: =IFERROR((I27+J27)/G27,"") -> 0.043729864 | M27: =IFERROR(I27/G27,"") -> 0.043729864
C29: FUNDS | D29: Fund Investment | E29: =COUNTIF('2. Exited'!$D$1:D44,$D29) -> 1 | F29: =SUMIF('2. Exited'!$D$1:$D$40,$D29,'2. Exited'!K$1:K$40) -> 50 | G29: =SUMIF('2. Exited'!$D$1:$D$40,$D29,'2. Exited'!L$1:L$40) -> 24.959693 | H29: =SUMIF('2. Exited'!$D$1:$D$40,$D29,'2. Exited'!M$1:M$40) -> 0 | I29: =SUMIF('2. Exited'!$D$1:$D$40,$D29,'2. Exited'!N$1:N$40) -> 25.403521 | J29: =SUMIF('2. Exited'!$D$1:$D$40,$D29,'2. Exited'!O$1:O$40) -> 0 | K29: =SUMIF('2. Exited'!$D$1:$D$40,$D29,'2. Exited'!P$1:P$40) -> 0.44382835 | L29: =IFERROR((I29+J29)/G29,"") -> 1.0177818 | M29: =IFERROR(I29/G29,"") -> 1.0177818
C31: TOTAL | E31: =E25+E27+E29 -> 11 | F31: =F25+F27+F29 -> 1454.7904 | G31: =G25+G27+G29 -> 1429.7501 | H31: =H25+H27+H29 -> 0 | I31: =I25+I27+I29 -> 1269.1165 | J31: =J25+J27+J29 -> 0 | K31: =K25+K27+K29 -> -160.63362 | L31: =IFERROR((I31+J31)/G31,"") -> 0.88764917 | M31: =IFERROR(I31/G31,"") -> 0.88764917
B34: * Includes Convertibles
E36: CHECKS | F36: =ROUND(F17,5)=ROUND('1. Live'!K44,5) -> TRUE | G36: =ROUND(G17,5)=ROUND('1. Live'!L44,5) -> TRUE | H36: =ROUND(H17,5)=ROUND('1. Live'!M44,5) -> TRUE | I36: =ROUND(I17,5)=ROUND('1. Live'!N44,5) -> TRUE | J36: =ROUND(J17,5)=ROUND('1. Live'!O44,5) -> TRUE | K36: =ROUND(K17,5)=ROUND('1. Live'!P44,5) -> TRUE
F37: =F31='2. Exited'!K35 -> TRUE | G37: =G31='2. Exited'!L35 -> TRUE | H37: =H31='2. Exited'!M35 -> TRUE | I37: =I31='2. Exited'!N35 -> TRUE | J37: =J31='2. Exited'!O35 -> TRUE | K37: =K31='2. Exited'!P35 -> TRUE
F38: TRUE | G38: TRUE | H38: TRUE | I38: TRUE | J38: TRUE | K38: TRUE

Sheet 1. Live
C2: As of date | D2: ='D1'!D2 -> 45565
E5: 2 | F5: 3 | G5: 4 | H5: 5 | I5: 6 | J5: 7 | K5: 8 | L5: 9 | M5: 10 | N5: 11 | O5: 12 | P5: 13 | R5: 14 | S5: 15
C6: Deals | D6: Type | E6: Status | F6: Lead | G6: Investing Entity | H6: Vintageἀ | I6: Instrument | J6: % | K6: Committed | L6: Invested | M6: Remaining Commitment | N6: Distributions | O6: Carrying Value | P6: Gain | Q6: Gain till FY22 | R6: TVPI | S6: Additonal Upside/Downside
I7: # | J7: % | K7: $,m | L7: $,m | M7: $,m | N7: $,m | O7: $,m | P7: $,m | R7: X
C8: MOZN Holding RSC Ltd
C9: E-line Ventures LLC | D9: Direct Investment | E9: =VLOOKUP($C9,'9. All deals (a)'!$C$6:$Q$49,E$5,0) -> Unrealized | F9: =VLOOKUP($C9,'9. All deals (a)'!$C$6:$Q$49,F$5,0) -> Sushil | G9: =VLOOKUP($C9,'9. All deals (a)'!$C$6:$Q$49,G$5,0) -> Mozn | H9: =VLOOKUP($C9,'9. All deals (a)'!$C$6:$Q$49,H$5,0) -> 2023 | I9: =VLOOKUP($C9,'9. All deals (a)'!$C$6:$Q$49,I$5,0) -> B Prefs | J9: =VLOOKUP($C9,'9. All deals (a)'!$C$6:$Q$49,J$5,0) -> 0.11483736 | K9: =VLOOKUP($C9,'9. All deals (a)'!$C$6:$Q$49,K$5,0) -> 6 | L9: =VLOOKUP($C9,'9. All deals (a)'!$C$6:$Q$49,L$5,0) -> 6 | ... P9: =VLOOKUP($C9,'9. All deals (a)'!$C$6:$Q$49,P$5,0) -> 0 | Q9: n/a | R9: =VLOOKUP($C9,'9. All deals (a)'!$C$6:$Q$49,R$5,0) -> 1 | S9: Optionse
C10: WLD Tokens | D10: Direct Investment | E10: =VLOOKUP($C10,'9. All deals (a)'!$C$6:$Q$49,E$5,0) -> Unrealized | F10: =VLOOKUP($C10,'9. All deals (a)'!$C$6:$Q$49,F$5,0) -> Divyesh | G10: =VLOOKUP($C10,'9. All deals (a)'!$C$6:$Q$49,G$5,0) -> Mozn | H10: =VLOOKUP($C10,'9. All deals (a)'!$C$6:$Q$49,H$5,0) -> 2023 | I10: =VLOOKUP($C10,'9. All deals (a)'!$C$6:$Q$49,I$5,0) -> Tokens | J10: =VLOOKUP($C10,'9. All deals (a)'!$C$6:$Q$49,J$5,0) -> 0.00625 | K10: =VLOOKUP($C10,'9. All deals (a)'!$C$6:$Q$49,K$5,0) -> 0.006875 | L10: =VLOOKUP($C10,'9. All deals (a)'!$C$6:$Q$49,L$5,0) -> 0.006875 | ... P10: =VLOOKUP($C10,'9. All deals (a)'!$C$6:$Q$49,P$5,0) -> 118.20562 | Q10: n/a | R10: =VLOOKUP($C10,'9. All deals (a)'!$C$6:$Q$49,R$5,0) -> NM
C11: Tools for Humanity Corporation | D11: Direct Investment | E11: =VLOOKUP($C11,'9. All deals (a)'!$C$6:$Q$49,E$5,0) -> Unrealized | F11: =VLOOKUP($C11,'9. All deals (a)'!$C$6:$Q$49,F$5,0) -> Divyesh | G11: =VLOOKUP($C11,'9. All deals (a)'!$C$6:$Q$49,G$5,0) -> Mozn | H11: =VLOOKUP($C11,'9. All deals (a)'!$C$6:$Q$49,H$5,0) -> 2023 | I11: =VLOOKUP($C11,'9. All deals (a)'!$C$6:$Q$49,I$5,0) -> C Prefs | J11: =VLOOKUP($C11,'9. All deals (a)'!$C$6:$Q$49,J$5,0) -> 0.0062621983 | K11: =VLOOKUP($C11,'9. All deals (a)'!$C$6:$Q$49,K$5,0) -> 14.999999 | L11: =VLOOKUP($C11,'9. All deals (a)'!$C$6:$Q$49,L$5,0) -> 14.999999 | ... P11: =VLOOKUP($C11,'9. All deals (a)'!$C$6:$Q$49,P$5,0) -> 0 | Q11: n/a | R11: =VLOOKUP($C11,'9. All deals (a)'!$C$6:$Q$49,R$5,0) -> 1
C12: eSpace | D12: Direct Investment | E12: =VLOOKUP($C12,'9. All deals (a)'!$C$6:$Q$49,E$5,0) -> Unrealized | F12: =VLOOKUP($C12,'9. All deals (a)'!$C$6:$Q$49,F$5,0) -> Anton | G12: =VLOOKUP($C12,'9. All deals (a)'!$C$6:$Q$49,G$5,0) -> Mozn 4 | H12: =VLOOKUP($C12,'9. All deals (a)'!$C$6:$Q$49,H$5,0) -> 2022 | I12: =VLOOKUP($C12,'9. All deals (a)'!$C$6:$Q$49,I$5,0) -> B Prefs | J12: =VLOOKUP($C12,'9. All deals (a)'!$C$6:$Q$49,J$5,0) -> 0.027864956 | K12: =VLOOKUP($C12,'9. All deals (a)'!$C$6:$Q$49,K$5,0) -> 15 | L12: =VLOOKUP($C12,'9. All deals (a)'!$C$6:$Q$49,L$5,0) -> 15 | ... P12: =VLOOKUP($C12,'9. All deals (a)'!$C$6:$Q$49,P$5,0) -> 5.8881215 | Q12: 0 | R12: =VLOOKUP($C12,'9. All deals (a)'!$C$6:$Q$49,R$5,0) -> 1.3925414
C13: Applied AI Corporation Limited | D13: Direct Investment | E13: =VLOOKUP($C13,'9. All deals (a)'!$C$6:$Q$49,E$5,0) -> Unrealized | F13: =VLOOKUP($C13,'9. All deals (a)'!$C$6:$Q$49,F$5,0) -> Divyesh | G13: =VLOOKUP($C13,'9. All deals (a)'!$C$6:$Q$49,G$5,0) -> Mozn | H13: =VLOOKUP($C13,'9. All deals (a)'!$C$6:$Q$49,H$5,0) -> 2022 | I13: =VLOOKUP($C13,'9. All deals (a)'!$C$6:$Q$49,I$5,0) -> Convertible Note | J13: =VLOOKUP($C13,'9. All deals (a)'!$C$6:$Q$49,J$5,0) -> n/a | K13: =VLOOKUP($C13,'9. All deals (a)'!$C$6:$Q$49,K$5,0) -> 15 | L13: =VLOOKUP($C13,'9. All deals (a)'!$C$6:$Q$49,L$5,0) -> 11.5 | ... P13: =VLOOKUP($C13,'9. All deals (a)'!$C$6:$Q$49,P$5,0) -> 0 | Q13: 0 | R13: =VLOOKUP($C13,'9. All deals (a)'!$C$6:$Q$49,R$5,0) -> 1
C14: Cerebras Systems Inc | D14: Direct Investment | E14: =VLOOKUP($C14,'9. All deals (a)'!$C$6:$Q$49,E$5,0) -> Unrealized | F14: =VLOOKUP($C14,'9. All deals (a)'!$C$6:$Q$49,F$5,0) -> Ignasi | G14: =VLOOKUP($C14,'9. All deals (a)'!$C$6:$Q$49,G$5,0) -> Mozn | H14: =VLOOKUP($C14,'9. All deals (a)'!$C$6:$Q$49,H$5,0) -> 2021 | I14: =VLOOKUP($C14,'9. All deals (a)'!$C$6:$Q$49,I$5,0) -> F Prefs | J14: =VLOOKUP($C14,'9. All deals (a)'!$C$6:$Q$49,J$5,0) -> 0.0091172068 | K14: =VLOOKUP($C14,'9. All deals (a)'!$C$6:$Q$49,K$5,0) -> 39.999983 | L14: =VLOOKUP($C14,'9. All deals (a)'!$C$6:$Q$49,L$5,0) -> 39.999983 | ... P14: =VLOOKUP($C14,'9. All deals (a)'!$C$6:$Q$49,P$5,0) -> -18.8645 | Q14: 0 | R14: =VLOOKUP($C14,'9. All deals (a)'!$C$6:$Q$49,R$5,0) -> 0.5283873
C15: Endless Studios LLC | D15: Direct Investment | E15: =VLOOKUP($C15,'9. All deals (a)'!$C$6:$Q$49,E$5,0) -> Unrealized | F15: =VLOOKUP($C15,'9. All deals (a)'!$C$6:$Q$49,F$5,0) -> Sushil | G15: =VLOOKUP($C15,'9. All deals (a)'!$C$6:$Q$49,G$5,0) -> Mozn | H15: =VLOOKUP($C15,'9. All deals (a)'!$C$6:$Q$49,H$5,0) -> 2021 | I15: =VLOOKUP($C15,'9. All deals (a)'!$C$6:$Q$49,I$5,0) -> A Pref Units | J15: =VLOOKUP($C15,'9. All deals (a)'!$C$6:$Q$49,J$5,0) -> 0.16080402 | K15: =VLOOKUP($C15,'9. All deals (a)'!$C$6:$Q$49,K$5,0) -> 8 | L15: =VLOOKUP($C15,'9. All deals (a)'!$C$6:$Q$49,L$5,0) -> 8 | ... P15: =VLOOKUP($C15,'9. All deals (a)'!$C$6:$Q$49,P$5,0) -> 0 | Q15: 0 | R15: =VLOOKUP($C15,'9. All deals (a)'!$C$6:$Q$49,R$5,0) -> 1
C16: Heygears | D16: Direct Investment | E16: =VLOOKUP($C16,'9. All deals (a)'!$C$6:$Q$49,E$5,0) -> Unrealized | F16: =VLOOKUP($C16,'9. All deals (a)'!$C$6:$Q$49,F$5,0) -> Elaine | G16: =VLOOKUP($C16,'9. All deals (a)'!$C$6:$Q$49,G$5,0) -> Mozn | H16: =VLOOKUP($C16,'9. All deals (a)'!$C$6:$Q$49,H$5,0) -> 2020 | I16: =VLOOKUP($C16,'9. All deals (a)'!$C$6:$Q$49,I$5,0) -> Registered Capital | J16: =VLOOKUP($C16,'9. All deals (a)'!$C$6:$Q$49,J$5,0) -> 0.1438 | K16: =VLOOKUP($C16,'9. All deals (a)'!$C$6:$Q$49,K$5,0) -> 60 | L16: =VLOOKUP($C16,'9. All deals (a)'!$C$6:$Q$49,L$5,0) -> 60 | ... P16: =VLOOKUP($C16,'9. All deals (a)'!$C$6:$Q$49,P$5,0) -> 93.732583 | Q16: 96.4 | R16: =VLOOKUP($C16,'9. All deals (a)'!$C$6:$Q$49,R$5,0) -> 2.5622097
C17: Beyond Limits | D17: Direct Investment | E17: =VLOOKUP($C17,'9. All deals (a)'!$C$6:$Q$49,E$5,0) -> Unrealized | F17: =VLOOKUP($C17,'9. All deals (a)'!$C$6:$Q$49,F$5,0) -> Divyesh | G17: =VLOOKUP($C17,'9. All deals (a)'!$C$6:$Q$49,G$5,0) -> Mozn | H17: =VLOOKUP($C17,'9. All deals (a)'!$C$6:$Q$49,H$5,0) -> 2020 | I17: =VLOOKUP($C17,'9. All deals (a)'!$C$6:$Q$49,I$5,0) -> C Prefs | J17: =VLOOKUP($C17,'9. All deals (a)'!$C$6:$Q$49,J$5,0) -> 0.094347728 | K17: =VLOOKUP($C17,'9. All deals (a)'!$C$6:$Q$49,K$5,0) -> 90 | L17: =VLOOKUP($C17,'9. All deals (a)'!$C$6:$Q$49,L$5,0) -> 90 | ... P17: =VLOOKUP($C17,'9. All deals (a)'!$C$6:$Q$49,P$5,0) -> -44.49923 | Q17: 1.042 | R17: =VLOOKUP($C17,'9. All deals (a)'!$C$6:$Q$49,R$5,0) -> 0.50556411
C18: ONT plc | D18: Direct Investment | E18: =VLOOKUP($C18,'9. All deals (a)'!$C$6:$Q$49,E$5,0) -> Unrealized | F18: =VLOOKUP($C18,'9. All deals (a)'!$C$6:$Q$49,F$5,0) -> Divyesh | G18: =VLOOKUP($C18,'9. All deals (a)'!$C$6:$Q$49,G$5,0) -> Mozn | H18: =VLOOKUP($C18,'9. All deals (a)'!$C$6:$Q$49,H$5,0) -> 2020 | I18: =VLOOKUP($C18,'9. All deals (a)'!$C$6:$Q$49,I$5,0) -> Ordinary Shares | J18: =VLOOKUP($C18,'9. All deals (a)'!$C$6:$Q$49,J$5,0) -> 0.047112659 | K18: =VLOOKUP($C18,'9. All deals (a)'!$C$6:$Q$49,K$5,0) -> 141.47026 | L18: =VLOOKUP($C18,'9. All deals (a)'!$C$6:$Q$49,L$5,0) -> 141.47026 | ... P18: =VLOOKUP($C18,'9. All deals (a)'!$C$6:$Q$49,P$5,0) -> -47.137451 | Q18: -9.845 | R18: =VLOOKUP($C18,'9. All deals (a)'!$C$6:$Q$49,R$5,0) -> 0.66680311
C19: Flyr Inc | D19: Direct Investment | E19: =VLOOKUP($C19,'9. All deals (a)'!$C$6:$Q$49,E$5,0) -> Unrealized | F19: =VLOOKUP($C19,'9. All deals (a)'!$C$6:$Q$49,F$5,0) -> Sushil | G19: =VLOOKUP($C19,'9. All deals (a)'!$C$6:$Q$49,G$5,0) -> Mozn | H19: =VLOOKUP($C19,'9. All deals (a)'!$C$6:$Q$49,H$5,0) -> 2019 | I19: =VLOOKUP($C19,'9. All deals (a)'!$C$6:$Q$49,I$5,0) -> B-1,2 Prefs | J19: =VLOOKUP($C19,'9. All deals (a)'!$C$6:$Q$49,J$5,0) -> 0.041582449 | K19: =VLOOKUP($C19,'9. All deals (a)'!$C$6:$Q$49,K$5,0) -> 10 | L19: =VLOOKUP($C19,'9. All deals (a)'!$C$6:$Q$49,L$5,0) -> 10 | ... P19: =VLOOKUP($C19,'9. All deals (a)'!$C$6:$Q$49,P$5,0) -> 27.11873 | Q19: 68.1 | R19: =VLOOKUP($C19,'9. All deals (a)'!$C$6:$Q$49,R$5,0) -> 3.711873 | S19: Flyr Warrantsa
K21: =SUM(K9:K19) -> 400.47712 | L21: =SUM(L9:L19) -> 396.97712 | M21: =SUM(M9:M19) -> 3.5 | N21: =SUM(N9:N19) -> 0 | O21: =SUM(O9:O19) -> 531.421 | P21: =O21+N21-L21 -> 134.44388 | Q21: =SUM(Q9:Q19) -> 155.697 | R21: =(N21+O21)/L21 -> 1.3386691
C23: G42 Investments AI Holding RSC Ltd
C24: DriveNets | D24: Direct Investment | E24: =VLOOKUP($C24,'9. All deals (a)'!$C$6:$Q$49,E$5,0) -> Unrealized | F24: =VLOOKUP($C24,'9. All deals (a)'!$C$6:$Q$49,F$5,0) -> Anton | G24: =VLOOKUP($C24,'9. All deals (a)'!$C$6:$Q$49,G$5,0) -> G42 | H24: =VLOOKUP($C24,'9. All deals (a)'!$C$6:$Q$49,H$5,0) -> 2022 | I24: =VLOOKUP($C24,'9. All deals (a)'!$C$6:$Q$49,I$5,0) -> Equity-TBC | J24: =VLOOKUP($C24,'9. All deals (a)'!$C$6:$Q$49,J$5,0) -> 0.11141914 | K24: =VLOOKUP($C24,'9. All deals (a)'!$C$6:$Q$49,K$5,0) -> 300 | L24: =VLOOKUP($C24,'9. All deals (a)'!$C$6:$Q$49,L$5,0) -> 300 | ... P24: =VLOOKUP($C24,'9. All deals (a)'!$C$6:$Q$49,P$5,0) -> -95.4 | Q24: 0 | R24: =VLOOKUP($C24,'9. All deals (a)'!$C$6:$Q$49,R$5,0) -> 0.682 | S24: DN Warrants b
C25: vTv Therapeutics Inc. | D25: Direct Investment | E25: =VLOOKUP($C25,'9. All deals (a)'!$C$6:$Q$49,E$5,0) -> Unrealized | F25: =VLOOKUP($C25,'9. All deals (a)'!$C$6:$Q$49,F$5,0) -> Divyesh | G25: =VLOOKUP($C25,'9. All deals (a)'!$C$6:$Q$49,G$5,0) -> G42 | H25: =VLOOKUP($C25,'9. All deals (a)'!$C$6:$Q$49,H$5,0) -> 2022 | I25: =VLOOKUP($C25,'9. All deals (a)'!$C$6:$Q$49,I$5,0) -> Ordinary Shares | J25: =VLOOKUP($C25,'9. All deals (a)'!$C$6:$Q$49,J$5,0) -> 0.0021343582 | K25: =VLOOKUP($C25,'9. All deals (a)'!$C$6:$Q$49,K$5,0) -> 24.53125 | L25: =VLOOKUP($C25,'9. All deals (a)'!$C$6:$Q$49,L$5,0) -> 24.53125 | ... P25: =VLOOKUP($C25,'9. All deals (a)'!$C$6:$Q$49,P$5,0) -> -21.009003 | Q25: -1.348 | R25: =VLOOKUP($C25,'9. All deals (a)'!$C$6:$Q$49,R$5,0) -> 0.14358205 | S25: vTv $30m milestn payment c
C26: North Summit Capital Fund | D26: Fund Investment | E26: =VLOOKUP($C26,'9. All deals (a)'!$C$6:$Q$49,E$5,0) -> Unrealized | F26: =VLOOKUP($C26,'9. All deals (a)'!$C$6:$Q$49,F$5,0) -> Elaine | G26: =VLOOKUP($C26,'9. All deals (a)'!$C$6:$Q$49,G$5,0) -> G42 Investments | H26: =VLOOKUP($C26,'9. All deals (a)'!$C$6:$Q$49,H$5,0) -> 2020 | I26: =VLOOKUP($C26,'9. All deals (a)'!$C$6:$Q$49,I$5,0) -> LP | J26: =VLOOKUP($C26,'9. All deals (a)'!$C$6:$Q$49,J$5,0) -> n/a | K26: =VLOOKUP($C26,'9. All deals (a)'!$C$6:$Q$49,K$5,0) -> 83.63035 | L26: =VLOOKUP($C26,'9. All deals (a)'!$C$6:$Q$49,L$5,0) -> 83.27035 | ... P26: =VLOOKUP($C26,'9. All deals (a)'!$C$6:$Q$49,P$5,0) -> 15.869967 | Q26: -0.306 | R26: =VLOOKUP($C26,'9. All deals (a)'!$C$6:$Q$49,R$5,0) -> 1.1905836
C27: New Space Capital Fund I | D27: Fund Investment | E27: =VLOOKUP($C27,'9. All deals (a)'!$C$6:$Q$49,E$5,0) -> Unrealized | F27: =VLOOKUP($C27,'9. All deals (a)'!$C$6:$Q$49,F$5,0) -> Sushil | G27: =VLOOKUP($C27,'9. All deals (a)'!$C$6:$Q$49,G$5,0) -> G42 Investments | H27: =VLOOKUP($C27,'9. All deals (a)'!$C$6:$Q$49,H$5,0) -> 2020 | I27: =VLOOKUP($C27,'9. All deals (a)'!$C$6:$Q$49,I$5,0) -> LP | J27: =VLOOKUP($C27,'9. All deals (a)'!$C$6:$Q$49,J$5,0) -> n/a | K27: =VLOOKUP($C27,'9. All deals (a)'!$C$6:$Q$49,K$5,0) -> 25.877847 | L27: =VLOOKUP($C27,'9. All deals (a)'!$C$6:$Q$49,L$5,0) -> 15.922439 | ... P27: =VLOOKUP($C27,'9. All deals (a)'!$C$6:$Q$49,P$5,0) -> 9.1110015 | Q27: 5.445 | R27: =VLOOKUP($C27,'9. All deals (a)'!$C$6:$Q$49,R$5,0) -> 1.5722114
C28: New Space Capital GP Com SCSp | D28: Fund Investment | E28: =VLOOKUP($C28,'9. All deals (a)'!$C$6:$Q$49,E$5,0) -> Unrealized | F28: =VLOOKUP($C28,'9. All deals (a)'!$C$6:$Q$49,F$5,0) -> Sushil | G28: =VLOOKUP($C28,'9. All deals (a)'!$C$6:$Q$49,G$5,0) -> G42 Investments | H28: =VLOOKUP($C28,'9. All deals (a)'!$C$6:$Q$49,H$5,0) -> 2023 | I28: =VLOOKUP($C28,'9. All deals (a)'!$C$6:$Q$49,I$5,0) -> LP | J28: =VLOOKUP($C28,'9. All deals (a)'!$C$6:$Q$49,J$5,0) -> n/a | K28: =VLOOKUP($C28,'9. All deals (a)'!$C$6:$Q$49,K$5,0) -> 2.7058824 | L28: =VLOOKUP($C28,'9. All deals (a)'!$C$6:$Q$49,L$5,0) -> 2.7058824 | ... P28: =VLOOKUP($C28,'9. All deals (a)'!$C$6:$Q$49,P$5,0) -> 0.96722726 | Q28: 0 | R28: =VLOOKUP($C28,'9. All deals (a)'!$C$6:$Q$49,R$5,0) -> 1.3574536
C29: Acies Investments Fund I, L.P. | D29: Fund Investment | E29: =VLOOKUP($C29,'9. All deals (a)'!$C$6:$Q$49,E$5,0) -> Unrealized | F29: =VLOOKUP($C29,'9. All deals (a)'!$C$6:$Q$49,F$5,0) -> Divyesh | G29: =VLOOKUP($C29,'9. All deals (a)'!$C$6:$Q$49,G$5,0) -> G42 Investments | H29: =VLOOKUP($C29,'9. All deals (a)'!$C$6:$Q$49,H$5,0) -> 2021 | I29: =VLOOKUP($C29,'9. All deals (a)'!$C$6:$Q$49,I$5,0) -> LP | J29: =VLOOKUP($C29,'9. All deals (a)'!$C$6:$Q$49,J$5,0) -> 0.33 | K29: =VLOOKUP($C29,'9. All deals (a)'!$C$6:$Q$49,K$5,0) -> 17.1125 | L29: =VLOOKUP($C29,'9. All deals (a)'!$C$6:$Q$49,L$5,0) -> 14.015137 | ... P29: =VLOOKUP($C29,'9. All deals (a)'!$C$6:$Q$49,P$5,0) -> -3.1399255 | Q29: -0.306 | R29: =VLOOKUP($C29,'9. All deals (a)'!$C$6:$Q$49,R$5,0) -> 0.77596185 | S29: 9.9% GP | Anchorf
K31: =SUM(K24:K29) -> 453.85783 | L31: =SUM(L24:L29) -> 440.44506 | M31: =SUM(M24:M29) -> 15.826355 | N31: =SUM(N24:N29) -> 11.23534 | O31: =SUM(O24:O29) -> 335.60899 | P31: =O31+N31-L31 -> -93.600733 | Q31: =SUM(Q24:Q29) -> 3.485 | R31: =(N31+O31)/L31 -> 0.78748602
C33: G42 Capital SPV RSC Ltd
C34: Life Biosciences LLC | D34: Direct Investment | E34: =VLOOKUP($C34,'9. All deals (a)'!$C$6:$Q$49,E$5,0) -> Unrealized | F34: =VLOOKUP($C34,'9. All deals (a)'!$C$6:$Q$49,F$5,0) -> Divyesh | G34: =VLOOKUP($C34,'9. All deals (a)'!$C$6:$Q$49,G$5,0) -> G42 Capital | H34: =VLOOKUP($C34,'9. All deals (a)'!$C$6:$Q$49,H$5,0) -> 2024 | I34: =VLOOKUP($C34,'9. All deals (a)'!$C$6:$Q$49,I$5,0) -> Convertible Note | J34: =VLOOKUP($C34,'9. All deals (a)'!$C$6:$Q$49,J$5,0) -> n/a | K34: =VLOOKUP($C34,'9. All deals (a)'!$C$6:$Q$49,K$5,0) -> 20 | L34: =VLOOKUP($C34,'9. All deals (a)'!$C$6:$Q$49,L$5,0) -> 20 | ... P34: =VLOOKUP($C34,'9. All deals (a)'!$C$6:$Q$49,P$5,0) -> 0 | Q34: 0 | R34: =VLOOKUP($C34,'9. All deals (a)'!$C$6:$Q$49,R$5,0) -> 1
C35: Verses AI Inc | D35: Direct Investment | E35: =VLOOKUP($C35,'9. All deals (a)'!$C$6:$Q$49,E$5,0) -> Unrealized | F35: =VLOOKUP($C35,'9. All deals (a)'!$C$6:$Q$49,F$5,0) -> Divyesh | G35: =VLOOKUP($C35,'9. All deals (a)'!$C$6:$Q$49,G$5,0) -> G42 Capital | H35: =VLOOKUP($C35,'9. All deals (a)'!$C$6:$Q$49,H$5,0) -> 2024 | I35: =VLOOKUP($C35,'9. All deals (a)'!$C$6:$Q$49,I$5,0) -> Convertible Debenture | J35: =VLOOKUP($C35,'9. All deals (a)'!$C$6:$Q$49,J$5,0) -> n/a | K35: =VLOOKUP($C35,'9. All deals (a)'!$C$6:$Q$49,K$5,0) -> 10 | L35: =VLOOKUP($C35,'9. All deals (a)'!$C$6:$Q$49,L$5,0) -> 10 | ... P35: =VLOOKUP($C35,'9. All deals (a)'!$C$6:$Q$49,P$5,0) -> 0 | Q35: 0 | R35: =VLOOKUP($C35,'9. All deals (a)'!$C$6:$Q$49,R$5,0) -> 1 | S35: =VLOOKUP($C35,'9. All deals (a)'!$C$6:$Q$49,S$5,0) -> Revenue linked RSUs
K37: =SUM(K34:K35) -> 30 | L37: =SUM(L34:L35) -> 30 | M37: =SUM(M34:M35) -> 0 | N37: =SUM(N34:N35) -> 0 | O37: =SUM(O34:O35) -> 30 | P37: =SUM(P34:P35) -> 0 | Q37: =SUM(Q34:Q35) -> 0 | R37: =(N37+O37)/L37 -> 1
C39: Core42 Holding RSC Ltd
C40: School Hack (AIREV Holding Limited) | D40: Direct Investment | E40: =VLOOKUP($C40,'9. All deals (a)'!$C$6:$Q$49,E$5,0) -> Unrealized | F40: =VLOOKUP($C40,'9. All deals (a)'!$C$6:$Q$49,F$5,0) -> Camillo | G40: =VLOOKUP($C40,'9. All deals (a)'!$C$6:$Q$49,G$5,0) -> Core42 5 | H40: =VLOOKUP($C40,'9. All deals (a)'!$C$6:$Q$49,H$5,0) -> 2024 | I40: =VLOOKUP($C40,'9. All deals (a)'!$C$6:$Q$49,I$5,0) -> Preferred Shares | J40: =VLOOKUP($C40,'9. All deals (a)'!$C$6:$Q$49,J$5,0) -> 0.25 | K40: =VLOOKUP($C40,'9. All deals (a)'!$C$6:$Q$49,K$5,0) -> 2.75 | L40: =VLOOKUP($C40,'9. All deals (a)'!$C$6:$Q$49,L$5,0) -> 2.5 | ... P40: =VLOOKUP($C40,'9. All deals (a)'!$C$6:$Q$49,P$5,0) -> 0 | Q40: 0 | R40: =VLOOKUP($C40,'9. All deals (a)'!$C$6:$Q$49,R$5,0) -> 1 | S40: Cloud Creditg
K42: =SUM(K40) -> 2.75 | L42: =SUM(L40) -> 2.5 | M42: =SUM(M40) -> 0.25 | N42: =SUM(N40) -> 0 | O42: =SUM(O40) -> 2.5 | P42: =SUM(P40) -> 0 | Q42: =SUM(Q40) -> 0 | R42: =(N42+O42)/L42 -> 1
K44: =K21+K31+K37+K42 -> 887.08495 | L44: =L21+L31+L37+L42 -> 869.92218 | M44: =M21+M31+M37+M42 -> 19.576355 | N44: =N21+N31+N37+N42 -> 11.23534 | O44: =O21+O31+O37+O42 -> 899.52998 | P44: =P21+P31+P37+P42 -> 40.843147 | Q44: =Q21+Q31+Q37+Q42 -> 159.182 | R44: =(N44+O44)/L44 -> 1.0469503
I47: Checks: | K47: =K21+'2. Exited'!K19='9. All deals (b)'!K30 -> TRUE | L47: =L21+'2. Exited'!L19='9. All deals (b)'!L30 -> TRUE | M47: =M21+'2. Exited'!M19='9. All deals (b)'!M30 -> TRUE | N47: =N21+'2. Exited'!N19='9. All deals (b)'!N30 -> TRUE | O47: =O21+'2. Exited'!O19='9. All deals (b)'!O30 -> TRUE | P47: =P21+'2. Exited'!P19='9. All deals (b)'!P30 -> TRUE | Q47: =Q21+'2. Exited'!Q19='9. All deals (b)'!Q30 -> TRUE
C48: For Notes, refer to 9. All deals (a) | K48: =ROUND(K31+'2. Exited'!K25,5)=ROUND('9. All deals (b)'!K42,5) -> TRUE | L48: =ROUND(L31+'2. Exited'!L25,5)=ROUND('9. All deals (b)'!L42,5) -> TRUE | M48: =ROUND(M31+'2. Exited'!M25,5)=ROUND('9. All deals (b)'!M42,5) -> TRUE | N48: =ROUND(N31+'2. Exited'!N25,5)=ROUND('9. All deals (b)'!N42,5) -> TRUE | O48: =ROUND(O31+'2. Exited'!O25,5)=ROUND('9. All deals (b)'!O42,5) -> TRUE | P48: =ROUND(P31+'2. Exited'!P25,5)=ROUND('9. All deals (b)'!P42,5) -> TRUE | Q48: =ROUND(Q31+'2. Exited'!Q25,5)=ROUND('9. All deals (b)'!Q42,5) -> TRUE
C49: Position Exited or written off are highlighted | K49: =ROUND(K44+'2. Exited'!K35,5)=ROUND('9. All deals (b)'!K55,5) -> TRUE | L49: =ROUND(L44+'2. Exited'!L35,5)=ROUND('9. All deals (b)'!L55,5) -> TRUE | M49: =ROUND(M44+'2. Exited'!M35,5)=ROUND('9. All deals (b)'!M55,5) -> TRUE | N49: =ROUND(N44+'2. Exited'!N35,5)=ROUND('9. All deals (b)'!N55,5) -> TRUE | O49: =ROUND(O44+'2. Exited'!O35,5)=ROUND('9. All deals (b)'!O55,5) -> TRUE | P49: =ROUND(P44+'2. Exited'!P35,5)=ROUND('9. All deals (b)'!P55,5) -> TRUE | Q49: =ROUND(Q44+'2. Exited'!Q35,5)=ROUND('9. All deals (b)'!Q55,5) -> TRUE

Sheet 2. Exited
C2: As of date | D2: ='D1'!D2 -> 45565
C3: EXITED INVESTMENTS
E5: 2 | F5: 3 | G5: 4 | H5: 5 | I5: 6 | J5: 7 | K5: 8 | L5: 9 | M5: 10 | N5: 11 | O5: 12 | P5: 13 | R5: 14 | S5: 15
C6: Deals | D6: Type | E6: Status | F6: Lead | G6: Investing Entity | H6: Vintageἀ | I6: Instrument | J6: % | K6: Committed | L6: Invested | M6: Remaining Commitment | N6: Distributions | O6: Carrying Value | P6: Gain | Q6: Gain till FY22 | R6: TVPI | S6: Additonal Upside/Downside
I7: # | J7: % | K7: $,m | L7: $,m | M7: $,m | N7: $,m | O7: $,m | P7: $,m | R7: X
C8: MOZN Holding RSC Ltd
C9: X-fusion | D9: Direct Investment | E9: =VLOOKUP($C9,'9. All deals (a)'!$C$6:$Q$49,E$5,0) -> Realized | F9: =VLOOKUP($C9,'9. All deals (a)'!$C$6:$Q$49,F$5,0) -> Elaine | G9: =VLOOKUP($C9,'9. All deals (a)'!$C$6:$Q$49,G$5,0) -> Mozn 2 | H9: =VLOOKUP($C9,'9. All deals (a)'!$C$6:$Q$49,H$5,0) -> 2022 | I9: =VLOOKUP($C9,'9. All deals (a)'!$C$6:$Q$49,I$5,0) -> Equity-TBC | J9: =VLOOKUP($C9,'9. All deals (a)'!$C$6:$Q$49,J$5,0) -> 0.051 | K9: =VLOOKUP($C9,'9. All deals (a)'!$C$6:$Q$49,K$5,0) -> 493.50096 | L9: =VLOOKUP($C9,'9. All deals (a)'!$C$6:$Q$49,L$5,0) -> 493.50096 | ... P9: =VLOOKUP($C9,'9. All deals (a)'!$C$6:$Q$49,P$5,0) -> -90.500956 | Q9: -64.391 | R9: =VLOOKUP($C9,'9. All deals (a)'!$C$6:$Q$49,R$5,0) -> 0.81661443 | S9: Full Exit
C10: Mena Mobile Inc (Debt) | D10: Debt Investment | E10: =VLOOKUP($C10,'9. All deals (a)'!$C$6:$Q$49,E$5,0) -> Written-off | F10: =VLOOKUP($C10,'9. All deals (a)'!$C$6:$Q$49,F$5,0) -> Elaine | G10: =VLOOKUP($C10,'9. All deals (a)'!$C$6:$Q$49,G$5,0) -> Mozn | H10: =VLOOKUP($C10,'9. All deals (a)'!$C$6:$Q$49,H$5,0) -> 2021 | I10: =VLOOKUP($C10,'9. All deals (a)'!$C$6:$Q$49,I$5,0) -> Loan | J10: =VLOOKUP($C10,'9. All deals (a)'!$C$6:$Q$49,J$5,0) -> n/a | K10: =VLOOKUP($C10,'9. All deals (a)'!$C$6:$Q$49,K$5,0) -> 2.353982 | L10: =VLOOKUP($C10,'9. All deals (a)'!$C$6:$Q$49,L$5,0) -> 2.353982 | ... P10: =VLOOKUP($C10,'9. All deals (a)'!$C$6:$Q$49,P$5,0) -> -2.353982 | Q10: 0 | R10: =VLOOKUP($C10,'9. All deals (a)'!$C$6:$Q$49,R$5,0) -> 0 | S10: Written Off
C11: Esyasoft Holding (Debt) | D11: Debt Investment | E11: =VLOOKUP($C11,'9. All deals (a)'!$C$6:$Q$49,E$5,0) -> Realized | F11: =VLOOKUP($C11,'9. All deals (a)'!$C$6:$Q$49,F$5,0) -> Sushil | G11: =VLOOKUP($C11,'9. All deals (a)'!$C$6:$Q$49,G$5,0) -> Mozn | H11: =VLOOKUP($C11,'9. All deals (a)'!$C$6:$Q$49,H$5,0) -> 2021 | I11: =VLOOKUP($C11,'9. All deals (a)'!$C$6:$Q$49,I$5,0) -> Loan | J11: =VLOOKUP($C11,'9. All deals (a)'!$C$6:$Q$49,J$5,0) -> n/a | K11: =VLOOKUP($C11,'9. All deals (a)'!$C$6:$Q$49,K$5,0) -> 0.411765 | L11: =VLOOKUP($C11,'9. All deals (a)'!$C$6:$Q$49,L$5,0) -> 0.411765 | ... P11: =VLOOKUP($C11,'9. All deals (a)'!$C$6:$Q$49,P$5,0) -> 0.05901965 | Q11: 0.05901965 | R11: =VLOOKUP($C11,'9. All deals (a)'!$C$6:$Q$49,R$5,0) -> 1.1433333 | S11: Full Exit
C12: Jysan Technologies | D12: Direct Investment | E12: =VLOOKUP($C12,'9. All deals (a)'!$C$6:$Q$49,E$5,0) -> Realized | F12: =VLOOKUP($C12,'9. All deals (a)'!$C$6:$Q$49,F$5,0) -> Sushil | G12: =VLOOKUP($C12,'9. All deals (a)'!$C$6:$Q$49,G$5,0) -> Mozn 1 | H12: =VLOOKUP($C12,'9. All deals (a)'!$C$6:$Q$49,H$5,0) -> 2021 | I12: =VLOOKUP($C12,'9. All deals (a)'!$C$6:$Q$49,I$5,0) -> A (Ordinary Shares) | J12: =VLOOKUP($C12,'9. All deals (a)'!$C$6:$Q$49,J$5,0) -> 0.03 | K12: =VLOOKUP($C12,'9. All deals (a)'!$C$6:$Q$49,K$5,0) -> 20 | L12: =VLOOKUP($C12,'9. All deals (a)'!$C$6:$Q$49,L$5,0) -> 20 | ... P12: =VLOOKUP($C12,'9. All deals (a)'!$C$6:$Q$49,P$5,0) -> 4.5 | Q12: 0 | R12: =VLOOKUP($C12,'9. All deals (a)'!$C$6:$Q$49,R$5,0) -> 1.225 | S12: Full Exit
C13: Instadeep Limited | D13: Direct Investment | E13: =VLOOKUP($C13,'9. All deals (a)'!$C$6:$Q$49,E$5,0) -> Realized | F13: =VLOOKUP($C13,'9. All deals (a)'!$C$6:$Q$49,F$5,0) -> Ignasi | G13: =VLOOKUP($C13,'9. All deals (a)'!$C$6:$Q$49,G$5,0) -> Mozn | H13: =VLOOKUP($C13,'9. All deals (a)'!$C$6:$Q$49,H$5,0) -> 2021 | I13: =VLOOKUP($C13,'9. All deals (a)'!$C$6:$Q$49,I$5,0) -> B Prefs | J13: =VLOOKUP($C13,'9. All deals (a)'!$C$6:$Q$49,J$5,0) -> 0.011489406 | K13: =VLOOKUP($C13,'9. All deals (a)'!$C$6:$Q$49,K$5,0) -> 5.0237202 | L13: =VLOOKUP($C13,'9. All deals (a)'!$C$6:$Q$49,L$5,0) -> 5.0237202 | ... P13: =VLOOKUP($C13,'9. All deals (a)'!$C$6:$Q$49,P$5,0) -> 2.9184723 | Q13: 1.6721788 | R13: =VLOOKUP($C13,'9. All deals (a)'!$C$6:$Q$49,R$5,0) -> 1.5809385 | S13: Full Exit
C14: Esyasoft Holding | D14: Direct Investment | E14: =VLOOKUP($C14,'9. All deals (a)'!$C$6:$Q$49,E$5,0) -> Realized | F14: =VLOOKUP($C14,'9. All deals (a)'!$C$6:$Q$49,F$5,0) -> Sushil | G14: =VLOOKUP($C14,'9. All deals (a)'!$C$6:$Q$49,G$5,0) -> Mozn | H14: =VLOOKUP($C14,'9. All deals (a)'!$C$6:$Q$49,H$5,0) -> 2020 | I14: =VLOOKUP($C14,'9. All deals (a)'!$C$6:$Q$49,I$5,0) -> Convertible Note | J14: =VLOOKUP($C14,'9. All deals (a)'!$C$6:$Q$49,J$5,0) -> n/a | K14: =VLOOKUP($C14,'9. All deals (a)'!$C$6:$Q$49,K$5,0) -> 2.5 | L14: =VLOOKUP($C14,'9. All deals (a)'!$C$6:$Q$49,L$5,0) -> 2.5 | ... P14: =VLOOKUP($C14,'9. All deals (a)'!$C$6:$Q$49,P$5,0) -> 2.5 | Q14: 2.5 | R14: =VLOOKUP($C14,'9. All deals (a)'!$C$6:$Q$49,R$5,0) -> 2 | S14: Full Exit
C15: Mena Mobile Inc | D15: Direct Investment | E15: =VLOOKUP($C15,'9. All deals (a)'!$C$6:$Q$49,E$5,0) -> Written-off | F15: =VLOOKUP($C15,'9. All deals (a)'!$C$6:$Q$49,F$5,0) -> Elaine | G15: =VLOOKUP($C15,'9. All deals (a)'!$C$6:$Q$49,G$5,0) -> Mozn | H15: =VLOOKUP($C15,'9. All deals (a)'!$C$6:$Q$49,H$5,0) -> 2019 | I15: =VLOOKUP($C15,'9. All deals (a)'!$C$6:$Q$49,I$5,0) -> B Prefs | J15: =VLOOKUP($C15,'9. All deals (a)'!$C$6:$Q$49,J$5,0) -> 0.14 | K15: =VLOOKUP($C15,'9. All deals (a)'!$C$6:$Q$49,K$5,0) -> 8 | L15: =VLOOKUP($C15,'9. All deals (a)'!$C$6:$Q$49,L$5,0) -> 8 | ... P15: =VLOOKUP($C15,'9. All deals (a)'!$C$6:$Q$49,P$5,0) -> -8 | Q15: -8 | R15: =VLOOKUP($C15,'9. All deals (a)'!$C$6:$Q$49,R$5,0) -> 0 | S15: Written Off
C16: Glass Earth Holdings LLC | D16: Debt Investment | E16: =VLOOKUP($C16,'9. All deals (a)'!$C$6:$Q$49,E$5,0) -> Written-off | F16: =VLOOKUP($C16,'9. All deals (a)'!$C$6:$Q$49,F$5,0) -> Marty | G16: =VLOOKUP($C16,'9. All deals (a)'!$C$6:$Q$49,G$5,0) -> Mozn | H16: =VLOOKUP($C16,'9. All deals (a)'!$C$6:$Q$49,H$5,0) -> 2019 | I16: =VLOOKUP($C16,'9. All deals (a)'!$C$6:$Q$49,I$5,0) -> Promissory Note | J16: =VLOOKUP($C16,'9. All deals (a)'!$C$6:$Q$49,J$5,0) -> n/a | K16: =VLOOKUP($C16,'9. All deals (a)'!$C$6:$Q$49,K$5,0) -> 8 | L16: =VLOOKUP($C16,'9. All deals (a)'!$C$6:$Q$49,L$5,0) -> 8 | ... P16: =VLOOKUP($C16,'9. All deals (a)'!$C$6:$Q$49,P$5,0) -> -8 | Q16: -8 | R16: =VLOOKUP($C16,'9. All deals (a)'!$C$6:$Q$49,R$5,0) -> 0 | S16: =VLOOKUP($C16,'9. All deals (a)'!$C$6:$Q$49,S$5,0) -> In Default
C17: Jollychic Holding Limited | D17: Direct Investment | E17: =VLOOKUP($C17,'9. All deals (a)'!$C$6:$Q$49,E$5,0) -> Written-off | F17: =VLOOKUP($C17,'9. All deals (a)'!$C$6:$Q$49,F$5,0) -> Elaine | G17: =VLOOKUP($C17,'9. All deals (a)'!$C$6:$Q$49,G$5,0) -> Mozn | H17: =VLOOKUP($C17,'9. All deals (a)'!$C$6:$Q$49,H$5,0) -> 2019 | I17: =VLOOKUP($C17,'9. All deals (a)'!$C$6:$Q$49,I$5,0) -> C+ Prefs | J17: =VLOOKUP($C17,'9. All deals (a)'!$C$6:$Q$49,J$5,0) -> 0.056999998 | K17: =VLOOKUP($C17,'9. All deals (a)'!$C$6:$Q$49,K$5,0) -> 65 | L17: =VLOOKUP($C17,'9. All deals (a)'!$C$6:$Q$49,L$5,0) -> 65 | ... P17: =VLOOKUP($C17,'9. All deals (a)'!$C$6:$Q$49,P$5,0) -> -65 | Q17: -65 | R17: =VLOOKUP($C17,'9. All deals (a)'!$C$6:$Q$49,R$5,0) -> 0 | S17: =VLOOKUP($C17,'9. All deals (a)'!$C$6:$Q$49,S$5,0) -> In Liquidation
K19: =SUM(K9:K17) -> 604.79042 | L19: =SUM(L9:L17) -> 604.79042 | M19: =SUM(M9:M17) -> 0 | N19: =SUM(N9:N17) -> 440.91298 | O19: =SUM(O9:O17) -> 0 | P19: =O19+N19-L19 -> -163.87745 | Q19: =SUM(Q9:Q17) -> -141.1598 | R19: =(N19+O19)/L19 -> 0.72903432
C21: G42 Investments AI Holding RSC Ltd
C22: Honor Device Co Ltd | D22: Direct Investment | E22: =VLOOKUP($C22,'9. All deals (a)'!$C$6:$Q$49,E$5,0) -> Realized | F22: =VLOOKUP($C22,'9. All deals (a)'!$C$6:$Q$49,F$5,0) -> Elaine | G22: =VLOOKUP($C22,'9. All deals (a)'!$C$6:$Q$49,G$5,0) -> G42 3 | H22: =VLOOKUP($C22,'9. All deals (a)'!$C$6:$Q$49,H$5,0) -> 2022 | I22: =VLOOKUP($C22,'9. All deals (a)'!$C$6:$Q$49,I$5,0) -> Equity-TBC | J22: =VLOOKUP($C22,'9. All deals (a)'!$C$6:$Q$49,J$5,0) -> 0.018823528 | K22: =VLOOKUP($C22,'9. All deals (a)'!$C$6:$Q$49,K$5,0) -> 800 | L22: =VLOOKUP($C22,'9. All deals (a)'!$C$6:$Q$49,L$5,0) -> 800 | ... P22: =VLOOKUP($C22,'9. All deals (a)'!$C$6:$Q$49,P$5,0) -> 2.8 | Q22: 54.67 | R22: =VLOOKUP($C22,'9. All deals (a)'!$C$6:$Q$49,R$5,0) -> 1.0035
C23: Sinovation Disrupt Fund, L.P. | D23: Fund Investment | E23: =VLOOKUP($C23,'9. All deals (a)'!$C$6:$Q$49,E$5,0) -> Realized | F23: =VLOOKUP($C23,'9. All deals (a)'!$C$6:$Q$49,F$5,0) -> Elaine | G23: =VLOOKUP($C23,'9. All deals (a)'!$C$6:$Q$49,G$5,0) -> G42 Investments | H23: =VLOOKUP($C23,'9. All deals (a)'!$C$6:$Q$49,H$5,0) -> 2020 | I23: =VLOOKUP($C23,'9. All deals (a)'!$C$6:$Q$49,I$5,0) -> LP | J23: =VLOOKUP($C23,'9. All deals (a)'!$C$6:$Q$49,J$5,0) -> n/a | K23: =VLOOKUP($C23,'9. All deals (a)'!$C$6:$Q$49,K$5,0) -> 50 | L23: =VLOOKUP($C23,'9. All deals (a)'!$C$6:$Q$49,L$5,0) -> 24.959693 | ... P23: =VLOOKUP($C23,'9. All deals (a)'!$C$6:$Q$49,P$5,0) -> 0.44382835 | Q23: -1.265 | R23: =VLOOKUP($C23,'9. All deals (a)'!$C$6:$Q$49,R$5,0) -> 1.0177818
K25: =SUM(K22:K23) -> 850 | L25: =SUM(L22:L23) -> 824.95969 | M25: =SUM(M22:M23) -> 0 | N25: =SUM(N22:N23) -> 828.20352 | O25: =SUM(O22:O23) -> 0 | P25: =O25+N25-L25 -> 3.2438283 | Q25: =SUM(Q22:Q23) -> 53.405 | R25: =(N25+O25)/L25 -> 1.0039321 | S25: =O25+N25-L25 -> 3.2438283
C27: G42 Capital SPV RSC Ltd
C31: Core42 Holding RSC Ltd
K35: =K19+K25+K29+K33 -> 1454.7904 | L35: =L19+L25+L29+L33 -> 1429.7501 | M35: =M19+M25+M29+M33 -> 0 | N35: =N19+N25+N29+N33 -> 1269.1165 | O35: =O19+O25+O29+O33 -> 0 | P35: =P19+P25+P29+P33 -> -160.63362 | Q35: =Q19+Q25+Q29+Q33 -> -87.754802 | R35: =(N35+O35)/L35 -> 0.88764917
C39: For Notes, refer to 9. All deals (a)
C40: Position Exited or written off are highlighted

Sheet NAV
B2: NAV Date | C2: ='9. All deals (a)'!D2 -> 45565
B5: Investments | C5: Investing Entity | D5: Instrument | E5: Carrying Value | F5: Current Shares/Units | H5: Comment | J5: Date of Update | K5: 14 Apr 2024
E6: USD, Million | F6: # | G6: USD | J6: N A V R E P O R T I N G M A R 2 0 2 4 | N6: A R D E N T E S T I M A T E S M A R 2 0 2 4
E7: ="NAV | "& TEXT(C2,"dd")&" "&TEXT(C2,"mmm")&" "&TEXT(C2,"yyyy") -> NAV | 30 Sep 2024 | G7: ="PPS |" & TEXT(C2,"dd")&" "&TEXT(C2,"mmm")&" "&TEXT(C2,"yyyy") -> PPS |30 Sep 2024 | J7: Name | K7: Carrying Value, Reporting Feb 23 | L7: Carrying Value, Revised Mar 23 | M7: Delta | N7: Carrying Value as per Ardent (as of Dec 23) | O7: Low | P7: High | Q7: Average | R7: Change | S7: Rationale for Price Change
B9: Direct Investments | J9: Drive Nets | K9: 300 | L9: =Q9 -> 204.6 | M9: =L9-K9 -> -95.4 | N9: 300 | O9: 187.6 | P9: 221.6 | Q9: =AVERAGE(O9:P9) -> 204.6 | R9: =Q9-N9 -> -95.4 | S9: marked down
B10: ='9. All deals (a)'!C9 -> Jollychic Holding Limited | C10: ='9. All deals (a)'!F9 -> Mozn | D10: ='9. All deals (a)'!H9 -> C+ Prefs | E10: =F10*G10*10^-6 -> 0 | F10: =VLOOKUP(B10,'6. %'!$C$6:$I$40,2,0) -> 13458655 | H10: In liquidation | J10: Flyr | K10: 78.1 | L10: =Q10 -> 62.9 | M10: =L10-K10 -> -15.2 | N10: 80.3 | O10: 56.9 | P10: 68.9 | Q10: =AVERAGE(O10:P10) -> 62.9 | R10: =Q10-N10 -> -17.4 | S10: marked down
B11: ='9. All deals (a)'!C10 -> Mena Mobile Inc | C11: ='9. All deals (a)'!F10 -> Mozn | D11: ='9. All deals (a)'!H10 -> B Prefs | E11: 0 | F11: =VLOOKUP(B11,'6. %'!$C$6:$I$40,2,0) -> 21419829 | H11: As per 3rd Party | Ardent Estimates | Equity written off | J11: Beyond Limits | K11: 91 | L11: =Q11 -> 73.8 | M11: =L11-K11 -> -17.2 | N11: 102.1 | O11: 66.2 | P11: 81.4 | Q11: =AVERAGE(O11:P11) -> 73.8 | R11: =Q11-N11 -> -28.3 | S11: marked down
B12: ='9. All deals (a)'!C11 -> Flyr Inc | C12: ='9. All deals (a)'!F11 -> Mozn | D12: ='9. All deals (a)'!H11 -> B-1,2 Prefs | E12: =F12*G12*10^-6 -> 37.11873 | F12: =VLOOKUP(B12,'6. %'!$C$6:$I$40,2,0) -> 5205482 | G12: 7.1307 | H12: As per the recent fund raise completed in Dec 23 | J12: Worldcoin | K12: 15 | L12: =Q12 -> 161.9 | M12: =L12-K12 -> 146.9 | N12: =5.9*10^-3 -> 0.0059 | Q12: 161.9 | R12: =Q12-N12 -> 161.8941 | S12: marked up
B13: ='9. All deals (a)'!C12 -> Esyasoft Holding | C13: ='9. All deals (a)'!F12 -> Mozn | D13: ='9. All deals (a)'!H12 -> Convertible Note | E13: 0 | F13: =VLOOKUP(B13,'6. %'!$C$6:$I$40,2,0) -> n/a | H13: Exited at $5m (10th May) | Residual value = 0
B14: ='9. All deals (a)'!C13 -> Beyond Limits | C14: ='9. All deals (a)'!F13 -> Mozn | D14: ='9. All deals (a)'!H13 -> C Prefs | E14: =F14*G14/2/1000000 -> 45.50077 | F14: =VLOOKUP(B14,'6. %'!$C$6:$I$40,2,0) -> 17670202 | G14: 5.15 | H14: Marked down as per new round discussion Aug'24
B15: ='9. All deals (a)'!C14 -> ONT plc | C15: ='9. All deals (a)'!F14 -> Mozn | D15: ='9. All deals (a)'!H14 -> Ordinary Shares | E15: =F15*G15*10^-6 -> 94.332809 | F15: =VLOOKUP(B15,'6. %'!$C$6:$I$40,2,0) -> 44328120 | G15: =K18*K20 -> 2.128058 | H15: Listed & marked to market
B16: ='9. All deals (a)'!C15 -> Heygears | C16: ='9. All deals (a)'!F15 -> Mozn | D16: ='9. All deals (a)'!H15 -> Registered Capital | E16: =K34/1000000 -> 153.73258 | F16: ='CF (Equity, Debt)'!J20 -> 3565017.2 | H16: Adjusted for currency. Valued at the recent round | J16: Updated as on: | K16: =C2 -> 45565 | L16: source
B17: ='9. All deals (a)'!C16 -> Jysan Technologies | C17: ='9. All deals (a)'!F16 -> Mozn 1 | D17: ='9. All deals (a)'!H16 -> A (Ordinary Shares) | E17: 0 | F17: =VLOOKUP(B17,'6. %'!$C$6:$I$40,2,0) -> 7959497 | G17: =E17*10^6/F17 -> 0 | H17: Exited at $24.5m | J17: WLD Price | K17: =1.8914 -> 1.8914 | L17: CoinMarket Cap
B18: ='9. All deals (a)'!C17 -> Cerebras Systems Inc | C18: ='9. All deals (a)'!F17 -> Mozn | D18: ='9. All deals (a)'!H17 -> F Prefs | E18: =F18*G18*10^-6 -> 21.135483 | F18: =VLOOKUP(B18,'6. %'!$C$6:$I$40,2,0) -> 1441711 | G18: 14.66 | H18: Held at cost | J18: ONT Share price | K18: 1.591 | L18: LSE ONT
B19: ='9. All deals (a)'!C18 -> Endless Studios LLC | C19: ='9. All deals (a)'!F18 -> Mozn | D19: ='9. All deals (a)'!H18 -> A Pref Units | E19: =-'CF (Equity, Debt)'!E23-'CF (Equity, Debt)'!E41 -> 8 | F19: =VLOOKUP(B19,'6. %'!$C$6:$I$40,2,0) -> 8000000 | H19: Held at cost | J19: VTVT Share price | K19: 13.565 | L19: Nasdaq VTVT
B20: ='9. All deals (a)'!C19 -> Instadeep Limited | C20: ='9. All deals (a)'!F19 -> Mozn | D20: ='9. All deals (a)'!H19 -> B Prefs | E20: =-'CF (Equity, Debt)'!E24*G20 -> 0 | F20: =VLOOKUP(B20,'6. %'!$C$6:$I$40,2,0) -> 33267 | G20: 0 | H20: Exited at 1.56X | Residual Value = 0 | J20: GBP USD | K20: 1.33756 | L20: xe.com
B21: ='9. All deals (a)'!C20 -> X-fusion | C21: ='9. All deals (a)'!F20 -> Mozn 2 | D21: ='9. All deals (a)'!H20 -> Equity-TBC | E21: 0 | F21: =VLOOKUP(B21,'6. %'!$C$6:$I$40,2,0) -> n/a | H21: Exited at 0.82X | J21: USD RMB | K21: 7.01699 | L21: xe.com
B22: ='9. All deals (a)'!C21 -> DriveNets | C22: ='9. All deals (a)'!F21 -> G42 | D22: ='9. All deals (a)'!H21 -> Equity-TBC | E22: =L9 -> 204.6 | F22: =VLOOKUP(B22,'6. %'!$C$6:$I$40,2,0) -> 86882669 | H22: Held at cost | J22: EUR USD | K22: 1.11377 | L22: xe.com
B23: ='9. All deals (a)'!C22 -> vTv Therapeutics Inc. | C23: ='9. All deals (a)'!F22 -> G42 | D23: ='9. All deals (a)'!H22 -> Ordinary Shares | E23: =(F23*G23)*10^-6 -> 3.5222472 | F23: =VLOOKUP(B23,'6. %'!$C$6:$I$40,2,0) -> 259657 | G23: =K19 -> 13.565 | H23: Listed & marked to market
B24: ='9. All deals (a)'!C23 -> Honor Device Co Ltd | C24: ='9. All deals (a)'!F23 -> G42 3 | D24: ='9. All deals (a)'!H23 -> Equity-TBC | E24: 0 | F24: =VLOOKUP(B24,'6. %'!$C$6:$I$40,2,0) -> 6.0685078e+08 | H24: Exited at 1.0X
B25: ='9. All deals (a)'!C24 -> Applied AI Corporation Limited | C25: ='9. All deals (a)'!F24 -> Mozn | D25: ='9. All deals (a)'!H24 -> Convertible Note | E25: =-'CF (Equity, Debt)'!E32-'CF (Equity, Debt)'!E38-'CF (Equity, Debt)'!E47 -> 11.5 | F25: =VLOOKUP(B25,'6. %'!$C$6:$I$40,2,0) -> n/a | H25: Held at cost | J25: Heygears Oct 22
B26: ='9. All deals (a)'!C25 -> eSpace | C26: ='9. All deals (a)'!F25 -> Mozn 4 | D26: ='9. All deals (a)'!H25 -> B Prefs | E26: =F26*G26*10^-6 -> 20.888122 | F26: =VLOOKUP(B26,'6. %'!$C$6:$I$40,2,0) -> 417846 | G26: 49.99 | H26: Marked up, as converted as per the latest priced round | J26: Post Valuation closed in June 2021 (RMB) | K26: 7500000000
B27: ='9. All deals (a)'!C26 -> Tools for Humanity Corporation | C27: ='9. All deals (a)'!F26 -> Mozn | D27: ='9. All deals (a)'!H26 -> C Prefs | E27: ='9. All deals (a)'!K26 -> 14.999999 | F27: =VLOOKUP(B27,'6. %'!$C$6:$I$40,2,0) -> 65413 | H27: Held at cost | J27: G42 Stake | K27: 0.143832
B28: ='9. All deals (a)'!C27 -> WLD Tokens | C28: ='9. All deals (a)'!F27 -> Mozn | D28: ='9. All deals (a)'!H27 -> Tokens | E28: =F28*G28*10^-6 -> 118.2125 | F28: =VLOOKUP(B28,'6. %'!$C$6:$I$40,2,0) -> 62500000 | G28: =K17 -> 1.8914 | H28: source: coinmarket cap | J28: G42 Valuation before Discount (RMB) | K28: 1078740000
B29: ='9. All deals (a)'!C28 -> E-line Ventures LLC | C29: ='9. All deals (a)'!F28 -> Mozn | D29: ='9. All deals (a)'!H28 -> B Prefs | E29: =MAX('9. All deals (a)'!K28,F29*G29*10^-6) -> 6 | F29: =VLOOKUP(B29,'6. %'!$C$6:$I$40,2,0) -> 4477612 | H29: Held at cost | J29: Liquidity Discount | K29: 0
B30: ='9. All deals (a)'!C29 -> School Hack (AIREV Holding Limited) | C30: ='9. All deals (a)'!F29 -> Core42 5 | D30: ='9. All deals (a)'!H29 -> Preferred Shares | E30: =MAX('9. All deals (a)'!K29,F30*G30*10^-6) -> 2.5 | F30: =VLOOKUP(B30,'6. %'!$C$6:$I$40,2,0) -> 25000 | H30: Held at cost | J30: Minority Holding Discount | K30: 0
B31: ='9. All deals (a)'!C30 -> Life Biosciences LLC | C31: ='9. All deals (a)'!F30 -> G42 Capital | D31: ='9. All deals (a)'!H30 -> Convertible Note | E31: =-'CF (Equity, Debt)'!E49 -> 20 | F31: =VLOOKUP(B31,'6. %'!$C$6:$I$40,2,0) -> n/a | H31: Held at cost | J31: G42 Valuation (RMB) | K31: =K28*(1-K29)*(1-K30) -> 1078740000
B32: ='9. All deals (a)'!C31 -> Verses AI Inc | C32: ='9. All deals (a)'!F31 -> G42 Capital | D32: ='9. All deals (a)'!H31 -> Convertible Debenture | E32: =-'CF (Equity, Debt)'!E50 -> 10 | F32: =VLOOKUP(B32,'6. %'!$C$6:$I$40,2,0) -> n/a | H32: Held at cost
J33: Exchange Rate (RMB/USD) | K33: =K21 -> 7.01699
B34: Debt Investments | J34: G42 Valuation (USD) | K34: =K31/K33 -> 1.5373258e+08
B35: Glass Earth Holdings LLC | C35: Mozn | D35: Promissory Note | E35: ='9. All deals (a)'!N36 -> 0 | H35: In default | J35: Investment Cost of G42 (USD) | K35: 60000000
B36: Mena Mobile Inc (Debt) | C36: Mozn | D36: Loan | E36: 0 | H36: In liquidation
B37: Esyasoft Holding (Debt) | C37: Mozn | D37: Loan | E37: 0 | H37: Exited. Received payment of $470,784.65 ($411K+$59K)
B39: Funds Investments | J39: Checks
B40: New Space Capital Fund I | C40: G42 | D40: LP | E40: ='8. NewSpace'!I38*10^-6*K22-'CF (Funds)'!E50 -> 21.613971 | H40: Q2'24 capital account statement
B41: New Space Capital GP Com SCSp | C41: G42 | D41: GP | E41: =E40*'1. Live'!L28/'1. Live'!L27 -> 3.6731096 | H41: Q2'24 pro-rated | J41: =SUM(E10:E32) -> 772.04324 | K41: =J41='9. All deals (a)'!N33 -> TRUE
B42: North Summit Capital Fund | C42: G42 | D42: LP | E42: =91.324446 -> 91.324446 | H42: Q1'24 capital account statement | J42: =SUM(E35:E37) -> 0 | K42: =J42='9. All deals (a)'!N39 -> TRUE
B43: Sinovation Disrupt Fund, L.P. | C43: G42 | D43: LP | E43: 0 | H43: Exited | J43: =SUM(E40:E44) -> 127.48674 | K43: =J43='9. All deals (a)'!N47 -> TRUE
B44: Acies Investments Fund I, L.P. | C44: G42 | D44: LP | E44: 10.875212 | H44: Q2'24 capital account statement
B45: Note:
...

Sheet CF (Equity, Debt)
B2: E Q U I T Y
B3: Accounting entity | C3: Investment | D3: Payment date | E3: Contributions (in USD, Mn) | F3: Distributions (in USD, Mn) | G3: Currency | H3: Investment / Exit Amt (investee currency) | I3: Investment / Exit Amount (USD) | J3: Consideration (shares) | K3: Comment | N3: NOTES
B4: =VLOOKUP(C4,'9. All deals (a)'!$C$9:$F$46,4,0) -> Mozn | C4: Jollychic Holding Limited | D4: 43470 | E4: =-I4*10^-6 -> -30 | G4: USD | H4: 30000000 | I4: =H4 -> 30000000 | J4: 6100312 | N4: USD AED | O4: 3.678
B5: =VLOOKUP(C5,'9. All deals (a)'!$C$9:$F$46,4,0) -> Mozn | C5: Jollychic Holding Limited | D5: 43724 | E5: =-I5*10^-6 -> -20 | G5: USD | H5: 20000000 | I5: =H5 -> 20000000 | J5: 4204767.4
B6: =VLOOKUP(C6,'9. All deals (a)'!$C$9:$F$46,4,0) -> Mozn | C6: Jollychic Holding Limited | D6: 43724 | E6: =-I6*10^-6 -> -15 | G6: USD | H6: 15000000 | I6: =H6 -> 15000000 | J6: 3153575.6
B7: =VLOOKUP(C7,'9. All deals (a)'!$C$9:$F$46,4,0) -> Mozn | C7: Mena Mobile Inc | D7: 43563 | E7: =-I7*10^-6 -> -8 | G7: USD | H7: 8000000 | I7: =H7 -> 8000000 | J7: 21419829
B8: =VLOOKUP(C8,'9. All deals (a)'!$C$9:$F$46,4,0) -> Mozn | C8: Flyr Inc | D8: 43570 | E8: =-I8*10^-6 -> -4.9999981 | G8: USD | H8: 4999998.1 | I8: =H8 -> 4999998.1 | J8: 2625467
B9: =VLOOKUP(C9,'9. All deals (a)'!$C$9:$F$46,4,0) -> Mozn | C9: Flyr Inc | D9: 43915 | E9: =-I9*10^-6 -> -5.0000019 | G9: USD | H9: =10000000-H8 -> 5000001.9 | I9: =H9 -> 5000001.9 | J9: 2580015
B10: =VLOOKUP(C10,'9. All deals (a)'!$C$9:$F$46,4,0) -> Mozn | C10: Esyasoft Holding | D10: 43870 | E10: =-I10*10^-6 -> -2.5 | G10: USD | H10: 2500000 | I10: =H10 -> 2500000 | J10: N/A
B11: =VLOOKUP(C11,'9. All deals (a)'!$C$9:$F$46,4,0) -> Mozn | C11: Beyond Limits | D11: 43879 | E11: =-I11*10^-6 -> -20 | G11: USD | H11: 20000000 | I11: =H11 -> 20000000 | J11: 4084038
B12: =VLOOKUP(C12,'9. All deals (a)'!$C$9:$F$46,4,0) -> Mozn | C12: Beyond Limits | D12: 43921 | E12: =-I12*10^-6 -> -30 | G12: USD | H12: 30000000 | I12: =H12 -> 30000000 | J12: 5822642
B13: =VLOOKUP(C13,'9. All deals (a)'!$C$9:$F$46,4,0) -> Mozn | C13: Beyond Limits | D13: 43989 | E13: =-I13*10^-6 -> -30 | G13: USD | H13: 30000000 | I13: =H13 -> 30000000 | J13: 5822642
B14: =VLOOKUP(C14,'9. All deals (a)'!$C$9:$F$46,4,0) -> Mozn | C14: Beyond Limits | D14: 44103 | E14: =-I14*10^-6 -> -10 | G14: USD | H14: 10000000 | I14: =H14 -> 10000000 | J14: 1940880
B15: =VLOOKUP(C15,'9. All deals (a)'!$C$9:$F$46,4,0) -> Mozn | C15: ONT plc | D15: 43968 | E15: =-I15*10^-6 -> -50 | G15: USD | H15: 50000000 | I15: 50000000 | J15: 15277680
B16: =VLOOKUP(C16,'9. All deals (a)'!$C$9:$F$46,4,0) -> Mozn | C16: ONT plc | D16: 44006 | E16: =-I16*10^-6 -> -27.268351 | G16: GBP | H16: 21029625 | I16: 27268351 | J16: 9000000
B17: =VLOOKUP(C17,'9. All deals (a)'!$C$9:$F$46,4,0) -> Mozn | C17: ONT plc | D17: 43837 | E17: =-I17*10^-6 -> -18.109441 | G17: GBP | H17: 14386480 | I17: 18109441 | J17: 6362180
B18: =VLOOKUP(C18,'9. All deals (a)'!$C$9:$F$46,4,0) -> Mozn | C18: ONT plc | D18: 43990 | E18: =-I18*10^-6 -> -34.851687 | G18: GBP | H18: 26085573 | I18: 34851687 | J18: 11381140
B19: =VLOOKUP(C19,'9. All deals (a)'!$C$9:$F$46,4,0) -> Mozn | C19: ONT plc | D19: 44315 | E19: =-I19*10^-6 -> -11.24078 | G19: GBP | H19: 8074920 | I19: 11240780 | J19: 2307120
B20: =VLOOKUP(C20,'9. All deals (a)'!$C$9:$F$46,4,0) -> Mozn | C20: Heygears | D20: 44166 | E20: =-I20*10^-6 -> -60 | G20: USD | H20: 60000000 | I20: =H20 -> 60000000 | J20: 3565017.2
B21: =VLOOKUP(C21,'9. All deals (a)'!$C$9:$F$46,4,0) -> Mozn 1 | C21: Jysan Technologies | D21: 44363 | E21: =-I21*10^-6 -> -20 | G21: USD | H21: 20000000 | I21: =H21 -> 20000000 | J21: 7959497
B22: =VLOOKUP(C22,'9. All deals (a)'!$C$9:$F$46,4,0) -> Mozn | C22: Cerebras Systems Inc | D22: 44488 | E22: =-I22*10^-6 -> -39.999983 | G22: USD | H22: 39999983 | I22: =H22 -> 39999983 | J22: 1441711
B23: =VLOOKUP(C23,'9. All deals (a)'!$C$9:$F$46,4,0) -> Mozn | C23: Endless Studios LLC | D23: 44494 | E23: =-I23*10^-6 -> -3 | G23: USD | H23: 3000000 | I23: =H23 -> 3000000 | J23: 3000000
B24: =VLOOKUP(C24,'9. All deals (a)'!$C$9:$F$46,4,0) -> Mozn | C24: Instadeep Limited | D24: 44550 | E24: =-I24*10^-6 -> -5.0237202 | G24: GBP | H24: 3679995.5 | I24: 5023720.2 | J24: 33267
B25: =VLOOKUP(C25,'9. All deals (a)'!$C$9:$F$46,4,0) -> Mozn 2 | C25: X-fusion | D25: 44574 | E25: =-I25*10^-6 -> -493.50096 | G25: USD | H25: 8.9350096e+08 | I25: 4.9350096e+08
B26: =VLOOKUP(C26,'9. All deals (a)'!$C$9:$F$46,4,0) -> G42 | C26: DriveNets | D26: 44643 | E26: =-I26*10^-6 -> -200 | G26: USD | H26: 200000000 | I26: =H26 -> 200000000
B27: =VLOOKUP(C27,'9. All deals (a)'!$C$9:$F$46,4,0) -> G42 | C27: DriveNets | D27: 44680 | E27: =-I27*10^-6 -> -100 | G27: USD | H27: 100000000 | I27: =H27 -> 100000000
B28: =VLOOKUP(C28,'9. All deals (a)'!$C$9:$F$46,4,0) -> Mozn | C28: Esyasoft Holding | D28: 44691 | F28: 5 | G28: USD
B29: =VLOOKUP(C29,'9. All deals (a)'!$C$9:$F$46,4,0) -> G42 | C29: vTv Therapeutics Inc. | D29: 44712 | E29: =-I29*10^-6 -> -12.5 | G29: USD | H29: 12500000 | I29: =H29 -> 12500000 | J29: ='6. %'!D22 -> 259657
B30: =VLOOKUP(C30,'9. All deals (a)'!$C$9:$F$46,4,0) -> G42 3 | C30: Honor Device Co Ltd | D30: 44769 | E30: =-I30*10^-6 -> -600 | G30: USD | H30: 600000000 | I30: =H30 -> 600000000
B31: =VLOOKUP(C31,'9. All deals (a)'!$C$9:$F$46,4,0) -> G42 3 | C31: Honor Device Co Ltd | D31: 44849 | E31: =-I31*10^-6 -> -200 | G31: USD | H31: 200000000 | I31: =H31 -> 200000000
B32: =VLOOKUP(C32,'9. All deals (a)'!$C$9:$F$46,4,0) -> Mozn | C32: Applied AI Corporation Limited | D32: 44861 | E32: =-I32*10^-6 -> -4.75 | G32: USD | H32: 4750000 | I32: =H32 -> 4750000
B33: =VLOOKUP(C33,'9. All deals (a)'!$C$9:$F$46,4,0) -> Mozn 4 | C33: eSpace | D33: 44892 | E33: =-I33*10^-6 -> -15 | G33: USD | H33: 15000000 | I33: =H33 -> 15000000
B34: =VLOOKUP(C34,'9. All deals (a)'!$C$9:$F$46,4,0) -> G42 | C34: vTv Therapeutics Inc. | D34: 44985 | E34: =-I34*10^-6 -> -12.03125 | G34: USD | H34: 12031250 | I34: =H34 -> 12031250 | J34: 10386274
B35: =VLOOKUP(C35,'9. All deals (a)'!$C$9:$F$46,4,0) -> Mozn | C35: Tools for Humanity Corporation | D35: 45075 | E35: =-I35*10^-6 -> -14.999999 | G35: USD | H35: 14999999 | I35: =H35 -> 14999999
B36: =VLOOKUP(C36,'9. All deals (a)'!$C$9:$F$46,4,0) -> Mozn | C36: WLD Tokens | D36: 45075 | E36: =-I36*10^-6 -> -0.005875 | G36: USD | I36: 5875
B37: =VLOOKUP(C37,'9. All deals (a)'!$C$9:$F$46,4,0) -> Mozn | C37: WLD Tokens | D37: 45114 | E37: =-I37*10^-6 -> -0.001 | G37: USD | I37: 1000
B38: =VLOOKUP(C38,'9. All deals (a)'!$C$9:$F$46,4,0) -> Mozn | C38: Applied AI Corporation Limited | D38: 45121 | E38: =-I38*10^-6 -> -2.75 | G38: USD | I38: 2750000
B39: =VLOOKUP(C39,'9. All deals (a)'!$C$9:$F$46,4,0) -> Mozn | C39: Instadeep Limited | D39: 45138 | F39: =I39*10^-6 -> 7.8207761 | G39: USD | H39: 6090345.2 | I39: 7820776.1
B40: =VLOOKUP(C40,'9. All deals (a)'!$C$9:$F$46,4,0) -> Mozn 1 | C40: Jysan Technologies | D40: 45149 | F40: 24.5 | G40: USD | I40: 24500000 | J40: 7959497
B41: =VLOOKUP(C41,'9. All deals (a)'!$C$9:$F$46,4,0) -> Mozn | C41: Endless Studios LLC | D41: 45167 | E41: =-I41*10^-6 -> -5 | G41: USD | I41: 5000000 | J41: 5000000
...

Sheet CF (Funds)
B2: F U N D S
B3: Entity | C3: Investment | D3: Payment date | E3: Contributions (USD, Mn) | F3: Distributions (USD, Mn) | G3: Currency | H3: Cashflows | I3: Description | J3: TEST
B4: G42 | C4: Sinovation Disrupt Fund, L.P. | D4: 44153 | E4: =H4 -> -10.5 | G4: USD | H4: -10.5 | I4: 1st Capital Call | J4: =SUM(E4:E58) -> -140.8735
B5: G42 | C5: Sinovation Disrupt Fund, L.P. | D5: 44238 | E5: =H5 -> 4.214027 | G5: USD | H5: 4.214027 | I5: Partial return of the 1st Capital Call | J5: ='9. All deals (a)'!K47 -> 140.8735
B6: G42 | C6: Sinovation Disrupt Fund, L.P. | D6: 44238 | F6: =H6 -> 0.05044835 | G6: USD | H6: 0.05044835 | I6: Interest Catchup | J6: =ROUND(J5,5)=-ROUND(J4,5) -> TRUE
B7: G42 | C7: Sinovation Disrupt Fund, L.P. | D7: 44285 | E7: =H7 -> -6.433746 | G7: USD | H7: -6.433746 | I7: 2nd Capital Calll
B8: G42 | C8: Sinovation Disrupt Fund, L.P. | D8: 44269 | E8: =H8 -> 1.1352074 | G8: USD | H8: 1.1352074 | I8: Return of Capital fund
B9: G42 | C9: Sinovation Disrupt Fund, L.P. | D9: 44269 | F9: =H9 -> 0.0259 | G9: USD | H9: 0.0259 | I9: Interest Catchup
B10: G42 | C10: Sinovation Disrupt Fund, L.P. | D10: 44483 | E10: =H10 -> -7.567138 | G10: USD | H10: -7.567138 | I10: 3rd Capital Call
B11: G42 | C11: Sinovation Disrupt Fund, L.P. | D11: 44554 | E11: =H11 -> -7.385016 | G11: USD | H11: -7.385016 | I11: 4th Capital Call
B12: G42 | C12: Sinovation Disrupt Fund, L.P. | D12: 44554 | E12: =H12 -> 4.0733456 | G12: USD | H12: 4.0733456 | I12: Return of Capital fund
B13: G42 | C13: Sinovation Disrupt Fund, L.P. | D13: 44554 | F13: =H13 -> 0.139694 | G13: USD | H13: 0.139694 | I13: Interest Catchup
B14: G42 | C14: Sinovation Disrupt Fund, L.P. | D14: 44703 | E14: =H14 -> 5.673074 | G14: USD | H14: 5.673074 | I14: Return of Capital fund
B15: G42 | C15: Sinovation Disrupt Fund, L.P. | D15: 44703 | F15: =H15 -> 0.227786 | G15: USD | H15: 0.227786 | I15: Interest Catchup
B16: G42 | C16: Sinovation Disrupt Fund, L.P. | D16: 44776 | E16: =H16 -> -3.235493 | G16: USD | H16: -3.235493 | I16: 5th Capital Call
B17: G42 | C17: Sinovation Disrupt Fund, L.P. | D17: 44960 | E17: =H17 -> -2.631528 | G17: USD | H17: -2.631528 | I17: 6th Capital Call
B18: G42 | C18: Sinovation Disrupt Fund, L.P. | D18: 45085 | E18: =H18 -> 1.912557 | G18: USD | H18: 1.912557 | I18: Return of Capital fund
B19: G42 | C19: Sinovation Disrupt Fund, L.P. | D19: 45166 | E19: -1.799122 | G19: USD | H19: -1.799122 | I19: 7th Capital Call
B20: G42 | C20: Sinovation Disrupt Fund, L.P. | D20: 45218 | E20: -2.415861 | G20: USD | H20: -2.415861 | I20: 8th Capital Call
B21: G42 | C21: Sinovation Disrupt Fund, L.P. | D21: 45323 | F21: =24.959693 -> 24.959693 | G21: USD | H21: =F21 -> 24.959693 | I21: Exit Proceeds (full and final)
B22: G42 | C22: North Summit Capital Fund | D22: 43665 | E22: =H22 -> -3 | G22: USD | H22: -3 | I22: 1st Capital Call
B23: G42 | C23: North Summit Capital Fund | D23: 43983 | E23: =H23 -> -4.485 | G23: USD | H23: -4.485 | I23: 2nd Capital Calll
B24: G42 | C24: North Summit Capital Fund | D24: 43879 | E24: =H24 -> -9.50975 | G24: USD | H24: -9.50975 | I24: 3rd Capital Call
B25: G42 | C25: North Summit Capital Fund | D25: 43934 | E25: =H25 -> -41.3 | G25: USD | H25: -41.3 | I25: 4th Capital Call
B26: G42 | C26: North Summit Capital Fund | D26: 44151 | E26: =H26 -> 9.95 | G26: USD | H26: 9.95 | I26: 5th Capital Call-Partial return of the 4th Capital Call
B27: G42 | C27: North Summit Capital Fund | D27: 44151 | E27: =H27 -> -10.455 | G27: USD | H27: -10.455 | I27: 5th Capital Call
B28: G42 | C28: North Summit Capital Fund | D28: 44196 | E28: =H28 -> 4.975 | G28: USD | H28: 4.975 | I28: 6th Capital Call-Partial return of the 4th Capital Call
B29: G42 | C29: North Summit Capital Fund | D29: 44196 | E29: =H29 -> -3.452293 | G29: USD | H29: -3.452293 | I29: 6th Capital Call
B30: G42 | C30: North Summit Capital Fund | D30: 44196 | F30: =H30 -> 0.582902 | G30: USD | H30: 0.582902 | I30: 6th Capital Call-Dividends from Project Topscore
B31: G42 | C31: North Summit Capital Fund | D31: 44370 | E31: =H31 -> -5.97 | G31: USD | H31: -5.97 | I31: 7th Capital Call
B32: G42 | C32: North Summit Capital Fund | D32: 44400 | E32: =H32 -> -0.75 | G32: USD | H32: -0.75 | I32: 8th Capital Call
B33: G42 | C33: North Summit Capital Fund | D33: 44400 | F33: =H33 -> 0.445059 | G33: USD | H33: 0.445059 | I33: 8th Capital Call-Dividends from Project Topscore
B34: G42 | C34: North Summit Capital Fund | D34: 44554 | E34: =H34 -> 1.78239 | G34: USD | H34: 1.78239 | I34: 9th Capital Call-Return of Capital Fund
B35: G42 | C35: North Summit Capital Fund | D35: 44676 | E35: =H35 -> -21 | G35: USD | H35: -21 | I35: 12th Capital Call
B36: G42 | C36: North Summit Capital Fund | D36: 45243 | F36: =H36 -> 6.78791 | G36: USD | H36: 6.78791 | I36: 13th Capital Call & Distribution #4
B37: G42 | C37: North Summit Capital Fund | D37: 45470 | E37: =H37 -> -0.055697 | G37: USD | H37: =-55697*10^-6 -> -0.055697 | I37: 14th Capital Call
B38: G42 | C38: New Space Capital Fund I | D38: 44087 | E38: =H38*1.1 -> -20.917553 | G38: EUR | H38: -19.015957 | I38: Drawdown1
B39: G42 | C39: New Space Capital Fund I | D39: 44287 | E39: -0.21103182 | G39: EUR | H39: -0.21103182 | I39: Drawdown2
B40: G42 | C40: New Space Capital Fund I | D40: 44442 | E40: =1.18*H40 -> -0.23965473 | G40: EUR | H40: =-203097.23*10^-6 -> -0.20309723 | I40: Drawdown3
B41: G42 | C41: New Space Capital Fund I | D41: 44623 | E41: =1.11*H41 -> -0.25893585 | G41: EUR | H41: =-233275.54*10^-6 -> -0.23327554 | I41: Drawdown4
...

Sheet 6. %
C2: % OWNERSHIP
C3: As of date | D3: ='9. All deals (a)'!D2 -> 45565
C6: Deals | D6: Shares / Units | E6: Total | F6: % | G6: Source for % holding | H6: Incorporation/Jurisdiction | I6: Country
C8: Direct Investments
B9: Written Off | C9: ='9. All deals (a)'!C9 -> Jollychic Holding Limited | D9: 13458655 | E9: 236116762 | F9: =D9/E9 -> 0.056999998 | G9: Dan Kong | H9: Cayman Islands | I9: Cayman Islands
B10: Written Off | C10: ='9. All deals (a)'!C10 -> Mena Mobile Inc | D10: 21419829 | E10: 152998776 | F10: =D10/E10 -> 0.14 | G10: Dan Kong | H10: Cayman Islands | I10: Cayman Islands
C11: ='9. All deals (a)'!C11 -> Flyr Inc | D11: 5205482 | E11: ='[1]Summary Cap Table'!$D$59 -> 125184593 | F11: =D11/E11 -> 0.041582449 | G11: Cap Table as of Jun'22 | H11: Delaware Corporation | I11: USA
B12: Exited | C12: ='9. All deals (a)'!C12 -> Esyasoft Holding | D12: n/a | E12: n/a | F12: n/a | G12: n/a; exited | H12: DIFC | I12: Dubai, UAE
C13: ='9. All deals (a)'!C13 -> Beyond Limits | D13: 17670202 | E13: 187288050 | F13: =D13/E13 -> 0.094347728 | G13: Cap Table | H13: Delaware Corporation | I13: USA
C14: ='9. All deals (a)'!C14 -> ONT plc | D14: 44328120 | E14: 940896164 | F14: =D14/E14 -> 0.047112659 | G14: LSE Announcement | H14: UK | I14: UK
C15: ='9. All deals (a)'!C15 -> Heygears | D15: 3565017.2 | E15: =D15/F15 -> 24791497 | F15: 0.1438 | G15: Dan Kong | H15: PRC | I15: China
B16: Exited | C16: ='9. All deals (a)'!C16 -> Jysan Technologies | D16: 7959497 | E16: 2.6531657e+08 | F16: 0.03 | G16: Txn docs | H16: UK | I16: UK
C17: ='9. All deals (a)'!C17 -> Cerebras Systems Inc | D17: 1441711 | E17: 158130778 | F17: =D17/E17 -> 0.0091172068 | G17: Cap table as of Dec'22 | H17: Delaware Corporation | I17: USA
C18: ='9. All deals (a)'!C18 -> Endless Studios LLC | D18: 8000000 | E18: =38750000+11000000 -> 49750000 | F18: =D18/E18 -> 0.16080402 | G18: Cap table as of Dec'22 | H18: Delaware Corporation | I18: USA
B19: Exited | C19: ='9. All deals (a)'!C19 -> Instadeep Limited | D19: 33267 | E19: 2895450 | F19: =D19/E19 -> 0.011489406 | G19: Txn docs; exit underway | H19: UK | I19: UK
B20: Exited | C20: ='9. All deals (a)'!C20 -> X-fusion | D20: n/a | E20: n/a | F20: =10% * 51% -> 0.051 | G20: Dan Kong | H20: PRC | I20: China
C21: ='9. All deals (a)'!C21 -> DriveNets | D21: 86882669 | E21: 779782293 | F21: =D21/E21 -> 0.11141914 | G21: Cap table as of Mar'23 | H21: Israeli Pvt Company | I21: Israel
