Workbook
Name Company: [1]UEL!$B$18:$B$20
Name Dates: [1]ONT!$N$2:$AN$2
Name DetailedCapShares: '[2]Current Cap'!$T$133
Name FAGroup: [1]UEL!$B$3:$B$15
Name IQ_CH: 110000
Name IQ_CQ: 5000
Name IQ_CY: 10000
Name IQ_DAILY: 500000
Name IQ_FH: 100000
Name IQ_FQ: 500
Name IQ_FY: 1000
Name IQ_LTM: 2000
Name IQ_MONTH: 15000
Name IQ_NTM: 6000
Name IQ_WEEK: 50000
Name IQ_YTD: 3000

Sheet D
C2: Date of NAV | D2: 45322 | E2: =TEXT(D2,"dddddd") -> Wednesday
H3: D A S H B O A R D | L3: figures in USD Millions
D6: # Investments | E6: Committed | F6: Invested | G6: Remaining | H6: Distributions | I6: Residual Value | J6: IRR | K6: TVPI | L6: RPI | M6: DPI
C8: EQUITY | D8: =COUNTIF('S | 01 '!C10:C32,"*") -> 21 | E8: ='1. IRR Equity'!AH35 -> 2121.7862 | F8: ='1. IRR Equity'!AI35 -> 2118.283 | G8: ='1. IRR Equity'!AJ35 -> 3.5031614 | H8: ='1. IRR Equity'!AK35 -> 1243.2422 | I8: ='1. IRR Equity'!AL35 -> 828.59461 | J8: ='1. IRR Equity'!AM35 -> -0.011569161 | K8: ='1. IRR Equity'!AN35 -> 0.97807364 | L8: ='1. IRR Equity'!AO35 -> 0.39116331 | M8: ='1. IRR Equity'!AP35 -> 0.58691033
C11: DEBT | D11: =COUNTIF('S | 01 '!C35:C37,"*") -> 3 | E11: ='2. IRR Debt'!Q12 -> 10.765747 | F11: ='2. IRR Debt'!R12 -> 10.765747 | G11: ='2. IRR Debt'!S12 -> 0 | H11: ='2. IRR Debt'!T12 -> 0.47078465 | I11: ='2. IRR Debt'!U12 -> 0 | J11: ='2. IRR Debt'!V12 -> -0.71226245 | K11: ='2. IRR Debt'!W12 -> 0.043729864 | L11: ='2. IRR Debt'!X12 -> 0 | M11: ='2. IRR Debt'!Y12 -> 0.043729864
C14: FUNDS | D14: =COUNTIF('S | 01 '!C41:C45,"*") -> 5 | E14: ='3. IRR Funds'!Q15 -> 184.17552 | F14: ='3. IRR Funds'!R15 -> 138.88392 | G14: ='3. IRR Funds'!S15 -> 53.107474 | H14: ='3. IRR Funds'!T15 -> 11.215474 | I14: ='3. IRR Funds'!U15 -> 126.55296 | J14: ='3. IRR Funds'!V15 -> 2.9802322e-09 | K14: ='3. IRR Funds'!W15 -> 0.99196821 | L14: ='3. IRR Funds'!X15 -> 0.91121391 | M14: ='3. IRR Funds'!Y15 -> 0.0807543
C17: TOTAL | D17: =D8+D11+D14 -> 29 | E17: =E8+E11+E14 -> 2316.7275 | F17: =F8+F11+F14 -> 2267.9327 | G17: =G8+G11+G14 -> 56.610636 | H17: =H8+H11+H14 -> 1254.9285 | I17: =I8+I11+I14 -> 955.14756 | J17: ='4.All'!N9 -> -0.012957468 | K17: =(H17+I17)/F17 -> 0.97448924 | L17: =I17/F17 -> 0.4211534 | M17: =H17/F17 -> 0.55333584
E19: =E17='S | 01 '!J48 -> TRUE | F19: =F17='S | 01 '!K48 -> TRUE | G19: =ROUND(G17,1)=ROUND('S | 01 '!L48,1) -> FALSE | H19: =ROUND(H17,1)=ROUND('S | 01 '!M48,1) -> TRUE | I19: =ROUND(I17,1)=ROUND('S | 01 '!N48,1) -> TRUE

Sheet S | 01 
C2: As of date | D2: =D!D2 -> 45322
C6: Deals | D6: Status | E6: Lead | F6: Investing Entity | G6: Vintageἀ | H6: Instrument | I6: % | J6: Committed | K6: Invested | L6: Remaining Commitment | M6: Distributions | N6: Carrying Value | O6: Gain | P6: TVPI | Q6: IRRβ | R6: Additonal Upside/Downside
G7: # | I7: % | J7: $,m | K7: $,m | L7: $,m | M7: $,m | N7: $,m | O7: $,m | P7: X | Q7: %
C9: Direct Investments
C10: Jollychic Holding Limited | D10: Written-off | E10: Elaine | F10: Mozn | G10: 2019 | H10: C+ Prefs | I10: ='6. %'!F9 -> 0.056999998 | J10: 65 | K10: =-SUMIF('CF (Equity, Debt)'!$C$3:$K$51,'S | 01 '!C10,'CF (Equity, Debt)'!$E$3:$E$51) -> 65 | L10: 0 | M10: =SUMIF('CF (Equity, Debt)'!$C$3:$K$51,'S | 01 '!C10,'CF (Equity, Debt)'!$F$3:$F$51) -> 0 | N10: =VLOOKUP(C10,NAV!$B$4:$E$46,4,0) -> 0 | O10: =N10+M10-K10 -> -65 | P10: =(M10+N10)/K10 -> 0 | Q10: =VLOOKUP(C10,'1. IRR Equity'!$AG$12:$AP$30,7,0) -> NM | R10: In Liquidation
C11: Mena Mobile Inc | D11: Written-off | E11: Elaine | F11: Mozn | G11: 2019 | H11: B Prefs | I11: ='6. %'!F10 -> 0.14 | J11: 8 | K11: =-SUMIF('CF (Equity, Debt)'!$C$3:$K$51,'S | 01 '!C11,'CF (Equity, Debt)'!$E$3:$E$51) -> 8 | L11: 0 | M11: =SUMIF('CF (Equity, Debt)'!$C$3:$K$51,'S | 01 '!C11,'CF (Equity, Debt)'!$F$3:$F$51) -> 0 | N11: =VLOOKUP(C11,NAV!$B$4:$E$46,4,0) -> 0 | O11: =N11+M11-K11 -> -8 | P11: =(M11+N11)/K11 -> 0 | Q11: =VLOOKUP(C11,'1. IRR Equity'!$AG$12:$AP$30,7,0) -> NM | R11: In Liquidation
C12: Flyr Inc | D12: Unrealized | E12: Sushil | F12: Mozn | G12: 2019 | H12: B-1,2 Prefs | I12: ='6. %'!F11 -> 0.085025485 | J12: 10 | K12: =-SUMIF('CF (Equity, Debt)'!$C$3:$K$51,'S | 01 '!C12,'CF (Equity, Debt)'!$E$3:$E$51) -> 10 | L12: 0 | M12: =SUMIF('CF (Equity, Debt)'!$C$3:$K$51,'S | 01 '!C12,'CF (Equity, Debt)'!$F$3:$F$51) -> 0 | N12: =VLOOKUP(C12,NAV!$B$4:$E$46,4,0) -> 78.08223 | O12: =N12+M12-K12 -> 68.08223 | P12: =(M12+N12)/K12 -> 7.808223 | Q12: =VLOOKUP(C12,'1. IRR Equity'!$AG$12:$AP$30,7,0) -> 0.59885044 | R12: Flyr Warrantsa 2025 expiry
C13: Esyasoft Holding | D13: Realized | E13: Sushil | F13: Mozn | G13: 2020 | H13: Convertible Note | I13: ='6. %'!F12 -> n/a | J13: 2.5 | K13: =-SUMIF('CF (Equity, Debt)'!$C$3:$K$51,'S | 01 '!C13,'CF (Equity, Debt)'!$E$3:$E$51) -> 2.5 | L13: 0 | M13: =SUMIF('CF (Equity, Debt)'!$C$3:$K$51,'S | 01 '!C13,'CF (Equity, Debt)'!$F$3:$F$51) -> 5 | N13: =VLOOKUP(C13,NAV!$B$4:$E$46,4,0) -> 0 | O13: =N13+M13-K13 -> 2.5 | P13: =(M13+N13)/K13 -> 2 | Q13: =VLOOKUP(C13,'1. IRR Equity'!$AG$12:$AP$30,7,0) -> 0.36091766
C14: Beyond Limits | D14: Unrealized | E14: Divyesh | F14: Mozn | G14: 2020 | H14: C Prefs | I14: ='6. %'!F13 -> 0.097965107 | J14: 90 | K14: =-SUMIF('CF (Equity, Debt)'!$C$3:$K$51,'S | 01 '!C14,'CF (Equity, Debt)'!$E$3:$E$51) -> 90 | L14: 0 | M14: =SUMIF('CF (Equity, Debt)'!$C$3:$K$51,'S | 01 '!C14,'CF (Equity, Debt)'!$F$3:$F$51) -> 0 | N14: =VLOOKUP(C14,NAV!$B$4:$E$46,4,0) -> 91.00154 | O14: =N14+M14-K14 -> 1.0015403 | P14: =(M14+N14)/K14 -> 1.0111282 | Q14: =VLOOKUP(C14,'1. IRR Equity'!$AG$12:$AP$30,7,0) -> 0.0029582828
C15: ONT plc | D15: Unrealized | E15: Divyesh | F15: Mozn | G15: 2020 | H15: Ordinary Shares | I15: ='6. %'!F14 -> 0.051651565 | J15: 141.47026 | K15: =-SUMIF('CF (Equity, Debt)'!$C$3:$K$51,'S | 01 '!C15,'CF (Equity, Debt)'!$E$3:$E$51) -> 141.47026 | L15: 0 | M15: =SUMIF('CF (Equity, Debt)'!$C$3:$K$51,'S | 01 '!C15,'CF (Equity, Debt)'!$F$3:$F$51) -> 0 | N15: =VLOOKUP(C15,NAV!$B$4:$E$46,4,0) -> 90.139175 | O15: =N15+M15-K15 -> -51.331085 | P15: =(M15+N15)/K15 -> 0.63715989 | Q15: =VLOOKUP(C15,'1. IRR Equity'!$AG$12:$AP$30,7,0) -> -0.11648149
C16: Heygears | D16: Unrealized | E16: Elaine | F16: Mozn | G16: 2020 | H16: Registered Capital | I16: ='6. %'!F15 -> 0.1438 | J16: 60 | K16: =-SUMIF('CF (Equity, Debt)'!$C$3:$K$51,'S | 01 '!C16,'CF (Equity, Debt)'!$E$3:$E$51) -> 60 | L16: 0 | M16: =SUMIF('CF (Equity, Debt)'!$C$3:$K$51,'S | 01 '!C16,'CF (Equity, Debt)'!$F$3:$F$51) -> 0 | N16: =VLOOKUP(C16,NAV!$B$4:$E$46,4,0) -> 148.04984 | O16: =N16+M16-K16 -> 88.049841 | P16: =(M16+N16)/K16 -> 2.4674974 | Q16: =VLOOKUP(C16,'1. IRR Equity'!$AG$12:$AP$30,7,0) -> 0.33000317
C17: Jysan Technologies | D17: Realized | E17: Sushil | F17: Mozn 1 | G17: 2021 | H17: A (Ordinary Shares) | I17: ='6. %'!F16 -> 0.03 | J17: 20 | K17: =-SUMIF('CF (Equity, Debt)'!$C$3:$K$51,'S | 01 '!C17,'CF (Equity, Debt)'!$E$3:$E$51) -> 20 | L17: 0 | M17: =SUMIF('CF (Equity, Debt)'!$C$3:$K$51,'S | 01 '!C17,'CF (Equity, Debt)'!$F$3:$F$51) -> 24.5 | N17: =VLOOKUP(C17,NAV!$B$4:$E$46,4,0) -> 0 | O17: =N17+M17-K17 -> 4.5 | P17: =(M17+N17)/K17 -> 1.225 | Q17: =VLOOKUP(C17,'1. IRR Equity'!$AG$12:$AP$30,7,0) -> 0.098824507
C18: Cerebras Systems Inc | D18: Unrealized | E18: Ignasi | F18: Mozn | G18: 2021 | H18: F Prefs | I18: ='6. %'!F17 -> 0.0091172068 | J18: 40 | K18: =-SUMIF('CF (Equity, Debt)'!$C$3:$K$51,'S | 01 '!C18,'CF (Equity, Debt)'!$E$3:$E$51) -> 39.999983 | L18: 0 | M18: =SUMIF('CF (Equity, Debt)'!$C$3:$K$51,'S | 01 '!C18,'CF (Equity, Debt)'!$F$3:$F$51) -> 0 | N18: =VLOOKUP(C18,NAV!$B$4:$E$46,4,0) -> 39.999983 | O18: =N18+M18-K18 -> 0 | P18: =(M18+N18)/K18 -> 1 | Q18: =VLOOKUP(C18,'1. IRR Equity'!$AG$12:$AP$30,7,0) -> 2.9802322e-09
C19: Endless Studios LLC | D19: Unrealized | E19: Sushil | F19: Mozn | G19: 2021 | H19: A Pref Units | I19: ='6. %'!F18 -> 0.16080402 | J19: =K19 -> 8 | K19: =-SUMIF('CF (Equity, Debt)'!$C$3:$K$51,'S | 01 '!C19,'CF (Equity, Debt)'!$E$3:$E$51) -> 8 | L19: 0 | M19: =SUMIF('CF (Equity, Debt)'!$C$3:$K$51,'S | 01 '!C19,'CF (Equity, Debt)'!$F$3:$F$51) -> 0 | N19: =VLOOKUP(C19,NAV!$B$4:$E$46,4,0) -> 8 | O19: =N19+M19-K19 -> 0 | P19: =(M19+N19)/K19 -> 1 | Q19: =VLOOKUP(C19,'1. IRR Equity'!$AG$12:$AP$30,7,0) -> 2.9802322e-09
C20: Instadeep Limited | D20: Realized | E20: Ignasi | F20: Mozn | G20: 2021 | H20: B Prefs | I20: ='6. %'!F19 -> 0.011489406 | J20: 5.0278212 | K20: =-SUMIF('CF (Equity, Debt)'!$C$3:$K$51,'S | 01 '!C20,'CF (Equity, Debt)'!$E$3:$E$51) -> 5.0237202 | L20: 0 | M20: =SUMIF('CF (Equity, Debt)'!$C$3:$K$51,'S | 01 '!C20,'CF (Equity, Debt)'!$F$3:$F$51) -> 7.9421925 | N20: =VLOOKUP(C20,NAV!$B$4:$E$46,4,0) -> 0 | O20: =N20+M20-K20 -> 2.9184723 | P20: =(M20+N20)/K20 -> 1.5809385 | Q20: =VLOOKUP(C20,'1. IRR Equity'!$AG$12:$AP$30,7,0) -> 0.32803498
C21: X-fusion | D21: Realized | E21: Elaine | F21: Mozn 2 | G21: 2022 | H21: Equity-TBC | I21: ='6. %'!F20 -> 0.051 | J21: 493.5 | K21: =-SUMIF('CF (Equity, Debt)'!$C$3:$K$51,'S | 01 '!C21,'CF (Equity, Debt)'!$E$3:$E$51) -> 493.50096 | L21: 0 | M21: =SUMIF('CF (Equity, Debt)'!$C$3:$K$51,'S | 01 '!C21,'CF (Equity, Debt)'!$F$3:$F$51) -> 403 | N21: =VLOOKUP(C21,NAV!$B$4:$E$46,4,0) -> 0 | O21: =N21+M21-K21 -> -90.500956 | P21: =(M21+N21)/K21 -> 0.81661443 | Q21: =VLOOKUP(C21,'1. IRR Equity'!$AG$12:$AP$30,7,0) -> -0.10752884
C22: DriveNets | D22: Unrealized | E22: Anton | F22: G42 | G22: 2022 | H22: Equity-TBC | I22: ='6. %'!F21 -> 0.11141914 | J22: 300 | K22: =-SUMIF('CF (Equity, Debt)'!$C$3:$K$51,'S | 01 '!C22,'CF (Equity, Debt)'!$E$3:$E$51) -> 300 | L22: =0 -> 0 | M22: =SUMIF('CF (Equity, Debt)'!$C$3:$K$51,'S | 01 '!C22,'CF (Equity, Debt)'!$F$3:$F$51) -> 0 | N22: =VLOOKUP(C22,NAV!$B$4:$E$46,4,0) -> 300 | O22: =N22+M22-K22 -> 0 | P22: =(M22+N22)/K22 -> 1 | Q22: =VLOOKUP(C22,'1. IRR Equity'!$AG$12:$AP$30,7,0) -> 2.9802322e-09 | R22: DN Warrants b
C23: vTv Therapeutics Inc. | D23: Unrealized | E23: Divyesh | F23: G42 | G23: 2022 | H23: Ordinary Shares | I23: ='6. %'!F22 -> 0.0022129091 | J23: =K23 -> 24.53125 | K23: =-SUMIF('CF (Equity, Debt)'!$C$3:$K$51,'S | 01 '!C23,'CF (Equity, Debt)'!$E$3:$E$51) -> 24.53125 | L23: =J23-K23 -> 0 | M23: =SUMIF('CF (Equity, Debt)'!$C$3:$K$51,'S | 01 '!C23,'CF (Equity, Debt)'!$F$3:$F$51) -> 0 | N23: =VLOOKUP(C23,NAV!$B$4:$E$46,4,0) -> 2.1837154 | O23: =N23+M23-K23 -> -22.347535 | P23: =(M23+N23)/K23 -> 0.089017697 | Q23: =VLOOKUP(C23,'1. IRR Equity'!$AG$12:$AP$30,7,0) -> -0.87320089 | R23: vTv $30m milestn payment c
C24: Honor Device Co Ltd | D24: Realized | E24: Elaine | F24: G42 3 | G24: 2022 | H24: Equity-TBC | I24: ='6. %'!F23 -> 0.018823528 | J24: =K24 -> 800 | K24: =-SUMIF('CF (Equity, Debt)'!$C$3:$K$51,'S | 01 '!C24,'CF (Equity, Debt)'!$E$3:$E$51) -> 800 | L24: =J24-K24 -> 0 | M24: =SUMIF('CF (Equity, Debt)'!$C$3:$K$51,'S | 01 '!C24,'CF (Equity, Debt)'!$F$3:$F$51) -> 802.8 | N24: =VLOOKUP(C24,NAV!$B$4:$E$46,4,0) -> 0 | O24: =N24+M24-K24 -> 2.8 | P24: =(M24+N24)/K24 -> 1.0035 | Q24: =VLOOKUP(C24,'1. IRR Equity'!$AG$12:$AP$30,7,0) -> 0.0029359251
C25: Applied AI Corporation Limited | D25: Unrealized | E25: Divyesh | F25: Mozn | G25: 2022 | H25: Convertible Note | I25: ='6. %'!F24 -> n/a | J25: 15 | K25: =-SUMIF('CF (Equity, Debt)'!$C$3:$K$51,'S | 01 '!C25,'CF (Equity, Debt)'!$E$3:$E$51) -> 11.5 | L25: =J25-K25 -> 3.5 | M25: 0 | N25: =VLOOKUP(C25,NAV!$B$4:$E$46,4,0) -> 11.5 | O25: =N25+M25-K25 -> 0 | P25: =(M25+N25)/K25 -> 1 | Q25: =VLOOKUP(C25,'1. IRR Equity'!$AG$12:$AP$30,7,0) -> 2.9802322e-09
C26: eSpace | D26: Unrealized | E26: Anton | F26: Mozn 4 | G26: 2022 | H26: B Prefs | I26: ='6. %'!F25 -> 0.027864956 | J26: 15 | K26: =-SUMIF('CF (Equity, Debt)'!$C$3:$K$51,'S | 01 '!C26,'CF (Equity, Debt)'!$E$3:$E$51) -> 15 | L26: =J26-K26 -> 0 | M26: 0 | N26: =VLOOKUP(C26,NAV!$B$4:$E$46,4,0) -> 20.888122 | O26: =N26+M26-K26 -> 5.8881215 | P26: =(M26+N26)/K26 -> 1.3925414 | Q26: =VLOOKUP(C26,'1. IRR Equity'!$AG$12:$AP$30,7,0) -> 0.32455407
C27: Tools for Humanity Corporation | D27: Unrealized | E27: Divyesh | F27: Mozn | G27: 2023 | H27: C Prefs | I27: ='6. %'!F26 -> 0.0062621983 | J27: =K27 -> 14.999999 | K27: =-SUMIF('CF (Equity, Debt)'!$C$3:$K$51,'S | 01 '!C27,'CF (Equity, Debt)'!$E$3:$E$51) -> 14.999999 | L27: =J27-K27 -> 0 | M27: =M26 -> 0 | N27: =VLOOKUP(C27,NAV!$B$4:$E$46,4,0) -> 14.999999 | O27: =N27+M27-K27 -> 0 | P27: =(M27+N27)/K27 -> 1 | Q27: =VLOOKUP(C27,'1. IRR Equity'!$AG$12:$AP$30,7,0) -> 2.9802322e-09
C28: WLD Tokens | D28: Unrealized | E28: Divyesh | F28: Mozn | G28: 2023 | H28: Tokens | I28: ='6. %'!F27 -> 0.00625 | J28: =K28 -> 0.006875 | K28: =-SUMIF('CF (Equity, Debt)'!$C$3:$K$51,'S | 01 '!C28,'CF (Equity, Debt)'!$E$3:$E$51) -> 0.006875 | L28: =J28-K28 -> 0 | M28: =M27 -> 0 | N28: =VLOOKUP(C28,NAV!$B$4:$E$46,4,0) -> 15 | O28: =N28+M28-K28 -> 14.993125 | P28: NM | Q28: =VLOOKUP(C28,'1. IRR Equity'!$AG$12:$AP$30,7,0) -> NM | R28: Crypto Tokensd
C29: E-line Ventures LLC | D29: Unrealized | E29: Sushil | F29: Mozn | G29: 2023 | H29: B Prefs | I29: ='6. %'!F28 -> 0.11483736 | J29: =K29 -> 6 | K29: =-SUMIF('CF (Equity, Debt)'!$C$3:$K$51,'S | 01 '!C29,'CF (Equity, Debt)'!$E$3:$E$51) -> 6 | L29: =J29-K29 -> 0 | M29: =M28 -> 0 | N29: =VLOOKUP(C29,NAV!$B$4:$E$46,4,0) -> 6 | O29: =N29+M29-K29 -> 0 | P29: NM | Q29: NM | R29: Optionse
C30: School Hack (AIREV Holding Limited) | D30: Unrealized | E30: Camillo | F30: Core42 | G30: 2024 | H30: Preferred Shares | I30: ='6. %'!F29 -> 0.25 | J30: 2.75 | K30: =-SUMIF('CF (Equity, Debt)'!$C$3:$K$51,'S | 01 '!C30,'CF (Equity, Debt)'!$E$3:$E$51) -> 2.75 | L30: =J30-K30 -> 0 | M30: =M29 -> 0 | N30: =VLOOKUP(C30,NAV!$B$4:$E$46,4,0) -> 2.75 | O30: =N30+M30-K30 -> 0 | P30: NM | Q30: NM | R30: Cloud Creditg
J32: =SUM(J10:J30) -> 2121.7862 | K32: =SUM(K10:K30) -> 2118.283 | L32: =SUM(L10:L30) -> 3.5 | M32: =SUM(M10:M30) -> 1243.2422 | N32: =SUM(N10:N30) -> 828.59461 | O32: =SUM(O10:O30) -> -46.446245 | P32: =(M32+N32)/K32 -> 0.97807364 | Q32: ='1. IRR Equity'!AH40 -> -0.011569161
C34: Debt Investments
C35: Glass Earth Holdings LLC | D35: Written-off | E35: Marty | F35: Mozn | G35: 2019 | H35: Promissory Note | I35: n/a | J35: 8 | K35: 8 | L35: 0 | M35: 0 | N35: 0 | O35: =N35+M35-K35 -> -8 | P35: =(M35+N35)/K35 -> 0 | Q35: =VLOOKUP(C35,'2. IRR Debt'!$P$9:$Y$11,7,0) -> NM | R35: In Default
C36: Mena Mobile Inc (Debt) | D36: Written-off | E36: Elaine | F36: Mozn | G36: 2021 | H36: Loan | I36: n/a | J36: 2.353982 | K36: =J36 -> 2.353982 | L36: 0 | M36: 0 | N36: =VLOOKUP(C36,NAV!$B$4:$E$46,4,0) -> 0 | O36: =N36+M36-K36 -> -2.353982 | P36: =(M36+N36)/K36 -> 0 | Q36: =VLOOKUP(C36,'2. IRR Debt'!$P$9:$Y$11,7,0) -> NM | R36: In Liquidation
C37: Esyasoft Holding (Debt) | D37: Realized | E37: Sushil | F37: Mozn | G37: 2021 | H37: Loan | I37: n/a | J37: 0.411765 | K37: 0.411765 | L37: 0 | M37: ='CF (Equity, Debt)'!F56 -> 0.47078465 | N37: 0 | O37: =N37+M37-K37 -> 0.05901965 | P37: =(M37+N37)/K37 -> 1.1433333 | Q37: =VLOOKUP(C37,'2. IRR Debt'!$P$9:$Y$11,7,0) -> 0.075277027
J38: =SUM(J35:J37) -> 10.765747 | K38: =SUM(K35:K37) -> 10.765747 | L38: =SUM(L35:L37) -> 0 | M38: =SUM(M35:M37) -> 0.47078465 | N38: =SUM(N35:N37) -> 0 | O38: =N38+M38-K38 -> -10.294962 | P38: =(M38+N38)/K38 -> 0.043729864 | Q38: ='2. IRR Debt'!Q15 -> -0.71226245
C40: Funds Investments
C41: New Space Capital Fund I | D41: Unrealized | E41: Sushil | F41: G42 | G41: 2020 | H41: LP | I41: n/a | J41: =K41+L41 -> 31.022787 | K41: =-SUMIF('CF (Funds)'!$B$3:$D$2006,C41,'CF (Funds)'!$D$3:$D$2006) -> 13.988553 | L41: ='5. NewSpace'!I54 -> 17.034234 | M41: =SUM('CF (Funds)'!E36:E42) -> 2.9557744 | N41: =VLOOKUP(C41,NAV!$B$4:$E$46,4,0) -> 13.277945 | O41: =N41+M41-K41 -> 2.2451661 | P41: =(M41+N41)/K41 -> 1.1605002 | Q41: =VLOOKUP(C41,'3. IRR Funds'!$P$7:$Y$15,7,0) -> 0.036116043
C42: New Space Capital GP Com SCSp | D42: Unrealized | E42: Sushil | F42: G42 | G42: 2023 | H42: LP | I42: n/a | J42: =2.3/0.85 -> 2.7058824 | K42: 2.7058824 | L42: 0 | M42: 0 | N42: =VLOOKUP(C42,NAV!$B$4:$E$46,4,0) -> 2.5684255 | O42: =N42+M42-K42 -> -0.13745685 | P42: =(M42+N42)/K42 -> 0.94920073 | Q42: =VLOOKUP(C42,'3. IRR Funds'!$P$7:$Y$15,7,0) -> 0
C43: North Summit Capital Fund | D43: Unrealized | E43: Elaine | F43: G42 | G43: 2020 | H43: LP | I43: n/a | J43: =K43+L43 -> 83.334353 | K43: =-SUMIF('CF (Funds)'!$B$3:$D$2006,C43,'CF (Funds)'!$D$3:$D$2006) -> 83.214653 | L43: =217.813308-217.693608 -> 0.1197 | M43: =SUM('CF (Funds)'!E25:'CF (Funds)'!E35) -> 7.815871 | N43: =VLOOKUP(C43,NAV!$B$4:$E$46,4,0) -> 74.725861 | O43: =N43+M43-K43 -> -0.672921 | P43: =(M43+N43)/K43 -> 0.99191343 | Q43: =VLOOKUP(C43,'3. IRR Funds'!$P$7:$Y$15,7,0) -> -0.0025177218
C44: Sinovation Disrupt Fund, L.P. | D44: Realized | E44: Elaine | F44: G42 | G44: 2020 | H44: LP | I44: n/a | J44: 50 | K44: =-SUMIF('CF (Funds)'!$B$3:$D$2006,C44,'CF (Funds)'!$D$3:$D$2006) -> 24.959693 | L44: =J44-K44 -> 25.040307 | M44: =SUM('CF (Funds)'!E3:E20) -> 0.44382835 | N44: =VLOOKUP(C44,NAV!$B$4:$E$46,4,0) -> 23.670303 | O44: =N44+M44-K44 -> -0.84556165 | P44: =(M44+N44)/K44 -> 0.96612291 | Q44: =VLOOKUP(C44,'3. IRR Funds'!$P$7:$Y$15,7,0) -> -0.014868453
C45: Acies Investments Fund I, L.P. | D45: Unrealized | E45: Divyesh | F45: G42 | G45: 2021 | H45: LP | I45: 0.33 | J45: 17.1125 | K45: =-SUMIF('CF (Funds)'!$B$3:$D$2006,C45,'CF (Funds)'!$D$3:$D$2006) -> 14.015137 | L45: =J45-K45 -> 3.0973625 | M45: 0 | N45: =VLOOKUP(C45,NAV!$B$4:$E$46,4,0) -> 12.310425 | O45: =N45+M45-K45 -> -1.7047125 | P45: =(M45+N45)/K45 -> 0.87836634 | Q45: =VLOOKUP(C45,'3. IRR Funds'!$P$7:$Y$15,7,0) -> -0.071990828 | R45: 9.9% GP | Anchorf
J46: =SUM(J41:J45) -> 184.17552 | K46: =SUM(K41:K45) -> 138.88392 | L46: =SUM(L41:L45) -> 45.291603 | M46: =SUM(M41:M45) -> 11.215474 | N46: =SUM(N41:N45) -> 126.55296 | O46: =N46+M46-K46 -> -1.1154859 | P46: =(M46+N46)/K46 -> 0.99196821 | Q46: ='3. IRR Funds'!Q18 -> 2.9802322e-09
C48: Total | J48: =J32+J38+J46 -> 2316.7275 | K48: =K32+K38+K46 -> 2267.9327 | L48: =L32+L38+L46 -> 48.791603 | M48: =M32+M38+M46 -> 1254.9285 | N48: =N32+N38+N46 -> 955.14756 | O48: =N48+M48-K48 -> -57.856694 | P48: =(M48+N48)/K48 -> 0.97448924 | Q48: ='4.All'!N9 -> -0.012957468
K49: =ROUND(K48,2)=ROUND('4.All'!J9,2) -> TRUE | M49: =ROUND(M48,2)=ROUND('4.All'!L9,2) -> TRUE | N49: =ROUND(N48,2)=ROUND('4.All'!M9,2) -> TRUE
...

Sheet S | 02
C2: As of date | E2: =D!D2 -> 45322
E5: 2 | F5: 3 | G5: 4 | H5: 5 | I5: 6 | J5: 7 | K5: 8 | L5: 9 | M5: 11 | N5: 12 | O5: 13 | Q5: 15 | R5: 14 | S5: 10 | T5: 16
C6: Deals | D6: Type | E6: Status | F6: Lead | G6: Investing Entity | H6: Vintageἀ | I6: Instrument | J6: % | K6: Committed | L6: Invested | M6: Distributions | N6: Carrying Value | O6: Gain | P6: Gain till FY22 | Q6: IRRβ | R6: TVPI | S6: Remaining Commitment | T6: Additonal Upside/Downside
I7: # | J7: % | K7: $,m | L7: $,m | M7: $,m | N7: $,m | O7: $,m | Q7: % | R7: X | S7: $,m | W7: MOZN
C9: School Hack (AIREV Holding Limited) | D9: Direct Investment | E9: =VLOOKUP($C9,'S | 01 '!$C$6:$R$48,E$5,0) -> Unrealized | F9: =VLOOKUP($C9,'S | 01 '!$C$6:$R$48,F$5,0) -> Camillo | G9: =VLOOKUP($C9,'S | 01 '!$C$6:$R$48,G$5,0) -> Core42 | H9: =VLOOKUP($C9,'S | 01 '!$C$6:$R$48,H$5,0) -> 2024 | I9: =VLOOKUP($C9,'S | 01 '!$C$6:$R$48,I$5,0) -> Preferred Shares | J9: =VLOOKUP($C9,'S | 01 '!$C$6:$R$48,J$5,0) -> 0.25 | K9: =VLOOKUP($C9,'S | 01 '!$C$6:$R$48,K$5,0) -> 2.75 | L9: =VLOOKUP($C9,'S | 01 '!$C$6:$R$48,L$5,0) -> 2.75 | ... O9: =VLOOKUP($C9,'S | 01 '!$C$6:$R$48,O$5,0) -> 0 | P9: n/a | Q9: =VLOOKUP($C9,'S | 01 '!$C$6:$R$48,Q$5,0) -> NM | R9: =VLOOKUP($C9,'S | 01 '!$C$6:$R$48,R$5,0) -> NM | S9: =VLOOKUP($C9,'S | 01 '!$C$6:$R$48,S$5,0) -> 0 | T9: Cloud Creditg
C10: E-line Ventures LLC | D10: Direct Investment | E10: =VLOOKUP($C10,'S | 01 '!$C$6:$R$48,E$5,0) -> Unrealized | F10: =VLOOKUP($C10,'S | 01 '!$C$6:$R$48,F$5,0) -> Sushil | G10: =VLOOKUP($C10,'S | 01 '!$C$6:$R$48,G$5,0) -> Mozn | H10: =VLOOKUP($C10,'S | 01 '!$C$6:$R$48,H$5,0) -> 2023 | I10: =VLOOKUP($C10,'S | 01 '!$C$6:$R$48,I$5,0) -> B Prefs | J10: =VLOOKUP($C10,'S | 01 '!$C$6:$R$48,J$5,0) -> 0.11483736 | K10: =VLOOKUP($C10,'S | 01 '!$C$6:$R$48,K$5,0) -> 6 | L10: =VLOOKUP($C10,'S | 01 '!$C$6:$R$48,L$5,0) -> 6 | ... O10: =VLOOKUP($C10,'S | 01 '!$C$6:$R$48,O$5,0) -> 0 | P10: n/a | Q10: =VLOOKUP($C10,'S | 01 '!$C$6:$R$48,Q$5,0) -> NM | R10: =VLOOKUP($C10,'S | 01 '!$C$6:$R$48,R$5,0) -> NM | S10: =VLOOKUP($C10,'S | 01 '!$C$6:$R$48,S$5,0) -> 0 | T10: Optionse
C11: WLD Tokens | D11: Direct Investment | E11: =VLOOKUP($C11,'S | 01 '!$C$6:$R$48,E$5,0) -> Unrealized | F11: =VLOOKUP($C11,'S | 01 '!$C$6:$R$48,F$5,0) -> Divyesh | G11: =VLOOKUP($C11,'S | 01 '!$C$6:$R$48,G$5,0) -> Mozn | H11: =VLOOKUP($C11,'S | 01 '!$C$6:$R$48,H$5,0) -> 2023 | I11: =VLOOKUP($C11,'S | 01 '!$C$6:$R$48,I$5,0) -> Tokens | J11: =VLOOKUP($C11,'S | 01 '!$C$6:$R$48,J$5,0) -> 0.00625 | K11: =VLOOKUP($C11,'S | 01 '!$C$6:$R$48,K$5,0) -> 0.006875 | L11: =VLOOKUP($C11,'S | 01 '!$C$6:$R$48,L$5,0) -> 0.006875 | ... O11: =VLOOKUP($C11,'S | 01 '!$C$6:$R$48,O$5,0) -> 14.993125 | P11: n/a | Q11: =VLOOKUP($C11,'S | 01 '!$C$6:$R$48,Q$5,0) -> NM | R11: =VLOOKUP($C11,'S | 01 '!$C$6:$R$48,R$5,0) -> NM | S11: =VLOOKUP($C11,'S | 01 '!$C$6:$R$48,S$5,0) -> 0 | T11: =VLOOKUP($C11,'S | 01 '!$C$6:$R$48,T$5,0) -> Crypto Tokensd
C12: Tools for Humanity Corporation | D12: Direct Investment | E12: =VLOOKUP($C12,'S | 01 '!$C$6:$R$48,E$5,0) -> Unrealized | F12: =VLOOKUP($C12,'S | 01 '!$C$6:$R$48,F$5,0) -> Divyesh | G12: =VLOOKUP($C12,'S | 01 '!$C$6:$R$48,G$5,0) -> Mozn | H12: =VLOOKUP($C12,'S | 01 '!$C$6:$R$48,H$5,0) -> 2023 | I12: =VLOOKUP($C12,'S | 01 '!$C$6:$R$48,I$5,0) -> C Prefs | J12: =VLOOKUP($C12,'S | 01 '!$C$6:$R$48,J$5,0) -> 0.0062621983 | K12: =VLOOKUP($C12,'S | 01 '!$C$6:$R$48,K$5,0) -> 14.999999 | L12: =VLOOKUP($C12,'S | 01 '!$C$6:$R$48,L$5,0) -> 14.999999 | ... O12: =VLOOKUP($C12,'S | 01 '!$C$6:$R$48,O$5,0) -> 0 | P12: n/a | Q12: =VLOOKUP($C12,'S | 01 '!$C$6:$R$48,Q$5,0) -> 2.9802322e-09 | R12: =VLOOKUP($C12,'S | 01 '!$C$6:$R$48,R$5,0) -> 1 | S12: =VLOOKUP($C12,'S | 01 '!$C$6:$R$48,S$5,0) -> 0
C13: eSpace | D13: Direct Investment | E13: =VLOOKUP($C13,'S | 01 '!$C$6:$R$48,E$5,0) -> Unrealized | F13: =VLOOKUP($C13,'S | 01 '!$C$6:$R$48,F$5,0) -> Anton | G13: =VLOOKUP($C13,'S | 01 '!$C$6:$R$48,G$5,0) -> Mozn 4 | H13: =VLOOKUP($C13,'S | 01 '!$C$6:$R$48,H$5,0) -> 2022 | I13: =VLOOKUP($C13,'S | 01 '!$C$6:$R$48,I$5,0) -> B Prefs | J13: =VLOOKUP($C13,'S | 01 '!$C$6:$R$48,J$5,0) -> 0.027864956 | K13: =VLOOKUP($C13,'S | 01 '!$C$6:$R$48,K$5,0) -> 15 | L13: =VLOOKUP($C13,'S | 01 '!$C$6:$R$48,L$5,0) -> 15 | ... O13: =VLOOKUP($C13,'S | 01 '!$C$6:$R$48,O$5,0) -> 5.8881215 | P13: 0 | Q13: =VLOOKUP($C13,'S | 01 '!$C$6:$R$48,Q$5,0) -> 0.32455407 | R13: =VLOOKUP($C13,'S | 01 '!$C$6:$R$48,R$5,0) -> 1.3925414 | S13: =VLOOKUP($C13,'S | 01 '!$C$6:$R$48,S$5,0) -> 0 | W13: Invested | X13: =L31 -> 1004.5175
C14: Applied AI Corporation Limited | D14: Direct Investment | E14: =VLOOKUP($C14,'S | 01 '!$C$6:$R$48,E$5,0) -> Unrealized | F14: =VLOOKUP($C14,'S | 01 '!$C$6:$R$48,F$5,0) -> Divyesh | G14: =VLOOKUP($C14,'S | 01 '!$C$6:$R$48,G$5,0) -> Mozn | H14: =VLOOKUP($C14,'S | 01 '!$C$6:$R$48,H$5,0) -> 2022 | I14: =VLOOKUP($C14,'S | 01 '!$C$6:$R$48,I$5,0) -> Convertible Note | J14: =VLOOKUP($C14,'S | 01 '!$C$6:$R$48,J$5,0) -> n/a | K14: =VLOOKUP($C14,'S | 01 '!$C$6:$R$48,K$5,0) -> 15 | L14: =VLOOKUP($C14,'S | 01 '!$C$6:$R$48,L$5,0) -> 11.5 | ... O14: =VLOOKUP($C14,'S | 01 '!$C$6:$R$48,O$5,0) -> 0 | P14: 0 | Q14: =VLOOKUP($C14,'S | 01 '!$C$6:$R$48,Q$5,0) -> 2.9802322e-09 | R14: =VLOOKUP($C14,'S | 01 '!$C$6:$R$48,R$5,0) -> 1 | S14: =VLOOKUP($C14,'S | 01 '!$C$6:$R$48,S$5,0) -> 3.5 | W14: NAV | X14: =N31 -> 526.41089
C15: X-fusion | D15: Direct Investment | E15: =VLOOKUP($C15,'S | 01 '!$C$6:$R$48,E$5,0) -> Realized | F15: =VLOOKUP($C15,'S | 01 '!$C$6:$R$48,F$5,0) -> Elaine | G15: =VLOOKUP($C15,'S | 01 '!$C$6:$R$48,G$5,0) -> Mozn 2 | H15: =VLOOKUP($C15,'S | 01 '!$C$6:$R$48,H$5,0) -> 2022 | I15: =VLOOKUP($C15,'S | 01 '!$C$6:$R$48,I$5,0) -> Equity-TBC | J15: =VLOOKUP($C15,'S | 01 '!$C$6:$R$48,J$5,0) -> 0.051 | K15: =VLOOKUP($C15,'S | 01 '!$C$6:$R$48,K$5,0) -> 493.5 | L15: =VLOOKUP($C15,'S | 01 '!$C$6:$R$48,L$5,0) -> 493.50096 | ... O15: =VLOOKUP($C15,'S | 01 '!$C$6:$R$48,O$5,0) -> -90.500956 | P15: -64.391 | Q15: =VLOOKUP($C15,'S | 01 '!$C$6:$R$48,Q$5,0) -> -0.10752884 | R15: =VLOOKUP($C15,'S | 01 '!$C$6:$R$48,R$5,0) -> 0.81661443 | S15: =VLOOKUP($C15,'S | 01 '!$C$6:$R$48,S$5,0) -> 0 | W15: Gain | X15: =O31 -> -37.193673
C16: Mena Mobile Inc (Debt) | D16: Debt Investment | E16: =VLOOKUP($C16,'S | 01 '!$C$6:$R$48,E$5,0) -> Written-off | F16: =VLOOKUP($C16,'S | 01 '!$C$6:$R$48,F$5,0) -> Elaine | G16: =VLOOKUP($C16,'S | 01 '!$C$6:$R$48,G$5,0) -> Mozn | H16: =VLOOKUP($C16,'S | 01 '!$C$6:$R$48,H$5,0) -> 2021 | I16: =VLOOKUP($C16,'S | 01 '!$C$6:$R$48,I$5,0) -> Loan | J16: =VLOOKUP($C16,'S | 01 '!$C$6:$R$48,J$5,0) -> n/a | K16: =VLOOKUP($C16,'S | 01 '!$C$6:$R$48,K$5,0) -> 2.353982 | L16: =VLOOKUP($C16,'S | 01 '!$C$6:$R$48,L$5,0) -> 2.353982 | ... O16: =VLOOKUP($C16,'S | 01 '!$C$6:$R$48,O$5,0) -> -2.353982 | P16: 0 | Q16: =VLOOKUP($C16,'S | 01 '!$C$6:$R$48,Q$5,0) -> NM | R16: =VLOOKUP($C16,'S | 01 '!$C$6:$R$48,R$5,0) -> 0 | S16: =VLOOKUP($C16,'S | 01 '!$C$6:$R$48,S$5,0) -> 0 | W16: YTD Gains | X16: =X15-P31 -> -51.730871
C17: Esyasoft Holding (Debt) | D17: Debt Investment | E17: =VLOOKUP($C17,'S | 01 '!$C$6:$R$48,E$5,0) -> Realized | F17: =VLOOKUP($C17,'S | 01 '!$C$6:$R$48,F$5,0) -> Sushil | G17: =VLOOKUP($C17,'S | 01 '!$C$6:$R$48,G$5,0) -> Mozn | H17: =VLOOKUP($C17,'S | 01 '!$C$6:$R$48,H$5,0) -> 2021 | I17: =VLOOKUP($C17,'S | 01 '!$C$6:$R$48,I$5,0) -> Loan | J17: =VLOOKUP($C17,'S | 01 '!$C$6:$R$48,J$5,0) -> n/a | K17: =VLOOKUP($C17,'S | 01 '!$C$6:$R$48,K$5,0) -> 0.411765 | L17: =VLOOKUP($C17,'S | 01 '!$C$6:$R$48,L$5,0) -> 0.411765 | ... O17: =VLOOKUP($C17,'S | 01 '!$C$6:$R$48,O$5,0) -> 0.05901965 | P17: 0.05901965 | Q17: =VLOOKUP($C17,'S | 01 '!$C$6:$R$48,Q$5,0) -> 0.075277027 | R17: =VLOOKUP($C17,'S | 01 '!$C$6:$R$48,R$5,0) -> 1.1433333 | S17: =VLOOKUP($C17,'S | 01 '!$C$6:$R$48,S$5,0) -> 0 | W17: IRR | X17: =Q31 -> -0.014740654
C18: Jysan Technologies | D18: Direct Investment | E18: =VLOOKUP($C18,'S | 01 '!$C$6:$R$48,E$5,0) -> Realized | F18: =VLOOKUP($C18,'S | 01 '!$C$6:$R$48,F$5,0) -> Sushil | G18: =VLOOKUP($C18,'S | 01 '!$C$6:$R$48,G$5,0) -> Mozn 1 | H18: =VLOOKUP($C18,'S | 01 '!$C$6:$R$48,H$5,0) -> 2021 | I18: =VLOOKUP($C18,'S | 01 '!$C$6:$R$48,I$5,0) -> A (Ordinary Shares) | J18: =VLOOKUP($C18,'S | 01 '!$C$6:$R$48,J$5,0) -> 0.03 | K18: =VLOOKUP($C18,'S | 01 '!$C$6:$R$48,K$5,0) -> 20 | L18: =VLOOKUP($C18,'S | 01 '!$C$6:$R$48,L$5,0) -> 20 | ... O18: =VLOOKUP($C18,'S | 01 '!$C$6:$R$48,O$5,0) -> 4.5 | P18: 0 | Q18: =VLOOKUP($C18,'S | 01 '!$C$6:$R$48,Q$5,0) -> 0.098824507 | R18: =VLOOKUP($C18,'S | 01 '!$C$6:$R$48,R$5,0) -> 1.225 | S18: =VLOOKUP($C18,'S | 01 '!$C$6:$R$48,S$5,0) -> 0
C19: Instadeep Limited | D19: Direct Investment | E19: =VLOOKUP($C19,'S | 01 '!$C$6:$R$48,E$5,0) -> Realized | F19: =VLOOKUP($C19,'S | 01 '!$C$6:$R$48,F$5,0) -> Ignasi | G19: =VLOOKUP($C19,'S | 01 '!$C$6:$R$48,G$5,0) -> Mozn | H19: =VLOOKUP($C19,'S | 01 '!$C$6:$R$48,H$5,0) -> 2021 | I19: =VLOOKUP($C19,'S | 01 '!$C$6:$R$48,I$5,0) -> B Prefs | J19: =VLOOKUP($C19,'S | 01 '!$C$6:$R$48,J$5,0) -> 0.011489406 | K19: =VLOOKUP($C19,'S | 01 '!$C$6:$R$48,K$5,0) -> 5.0278212 | L19: =VLOOKUP($C19,'S | 01 '!$C$6:$R$48,L$5,0) -> 5.0237202 | ... O19: =VLOOKUP($C19,'S | 01 '!$C$6:$R$48,O$5,0) -> 2.9184723 | P19: 1.6721788 | Q19: =VLOOKUP($C19,'S | 01 '!$C$6:$R$48,Q$5,0) -> 0.32803498 | R19: =VLOOKUP($C19,'S | 01 '!$C$6:$R$48,R$5,0) -> 1.5809385 | S19: =VLOOKUP($C19,'S | 01 '!$C$6:$R$48,S$5,0) -> 0
C20: Cerebras Systems Inc | D20: Direct Investment | E20: =VLOOKUP($C20,'S | 01 '!$C$6:$R$48,E$5,0) -> Unrealized | F20: =VLOOKUP($C20,'S | 01 '!$C$6:$R$48,F$5,0) -> Ignasi | G20: =VLOOKUP($C20,'S | 01 '!$C$6:$R$48,G$5,0) -> Mozn | H20: =VLOOKUP($C20,'S | 01 '!$C$6:$R$48,H$5,0) -> 2021 | I20: =VLOOKUP($C20,'S | 01 '!$C$6:$R$48,I$5,0) -> F Prefs | J20: =VLOOKUP($C20,'S | 01 '!$C$6:$R$48,J$5,0) -> 0.0091172068 | K20: =VLOOKUP($C20,'S | 01 '!$C$6:$R$48,K$5,0) -> 40 | L20: =VLOOKUP($C20,'S | 01 '!$C$6:$R$48,L$5,0) -> 39.999983 | ... O20: =VLOOKUP($C20,'S | 01 '!$C$6:$R$48,O$5,0) -> 0 | P20: 0 | Q20: =VLOOKUP($C20,'S | 01 '!$C$6:$R$48,Q$5,0) -> 2.9802322e-09 | R20: =VLOOKUP($C20,'S | 01 '!$C$6:$R$48,R$5,0) -> 1 | S20: =VLOOKUP($C20,'S | 01 '!$C$6:$R$48,S$5,0) -> 0
C21: Endless Studios LLC | D21: Direct Investment | E21: =VLOOKUP($C21,'S | 01 '!$C$6:$R$48,E$5,0) -> Unrealized | F21: =VLOOKUP($C21,'S | 01 '!$C$6:$R$48,F$5,0) -> Sushil | G21: =VLOOKUP($C21,'S | 01 '!$C$6:$R$48,G$5,0) -> Mozn | H21: =VLOOKUP($C21,'S | 01 '!$C$6:$R$48,H$5,0) -> 2021 | I21: =VLOOKUP($C21,'S | 01 '!$C$6:$R$48,I$5,0) -> A Pref Units | J21: =VLOOKUP($C21,'S | 01 '!$C$6:$R$48,J$5,0) -> 0.16080402 | K21: =VLOOKUP($C21,'S | 01 '!$C$6:$R$48,K$5,0) -> 8 | L21: =VLOOKUP($C21,'S | 01 '!$C$6:$R$48,L$5,0) -> 8 | ... O21: =VLOOKUP($C21,'S | 01 '!$C$6:$R$48,O$5,0) -> 0 | P21: 0 | Q21: =VLOOKUP($C21,'S | 01 '!$C$6:$R$48,Q$5,0) -> 2.9802322e-09 | R21: =VLOOKUP($C21,'S | 01 '!$C$6:$R$48,R$5,0) -> 1 | S21: =VLOOKUP($C21,'S | 01 '!$C$6:$R$48,S$5,0) -> 0
C22: Esyasoft Holding | D22: Direct Investment | E22: =VLOOKUP($C22,'S | 01 '!$C$6:$R$48,E$5,0) -> Realized | F22: =VLOOKUP($C22,'S | 01 '!$C$6:$R$48,F$5,0) -> Sushil | G22: =VLOOKUP($C22,'S | 01 '!$C$6:$R$48,G$5,0) -> Mozn | H22: =VLOOKUP($C22,'S | 01 '!$C$6:$R$48,H$5,0) -> 2020 | I22: =VLOOKUP($C22,'S | 01 '!$C$6:$R$48,I$5,0) -> Convertible Note | J22: =VLOOKUP($C22,'S | 01 '!$C$6:$R$48,J$5,0) -> n/a | K22: =VLOOKUP($C22,'S | 01 '!$C$6:$R$48,K$5,0) -> 2.5 | L22: =VLOOKUP($C22,'S | 01 '!$C$6:$R$48,L$5,0) -> 2.5 | ... O22: =VLOOKUP($C22,'S | 01 '!$C$6:$R$48,O$5,0) -> 2.5 | P22: 2.5 | Q22: =VLOOKUP($C22,'S | 01 '!$C$6:$R$48,Q$5,0) -> 0.36091766 | R22: =VLOOKUP($C22,'S | 01 '!$C$6:$R$48,R$5,0) -> 2 | S22: =VLOOKUP($C22,'S | 01 '!$C$6:$R$48,S$5,0) -> 0
C23: Heygears | D23: Direct Investment | E23: =VLOOKUP($C23,'S | 01 '!$C$6:$R$48,E$5,0) -> Unrealized | F23: =VLOOKUP($C23,'S | 01 '!$C$6:$R$48,F$5,0) -> Elaine | G23: =VLOOKUP($C23,'S | 01 '!$C$6:$R$48,G$5,0) -> Mozn | H23: =VLOOKUP($C23,'S | 01 '!$C$6:$R$48,H$5,0) -> 2020 | I23: =VLOOKUP($C23,'S | 01 '!$C$6:$R$48,I$5,0) -> Registered Capital | J23: =VLOOKUP($C23,'S | 01 '!$C$6:$R$48,J$5,0) -> 0.1438 | K23: =VLOOKUP($C23,'S | 01 '!$C$6:$R$48,K$5,0) -> 60 | L23: =VLOOKUP($C23,'S | 01 '!$C$6:$R$48,L$5,0) -> 60 | ... O23: =VLOOKUP($C23,'S | 01 '!$C$6:$R$48,O$5,0) -> 88.049841 | P23: 96.4 | Q23: =VLOOKUP($C23,'S | 01 '!$C$6:$R$48,Q$5,0) -> 0.33000317 | R23: =VLOOKUP($C23,'S | 01 '!$C$6:$R$48,R$5,0) -> 2.4674974 | S23: =VLOOKUP($C23,'S | 01 '!$C$6:$R$48,S$5,0) -> 0
C24: Beyond Limits | D24: Direct Investment | E24: =VLOOKUP($C24,'S | 01 '!$C$6:$R$48,E$5,0) -> Unrealized | F24: =VLOOKUP($C24,'S | 01 '!$C$6:$R$48,F$5,0) -> Divyesh | G24: =VLOOKUP($C24,'S | 01 '!$C$6:$R$48,G$5,0) -> Mozn | H24: =VLOOKUP($C24,'S | 01 '!$C$6:$R$48,H$5,0) -> 2020 | I24: =VLOOKUP($C24,'S | 01 '!$C$6:$R$48,I$5,0) -> C Prefs | J24: =VLOOKUP($C24,'S | 01 '!$C$6:$R$48,J$5,0) -> 0.097965107 | K24: =VLOOKUP($C24,'S | 01 '!$C$6:$R$48,K$5,0) -> 90 | L24: =VLOOKUP($C24,'S | 01 '!$C$6:$R$48,L$5,0) -> 90 | ... O24: =VLOOKUP($C24,'S | 01 '!$C$6:$R$48,O$5,0) -> 1.0015403 | P24: 1.042 | Q24: =VLOOKUP($C24,'S | 01 '!$C$6:$R$48,Q$5,0) -> 0.0029582828 | R24: =VLOOKUP($C24,'S | 01 '!$C$6:$R$48,R$5,0) -> 1.0111282 | S24: =VLOOKUP($C24,'S | 01 '!$C$6:$R$48,S$5,0) -> 0
C25: ONT plc | D25: Direct Investment | E25: =VLOOKUP($C25,'S | 01 '!$C$6:$R$48,E$5,0) -> Unrealized | F25: =VLOOKUP($C25,'S | 01 '!$C$6:$R$48,F$5,0) -> Divyesh | G25: =VLOOKUP($C25,'S | 01 '!$C$6:$R$48,G$5,0) -> Mozn | H25: =VLOOKUP($C25,'S | 01 '!$C$6:$R$48,H$5,0) -> 2020 | I25: =VLOOKUP($C25,'S | 01 '!$C$6:$R$48,I$5,0) -> Ordinary Shares | J25: =VLOOKUP($C25,'S | 01 '!$C$6:$R$48,J$5,0) -> 0.051651565 | K25: =VLOOKUP($C25,'S | 01 '!$C$6:$R$48,K$5,0) -> 141.47026 | L25: =VLOOKUP($C25,'S | 01 '!$C$6:$R$48,L$5,0) -> 141.47026 | ... O25: =VLOOKUP($C25,'S | 01 '!$C$6:$R$48,O$5,0) -> -51.331085 | P25: -9.845 | Q25: =VLOOKUP($C25,'S | 01 '!$C$6:$R$48,Q$5,0) -> -0.11648149 | R25: =VLOOKUP($C25,'S | 01 '!$C$6:$R$48,R$5,0) -> 0.63715989 | S25: =VLOOKUP($C25,'S | 01 '!$C$6:$R$48,S$5,0) -> 0
C26: Flyr Inc | D26: Direct Investment | E26: =VLOOKUP($C26,'S | 01 '!$C$6:$R$48,E$5,0) -> Unrealized | F26: =VLOOKUP($C26,'S | 01 '!$C$6:$R$48,F$5,0) -> Sushil | G26: =VLOOKUP($C26,'S | 01 '!$C$6:$R$48,G$5,0) -> Mozn | H26: =VLOOKUP($C26,'S | 01 '!$C$6:$R$48,H$5,0) -> 2019 | I26: =VLOOKUP($C26,'S | 01 '!$C$6:$R$48,I$5,0) -> B-1,2 Prefs | J26: =VLOOKUP($C26,'S | 01 '!$C$6:$R$48,J$5,0) -> 0.085025485 | K26: =VLOOKUP($C26,'S | 01 '!$C$6:$R$48,K$5,0) -> 10 | L26: =VLOOKUP($C26,'S | 01 '!$C$6:$R$48,L$5,0) -> 10 | ... O26: =VLOOKUP($C26,'S | 01 '!$C$6:$R$48,O$5,0) -> 68.08223 | P26: 68.1 | Q26: =VLOOKUP($C26,'S | 01 '!$C$6:$R$48,Q$5,0) -> 0.59885044 | R26: =VLOOKUP($C26,'S | 01 '!$C$6:$R$48,R$5,0) -> 7.808223 | S26: =VLOOKUP($C26,'S | 01 '!$C$6:$R$48,S$5,0) -> 0 | T26: Flyr Warrantsa
C27: Mena Mobile Inc | D27: Direct Investment | E27: =VLOOKUP($C27,'S | 01 '!$C$6:$R$48,E$5,0) -> Written-off | F27: =VLOOKUP($C27,'S | 01 '!$C$6:$R$48,F$5,0) -> Elaine | G27: =VLOOKUP($C27,'S | 01 '!$C$6:$R$48,G$5,0) -> Mozn | H27: =VLOOKUP($C27,'S | 01 '!$C$6:$R$48,H$5,0) -> 2019 | I27: =VLOOKUP($C27,'S | 01 '!$C$6:$R$48,I$5,0) -> B Prefs | J27: =VLOOKUP($C27,'S | 01 '!$C$6:$R$48,J$5,0) -> 0.14 | K27: =VLOOKUP($C27,'S | 01 '!$C$6:$R$48,K$5,0) -> 8 | L27: =VLOOKUP($C27,'S | 01 '!$C$6:$R$48,L$5,0) -> 8 | ... O27: =VLOOKUP($C27,'S | 01 '!$C$6:$R$48,O$5,0) -> -8 | P27: -8 | Q27: =VLOOKUP($C27,'S | 01 '!$C$6:$R$48,Q$5,0) -> NM | R27: =VLOOKUP($C27,'S | 01 '!$C$6:$R$48,R$5,0) -> 0 | S27: =VLOOKUP($C27,'S | 01 '!$C$6:$R$48,S$5,0) -> 0
C28: Glass Earth Holdings LLC | D28: Debt Investment | E28: =VLOOKUP($C28,'S | 01 '!$C$6:$R$48,E$5,0) -> Written-off | F28: =VLOOKUP($C28,'S | 01 '!$C$6:$R$48,F$5,0) -> Marty | G28: =VLOOKUP($C28,'S | 01 '!$C$6:$R$48,G$5,0) -> Mozn | H28: =VLOOKUP($C28,'S | 01 '!$C$6:$R$48,H$5,0) -> 2019 | I28: =VLOOKUP($C28,'S | 01 '!$C$6:$R$48,I$5,0) -> Promissory Note | J28: =VLOOKUP($C28,'S | 01 '!$C$6:$R$48,J$5,0) -> n/a | K28: =VLOOKUP($C28,'S | 01 '!$C$6:$R$48,K$5,0) -> 8 | L28: =VLOOKUP($C28,'S | 01 '!$C$6:$R$48,L$5,0) -> 8 | ... O28: =VLOOKUP($C28,'S | 01 '!$C$6:$R$48,O$5,0) -> -8 | P28: -8 | Q28: =VLOOKUP($C28,'S | 01 '!$C$6:$R$48,Q$5,0) -> NM | R28: =VLOOKUP($C28,'S | 01 '!$C$6:$R$48,R$5,0) -> 0 | S28: =VLOOKUP($C28,'S | 01 '!$C$6:$R$48,S$5,0) -> 0 | T28: =VLOOKUP($C28,'S | 01 '!$C$6:$R$48,T$5,0) -> In Default
C29: Jollychic Holding Limited | D29: Direct Investment | E29: =VLOOKUP($C29,'S | 01 '!$C$6:$R$48,E$5,0) -> Written-off | F29: =VLOOKUP($C29,'S | 01 '!$C$6:$R$48,F$5,0) -> Elaine | G29: =VLOOKUP($C29,'S | 01 '!$C$6:$R$48,G$5,0) -> Mozn | H29: =VLOOKUP($C29,'S | 01 '!$C$6:$R$48,H$5,0) -> 2019 | I29: =VLOOKUP($C29,'S | 01 '!$C$6:$R$48,I$5,0) -> C+ Prefs | J29: =VLOOKUP($C29,'S | 01 '!$C$6:$R$48,J$5,0) -> 0.056999998 | K29: =VLOOKUP($C29,'S | 01 '!$C$6:$R$48,K$5,0) -> 65 | L29: =VLOOKUP($C29,'S | 01 '!$C$6:$R$48,L$5,0) -> 65 | ... O29: =VLOOKUP($C29,'S | 01 '!$C$6:$R$48,O$5,0) -> -65 | P29: -65 | Q29: =VLOOKUP($C29,'S | 01 '!$C$6:$R$48,Q$5,0) -> NM | R29: =VLOOKUP($C29,'S | 01 '!$C$6:$R$48,R$5,0) -> 0 | S29: =VLOOKUP($C29,'S | 01 '!$C$6:$R$48,S$5,0) -> 0 | T29: =VLOOKUP($C29,'S | 01 '!$C$6:$R$48,T$5,0) -> In Liquidation
K31: =SUM(K9:K29) -> 1008.0207 | L31: =SUM(L9:L29) -> 1004.5175 | M31: =SUM(M9:M29) -> 440.91298 | N31: =SUM(N9:N29) -> 526.41089 | O31: =N31+M31-L31 -> -37.193673 | P31: =SUM(P9:P29) -> 14.537198 | Q31: ='4. Mozn-IRR'!L16 -> -0.014740654 | R31: =(M31+N31)/L31 -> 0.9629736 | S31: =SUM(S10:S29) -> 3.5
C33: Honor Device Co Ltd | D33: Direct Investment | E33: =VLOOKUP($C33,'S | 01 '!$C$6:$R$48,E$5,0) -> Realized | F33: =VLOOKUP($C33,'S | 01 '!$C$6:$R$48,F$5,0) -> Elaine | G33: =VLOOKUP($C33,'S | 01 '!$C$6:$R$48,G$5,0) -> G42 3 | H33: =VLOOKUP($C33,'S | 01 '!$C$6:$R$48,H$5,0) -> 2022 | I33: =VLOOKUP($C33,'S | 01 '!$C$6:$R$48,I$5,0) -> Equity-TBC | J33: =VLOOKUP($C33,'S | 01 '!$C$6:$R$48,J$5,0) -> 0.018823528 | K33: =VLOOKUP($C33,'S | 01 '!$C$6:$R$48,K$5,0) -> 800 | L33: =VLOOKUP($C33,'S | 01 '!$C$6:$R$48,L$5,0) -> 800 | ... O33: =VLOOKUP($C33,'S | 01 '!$C$6:$R$48,O$5,0) -> 2.8 | P33: 54.67 | Q33: =VLOOKUP($C33,'S | 01 '!$C$6:$R$48,Q$5,0) -> 0.0029359251 | R33: =VLOOKUP($C33,'S | 01 '!$C$6:$R$48,R$5,0) -> 1.0035 | S33: =VLOOKUP($C33,'S | 01 '!$C$6:$R$48,S$5,0) -> 0 | W33: G42
C34: DriveNets | D34: Direct Investment | E34: =VLOOKUP($C34,'S | 01 '!$C$6:$R$48,E$5,0) -> Unrealized | F34: =VLOOKUP($C34,'S | 01 '!$C$6:$R$48,F$5,0) -> Anton | G34: =VLOOKUP($C34,'S | 01 '!$C$6:$R$48,G$5,0) -> G42 | H34: =VLOOKUP($C34,'S | 01 '!$C$6:$R$48,H$5,0) -> 2022 | I34: =VLOOKUP($C34,'S | 01 '!$C$6:$R$48,I$5,0) -> Equity-TBC | J34: =VLOOKUP($C34,'S | 01 '!$C$6:$R$48,J$5,0) -> 0.11141914 | K34: =VLOOKUP($C34,'S | 01 '!$C$6:$R$48,K$5,0) -> 300 | L34: =VLOOKUP($C34,'S | 01 '!$C$6:$R$48,L$5,0) -> 300 | ... O34: =VLOOKUP($C34,'S | 01 '!$C$6:$R$48,O$5,0) -> 0 | P34: 0 | Q34: =VLOOKUP($C34,'S | 01 '!$C$6:$R$48,Q$5,0) -> 2.9802322e-09 | R34: =VLOOKUP($C34,'S | 01 '!$C$6:$R$48,R$5,0) -> 1 | S34: =VLOOKUP($C34,'S | 01 '!$C$6:$R$48,S$5,0) -> 0 | T34: DN Warrants b
C35: vTv Therapeutics Inc. | D35: Direct Investment | E35: =VLOOKUP($C35,'S | 01 '!$C$6:$R$48,E$5,0) -> Unrealized | F35: =VLOOKUP($C35,'S | 01 '!$C$6:$R$48,F$5,0) -> Divyesh | G35: =VLOOKUP($C35,'S | 01 '!$C$6:$R$48,G$5,0) -> G42 | H35: =VLOOKUP($C35,'S | 01 '!$C$6:$R$48,H$5,0) -> 2022 | I35: =VLOOKUP($C35,'S | 01 '!$C$6:$R$48,I$5,0) -> Ordinary Shares | J35: =VLOOKUP($C35,'S | 01 '!$C$6:$R$48,J$5,0) -> 0.0022129091 | K35: =VLOOKUP($C35,'S | 01 '!$C$6:$R$48,K$5,0) -> 24.53125 | L35: =VLOOKUP($C35,'S | 01 '!$C$6:$R$48,L$5,0) -> 24.53125 | ... O35: =VLOOKUP($C35,'S | 01 '!$C$6:$R$48,O$5,0) -> -22.347535 | P35: -1.348 | Q35: =VLOOKUP($C35,'S | 01 '!$C$6:$R$48,Q$5,0) -> -0.87320089 | R35: =VLOOKUP($C35,'S | 01 '!$C$6:$R$48,R$5,0) -> 0.089017697 | S35: =VLOOKUP($C35,'S | 01 '!$C$6:$R$48,S$5,0) -> 0 | T35: vTv $30m milestn payment c | W35: Invested | X35: =L42 -> 1263.4152
C36: North Summit Capital Fund | D36: Fund Investment | E36: =VLOOKUP($C36,'S | 01 '!$C$6:$R$48,E$5,0) -> Unrealized | F36: =VLOOKUP($C36,'S | 01 '!$C$6:$R$48,F$5,0) -> Elaine | G36: =VLOOKUP($C36,'S | 01 '!$C$6:$R$48,G$5,0) -> G42 | H36: =VLOOKUP($C36,'S | 01 '!$C$6:$R$48,H$5,0) -> 2020 | I36: =VLOOKUP($C36,'S | 01 '!$C$6:$R$48,I$5,0) -> LP | J36: =VLOOKUP($C36,'S | 01 '!$C$6:$R$48,J$5,0) -> n/a | K36: =VLOOKUP($C36,'S | 01 '!$C$6:$R$48,K$5,0) -> 83.334353 | L36: =VLOOKUP($C36,'S | 01 '!$C$6:$R$48,L$5,0) -> 83.214653 | ... O36: =VLOOKUP($C36,'S | 01 '!$C$6:$R$48,O$5,0) -> -0.672921 | P36: -0.306 | Q36: =VLOOKUP($C36,'S | 01 '!$C$6:$R$48,Q$5,0) -> -0.0025177218 | R36: =VLOOKUP($C36,'S | 01 '!$C$6:$R$48,R$5,0) -> 0.99191343 | S36: =VLOOKUP($C36,'S | 01 '!$C$6:$R$48,S$5,0) -> 0.1197 | W36: NAV | X36: =N42 -> 428.73667
C37: New Space Capital Fund I | D37: Fund Investment | E37: =VLOOKUP($C37,'S | 01 '!$C$6:$R$48,E$5,0) -> Unrealized | F37: =VLOOKUP($C37,'S | 01 '!$C$6:$R$48,F$5,0) -> Sushil | G37: =VLOOKUP($C37,'S | 01 '!$C$6:$R$48,G$5,0) -> G42 | H37: =VLOOKUP($C37,'S | 01 '!$C$6:$R$48,H$5,0) -> 2020 | I37: =VLOOKUP($C37,'S | 01 '!$C$6:$R$48,I$5,0) -> LP | J37: =VLOOKUP($C37,'S | 01 '!$C$6:$R$48,J$5,0) -> n/a | K37: =VLOOKUP($C37,'S | 01 '!$C$6:$R$48,K$5,0) -> 31.022787 | L37: =VLOOKUP($C37,'S | 01 '!$C$6:$R$48,L$5,0) -> 13.988553 | ... O37: =VLOOKUP($C37,'S | 01 '!$C$6:$R$48,O$5,0) -> 2.2451661 | P37: 5.445 | Q37: =VLOOKUP($C37,'S | 01 '!$C$6:$R$48,Q$5,0) -> 0.036116043 | R37: =VLOOKUP($C37,'S | 01 '!$C$6:$R$48,R$5,0) -> 1.1605002 | S37: =VLOOKUP($C37,'S | 01 '!$C$6:$R$48,S$5,0) -> 17.034234 | W37: Gain | X37: =O42 -> -20.663021
C38: New Space Capital GP Com SCSp | D38: Fund Investment | E38: =VLOOKUP($C38,'S | 01 '!$C$6:$R$48,E$5,0) -> Unrealized | F38: =VLOOKUP($C38,'S | 01 '!$C$6:$R$48,F$5,0) -> Sushil | G38: =VLOOKUP($C38,'S | 01 '!$C$6:$R$48,G$5,0) -> G42 | H38: =VLOOKUP($C38,'S | 01 '!$C$6:$R$48,H$5,0) -> 2023 | I38: =VLOOKUP($C38,'S | 01 '!$C$6:$R$48,I$5,0) -> LP | J38: =VLOOKUP($C38,'S | 01 '!$C$6:$R$48,J$5,0) -> n/a | K38: =VLOOKUP($C38,'S | 01 '!$C$6:$R$48,K$5,0) -> 2.7058824 | L38: =VLOOKUP($C38,'S | 01 '!$C$6:$R$48,L$5,0) -> 2.7058824 | ... O38: =VLOOKUP($C38,'S | 01 '!$C$6:$R$48,O$5,0) -> -0.13745685 | P38: 0 | Q38: =VLOOKUP($C38,'S | 01 '!$C$6:$R$48,Q$5,0) -> 0 | R38: =VLOOKUP($C38,'S | 01 '!$C$6:$R$48,R$5,0) -> 0.94920073 | S38: =VLOOKUP($C38,'S | 01 '!$C$6:$R$48,S$5,0) -> 0 | W38: YTD Gains | X38: =O42-P42 -> -77.553021
C39: Sinovation Disrupt Fund, L.P. | D39: Fund Investment | E39: =VLOOKUP($C39,'S | 01 '!$C$6:$R$48,E$5,0) -> Realized | F39: =VLOOKUP($C39,'S | 01 '!$C$6:$R$48,F$5,0) -> Elaine | G39: =VLOOKUP($C39,'S | 01 '!$C$6:$R$48,G$5,0) -> G42 | H39: =VLOOKUP($C39,'S | 01 '!$C$6:$R$48,H$5,0) -> 2020 | I39: =VLOOKUP($C39,'S | 01 '!$C$6:$R$48,I$5,0) -> LP | J39: =VLOOKUP($C39,'S | 01 '!$C$6:$R$48,J$5,0) -> n/a | K39: =VLOOKUP($C39,'S | 01 '!$C$6:$R$48,K$5,0) -> 50 | L39: =VLOOKUP($C39,'S | 01 '!$C$6:$R$48,L$5,0) -> 24.959693 | ... O39: =VLOOKUP($C39,'S | 01 '!$C$6:$R$48,O$5,0) -> -0.84556165 | P39: -1.265 | Q39: =VLOOKUP($C39,'S | 01 '!$C$6:$R$48,Q$5,0) -> -0.014868453 | R39: =VLOOKUP($C39,'S | 01 '!$C$6:$R$48,R$5,0) -> 0.96612291 | S39: =VLOOKUP($C39,'S | 01 '!$C$6:$R$48,S$5,0) -> 25.040307 | W39: IRR | X39: =Q42 -> -0.017151204
C40: Acies Investments Fund I, L.P. | D40: Fund Investment | E40: =VLOOKUP($C40,'S | 01 '!$C$6:$R$48,E$5,0) -> Unrealized | F40: =VLOOKUP($C40,'S | 01 '!$C$6:$R$48,F$5,0) -> Divyesh | G40: =VLOOKUP($C40,'S | 01 '!$C$6:$R$48,G$5,0) -> G42 | H40: =VLOOKUP($C40,'S | 01 '!$C$6:$R$48,H$5,0) -> 2021 | I40: =VLOOKUP($C40,'S | 01 '!$C$6:$R$48,I$5,0) -> LP | J40: =VLOOKUP($C40,'S | 01 '!$C$6:$R$48,J$5,0) -> 0.33 | K40: =VLOOKUP($C40,'S | 01 '!$C$6:$R$48,K$5,0) -> 17.1125 | L40: =VLOOKUP($C40,'S | 01 '!$C$6:$R$48,L$5,0) -> 14.015137 | ... O40: =VLOOKUP($C40,'S | 01 '!$C$6:$R$48,O$5,0) -> -1.7047125 | P40: -0.306 | Q40: =VLOOKUP($C40,'S | 01 '!$C$6:$R$48,Q$5,0) -> -0.071990828 | R40: =VLOOKUP($C40,'S | 01 '!$C$6:$R$48,R$5,0) -> 0.87836634 | S40: =VLOOKUP($C40,'S | 01 '!$C$6:$R$48,S$5,0) -> 3.0973625 | T40: 9.9% GP | Anchorf
W41: =O31-P31 -> -51.730871
K42: =SUM(K33:K40) -> 1308.7068 | L42: =SUM(L33:L40) -> 1263.4152 | M42: =SUM(M33:M40) -> 814.01547 | N42: =SUM(N33:N40) -> 428.73667 | O42: =N42+M42-L42 -> -20.663021 | P42: =SUM(P33:P40) -> 56.89 | Q42: ='4. G42-IRR'!L16 -> -0.017151204 | R42: =(M42+N42)/L42 -> 0.98364511 | S42: =SUM(S33:S40) -> 45.291603 | T42: =N42+M42-L42 -> -20.663021 | W42: =K42-L42 -> 45.291603
W43: =O42-P42 -> -77.553021
K44: =K31+K42 -> 2316.7275 | L44: =L31+L42 -> 2267.9327 | M44: =M31+M42 -> 1254.9285 | N44: =N31+N42 -> 955.14756 | O44: =O31+O42 -> -57.856694 | P44: =P31+P42 -> 71.427198 | Q44: ='4.All'!N9 -> -0.012957468 | R44: =(M44+N44)/L44 -> 0.97448924 | S44: =S31+S42 -> 48.791603 | W44: =SUM(M33:N35)-SUM(L33:L35) -> -19.547535
W45: =SUM(M36:N40)-SUM(L36:L40) -> -1.1154859
W46: =K42-L42 -> 45.291603
...

Sheet S | 03
C2: As of date | D2: ='S | 01 '!D2 -> 45322
P3: n/a refers to information not available
C6: Deals | D6: Status | E6: Lead | F6: Investing Entity | G6: Investing Entity (Legal Entity Name) | H6: Nature of Investing Entity | I6: Investments Tax Implication tax note 1 | J6: Instrument | K6: Listed / Unlisted | L6: Website link | M6: Pitchbook link | N6: Jurisdiction | O6: % | P6: Upside (Warrants, Milestone payments, ) | Q6: For Comments Refer to Note
C8: Direct Investments
C9: Jollychic Holding Limited | D9: Written-off | E9: Elaine | F9: Mozn | G9: Mozn Holding RSC Ltd | H9: Potential QFZP tax note 2 | I9: If qualifies for QFZP and hold the investment >= 12m, income/loss from the investee supposed to suject to 0% Corporate tax rate for Investing Entity | J9: C+ Prefs | L9: link | M9: link | N9: Cayman Islands | O9: 0.056999998 | Q9: 1
C10: Mena Mobile Inc | D10: Unrealized | E10: Elaine | F10: Mozn | G10: Mozn Holding RSC Ltd | H10: Potential QFZP tax note 2 | I10: If qualifies for QFZP and hold the investment >= 12m, income/loss from the investee supposed to suject to 0% Corporate tax rate for Investing Entity | J10: B Prefs | L10: link | M10: link | N10: Cayman Islands | O10: 0.14 | Q10: 2
C11: Flyr Inc | D11: Unrealized | E11: Sushil | F11: Mozn | G11: Mozn Holding RSC Ltd | H11: Potential QFZP tax note 2 | I11: If qualifies for QFZP and hold the investment >= 12m, income/loss from the investee supposed to suject to 0% Corporate tax rate for Investing Entity | J11: B-1,2 Prefs | L11: link | M11: link | N11: Delaware Corporation | O11: 0.085025485 | P11: Flyr Warrantsa | Q11: 3
C12: Esyasoft Holding | D12: Realized | E12: Sushil | F12: Mozn | G12: Mozn Holding RSC Ltd | H12: Potential QFZP tax note 2 | I12: If qualifies for QFZP and hold the investment >= 12m, income/loss from the investee supposed to suject to 0% Corporate tax rate for Investing Entity | J12: Convertible Note | L12: link | M12: n/a | N12: DIFC | O12: n/a | Q12: 4
C13: Beyond Limits | D13: Unrealized | E13: Divyesh | F13: Mozn | G13: Mozn Holding RSC Ltd | H13: Potential QFZP tax note 2 | I13: If qualifies for QFZP and hold the investment >= 12m, income/loss from the investee supposed to suject to 0% Corporate tax rate for Investing Entity | J13: C Prefs | L13: link | M13: link | N13: Delaware Corporation | O13: 0.097965107 | Q13: 5
C14: ONT plc | D14: Unrealized | E14: Divyesh | F14: Mozn | G14: Mozn Holding RSC Ltd | H14: Potential QFZP tax note 2 | I14: If qualifies for QFZP and hold the investment >= 12m, income/loss from the investee supposed to suject to 0% Corporate tax rate for Investing Entity | J14: Ordinary Shares | K14: Listed | L14: link | M14: link | N14: UK | O14: 0.051651565 | Q14: 6
C15: Heygears | D15: Unrealized | E15: Elaine | F15: Mozn | G15: Mozn Holding RSC Ltd | H15: Potential QFZP tax note 2 | I15: If qualifies for QFZP and hold the investment >= 12m, income/loss from the investee supposed to suject to 0% Corporate tax rate for Investing Entity | J15: Registered Capital | L15: link | M15: link | N15: PRC | O15: 0.1438 | Q15: 7
C16: Jysan Technologies | D16: Realized | E16: Sushil | F16: Mozn aa | G16: QAZ42 Investment SPV RSC Ltd | H16: Realized | I16: Realized | J16: A (Ordinary Shares) | L16: link | M16: n/a | N16: UK | O16: 0.03 | Q16: 8
C17: Cerebras Systems Inc | D17: Unrealized | E17: Ignasi | F17: Mozn | G17: Mozn Holding RSC Ltd | H17: Potential QFZP tax note 2 | I17: If qualifies for QFZP and hold the investment >= 12m, income/loss from the investee supposed to suject to 0% Corporate tax rate for Investing Entity | J17: F Prefs | L17: link | M17: link | N17: Delaware Corporation | O17: 0.0091172068 | Q17: 9
C18: Endless Studios LLC | D18: Unrealized | E18: Sushil | F18: Mozn | G18: Mozn Holding RSC Ltd | H18: Potential QFZP tax note 2 | I18: If qualifies for QFZP and hold the investment >= 12m, income/loss from the investee supposed to suject to 0% Corporate tax rate for Investing Entity. Currently we have one contribution made in Aug 2023 need to be monitored | J18: A Pref Units | L18: link | M18: link | N18: Delaware Corporation | O18: 0.16080402 | Q18: 10
C19: Instadeep Limited | D19: Realized | E19: Ignasi | F19: Mozn | G19: Mozn Holding RSC Ltd | H19: Potential QFZP tax note 2 | I19: If qualifies for QFZP and hold the investment >= 12m, income/loss from the investee supposed to suject to 0% Corporate tax rate for Investing Entity | J19: B Prefs | L19: link | M19: link | N19: UK | O19: 0.011489406 | Q19: 11
C20: X-fusion | D20: Realized | E20: Elaine | F20: Mozn bb | G20: Enterprise Connection Holding RSC Ltd | H20: Non-QFZP | I20: pending | J20: Equity-TBC | L20: link | M20: link | N20: PRC | O20: 0.051 | Q20: 12
C21: DriveNets | D21: Unrealized | E21: Anton | F21: G42 | G21: D2 Investments RSC Ltd | H21: Non-QFZP | I21: Should qualify for Participation interest | J21: Equity-TBC | L21: link | M21: link | N21: Israeli Pvt Company | O21: 0.11141914 | P21: DN Warrants b | Q21: 13
C22: vTv Therapeutics Inc. | D22: Unrealized | E22: Divyesh | F22: G42 | G22: G42 Investments AI Holdings RSC Ltd | H22: Potential QFZP tax note 2 | I22: If qualifies for QFZP and hold the investment >= 12m, income/loss from the investee supposed to suject to 0% Corporate tax rate for Investing Entity. Currently we have one contribution made in Feb 2023 need to be monitored | J22: Ordinary Shares | K22: Listed | L22: link | M22: link | N22: Delaware Corporation | O22: 0.0022129091 | P22: vTv $30m milestn payment c | Q22: 14
C23: Honor Device Co Ltd | D23: Realized | E23: Elaine | F23: G42 cc | G23: Smart Interaction1 Holding SPV RSC LTD | H23: pending | I23: pending | J23: Equity-TBC | L23: link | M23: link | N23: PRC | O23: 0.018823528 | Q23: 15
C24: Applied AI Corporation Limited | D24: Unrealized | E24: Divyesh | F24: Mozn | G24: Mozn Holding RSC Ltd | H24: Potential QFZP tax note 2 | I24: If qualifies for QFZP and hold the investment >= 12m, income/loss from the investee supposed to suject to 0% Corporate tax rate for Investing Entity. Currently we have one contribution made in July 2023 need to be monitored | J24: Convertible Note | L24: link | M24: link | N24: ADGM | O24: n/a | Q24: 16
C25: eSpace | D25: Unrealized | E25: Anton | F25: Mozn dd | G25: Constellation Investments SPV RSC Ltd (previously Smart Interaction5 Holding SPV RSC Ltd) | H25: Non-QFZP | I25: Taxable for only hold 2.8% of SAFE note in eSpace. | J25: B Prefs | L25: link | M25: link | N25: Delaware Corporation | O25: 0.027864956 | Q25: 17
C26: Tools for Humanity Corporation | D26: Unrealized | E26: Divyesh | F26: Mozn | G26: Mozn Holding RSC Ltd | H26: Potential QFZP tax note 2 | I26: If qualifies for QFZP and hold the investment >= 12m, income/loss from the investee supposed to suject to 0% Corporate tax rate for Investing Entity. Currently we have the contribution made in May 2023 need to be monitored | J26: C Prefs | L26: link | M26: link | N26: Delaware Corporation | O26: 0.0062621983 | Q26: 24
C27: WLD Tokens | D27: Unrealized | E27: Divyesh | F27: Mozn | G27: Mozn Holding RSC Ltd | H27: Potential QFZP tax note 2 | I27: If qualifies for QFZP and hold the investment >= 12m, income/loss from the investee supposed to suject to 0% Corporate tax rate for Investing Entity. Currently we have the Tokens. Future contributions need to be monitored | J27: Tokens | L27: link | M27: Coinbase | N27: DAO | Cayman Islands | O27: 0.00625 | Q27: 25 | T27: Preferred Shares
C28: E-line Ventures LLC | D28: Unrealized | E28: Sushil | F28: Mozn | G28: Mozn Holding RSC Ltd | H28: Potential QFZP tax note 2 | I28: If qualifies for QFZP and hold the investment >= 12m, income/loss from the investee supposed to suject to 0% Corporate tax rate for Investing Entity. Currently we have the contribution made in June 2023 need to be monitored | J28: B Prefs | L28: link | M28: link | N28: New Jersey, USA | O28: ='6. %'!F28 -> 0.11483736 | Q28: 26 | T28: B Prefs
C29: School Hack (AIREV Holding Limited) | D29: Unrealized | E29: Camillo | F29: Core42 | G29: Core42 Investments 1 SPV RSC LTD | J29: Preferred Shares | L29: link | M29: NA | N29: ADGM | O29: 0.25 | Q29: 27
C32: Debt Investments
C33: Glass Earth Holdings LLC | D33: In default | F33: Mozn | G33: G42 Investments AI Holdings RSC Ltd | H33: Potential QFZP tax note 2 | I33: not equity investment, taxable | J33: Promissory Note | L33: n/a | M33: n/a | N33: n/a | Q33: 16
C34: Mena Mobile Inc (Debt) | D34: In default | E34: Elaine | F34: Mozn | G34: Mozn Holding RSC Ltd | H34: Potential QFZP tax note 2 | I34: not equity investment, taxable | J34: Loan | L34: link | M34: link | N34: =N10 -> Cayman Islands | Q34: 17
C35: Esyasoft Holding (Debt) | D35: Unrealized | E35: Sushil | F35: Mozn | G35: Mozn Holding RSC Ltd | H35: Potential QFZP tax note 2 | I35: not equity investment, taxable | J35: Loan | L35: link | M35: n/a | N35: =N12 -> DIFC | Q35: 18
C38: Funds Investments
C39: New Space Capital Fund I | D39: Unrealized | E39: Sushil | F39: G42 | G39: G42 Investments AI Holdings RSC Ltd | H39: Potential QFZP tax note 2 | I39: If qualifies for QFZP and hold the investment >= 12m, income/loss from the investee supposed to suject to 0% Corporate tax rate for Investing Entity | J39: LP | L39: link | M39: link | N39: Luxembourg | O39: 0.22044082 | Q39: 19
C40: New Space Capital GP Com SCSp | D40: Unrealized | E40: Sushil | F40: G42 | G40: G42 Investments AI Holdings RSC Ltd | H40: Potential QFZP tax note 2 | I40: If qualifies for QFZP and hold the investment >= 12m, income/loss from the investee supposed to suject to 0% Corporate tax rate for Investing Entity | J40: GP | L40: link | M40: link | N40: Luxembourg | O40: 0.02016129 | Q40: 20
C41: North Summit Capital Fund | D41: Unrealized | E41: Elaine | F41: G42 | G41: Galbot Holding RSC Ltd | H41: Non-QFZP | I41: pending | J41: LP | L41: n/a | M41: link | N41: Cayman Islands | O41: 0.995 | Q41: 21
C42: Sinovation Disrupt Fund, L.P. | D42: Unrealized | E42: Elaine | F42: G42 | G42: G42 Investments AI Holdings RSC Ltd | H42: Potential QFZP tax note 2 | I42: If qualifies for QFZP and hold the investment >= 12m, income/loss from the investee supposed to suject to 0% Corporate tax rate for Investing Entity | J42: LP | L42: link | M42: link | N42: Cayman Islands | O42: 0.1006609 | Q42: 22
C43: Acies Investments Fund I, L.P. | D43: Unrealized | E43: Divyesh | F43: G42 | G43: G42 Investments AI Holdings RSC Ltd | H43: Potential QFZP tax note 2 | I43: If qualifies for QFZP and hold the investment >= 12m, income/loss from the investee supposed to suject to 0% Corporate tax rate for Investing Entity | J43: LP | L43: link | M43: link | N43: Delaware LLC | O43: 0.33333333 | P43: 9.9% GP | Anchor e | Q43: 23
B47: Notes:
B48: 1 | C48: Jollychic | D48: During 2021, Jollychic Holding Ltd has filed for its liquidation. Therefore, investment is considered to be fully impaired in Dec 21.
B49: 2 | C49: Mena Mobile | D49: Investment is written off based on the 3rd party valuation report
B50: 3 | C50: Flyr | D50: Within five years of the Initial Closing, for every USD 1mn of Qualifying Revenue generated, Flyr will issue, at no additional charge, 194,477 B-1 Prefs in the name of G42, up to a maximum of 1,264,100 B-1 Prefs.
B51: 4 | C51: Esyasoft Holding | D51: Investment in Esyasoft is in the form of Convertible Note which will convert to 21% interest on conversion on a fully diluted basis. As per Dec 2020 FS of Esyasoft, the CN was reflected as Debt - Exit of US$ 2.5 Mn Convertible Note @ 2.0x (MoC) i.e. US$ 5 Mn in May 22 - US$ 0.4 Mn represents Working Capital Loan - fully exited in Dec 22
...

Sheet NAV
B2: NAV Date | C2: ='S | 01 '!D2 -> 45322
B5: Investments | C5: Investing Entity | D5: Instrument | E5: Carrying Value | F5: Current Shares/Units | H5: Comment
E6: USD, Million | F6: # | G6: USD | J6: Updated as on: | K6: =C2 -> 45322
E7: ="NAV | "& TEXT(C2,"dd")&" "&TEXT(C2,"mmm")&" "&TEXT(C2,"yyyy") -> NAV | 31 Jan 2024 | G7: ="PPS |" & TEXT(C2,"dd")&" "&TEXT(C2,"mmm")&" "&TEXT(C2,"yyyy") -> PPS |31 Jan 2024 | L7: source
B8: Direct Investments | J8: ONT Share price | K8: 1.603 | L8: link | N8: Xfusion | O8: =5810000000/K15/1000000*(1-49.82%) -> 400.12709
B9: ='S | 01 '!C10 -> Jollychic Holding Limited | C9: ='S | 01 '!F10 -> Mozn | D9: ='S | 01 '!H10 -> C+ Prefs | E9: =F9*G9*10^-6 -> 0 | F9: =SUM('CF (Equity, Debt)'!J4:J6) -> 13458655 | H9: In liquidation | J9: VTVT Share price | K9: 8.41 | L9: link | N9: Honor | O9: =MAX(800,310000000000/K15/1000000*4.705882%*0.8/2) -> 800.85498
B10: ='S | 01 '!C11 -> Mena Mobile Inc | C10: ='S | 01 '!F11 -> Mozn | D10: ='S | 01 '!H11 -> B Prefs | E10: 0 | F10: ='CF (Equity, Debt)'!J7 -> 21419829 | H10: As per 3rd Party | Ardent Estimates | Equity written off | J10: GBP USD | K10: 1.26853 | L10: xe.com
B11: ='S | 01 '!C12 -> Flyr Inc | C11: ='S | 01 '!F12 -> Mozn | D11: ='S | 01 '!H12 -> B-1,2 Prefs | E11: =F11*G11*10^-6*(1-20%) -> 78.08223 | F11: 5205482 | G11: 18.75 | H11: At Series C PPS $18.75/share with 20% discount | J11: EUR USD | K11: 1.08667 | L11: xe.com
B12: ='S | 01 '!C13 -> Esyasoft Holding | C12: ='S | 01 '!F13 -> Mozn | D12: ='S | 01 '!H13 -> Convertible Note | E12: 0 | F12: n/a | H12: Exited at $5m (10th May) | Residual value = 0
B13: ='S | 01 '!C14 -> Beyond Limits | C13: ='S | 01 '!F14 -> Mozn | D13: ='S | 01 '!H14 -> C Prefs | E13: =F13*G13*10^-6 -> 91.00154 | F13: =SUM('CF (Equity, Debt)'!J11:J14) -> 17670202 | G13: 5.15 | H13: Held at cost (as per revised management guidance)
B14: ='S | 01 '!C15 -> ONT plc | C14: ='S | 01 '!F15 -> Mozn | D14: ='S | 01 '!H15 -> Ordinary Shares | E14: =F14*G14*10^-6 -> 90.139175 | F14: 44328120 | G14: =K8*K10 -> 2.0334536 | H14: Listed & marked to market | J14: Heygears Oct 22
B15: ='S | 01 '!C16 -> Heygears | C15: ='S | 01 '!F16 -> Mozn | D15: ='S | 01 '!H16 -> Registered Capital | E15: =K23/1000000 -> 148.04984 | F15: ='CF (Equity, Debt)'!J20 -> 4753356.3 | H15: Adjusted for currency. Valued at the recent round | J15: USD RMB | K15: 7.28633 | L15: xe.com
B16: ='S | 01 '!C17 -> Jysan Technologies | C16: ='S | 01 '!F17 -> Mozn 1 | D16: ='S | 01 '!H17 -> A (Ordinary Shares) | E16: 0 | F16: ='CF (Equity, Debt)'!J21 -> 7959497 | G16: =E16*10^6/F16 -> 0 | H16: Exited at $24.5m | J16: Post Valuation closed in June 2021 (RMB) | K16: 7500000000
B17: ='S | 01 '!C18 -> Cerebras Systems Inc | C17: ='S | 01 '!F18 -> Mozn | D17: ='S | 01 '!H18 -> F Prefs | E17: =-'CF (Equity, Debt)'!E22 -> 39.999983 | F17: ='6. %'!D17 -> 1441711 | H17: Held at cost. | J17: G42 Stake | K17: 0.143832
B18: ='S | 01 '!C19 -> Endless Studios LLC | C18: ='S | 01 '!F19 -> Mozn | D18: ='S | 01 '!H19 -> A Pref Units | E18: =-'CF (Equity, Debt)'!E23-'CF (Equity, Debt)'!E41 -> 8 | F18: ='CF (Equity, Debt)'!J23+'CF (Equity, Debt)'!J41 -> 8000000 | H18: Held at cost. | J18: G42 Valuation before Discount (RMB) | K18: 1078740000
B19: ='S | 01 '!C20 -> Instadeep Limited | C19: ='S | 01 '!F20 -> Mozn | D19: ='S | 01 '!H20 -> B Prefs | E19: =-'CF (Equity, Debt)'!E24*G19 -> 0 | F19: ='CF (Equity, Debt)'!J24 -> 33267 | G19: 0 | H19: Exited at 1.56X | Residual Value = 0 | J19: Liquidity Discount | K19: 0
B20: ='S | 01 '!C21 -> X-fusion | C20: ='S | 01 '!F21 -> Mozn 2 | D20: ='S | 01 '!H21 -> Equity-TBC | E20: 0 | F20: n/a | H20: Exited at 0.82X | J20: Minority Holding Discount | K20: 0
B21: ='S | 01 '!C22 -> DriveNets | C21: ='S | 01 '!F22 -> G42 | D21: ='S | 01 '!H22 -> Equity-TBC | E21: =-SUM('CF (Equity, Debt)'!E26:E27) -> 300 | F21: ='6. %'!D21 -> 86882669 | H21: Held at cost. | J21: G42 Valuation (RMB) | K21: =K18*(1-K19)*(1-K20) -> 1078740000
B22: ='S | 01 '!C23 -> vTv Therapeutics Inc. | C22: ='S | 01 '!F23 -> G42 | D22: ='S | 01 '!H23 -> Ordinary Shares | E22: =(F22*G22)*10^-6 -> 2.1837154 | F22: ='CF (Equity, Debt)'!J29 -> 259657 | G22: =K9 -> 8.41 | H22: Listed & marked to market | J22: Exchange Rate (RMB/USD) | K22: =K15 -> 7.28633
B23: ='S | 01 '!C24 -> Honor Device Co Ltd | C23: ='S | 01 '!F24 -> G42 3 | D23: ='S | 01 '!H24 -> Equity-TBC | E23: 0 | F23: n/a | H23: Exited at 1.0X | J23: G42 Valuation (USD) | K23: =K21/K22 -> 1.4804984e+08
B24: ='S | 01 '!C25 -> Applied AI Corporation Limited | C24: ='S | 01 '!F25 -> Mozn | D24: ='S | 01 '!H25 -> Convertible Note | E24: =-'CF (Equity, Debt)'!E32-'CF (Equity, Debt)'!E38-'CF (Equity, Debt)'!E47 -> 11.5 | F24: n/a | H24: Held at cost. | J24: Investment Cost of G42 (USD) | K24: 60000000
B25: ='S | 01 '!C26 -> eSpace | C25: ='S | 01 '!F26 -> Mozn 4 | D25: ='S | 01 '!H26 -> B Prefs | E25: =F25*G25*10^-6 -> 20.888122 | F25: 417846 | G25: 49.99 | H25: Marked up. | J25: Investment Multiple | K25: 1.9039182
B26: ='S | 01 '!C27 -> Tools for Humanity Corporation | C26: ='S | 01 '!F27 -> Mozn | D26: ='S | 01 '!H27 -> C Prefs | E26: ='S | 01 '!K27 -> 14.999999 | F26: ='6. %'!D26 -> 65413 | H26: Held at cost.
