Workbook
Name Company: [1]UEL!$B$18:$B$20
Name Dates: [1]ONT!$N$2:$AN$2
Name DetailedCapShares: '[2]Current Cap'!$T$133
Name FAGroup: [1]UEL!$B$3:$B$15
Name IQ_CH: 110000
Name IQ_CQ: 5000
Name IQ_CY: 10000
Name IQ_DAILY: 500000
Name IQ_FH: 100000
Name IQ_FQ: 500
Name IQ_FY: 1000
Name IQ_LTM: 2000
Name IQ_MONTH: 15000
Name IQ_NTM: 6000
Name IQ_WEEK: 50000
Name IQ_YTD: 3000

Sheet D
C2: Date of NAV | D2: 45473 | E2: =TEXT(D2,"dddddd") -> Sunday
H4: D A S H B O A R D
B5: USD Millions
D7: # Investments | E7: Committed | F7: Invested | G7: Remaining | H7: Distributions | I7: Residual Value | J7: Gain | K7: TVPI | L7: DPI
C9: EQUITY* | D9: =COUNTIF('S | 01 '!C9:C33,"*") -> 23 | E9: ='S | 01 '!J33 -> 2151.783 | F9: ='S | 01 '!K33 -> 2148.033 | G9: ='S | 01 '!L33 -> 3.75 | H9: ='S | 01 '!M33 -> 1243.2422 | I9: ='S | 01 '!N33 -> 757.71883 | J9: =H9+I9-F9 -> -147.07202 | K9: =(H9+I9)/F9 -> 0.93153177 | L9: =H9/F9 -> 0.57878169
C12: DEBT | D12: =COUNTIF('S | 01 '!C36:C38,"*") -> 3 | E12: ='S | 01 '!J39 -> 10.765747 | F12: ='S | 01 '!K39 -> 10.765747 | G12: ='S | 01 '!L39 -> 0 | H12: ='S | 01 '!M39 -> 0.47078465 | I12: ='S | 01 '!N39 -> 0 | J12: =H12+I12-F12 -> -10.294962 | K12: =(H12+I12)/F12 -> 0.043729864 | L12: =H12/F12 -> 0.043729864
C15: FUNDS | D15: =COUNTIF('S | 01 '!C42:C46,"*") -> 5 | E15: ='S | 01 '!J47 -> 178.33516 | F15: ='S | 01 '!K47 -> 140.8735 | G15: ='S | 01 '!L47 -> 15.352483 | H15: ='S | 01 '!M47 -> 36.638861 | I15: ='S | 01 '!N47 -> 108.15165 | J15: =H15+I15-F15 -> 3.9170112 | K15: =(H15+I15)/F15 -> 1.0278052 | L15: =H15/F15 -> 0.26008341
C18: TOTAL | D18: =D9+D12+D15 -> 31 | E18: =E9+E12+E15 -> 2340.884 | F18: =F9+F12+F15 -> 2299.6723 | G18: =G9+G12+G15 -> 19.102483 | H18: =H9+H12+H15 -> 1280.3518 | I18: =I9+I12+I15 -> 865.87048 | J18: =H18+I18-F18 -> -153.44997 | K18: =(H18+I18)/F18 -> 0.93327311 | L18: =H18/F18 -> 0.55675404
C20: * Includes Convertibles | E20: =E18='S | 01 '!J49 -> TRUE | F20: =F18='S | 01 '!K49 -> TRUE | G20: =ROUND(G18,1)=ROUND('S | 01 '!L49,1) -> TRUE | H20: =ROUND(H18,1)=ROUND('S | 01 '!M49,1) -> TRUE | I20: =ROUND(I18,1)=ROUND('S | 01 '!N49,1) -> TRUE

Sheet S | 01 
C2: As of date | D2: =D!D2 -> 45473 | E2: 1
C6: Deals | D6: Status | E6: Lead | F6: Investing Entity Ϋ | G6: Vintageἀ | H6: Instrument | I6: % | J6: Committed | K6: Invested | L6: Remaining Commitment | M6: Distributions | N6: Carrying Value | O6: Gain | P6: TVPI | Q6: Additional Upside/Downside
G7: # | I7: % | J7: $,m | K7: $,m | L7: $,m | M7: $,m | N7: $,m | O7: $,m | P7: X
C8: Equity or Equity like Investments
C9: Jollychic Holding Limited | D9: Written-off | E9: Elaine | F9: Mozn | G9: 2019 | H9: C+ Prefs | I9: ='6. %'!F9 -> 0.056999998 | J9: =K9 -> 65 | K9: =-SUMIF('CF (Equity, Debt)'!$C$3:$K$53,'S | 01 '!C9,'CF (Equity, Debt)'!$E$3:$E$53) -> 65 | L9: 0 | M9: =SUMIF('CF (Equity, Debt)'!$C$3:$K$53,'S | 01 '!C9,'CF (Equity, Debt)'!$F$3:$F$53) -> 0 | N9: =VLOOKUP(C9,NAV!$B$4:$E$44,4,0) -> 0 | O9: =N9+M9-K9 -> -65 | P9: =(M9+N9)/K9 -> 0 | Q9: In Liquidation
C10: Mena Mobile Inc | D10: Written-off | E10: Elaine | F10: Mozn | G10: 2019 | H10: B Prefs | I10: ='6. %'!F10 -> 0.14 | J10: =K10 -> 8 | K10: =-SUMIF('CF (Equity, Debt)'!$C$3:$K$53,'S | 01 '!C10,'CF (Equity, Debt)'!$E$3:$E$53) -> 8 | L10: 0 | M10: =SUMIF('CF (Equity, Debt)'!$C$3:$K$53,'S | 01 '!C10,'CF (Equity, Debt)'!$F$3:$F$53) -> 0 | N10: =VLOOKUP(C10,NAV!$B$4:$E$44,4,0) -> 0 | O10: =N10+M10-K10 -> -8 | P10: =(M10+N10)/K10 -> 0 | Q10: In Liquidation
C11: Flyr Inc | D11: Unrealized | E11: Sushil | F11: Mozn | G11: 2019 | H11: B-1,2 Prefs | I11: ='6. %'!F11 -> 0.085025485 | J11: =K11 -> 10 | K11: =-SUMIF('CF (Equity, Debt)'!$C$3:$K$53,'S | 01 '!C11,'CF (Equity, Debt)'!$E$3:$E$53) -> 10 | L11: 0 | M11: =SUMIF('CF (Equity, Debt)'!$C$3:$K$53,'S | 01 '!C11,'CF (Equity, Debt)'!$F$3:$F$53) -> 0 | N11: =VLOOKUP(C11,NAV!$B$4:$E$44,4,0) -> 37.11873 | O11: =N11+M11-K11 -> 27.11873 | P11: =(M11+N11)/K11 -> 3.711873 | Q11: Flyr Warrantsa 2025 expiry
C12: Esyasoft Holding | D12: Realized | E12: Sushil | F12: Mozn | G12: 2020 | H12: Convertible Note | I12: ='6. %'!F12 -> n/a | J12: =K12 -> 2.5 | K12: =-SUMIF('CF (Equity, Debt)'!$C$3:$K$53,'S | 01 '!C12,'CF (Equity, Debt)'!$E$3:$E$53) -> 2.5 | L12: 0 | M12: =SUMIF('CF (Equity, Debt)'!$C$3:$K$53,'S | 01 '!C12,'CF (Equity, Debt)'!$F$3:$F$53) -> 5 | N12: =VLOOKUP(C12,NAV!$B$4:$E$44,4,0) -> 0 | O12: =N12+M12-K12 -> 2.5 | P12: =(M12+N12)/K12 -> 2
C13: Beyond Limits | D13: Unrealized | E13: Divyesh | F13: Mozn | G13: 2020 | H13: C Prefs | I13: ='6. %'!F13 -> 0.094347728 | J13: =K13 -> 90 | K13: =-SUMIF('CF (Equity, Debt)'!$C$3:$K$53,'S | 01 '!C13,'CF (Equity, Debt)'!$E$3:$E$53) -> 90 | L13: 0 | M13: =SUMIF('CF (Equity, Debt)'!$C$3:$K$53,'S | 01 '!C13,'CF (Equity, Debt)'!$F$3:$F$53) -> 0 | N13: =VLOOKUP(C13,NAV!$B$4:$E$44,4,0) -> 73.8 | O13: =N13+M13-K13 -> -16.2 | P13: =(M13+N13)/K13 -> 0.82
C14: ONT plc | D14: Unrealized | E14: Divyesh | F14: Mozn | G14: 2020 | H14: Ordinary Shares | I14: ='6. %'!F14 -> 0.051651565 | J14: =K14 -> 141.47026 | K14: =-SUMIF('CF (Equity, Debt)'!$C$3:$K$53,'S | 01 '!C14,'CF (Equity, Debt)'!$E$3:$E$53) -> 141.47026 | L14: 0 | M14: =SUMIF('CF (Equity, Debt)'!$C$3:$K$53,'S | 01 '!C14,'CF (Equity, Debt)'!$F$3:$F$53) -> 0 | N14: =VLOOKUP(C14,NAV!$B$4:$E$44,4,0) -> 53.000051 | O14: =N14+M14-K14 -> -88.470208 | P14: =(M14+N14)/K14 -> 0.37463741
C15: Heygears | D15: Unrealized | E15: Elaine | F15: Mozn | G15: 2020 | H15: Registered Capital | I15: ='6. %'!F15 -> 0.1438 | J15: =K15 -> 60 | K15: =-SUMIF('CF (Equity, Debt)'!$C$3:$K$53,'S | 01 '!C15,'CF (Equity, Debt)'!$E$3:$E$53) -> 60 | L15: 0 | M15: =SUMIF('CF (Equity, Debt)'!$C$3:$K$53,'S | 01 '!C15,'CF (Equity, Debt)'!$F$3:$F$53) -> 0 | N15: =VLOOKUP(C15,NAV!$B$4:$E$44,4,0) -> 149.39859 | O15: =N15+M15-K15 -> 89.398592 | P15: =(M15+N15)/K15 -> 2.4899765
C16: Jysan Technologies | D16: Realized | E16: Sushil | F16: Mozn 1 | G16: 2021 | H16: A (Ordinary Shares) | I16: ='6. %'!F16 -> 0.03 | J16: =K16 -> 20 | K16: =-SUMIF('CF (Equity, Debt)'!$C$3:$K$53,'S | 01 '!C16,'CF (Equity, Debt)'!$E$3:$E$53) -> 20 | L16: 0 | M16: =SUMIF('CF (Equity, Debt)'!$C$3:$K$53,'S | 01 '!C16,'CF (Equity, Debt)'!$F$3:$F$53) -> 24.5 | N16: =VLOOKUP(C16,NAV!$B$4:$E$44,4,0) -> 0 | O16: =N16+M16-K16 -> 4.5 | P16: =(M16+N16)/K16 -> 1.225
C17: Cerebras Systems Inc | D17: Unrealized | E17: Ignasi | F17: Mozn | G17: 2021 | H17: F Prefs | I17: ='6. %'!F17 -> 0.0091172068 | J17: =K17 -> 39.999983 | K17: =-SUMIF('CF (Equity, Debt)'!$C$3:$K$53,'S | 01 '!C17,'CF (Equity, Debt)'!$E$3:$E$53) -> 39.999983 | L17: 0 | M17: =SUMIF('CF (Equity, Debt)'!$C$3:$K$53,'S | 01 '!C17,'CF (Equity, Debt)'!$F$3:$F$53) -> 0 | N17: =VLOOKUP(C17,NAV!$B$4:$E$44,4,0) -> 21.135483 | O17: =N17+M17-K17 -> -18.8645 | P17: =(M17+N17)/K17 -> 0.5283873
C18: Endless Studios LLC | D18: Unrealized | E18: Sushil | F18: Mozn | G18: 2021 | H18: A Pref Units | I18: ='6. %'!F18 -> 0.16080402 | J18: =K18 -> 8 | K18: =-SUMIF('CF (Equity, Debt)'!$C$3:$K$53,'S | 01 '!C18,'CF (Equity, Debt)'!$E$3:$E$53) -> 8 | L18: 0 | M18: =SUMIF('CF (Equity, Debt)'!$C$3:$K$53,'S | 01 '!C18,'CF (Equity, Debt)'!$F$3:$F$53) -> 0 | N18: =VLOOKUP(C18,NAV!$B$4:$E$44,4,0) -> 8 | O18: =N18+M18-K18 -> 0 | P18: =(M18+N18)/K18 -> 1
C19: Instadeep Limited | D19: Realized | E19: Ignasi | F19: Mozn | G19: 2021 | H19: B Prefs | I19: ='6. %'!F19 -> 0.011489406 | J19: =K19 -> 5.0237202 | K19: =-SUMIF('CF (Equity, Debt)'!$C$3:$K$53,'S | 01 '!C19,'CF (Equity, Debt)'!$E$3:$E$53) -> 5.0237202 | L19: 0 | M19: =SUMIF('CF (Equity, Debt)'!$C$3:$K$53,'S | 01 '!C19,'CF (Equity, Debt)'!$F$3:$F$53) -> 7.9421925 | N19: =VLOOKUP(C19,NAV!$B$4:$E$44,4,0) -> 0 | O19: =N19+M19-K19 -> 2.9184723 | P19: =(M19+N19)/K19 -> 1.5809385
C20: X-fusion | D20: Realized | E20: Elaine | F20: Mozn 2 | G20: 2022 | H20: Equity-TBC | I20: ='6. %'!F20 -> 0.051 | J20: =K20 -> 493.50096 | K20: =-SUMIF('CF (Equity, Debt)'!$C$3:$K$53,'S | 01 '!C20,'CF (Equity, Debt)'!$E$3:$E$53) -> 493.50096 | L20: 0 | M20: =SUMIF('CF (Equity, Debt)'!$C$3:$K$53,'S | 01 '!C20,'CF (Equity, Debt)'!$F$3:$F$53) -> 403 | N20: =VLOOKUP(C20,NAV!$B$4:$E$44,4,0) -> 0 | O20: =N20+M20-K20 -> -90.500956 | P20: =(M20+N20)/K20 -> 0.81661443
C21: DriveNets | D21: Unrealized | E21: Anton | F21: G42 | G21: 2022 | H21: Equity-TBC | I21: ='6. %'!F21 -> 0.11141914 | J21: =K21 -> 300 | K21: =-SUMIF('CF (Equity, Debt)'!$C$3:$K$53,'S | 01 '!C21,'CF (Equity, Debt)'!$E$3:$E$53) -> 300 | L21: =0 -> 0 | M21: =SUMIF('CF (Equity, Debt)'!$C$3:$K$53,'S | 01 '!C21,'CF (Equity, Debt)'!$F$3:$F$53) -> 0 | N21: =VLOOKUP(C21,NAV!$B$4:$E$44,4,0) -> 204.6 | O21: =N21+M21-K21 -> -95.4 | P21: =(M21+N21)/K21 -> 0.682 | Q21: DN Warrants b
C22: vTv Therapeutics Inc. | D22: Unrealized | E22: Divyesh | F22: G42 | G22: 2022 | H22: Ordinary Shares | I22: ='6. %'!F22 -> 0.0021343582 | J22: =K22 -> 24.53125 | K22: =-SUMIF('CF (Equity, Debt)'!$C$3:$K$53,'S | 01 '!C22,'CF (Equity, Debt)'!$E$3:$E$53) -> 24.53125 | L22: =J22-K22 -> 0 | M22: =SUMIF('CF (Equity, Debt)'!$C$3:$K$53,'S | 01 '!C22,'CF (Equity, Debt)'!$F$3:$F$53) -> 0 | N22: =VLOOKUP(C22,NAV!$B$4:$E$44,4,0) -> 4.5855426 | O22: =N22+M22-K22 -> -19.945707 | P22: =(M22+N22)/K22 -> 0.18692658 | Q22: vTv $30m milestn payment c
C23: Honor Device Co Ltd | D23: Realized | E23: Elaine | F23: G42 3 | G23: 2022 | H23: Equity-TBC | I23: ='6. %'!F23 -> 0.018823528 | J23: =K23 -> 800 | K23: =-SUMIF('CF (Equity, Debt)'!$C$3:$K$53,'S | 01 '!C23,'CF (Equity, Debt)'!$E$3:$E$53) -> 800 | L23: =J23-K23 -> 0 | M23: =SUMIF('CF (Equity, Debt)'!$C$3:$K$53,'S | 01 '!C23,'CF (Equity, Debt)'!$F$3:$F$53) -> 802.8 | N23: =VLOOKUP(C23,NAV!$B$4:$E$44,4,0) -> 0 | O23: =N23+M23-K23 -> 2.8 | P23: =(M23+N23)/K23 -> 1.0035
C24: Applied AI Corporation Limited | D24: Unrealized | E24: Divyesh | F24: Mozn | G24: 2022 | H24: Convertible Note | I24: ='6. %'!F24 -> n/a | J24: 15 | K24: =-SUMIF('CF (Equity, Debt)'!$C$3:$K$53,'S | 01 '!C24,'CF (Equity, Debt)'!$E$3:$E$53) -> 11.5 | L24: =J24-K24 -> 3.5 | M24: 0 | N24: =VLOOKUP(C24,NAV!$B$4:$E$44,4,0) -> 11.5 | O24: =N24+M24-K24 -> 0 | P24: =(M24+N24)/K24 -> 1
C25: eSpace | D25: Unrealized | E25: Anton | F25: Mozn 4 | G25: 2022 | H25: B Prefs | I25: ='6. %'!F25 -> 0.027864956 | J25: =K25 -> 15 | K25: =-SUMIF('CF (Equity, Debt)'!$C$3:$K$53,'S | 01 '!C25,'CF (Equity, Debt)'!$E$3:$E$53) -> 15 | L25: =J25-K25 -> 0 | M25: 0 | N25: =VLOOKUP(C25,NAV!$B$4:$E$44,4,0) -> 20.888122 | O25: =N25+M25-K25 -> 5.8881215 | P25: =(M25+N25)/K25 -> 1.3925414
C26: Tools for Humanity Corporation | D26: Unrealized | E26: Divyesh | F26: Mozn | G26: 2023 | H26: C Prefs | I26: ='6. %'!F26 -> 0.0062621983 | J26: =K26 -> 14.999999 | K26: =-SUMIF('CF (Equity, Debt)'!$C$3:$K$53,'S | 01 '!C26,'CF (Equity, Debt)'!$E$3:$E$53) -> 14.999999 | L26: =J26-K26 -> 0 | M26: 0 | N26: =VLOOKUP(C26,NAV!$B$4:$E$44,4,0) -> 14.999999 | O26: =N26+M26-K26 -> 0 | P26: =(M26+N26)/K26 -> 1
C27: WLD Tokens | D27: Unrealized | E27: Divyesh | F27: Mozn | G27: 2023 | H27: Tokens | I27: ='6. %'!F27 -> 0.00625 | J27: =K27 -> 0.006875 | K27: =-SUMIF('CF (Equity, Debt)'!$C$3:$K$53,'S | 01 '!C27,'CF (Equity, Debt)'!$E$3:$E$53) -> 0.006875 | L27: =J27-K27 -> 0 | M27: 0 | N27: =VLOOKUP(C27,NAV!$B$4:$E$44,4,0) -> 120.19231 | O27: =N27+M27-K27 -> 120.18543 | P27: NM | Q27: Crypto Tokensd
C28: E-line Ventures LLC | D28: Unrealized | E28: Sushil | F28: Mozn | G28: 2023 | H28: B Prefs | I28: ='6. %'!F28 -> 0.11483736 | J28: =K28 -> 6 | K28: =-SUMIF('CF (Equity, Debt)'!$C$3:$K$53,'S | 01 '!C28,'CF (Equity, Debt)'!$E$3:$E$53) -> 6 | L28: =J28-K28 -> 0 | M28: 0 | N28: =VLOOKUP(C28,NAV!$B$4:$E$44,4,0) -> 6 | O28: =N28+M28-K28 -> 0 | P28: =(M28+N28)/K28 -> 1 | Q28: Optionse
C29: School Hack (AIREV Holding Limited) | D29: Unrealized | E29: Camillo | F29: Core42 5 | G29: 2024 | H29: Preferred Shares | I29: ='6. %'!F29 -> 0.25 | J29: =K29+0.25 -> 2.75 | K29: =-SUMIF('CF (Equity, Debt)'!$C$3:$K$53,'S | 01 '!C29,'CF (Equity, Debt)'!$E$3:$E$53) -> 2.5 | L29: =J29-K29 -> 0.25 | M29: 0 | N29: =VLOOKUP(C29,NAV!$B$4:$E$44,4,0) -> 2.5 | O29: =N29+M29-K29 -> 0 | P29: =(M29+N29)/K29 -> 1 | Q29: Cloud Creditg
C30: Life Biosciences LLC | D30: Unrealized | E30: Divyesh | F30: G42 Capital | G30: 2024 | H30: Convertible Note | I30: ='6. %'!F30 -> n/a | J30: =K30 -> 20 | K30: =-SUMIF('CF (Equity, Debt)'!$C$3:$K$53,'S | 01 '!C30,'CF (Equity, Debt)'!$E$3:$E$53) -> 20 | L30: =J30-K30 -> 0 | M30: 0 | N30: =VLOOKUP(C30,NAV!$B$4:$E$44,4,0) -> 20 | O30: =N30+M30-K30 -> 0 | P30: =(M30+N30)/K30 -> 1
C31: Verses AI Inc | D31: Unrealized | E31: Divyesh | F31: G42 Capital | G31: 2024 | H31: Convertible Debenture | I31: n/a | J31: 10 | K31: =-SUMIF('CF (Equity, Debt)'!$C$3:$K$53,'S | 01 '!C31,'CF (Equity, Debt)'!$E$3:$E$53) -> 10 | L31: =J31-K31 -> 0 | M31: 0 | N31: =VLOOKUP(C31,NAV!$B$4:$E$44,4,0) -> 10 | O31: =N31+M31-K31 -> 0 | P31: =(M31+N31)/K31 -> 1 | Q31: Revenue linked RSUs
J33: =SUM(J9:J31) -> 2151.783 | K33: =SUM(K9:K31) -> 2148.033 | L33: =SUM(L9:L31) -> 3.75 | M33: =SUM(M9:M31) -> 1243.2422 | N33: =SUM(N9:N31) -> 757.71883 | O33: =SUM(O9:O31) -> -147.07202 | P33: =(M33+N33)/K33 -> 0.93153177
C35: Debt Investments
C36: Glass Earth Holdings LLC | D36: Written-off | E36: Marty | F36: Mozn | G36: 2019 | H36: Promissory Note | I36: n/a | J36: 8 | K36: 8 | L36: 0 | M36: 0 | N36: 0 | O36: =N36+M36-K36 -> -8 | P36: =(M36+N36)/K36 -> 0 | Q36: In Default
C37: Mena Mobile Inc (Debt) | D37: Written-off | E37: Elaine | F37: Mozn | G37: 2021 | H37: Loan | I37: n/a | J37: 2.353982 | K37: =J37 -> 2.353982 | L37: 0 | M37: 0 | N37: =VLOOKUP(C37,NAV!$B$4:$E$44,4,0) -> 0 | O37: =N37+M37-K37 -> -2.353982 | P37: =(M37+N37)/K37 -> 0 | Q37: In Liquidation
C38: Esyasoft Holding (Debt) | D38: Realized | E38: Sushil | F38: Mozn | G38: 2021 | H38: Loan | I38: n/a | J38: 0.411765 | K38: 0.411765 | L38: 0 | M38: ='CF (Equity, Debt)'!F58 -> 0.47078465 | N38: 0 | O38: =N38+M38-K38 -> 0.05901965 | P38: =(M38+N38)/K38 -> 1.1433333
J39: =SUM(J36:J38) -> 10.765747 | K39: =SUM(K36:K38) -> 10.765747 | L39: =SUM(L36:L38) -> 0 | M39: =SUM(M36:M38) -> 0.47078465 | N39: =SUM(N36:N38) -> 0 | O39: =N39+M39-K39 -> -10.294962 | P39: =(M39+N39)/K39 -> 0.043729864
C41: Funds Investments
C42: New Space Capital Fund I | D42: Unrealized | E42: Sushil | F42: G42 Investments | G42: 2020 | H42: LP | I42: n/a | J42: ='8. NewSpace'!P7*10^-6*NAV!K21 -> 24.886432 | K42: =-SUMIF('CF (Funds)'!$C$4:$E$2011,C42,'CF (Funds)'!$E$4:$E$2011) -> 15.922439 | L42: ='8. NewSpace'!P22*10^-6*NAV!K21 -> 11.89512 | M42: =SUM('CF (Funds)'!F38:F61) -> 3.4194691 | N42: =VLOOKUP(C42,NAV!$B$4:$E$44,4,0) -> 19.274963 | O42: =N42+M42-K42 -> 6.7719935 | P42: =(M42+N42)/K42 -> 1.4253113
C43: New Space Capital GP Com SCSp | D43: Unrealized | E43: Sushil | F43: G42 Investments | G43: 2023 | H43: LP | I43: n/a | J43: =2.3/0.85 -> 2.7058824 | K43: 2.7058824 | L43: 0 | M43: 0 | N43: =VLOOKUP(C43,NAV!$B$4:$E$44,4,0) -> 3.2756152 | O43: =N43+M43-K43 -> 0.56973286 | P43: =(M43+N43)/K43 -> 1.2105534
C44: North Summit Capital Fund | D44: Unrealized | E44: Elaine | F44: G42 Investments | G44: 2020 | H44: LP | I44: n/a | J44: =K44+L44 -> 83.63035 | K44: =-SUMIF('CF (Funds)'!$C$4:$E$2011,C44,'CF (Funds)'!$E$4:$E$2011) -> 83.27035 | L44: =0.12*3 -> 0.36 | M44: =SUM('CF (Funds)'!F26:'CF (Funds)'!F36) -> 7.815871 | N44: =VLOOKUP(C44,NAV!$B$4:$E$44,4,0) -> 74.725861 | O44: =N44+M44-K44 -> -0.728618 | P44: =(M44+N44)/K44 -> 0.99124997
C45: Sinovation Disrupt Fund, L.P. | D45: Realized | E45: Elaine | F45: G42 Investments | G45: 2020 | H45: LP | I45: n/a | J45: 50 | K45: =-SUMIF('CF (Funds)'!$C$4:$E$2011,C45,'CF (Funds)'!$E$4:$E$2011) -> 24.959693 | L45: 0 | M45: =SUM('CF (Funds)'!F4:F21) -> 25.403521 | N45: =VLOOKUP(C45,NAV!$B$4:$E$44,4,0) -> 0 | O45: =N45+M45-K45 -> 0.44382835 | P45: =(M45+N45)/K45 -> 1.0177818
C46: Acies Investments Fund I, L.P. | D46: Unrealized | E46: Divyesh | F46: G42 Investments | G46: 2021 | H46: LP | I46: 0.33 | J46: 17.1125 | K46: =-SUMIF('CF (Funds)'!$C$4:$E$2011,C46,'CF (Funds)'!$E$4:$E$2011) -> 14.015137 | L46: =J46-K46 -> 3.0973625 | M46: 0 | N46: =VLOOKUP(C46,NAV!$B$4:$E$44,4,0) -> 10.875212 | O46: =N46+M46-K46 -> -3.1399255 | P46: =(M46+N46)/K46 -> 0.77596185 | Q46: 9.9% GP | Anchorf
J47: =SUM(J42:J46) -> 178.33516 | K47: =SUM(K42:K46) -> 140.8735 | L47: =SUM(L42:L46) -> 15.352483 | M47: =SUM(M42:M46) -> 36.638861 | N47: =SUM(N42:N46) -> 108.15165 | O47: =N47+M47-K47 -> 3.9170112 | P47: =(M47+N47)/K47 -> 1.0278052
...

Sheet S | 02
C2: As of date | D2: =D!D2 -> 45473
E5: 2 | F5: 3 | G5: 4 | H5: 5 | I5: 6 | J5: 7 | K5: 8 | L5: 9 | M5: 11 | N5: 12 | O5: 13 | Q5: 14 | R5: 10 | S5: 15
C6: Deals | D6: Type | E6: Status | F6: Lead | G6: Investing Entity | H6: Vintageἀ | I6: Instrument | J6: % | K6: Committed | L6: Invested | M6: Distributions | N6: Carrying Value | O6: Gain | P6: Gain till FY22 | Q6: TVPI | R6: Remaining Commitment | S6: Additonal Upside/Downside
I7: # | J7: % | K7: $,m | L7: $,m | M7: $,m | N7: $,m | O7: $,m | Q7: X | R7: $,m | V7: MOZN
C8: MOZN Holding RSC Ltd
C9: E-line Ventures LLC | D9: Direct Investment | E9: =VLOOKUP($C9,'S | 01 '!$C$6:$Q$49,E$5,0) -> Unrealized | F9: =VLOOKUP($C9,'S | 01 '!$C$6:$Q$49,F$5,0) -> Sushil | G9: =VLOOKUP($C9,'S | 01 '!$C$6:$Q$49,G$5,0) -> Mozn | H9: =VLOOKUP($C9,'S | 01 '!$C$6:$Q$49,H$5,0) -> 2023 | I9: =VLOOKUP($C9,'S | 01 '!$C$6:$Q$49,I$5,0) -> B Prefs | J9: =VLOOKUP($C9,'S | 01 '!$C$6:$Q$49,J$5,0) -> 0.11483736 | K9: =VLOOKUP($C9,'S | 01 '!$C$6:$Q$49,K$5,0) -> 6 | L9: =VLOOKUP($C9,'S | 01 '!$C$6:$Q$49,L$5,0) -> 6 | ... O9: =VLOOKUP($C9,'S | 01 '!$C$6:$Q$49,O$5,0) -> 0 | P9: n/a | Q9: =VLOOKUP($C9,'S | 01 '!$C$6:$Q$49,Q$5,0) -> 1 | R9: =VLOOKUP($C9,'S | 01 '!$C$6:$Q$49,R$5,0) -> 0 | S9: Optionse
C10: WLD Tokens | D10: Direct Investment | E10: =VLOOKUP($C10,'S | 01 '!$C$6:$Q$49,E$5,0) -> Unrealized | F10: =VLOOKUP($C10,'S | 01 '!$C$6:$Q$49,F$5,0) -> Divyesh | G10: =VLOOKUP($C10,'S | 01 '!$C$6:$Q$49,G$5,0) -> Mozn | H10: =VLOOKUP($C10,'S | 01 '!$C$6:$Q$49,H$5,0) -> 2023 | I10: =VLOOKUP($C10,'S | 01 '!$C$6:$Q$49,I$5,0) -> Tokens | J10: =VLOOKUP($C10,'S | 01 '!$C$6:$Q$49,J$5,0) -> 0.00625 | K10: =VLOOKUP($C10,'S | 01 '!$C$6:$Q$49,K$5,0) -> 0.006875 | L10: =VLOOKUP($C10,'S | 01 '!$C$6:$Q$49,L$5,0) -> 0.006875 | ... O10: =VLOOKUP($C10,'S | 01 '!$C$6:$Q$49,O$5,0) -> 120.18543 | P10: n/a | Q10: =VLOOKUP($C10,'S | 01 '!$C$6:$Q$49,Q$5,0) -> NM | R10: =VLOOKUP($C10,'S | 01 '!$C$6:$Q$49,R$5,0) -> 0
C11: Tools for Humanity Corporation | D11: Direct Investment | E11: =VLOOKUP($C11,'S | 01 '!$C$6:$Q$49,E$5,0) -> Unrealized | F11: =VLOOKUP($C11,'S | 01 '!$C$6:$Q$49,F$5,0) -> Divyesh | G11: =VLOOKUP($C11,'S | 01 '!$C$6:$Q$49,G$5,0) -> Mozn | H11: =VLOOKUP($C11,'S | 01 '!$C$6:$Q$49,H$5,0) -> 2023 | I11: =VLOOKUP($C11,'S | 01 '!$C$6:$Q$49,I$5,0) -> C Prefs | J11: =VLOOKUP($C11,'S | 01 '!$C$6:$Q$49,J$5,0) -> 0.0062621983 | K11: =VLOOKUP($C11,'S | 01 '!$C$6:$Q$49,K$5,0) -> 14.999999 | L11: =VLOOKUP($C11,'S | 01 '!$C$6:$Q$49,L$5,0) -> 14.999999 | ... O11: =VLOOKUP($C11,'S | 01 '!$C$6:$Q$49,O$5,0) -> 0 | P11: n/a | Q11: =VLOOKUP($C11,'S | 01 '!$C$6:$Q$49,Q$5,0) -> 1 | R11: =VLOOKUP($C11,'S | 01 '!$C$6:$Q$49,R$5,0) -> 0
C12: eSpace | D12: Direct Investment | E12: =VLOOKUP($C12,'S | 01 '!$C$6:$Q$49,E$5,0) -> Unrealized | F12: =VLOOKUP($C12,'S | 01 '!$C$6:$Q$49,F$5,0) -> Anton | G12: =VLOOKUP($C12,'S | 01 '!$C$6:$Q$49,G$5,0) -> Mozn 4 | H12: =VLOOKUP($C12,'S | 01 '!$C$6:$Q$49,H$5,0) -> 2022 | I12: =VLOOKUP($C12,'S | 01 '!$C$6:$Q$49,I$5,0) -> B Prefs | J12: =VLOOKUP($C12,'S | 01 '!$C$6:$Q$49,J$5,0) -> 0.027864956 | K12: =VLOOKUP($C12,'S | 01 '!$C$6:$Q$49,K$5,0) -> 15 | L12: =VLOOKUP($C12,'S | 01 '!$C$6:$Q$49,L$5,0) -> 15 | ... O12: =VLOOKUP($C12,'S | 01 '!$C$6:$Q$49,O$5,0) -> 5.8881215 | P12: 0 | Q12: =VLOOKUP($C12,'S | 01 '!$C$6:$Q$49,Q$5,0) -> 1.3925414 | R12: =VLOOKUP($C12,'S | 01 '!$C$6:$Q$49,R$5,0) -> 0 | V12: Invested | W12: =L30 -> 1001.7675
C13: Applied AI Corporation Limited | D13: Direct Investment | E13: =VLOOKUP($C13,'S | 01 '!$C$6:$Q$49,E$5,0) -> Unrealized | F13: =VLOOKUP($C13,'S | 01 '!$C$6:$Q$49,F$5,0) -> Divyesh | G13: =VLOOKUP($C13,'S | 01 '!$C$6:$Q$49,G$5,0) -> Mozn | H13: =VLOOKUP($C13,'S | 01 '!$C$6:$Q$49,H$5,0) -> 2022 | I13: =VLOOKUP($C13,'S | 01 '!$C$6:$Q$49,I$5,0) -> Convertible Note | J13: =VLOOKUP($C13,'S | 01 '!$C$6:$Q$49,J$5,0) -> n/a | K13: =VLOOKUP($C13,'S | 01 '!$C$6:$Q$49,K$5,0) -> 15 | L13: =VLOOKUP($C13,'S | 01 '!$C$6:$Q$49,L$5,0) -> 11.5 | ... O13: =VLOOKUP($C13,'S | 01 '!$C$6:$Q$49,O$5,0) -> 0 | P13: 0 | Q13: =VLOOKUP($C13,'S | 01 '!$C$6:$Q$49,Q$5,0) -> 1 | R13: =VLOOKUP($C13,'S | 01 '!$C$6:$Q$49,R$5,0) -> 3.5 | V13: NAV | W13: =N30 -> 516.03328
C14: X-fusion | D14: Direct Investment | E14: =VLOOKUP($C14,'S | 01 '!$C$6:$Q$49,E$5,0) -> Realized | F14: =VLOOKUP($C14,'S | 01 '!$C$6:$Q$49,F$5,0) -> Elaine | G14: =VLOOKUP($C14,'S | 01 '!$C$6:$Q$49,G$5,0) -> Mozn 2 | H14: =VLOOKUP($C14,'S | 01 '!$C$6:$Q$49,H$5,0) -> 2022 | I14: =VLOOKUP($C14,'S | 01 '!$C$6:$Q$49,I$5,0) -> Equity-TBC | J14: =VLOOKUP($C14,'S | 01 '!$C$6:$Q$49,J$5,0) -> 0.051 | K14: =VLOOKUP($C14,'S | 01 '!$C$6:$Q$49,K$5,0) -> 493.50096 | L14: =VLOOKUP($C14,'S | 01 '!$C$6:$Q$49,L$5,0) -> 493.50096 | ... O14: =VLOOKUP($C14,'S | 01 '!$C$6:$Q$49,O$5,0) -> -90.500956 | P14: -64.391 | Q14: =VLOOKUP($C14,'S | 01 '!$C$6:$Q$49,Q$5,0) -> 0.81661443 | R14: =VLOOKUP($C14,'S | 01 '!$C$6:$Q$49,R$5,0) -> 0 | S14: Full Exit | V14: Gain | W14: =O30 -> -44.821278
C15: Mena Mobile Inc (Debt) | D15: Debt Investment | E15: =VLOOKUP($C15,'S | 01 '!$C$6:$Q$49,E$5,0) -> Written-off | F15: =VLOOKUP($C15,'S | 01 '!$C$6:$Q$49,F$5,0) -> Elaine | G15: =VLOOKUP($C15,'S | 01 '!$C$6:$Q$49,G$5,0) -> Mozn | H15: =VLOOKUP($C15,'S | 01 '!$C$6:$Q$49,H$5,0) -> 2021 | I15: =VLOOKUP($C15,'S | 01 '!$C$6:$Q$49,I$5,0) -> Loan | J15: =VLOOKUP($C15,'S | 01 '!$C$6:$Q$49,J$5,0) -> n/a | K15: =VLOOKUP($C15,'S | 01 '!$C$6:$Q$49,K$5,0) -> 2.353982 | L15: =VLOOKUP($C15,'S | 01 '!$C$6:$Q$49,L$5,0) -> 2.353982 | ... O15: =VLOOKUP($C15,'S | 01 '!$C$6:$Q$49,O$5,0) -> -2.353982 | P15: 0 | Q15: =VLOOKUP($C15,'S | 01 '!$C$6:$Q$49,Q$5,0) -> 0 | R15: =VLOOKUP($C15,'S | 01 '!$C$6:$Q$49,R$5,0) -> 0 | S15: Written Off | V15: YTD Gains | W15: =W14-P30 -> -59.358477
C16: Esyasoft Holding (Debt) | D16: Debt Investment | E16: =VLOOKUP($C16,'S | 01 '!$C$6:$Q$49,E$5,0) -> Realized | F16: =VLOOKUP($C16,'S | 01 '!$C$6:$Q$49,F$5,0) -> Sushil | G16: =VLOOKUP($C16,'S | 01 '!$C$6:$Q$49,G$5,0) -> Mozn | H16: =VLOOKUP($C16,'S | 01 '!$C$6:$Q$49,H$5,0) -> 2021 | I16: =VLOOKUP($C16,'S | 01 '!$C$6:$Q$49,I$5,0) -> Loan | J16: =VLOOKUP($C16,'S | 01 '!$C$6:$Q$49,J$5,0) -> n/a | K16: =VLOOKUP($C16,'S | 01 '!$C$6:$Q$49,K$5,0) -> 0.411765 | L16: =VLOOKUP($C16,'S | 01 '!$C$6:$Q$49,L$5,0) -> 0.411765 | ... O16: =VLOOKUP($C16,'S | 01 '!$C$6:$Q$49,O$5,0) -> 0.05901965 | P16: 0.05901965 | Q16: =VLOOKUP($C16,'S | 01 '!$C$6:$Q$49,Q$5,0) -> 1.1433333 | R16: =VLOOKUP($C16,'S | 01 '!$C$6:$Q$49,R$5,0) -> 0 | S16: Full Exit | V16: IRR | W16: =#REF! -> #REF!
C17: Jysan Technologies | D17: Direct Investment | E17: =VLOOKUP($C17,'S | 01 '!$C$6:$Q$49,E$5,0) -> Realized | F17: =VLOOKUP($C17,'S | 01 '!$C$6:$Q$49,F$5,0) -> Sushil | G17: =VLOOKUP($C17,'S | 01 '!$C$6:$Q$49,G$5,0) -> Mozn 1 | H17: =VLOOKUP($C17,'S | 01 '!$C$6:$Q$49,H$5,0) -> 2021 | I17: =VLOOKUP($C17,'S | 01 '!$C$6:$Q$49,I$5,0) -> A (Ordinary Shares) | J17: =VLOOKUP($C17,'S | 01 '!$C$6:$Q$49,J$5,0) -> 0.03 | K17: =VLOOKUP($C17,'S | 01 '!$C$6:$Q$49,K$5,0) -> 20 | L17: =VLOOKUP($C17,'S | 01 '!$C$6:$Q$49,L$5,0) -> 20 | ... O17: =VLOOKUP($C17,'S | 01 '!$C$6:$Q$49,O$5,0) -> 4.5 | P17: 0 | Q17: =VLOOKUP($C17,'S | 01 '!$C$6:$Q$49,Q$5,0) -> 1.225 | R17: =VLOOKUP($C17,'S | 01 '!$C$6:$Q$49,R$5,0) -> 0 | S17: Full Exit
C18: Instadeep Limited | D18: Direct Investment | E18: =VLOOKUP($C18,'S | 01 '!$C$6:$Q$49,E$5,0) -> Realized | F18: =VLOOKUP($C18,'S | 01 '!$C$6:$Q$49,F$5,0) -> Ignasi | G18: =VLOOKUP($C18,'S | 01 '!$C$6:$Q$49,G$5,0) -> Mozn | H18: =VLOOKUP($C18,'S | 01 '!$C$6:$Q$49,H$5,0) -> 2021 | I18: =VLOOKUP($C18,'S | 01 '!$C$6:$Q$49,I$5,0) -> B Prefs | J18: =VLOOKUP($C18,'S | 01 '!$C$6:$Q$49,J$5,0) -> 0.011489406 | K18: =VLOOKUP($C18,'S | 01 '!$C$6:$Q$49,K$5,0) -> 5.0237202 | L18: =VLOOKUP($C18,'S | 01 '!$C$6:$Q$49,L$5,0) -> 5.0237202 | ... O18: =VLOOKUP($C18,'S | 01 '!$C$6:$Q$49,O$5,0) -> 2.9184723 | P18: 1.6721788 | Q18: =VLOOKUP($C18,'S | 01 '!$C$6:$Q$49,Q$5,0) -> 1.5809385 | R18: =VLOOKUP($C18,'S | 01 '!$C$6:$Q$49,R$5,0) -> 0 | S18: Full Exit
C19: Cerebras Systems Inc | D19: Direct Investment | E19: =VLOOKUP($C19,'S | 01 '!$C$6:$Q$49,E$5,0) -> Unrealized | F19: =VLOOKUP($C19,'S | 01 '!$C$6:$Q$49,F$5,0) -> Ignasi | G19: =VLOOKUP($C19,'S | 01 '!$C$6:$Q$49,G$5,0) -> Mozn | H19: =VLOOKUP($C19,'S | 01 '!$C$6:$Q$49,H$5,0) -> 2021 | I19: =VLOOKUP($C19,'S | 01 '!$C$6:$Q$49,I$5,0) -> F Prefs | J19: =VLOOKUP($C19,'S | 01 '!$C$6:$Q$49,J$5,0) -> 0.0091172068 | K19: =VLOOKUP($C19,'S | 01 '!$C$6:$Q$49,K$5,0) -> 39.999983 | L19: =VLOOKUP($C19,'S | 01 '!$C$6:$Q$49,L$5,0) -> 39.999983 | ... O19: =VLOOKUP($C19,'S | 01 '!$C$6:$Q$49,O$5,0) -> -18.8645 | P19: 0 | Q19: =VLOOKUP($C19,'S | 01 '!$C$6:$Q$49,Q$5,0) -> 0.5283873 | R19: =VLOOKUP($C19,'S | 01 '!$C$6:$Q$49,R$5,0) -> 0
C20: Endless Studios LLC | D20: Direct Investment | E20: =VLOOKUP($C20,'S | 01 '!$C$6:$Q$49,E$5,0) -> Unrealized | F20: =VLOOKUP($C20,'S | 01 '!$C$6:$Q$49,F$5,0) -> Sushil | G20: =VLOOKUP($C20,'S | 01 '!$C$6:$Q$49,G$5,0) -> Mozn | H20: =VLOOKUP($C20,'S | 01 '!$C$6:$Q$49,H$5,0) -> 2021 | I20: =VLOOKUP($C20,'S | 01 '!$C$6:$Q$49,I$5,0) -> A Pref Units | J20: =VLOOKUP($C20,'S | 01 '!$C$6:$Q$49,J$5,0) -> 0.16080402 | K20: =VLOOKUP($C20,'S | 01 '!$C$6:$Q$49,K$5,0) -> 8 | L20: =VLOOKUP($C20,'S | 01 '!$C$6:$Q$49,L$5,0) -> 8 | ... O20: =VLOOKUP($C20,'S | 01 '!$C$6:$Q$49,O$5,0) -> 0 | P20: 0 | Q20: =VLOOKUP($C20,'S | 01 '!$C$6:$Q$49,Q$5,0) -> 1 | R20: =VLOOKUP($C20,'S | 01 '!$C$6:$Q$49,R$5,0) -> 0
C21: Esyasoft Holding | D21: Direct Investment | E21: =VLOOKUP($C21,'S | 01 '!$C$6:$Q$49,E$5,0) -> Realized | F21: =VLOOKUP($C21,'S | 01 '!$C$6:$Q$49,F$5,0) -> Sushil | G21: =VLOOKUP($C21,'S | 01 '!$C$6:$Q$49,G$5,0) -> Mozn | H21: =VLOOKUP($C21,'S | 01 '!$C$6:$Q$49,H$5,0) -> 2020 | I21: =VLOOKUP($C21,'S | 01 '!$C$6:$Q$49,I$5,0) -> Convertible Note | J21: =VLOOKUP($C21,'S | 01 '!$C$6:$Q$49,J$5,0) -> n/a | K21: =VLOOKUP($C21,'S | 01 '!$C$6:$Q$49,K$5,0) -> 2.5 | L21: =VLOOKUP($C21,'S | 01 '!$C$6:$Q$49,L$5,0) -> 2.5 | ... O21: =VLOOKUP($C21,'S | 01 '!$C$6:$Q$49,O$5,0) -> 2.5 | P21: 2.5 | Q21: =VLOOKUP($C21,'S | 01 '!$C$6:$Q$49,Q$5,0) -> 2 | R21: =VLOOKUP($C21,'S | 01 '!$C$6:$Q$49,R$5,0) -> 0 | S21: Full Exit
C22: Heygears | D22: Direct Investment | E22: =VLOOKUP($C22,'S | 01 '!$C$6:$Q$49,E$5,0) -> Unrealized | F22: =VLOOKUP($C22,'S | 01 '!$C$6:$Q$49,F$5,0) -> Elaine | G22: =VLOOKUP($C22,'S | 01 '!$C$6:$Q$49,G$5,0) -> Mozn | H22: =VLOOKUP($C22,'S | 01 '!$C$6:$Q$49,H$5,0) -> 2020 | I22: =VLOOKUP($C22,'S | 01 '!$C$6:$Q$49,I$5,0) -> Registered Capital | J22: =VLOOKUP($C22,'S | 01 '!$C$6:$Q$49,J$5,0) -> 0.1438 | K22: =VLOOKUP($C22,'S | 01 '!$C$6:$Q$49,K$5,0) -> 60 | L22: =VLOOKUP($C22,'S | 01 '!$C$6:$Q$49,L$5,0) -> 60 | ... O22: =VLOOKUP($C22,'S | 01 '!$C$6:$Q$49,O$5,0) -> 89.398592 | P22: 96.4 | Q22: =VLOOKUP($C22,'S | 01 '!$C$6:$Q$49,Q$5,0) -> 2.4899765 | R22: =VLOOKUP($C22,'S | 01 '!$C$6:$Q$49,R$5,0) -> 0
C23: Beyond Limits | D23: Direct Investment | E23: =VLOOKUP($C23,'S | 01 '!$C$6:$Q$49,E$5,0) -> Unrealized | F23: =VLOOKUP($C23,'S | 01 '!$C$6:$Q$49,F$5,0) -> Divyesh | G23: =VLOOKUP($C23,'S | 01 '!$C$6:$Q$49,G$5,0) -> Mozn | H23: =VLOOKUP($C23,'S | 01 '!$C$6:$Q$49,H$5,0) -> 2020 | I23: =VLOOKUP($C23,'S | 01 '!$C$6:$Q$49,I$5,0) -> C Prefs | J23: =VLOOKUP($C23,'S | 01 '!$C$6:$Q$49,J$5,0) -> 0.094347728 | K23: =VLOOKUP($C23,'S | 01 '!$C$6:$Q$49,K$5,0) -> 90 | L23: =VLOOKUP($C23,'S | 01 '!$C$6:$Q$49,L$5,0) -> 90 | ... O23: =VLOOKUP($C23,'S | 01 '!$C$6:$Q$49,O$5,0) -> -16.2 | P23: 1.042 | Q23: =VLOOKUP($C23,'S | 01 '!$C$6:$Q$49,Q$5,0) -> 0.82 | R23: =VLOOKUP($C23,'S | 01 '!$C$6:$Q$49,R$5,0) -> 0
C24: ONT plc | D24: Direct Investment | E24: =VLOOKUP($C24,'S | 01 '!$C$6:$Q$49,E$5,0) -> Unrealized | F24: =VLOOKUP($C24,'S | 01 '!$C$6:$Q$49,F$5,0) -> Divyesh | G24: =VLOOKUP($C24,'S | 01 '!$C$6:$Q$49,G$5,0) -> Mozn | H24: =VLOOKUP($C24,'S | 01 '!$C$6:$Q$49,H$5,0) -> 2020 | I24: =VLOOKUP($C24,'S | 01 '!$C$6:$Q$49,I$5,0) -> Ordinary Shares | J24: =VLOOKUP($C24,'S | 01 '!$C$6:$Q$49,J$5,0) -> 0.051651565 | K24: =VLOOKUP($C24,'S | 01 '!$C$6:$Q$49,K$5,0) -> 141.47026 | L24: =VLOOKUP($C24,'S | 01 '!$C$6:$Q$49,L$5,0) -> 141.47026 | ... O24: =VLOOKUP($C24,'S | 01 '!$C$6:$Q$49,O$5,0) -> -88.470208 | P24: -9.845 | Q24: =VLOOKUP($C24,'S | 01 '!$C$6:$Q$49,Q$5,0) -> 0.37463741 | R24: =VLOOKUP($C24,'S | 01 '!$C$6:$Q$49,R$5,0) -> 0
C25: Flyr Inc | D25: Direct Investment | E25: =VLOOKUP($C25,'S | 01 '!$C$6:$Q$49,E$5,0) -> Unrealized | F25: =VLOOKUP($C25,'S | 01 '!$C$6:$Q$49,F$5,0) -> Sushil | G25: =VLOOKUP($C25,'S | 01 '!$C$6:$Q$49,G$5,0) -> Mozn | H25: =VLOOKUP($C25,'S | 01 '!$C$6:$Q$49,H$5,0) -> 2019 | I25: =VLOOKUP($C25,'S | 01 '!$C$6:$Q$49,I$5,0) -> B-1,2 Prefs | J25: =VLOOKUP($C25,'S | 01 '!$C$6:$Q$49,J$5,0) -> 0.085025485 | K25: =VLOOKUP($C25,'S | 01 '!$C$6:$Q$49,K$5,0) -> 10 | L25: =VLOOKUP($C25,'S | 01 '!$C$6:$Q$49,L$5,0) -> 10 | ... O25: =VLOOKUP($C25,'S | 01 '!$C$6:$Q$49,O$5,0) -> 27.11873 | P25: 68.1 | Q25: =VLOOKUP($C25,'S | 01 '!$C$6:$Q$49,Q$5,0) -> 3.711873 | R25: =VLOOKUP($C25,'S | 01 '!$C$6:$Q$49,R$5,0) -> 0 | S25: Flyr Warrantsa
C26: Mena Mobile Inc | D26: Direct Investment | E26: =VLOOKUP($C26,'S | 01 '!$C$6:$Q$49,E$5,0) -> Written-off | F26: =VLOOKUP($C26,'S | 01 '!$C$6:$Q$49,F$5,0) -> Elaine | G26: =VLOOKUP($C26,'S | 01 '!$C$6:$Q$49,G$5,0) -> Mozn | H26: =VLOOKUP($C26,'S | 01 '!$C$6:$Q$49,H$5,0) -> 2019 | I26: =VLOOKUP($C26,'S | 01 '!$C$6:$Q$49,I$5,0) -> B Prefs | J26: =VLOOKUP($C26,'S | 01 '!$C$6:$Q$49,J$5,0) -> 0.14 | K26: =VLOOKUP($C26,'S | 01 '!$C$6:$Q$49,K$5,0) -> 8 | L26: =VLOOKUP($C26,'S | 01 '!$C$6:$Q$49,L$5,0) -> 8 | ... O26: =VLOOKUP($C26,'S | 01 '!$C$6:$Q$49,O$5,0) -> -8 | P26: -8 | Q26: =VLOOKUP($C26,'S | 01 '!$C$6:$Q$49,Q$5,0) -> 0 | R26: =VLOOKUP($C26,'S | 01 '!$C$6:$Q$49,R$5,0) -> 0 | S26: Written Off
C27: Glass Earth Holdings LLC | D27: Debt Investment | E27: =VLOOKUP($C27,'S | 01 '!$C$6:$Q$49,E$5,0) -> Written-off | F27: =VLOOKUP($C27,'S | 01 '!$C$6:$Q$49,F$5,0) -> Marty | G27: =VLOOKUP($C27,'S | 01 '!$C$6:$Q$49,G$5,0) -> Mozn | H27: =VLOOKUP($C27,'S | 01 '!$C$6:$Q$49,H$5,0) -> 2019 | I27: =VLOOKUP($C27,'S | 01 '!$C$6:$Q$49,I$5,0) -> Promissory Note | J27: =VLOOKUP($C27,'S | 01 '!$C$6:$Q$49,J$5,0) -> n/a | K27: =VLOOKUP($C27,'S | 01 '!$C$6:$Q$49,K$5,0) -> 8 | L27: =VLOOKUP($C27,'S | 01 '!$C$6:$Q$49,L$5,0) -> 8 | ... O27: =VLOOKUP($C27,'S | 01 '!$C$6:$Q$49,O$5,0) -> -8 | P27: -8 | Q27: =VLOOKUP($C27,'S | 01 '!$C$6:$Q$49,Q$5,0) -> 0 | R27: =VLOOKUP($C27,'S | 01 '!$C$6:$Q$49,R$5,0) -> 0 | S27: =VLOOKUP($C27,'S | 01 '!$C$6:$Q$49,S$5,0) -> In Default
C28: Jollychic Holding Limited | D28: Direct Investment | E28: =VLOOKUP($C28,'S | 01 '!$C$6:$Q$49,E$5,0) -> Written-off | F28: =VLOOKUP($C28,'S | 01 '!$C$6:$Q$49,F$5,0) -> Elaine | G28: =VLOOKUP($C28,'S | 01 '!$C$6:$Q$49,G$5,0) -> Mozn | H28: =VLOOKUP($C28,'S | 01 '!$C$6:$Q$49,H$5,0) -> 2019 | I28: =VLOOKUP($C28,'S | 01 '!$C$6:$Q$49,I$5,0) -> C+ Prefs | J28: =VLOOKUP($C28,'S | 01 '!$C$6:$Q$49,J$5,0) -> 0.056999998 | K28: =VLOOKUP($C28,'S | 01 '!$C$6:$Q$49,K$5,0) -> 65 | L28: =VLOOKUP($C28,'S | 01 '!$C$6:$Q$49,L$5,0) -> 65 | ... O28: =VLOOKUP($C28,'S | 01 '!$C$6:$Q$49,O$5,0) -> -65 | P28: -65 | Q28: =VLOOKUP($C28,'S | 01 '!$C$6:$Q$49,Q$5,0) -> 0 | R28: =VLOOKUP($C28,'S | 01 '!$C$6:$Q$49,R$5,0) -> 0 | S28: =VLOOKUP($C28,'S | 01 '!$C$6:$Q$49,S$5,0) -> In Liquidation
K30: =SUM(K9:K28) -> 1005.2675 | L30: =SUM(L9:L28) -> 1001.7675 | M30: =SUM(M9:M28) -> 440.91298 | N30: =SUM(N9:N28) -> 516.03328 | O30: =N30+M30-L30 -> -44.821278 | P30: =SUM(P9:P28) -> 14.537198 | Q30: =(M30+N30)/L30 -> 0.95525781 | R30: =SUM(R9:R28) -> 3.5
C32: G42 Investments AI Holding RSC Ltd
C33: Honor Device Co Ltd | D33: Direct Investment | E33: =VLOOKUP($C33,'S | 01 '!$C$6:$Q$49,E$5,0) -> Realized | F33: =VLOOKUP($C33,'S | 01 '!$C$6:$Q$49,F$5,0) -> Elaine | G33: =VLOOKUP($C33,'S | 01 '!$C$6:$Q$49,G$5,0) -> G42 3 | H33: =VLOOKUP($C33,'S | 01 '!$C$6:$Q$49,H$5,0) -> 2022 | I33: =VLOOKUP($C33,'S | 01 '!$C$6:$Q$49,I$5,0) -> Equity-TBC | J33: =VLOOKUP($C33,'S | 01 '!$C$6:$Q$49,J$5,0) -> 0.018823528 | K33: =VLOOKUP($C33,'S | 01 '!$C$6:$Q$49,K$5,0) -> 800 | L33: =VLOOKUP($C33,'S | 01 '!$C$6:$Q$49,L$5,0) -> 800 | ... O33: =VLOOKUP($C33,'S | 01 '!$C$6:$Q$49,O$5,0) -> 2.8 | P33: 54.67 | Q33: =VLOOKUP($C33,'S | 01 '!$C$6:$Q$49,Q$5,0) -> 1.0035 | R33: =VLOOKUP($C33,'S | 01 '!$C$6:$Q$49,R$5,0) -> 0 | V33: G42
C34: DriveNets | D34: Direct Investment | E34: =VLOOKUP($C34,'S | 01 '!$C$6:$Q$49,E$5,0) -> Unrealized | F34: =VLOOKUP($C34,'S | 01 '!$C$6:$Q$49,F$5,0) -> Anton | G34: =VLOOKUP($C34,'S | 01 '!$C$6:$Q$49,G$5,0) -> G42 | H34: =VLOOKUP($C34,'S | 01 '!$C$6:$Q$49,H$5,0) -> 2022 | I34: =VLOOKUP($C34,'S | 01 '!$C$6:$Q$49,I$5,0) -> Equity-TBC | J34: =VLOOKUP($C34,'S | 01 '!$C$6:$Q$49,J$5,0) -> 0.11141914 | K34: =VLOOKUP($C34,'S | 01 '!$C$6:$Q$49,K$5,0) -> 300 | L34: =VLOOKUP($C34,'S | 01 '!$C$6:$Q$49,L$5,0) -> 300 | ... O34: =VLOOKUP($C34,'S | 01 '!$C$6:$Q$49,O$5,0) -> -95.4 | P34: 0 | Q34: =VLOOKUP($C34,'S | 01 '!$C$6:$Q$49,Q$5,0) -> 0.682 | R34: =VLOOKUP($C34,'S | 01 '!$C$6:$Q$49,R$5,0) -> 0 | S34: DN Warrants b
C35: vTv Therapeutics Inc. | D35: Direct Investment | E35: =VLOOKUP($C35,'S | 01 '!$C$6:$Q$49,E$5,0) -> Unrealized | F35: =VLOOKUP($C35,'S | 01 '!$C$6:$Q$49,F$5,0) -> Divyesh | G35: =VLOOKUP($C35,'S | 01 '!$C$6:$Q$49,G$5,0) -> G42 | H35: =VLOOKUP($C35,'S | 01 '!$C$6:$Q$49,H$5,0) -> 2022 | I35: =VLOOKUP($C35,'S | 01 '!$C$6:$Q$49,I$5,0) -> Ordinary Shares | J35: =VLOOKUP($C35,'S | 01 '!$C$6:$Q$49,J$5,0) -> 0.0021343582 | K35: =VLOOKUP($C35,'S | 01 '!$C$6:$Q$49,K$5,0) -> 24.53125 | L35: =VLOOKUP($C35,'S | 01 '!$C$6:$Q$49,L$5,0) -> 24.53125 | ... O35: =VLOOKUP($C35,'S | 01 '!$C$6:$Q$49,O$5,0) -> -19.945707 | P35: -1.348 | Q35: =VLOOKUP($C35,'S | 01 '!$C$6:$Q$49,Q$5,0) -> 0.18692658 | R35: =VLOOKUP($C35,'S | 01 '!$C$6:$Q$49,R$5,0) -> 0 | S35: vTv $30m milestn payment c | V35: Invested | W35: =L42 -> 1265.4048
C36: North Summit Capital Fund | D36: Fund Investment | E36: =VLOOKUP($C36,'S | 01 '!$C$6:$Q$49,E$5,0) -> Unrealized | F36: =VLOOKUP($C36,'S | 01 '!$C$6:$Q$49,F$5,0) -> Elaine | G36: =VLOOKUP($C36,'S | 01 '!$C$6:$Q$49,G$5,0) -> G42 Investments | H36: =VLOOKUP($C36,'S | 01 '!$C$6:$Q$49,H$5,0) -> 2020 | I36: =VLOOKUP($C36,'S | 01 '!$C$6:$Q$49,I$5,0) -> LP | J36: =VLOOKUP($C36,'S | 01 '!$C$6:$Q$49,J$5,0) -> n/a | K36: =VLOOKUP($C36,'S | 01 '!$C$6:$Q$49,K$5,0) -> 83.63035 | L36: =VLOOKUP($C36,'S | 01 '!$C$6:$Q$49,L$5,0) -> 83.27035 | ... O36: =VLOOKUP($C36,'S | 01 '!$C$6:$Q$49,O$5,0) -> -0.728618 | P36: -0.306 | Q36: =VLOOKUP($C36,'S | 01 '!$C$6:$Q$49,Q$5,0) -> 0.99124997 | R36: =VLOOKUP($C36,'S | 01 '!$C$6:$Q$49,R$5,0) -> 0.36 | V36: NAV | W36: =N42 -> 317.33719
C37: New Space Capital Fund I | D37: Fund Investment | E37: =VLOOKUP($C37,'S | 01 '!$C$6:$Q$49,E$5,0) -> Unrealized | F37: =VLOOKUP($C37,'S | 01 '!$C$6:$Q$49,F$5,0) -> Sushil | G37: =VLOOKUP($C37,'S | 01 '!$C$6:$Q$49,G$5,0) -> G42 Investments | H37: =VLOOKUP($C37,'S | 01 '!$C$6:$Q$49,H$5,0) -> 2020 | I37: =VLOOKUP($C37,'S | 01 '!$C$6:$Q$49,I$5,0) -> LP | J37: =VLOOKUP($C37,'S | 01 '!$C$6:$Q$49,J$5,0) -> n/a | K37: =VLOOKUP($C37,'S | 01 '!$C$6:$Q$49,K$5,0) -> 24.886432 | L37: =VLOOKUP($C37,'S | 01 '!$C$6:$Q$49,L$5,0) -> 15.922439 | ... O37: =VLOOKUP($C37,'S | 01 '!$C$6:$Q$49,O$5,0) -> 6.7719935 | P37: 5.445 | Q37: =VLOOKUP($C37,'S | 01 '!$C$6:$Q$49,Q$5,0) -> 1.4253113 | R37: =VLOOKUP($C37,'S | 01 '!$C$6:$Q$49,R$5,0) -> 11.89512 | V37: Gain | W37: =O42 -> -108.6287
C38: New Space Capital GP Com SCSp | D38: Fund Investment | E38: =VLOOKUP($C38,'S | 01 '!$C$6:$Q$49,E$5,0) -> Unrealized | F38: =VLOOKUP($C38,'S | 01 '!$C$6:$Q$49,F$5,0) -> Sushil | G38: =VLOOKUP($C38,'S | 01 '!$C$6:$Q$49,G$5,0) -> G42 Investments | H38: =VLOOKUP($C38,'S | 01 '!$C$6:$Q$49,H$5,0) -> 2023 | I38: =VLOOKUP($C38,'S | 01 '!$C$6:$Q$49,I$5,0) -> LP | J38: =VLOOKUP($C38,'S | 01 '!$C$6:$Q$49,J$5,0) -> n/a | K38: =VLOOKUP($C38,'S | 01 '!$C$6:$Q$49,K$5,0) -> 2.7058824 | L38: =VLOOKUP($C38,'S | 01 '!$C$6:$Q$49,L$5,0) -> 2.7058824 | ... O38: =VLOOKUP($C38,'S | 01 '!$C$6:$Q$49,O$5,0) -> 0.56973286 | P38: 0 | Q38: =VLOOKUP($C38,'S | 01 '!$C$6:$Q$49,Q$5,0) -> 1.2105534 | R38: =VLOOKUP($C38,'S | 01 '!$C$6:$Q$49,R$5,0) -> 0 | V38: YTD Gains | W38: =O42-P42 -> -165.5187
C39: Sinovation Disrupt Fund, L.P. | D39: Fund Investment | E39: =VLOOKUP($C39,'S | 01 '!$C$6:$Q$49,E$5,0) -> Realized | F39: =VLOOKUP($C39,'S | 01 '!$C$6:$Q$49,F$5,0) -> Elaine | G39: =VLOOKUP($C39,'S | 01 '!$C$6:$Q$49,G$5,0) -> G42 Investments | H39: =VLOOKUP($C39,'S | 01 '!$C$6:$Q$49,H$5,0) -> 2020 | I39: =VLOOKUP($C39,'S | 01 '!$C$6:$Q$49,I$5,0) -> LP | J39: =VLOOKUP($C39,'S | 01 '!$C$6:$Q$49,J$5,0) -> n/a | K39: =VLOOKUP($C39,'S | 01 '!$C$6:$Q$49,K$5,0) -> 50 | L39: =VLOOKUP($C39,'S | 01 '!$C$6:$Q$49,L$5,0) -> 24.959693 | ... O39: =VLOOKUP($C39,'S | 01 '!$C$6:$Q$49,O$5,0) -> 0.44382835 | P39: -1.265 | Q39: =VLOOKUP($C39,'S | 01 '!$C$6:$Q$49,Q$5,0) -> 1.0177818 | R39: =VLOOKUP($C39,'S | 01 '!$C$6:$Q$49,R$5,0) -> 0 | V39: IRR | W39: =#REF! -> #REF!
C40: Acies Investments Fund I, L.P. | D40: Fund Investment | E40: =VLOOKUP($C40,'S | 01 '!$C$6:$Q$49,E$5,0) -> Unrealized | F40: =VLOOKUP($C40,'S | 01 '!$C$6:$Q$49,F$5,0) -> Divyesh | G40: =VLOOKUP($C40,'S | 01 '!$C$6:$Q$49,G$5,0) -> G42 Investments | H40: =VLOOKUP($C40,'S | 01 '!$C$6:$Q$49,H$5,0) -> 2021 | I40: =VLOOKUP($C40,'S | 01 '!$C$6:$Q$49,I$5,0) -> LP | J40: =VLOOKUP($C40,'S | 01 '!$C$6:$Q$49,J$5,0) -> 0.33 | K40: =VLOOKUP($C40,'S | 01 '!$C$6:$Q$49,K$5,0) -> 17.1125 | L40: =VLOOKUP($C40,'S | 01 '!$C$6:$Q$49,L$5,0) -> 14.015137 | ... O40: =VLOOKUP($C40,'S | 01 '!$C$6:$Q$49,O$5,0) -> -3.1399255 | P40: -0.306 | Q40: =VLOOKUP($C40,'S | 01 '!$C$6:$Q$49,Q$5,0) -> 0.77596185 | R40: =VLOOKUP($C40,'S | 01 '!$C$6:$Q$49,R$5,0) -> 3.0973625 | S40: 9.9% GP | Anchorf
V41: =O30-P30 -> -59.358477
K42: =SUM(K33:K40) -> 1302.8664 | L42: =SUM(L33:L40) -> 1265.4048 | M42: =SUM(M33:M40) -> 839.43886 | N42: =SUM(N33:N40) -> 317.33719 | O42: =N42+M42-L42 -> -108.6287 | P42: =SUM(P33:P40) -> 56.89 | Q42: =(M42+N42)/L42 -> 0.91415498 | R42: =SUM(R33:R40) -> 15.352483 | S42: =N42+M42-L42 -> -108.6287 | V42: =K42-L42 -> 37.461663
V43: =O42-P42 -> -165.5187
C44: G42 Capital SPV RSC Ltd
C45: Life Biosciences LLC | D45: Direct Investment | E45: =VLOOKUP($C45,'S | 01 '!$C$6:$Q$49,E$5,0) -> Unrealized | F45: =VLOOKUP($C45,'S | 01 '!$C$6:$Q$49,F$5,0) -> Divyesh | G45: =VLOOKUP($C45,'S | 01 '!$C$6:$Q$49,G$5,0) -> G42 Capital | H45: =VLOOKUP($C45,'S | 01 '!$C$6:$Q$49,H$5,0) -> 2024 | I45: =VLOOKUP($C45,'S | 01 '!$C$6:$Q$49,I$5,0) -> Convertible Note | J45: =VLOOKUP($C45,'S | 01 '!$C$6:$Q$49,J$5,0) -> n/a | K45: =VLOOKUP($C45,'S | 01 '!$C$6:$Q$49,K$5,0) -> 20 | L45: =VLOOKUP($C45,'S | 01 '!$C$6:$Q$49,L$5,0) -> 20 | ... O45: =VLOOKUP($C45,'S | 01 '!$C$6:$Q$49,O$5,0) -> 0 | P45: 0 | Q45: =VLOOKUP($C45,'S | 01 '!$C$6:$Q$49,Q$5,0) -> 1 | R45: =VLOOKUP($C45,'S | 01 '!$C$6:$Q$49,R$5,0) -> 0
...

Sheet S | 03
C2: As of date | D2: ='S | 01 '!D2 -> 45473
P3: n/a refers to information not available
C6: Deals | D6: Status | E6: Lead | F6: Investing Entity | G6: Investing Entity (Legal Entity Name) | H6: Nature of Investing Entity | I6: Investments Tax Implication tax note 1 | J6: Instrument | K6: Listed / Unlisted | L6: Website link | M6: Pitchbook link | N6: Jurisdiction | O6: % | P6: Upside (Warrants, Milestone payments, ) | Q6: For Comments Refer to Note
C8: Direct Investments
C9: Jollychic Holding Limited | D9: Written-off | E9: Elaine | F9: Mozn | G9: Mozn Holding RSC Ltd | H9: Potential QFZP tax note 2 | I9: If qualifies for QFZP and hold the investment >= 12m, income/loss from the investee supposed to suject to 0% Corporate tax rate for Investing Entity | J9: C+ Prefs | L9: link | M9: link | N9: Cayman Islands | O9: 0.056999998 | Q9: 1
C10: Mena Mobile Inc | D10: Unrealized | E10: Elaine | F10: Mozn | G10: Mozn Holding RSC Ltd | H10: Potential QFZP tax note 2 | I10: If qualifies for QFZP and hold the investment >= 12m, income/loss from the investee supposed to suject to 0% Corporate tax rate for Investing Entity | J10: B Prefs | L10: link | M10: link | N10: Cayman Islands | O10: 0.14 | Q10: 2
C11: Flyr Inc | D11: Unrealized | E11: Sushil | F11: Mozn | G11: Mozn Holding RSC Ltd | H11: Potential QFZP tax note 2 | I11: If qualifies for QFZP and hold the investment >= 12m, income/loss from the investee supposed to suject to 0% Corporate tax rate for Investing Entity | J11: B-1,2 Prefs | L11: link | M11: link | N11: Delaware Corporation | O11: 0.085025485 | P11: Flyr Warrantsa | Q11: 3
C12: Esyasoft Holding | D12: Realized | E12: Sushil | F12: Mozn | G12: Mozn Holding RSC Ltd | H12: Potential QFZP tax note 2 | I12: If qualifies for QFZP and hold the investment >= 12m, income/loss from the investee supposed to suject to 0% Corporate tax rate for Investing Entity | J12: Convertible Note | L12: link | M12: n/a | N12: DIFC | O12: n/a | Q12: 4
C13: Beyond Limits | D13: Unrealized | E13: Divyesh | F13: Mozn | G13: Mozn Holding RSC Ltd | H13: Potential QFZP tax note 2 | I13: If qualifies for QFZP and hold the investment >= 12m, income/loss from the investee supposed to suject to 0% Corporate tax rate for Investing Entity | J13: C Prefs | L13: link | M13: link | N13: Delaware Corporation | O13: 0.097965107 | Q13: 5
C14: ONT plc | D14: Unrealized | E14: Divyesh | F14: Mozn | G14: Mozn Holding RSC Ltd | H14: Potential QFZP tax note 2 | I14: If qualifies for QFZP and hold the investment >= 12m, income/loss from the investee supposed to suject to 0% Corporate tax rate for Investing Entity | J14: Ordinary Shares | K14: Listed | L14: link | M14: link | N14: UK | O14: 0.051651565 | Q14: 6
C15: Heygears | D15: Unrealized | E15: Elaine | F15: Mozn | G15: Mozn Holding RSC Ltd | H15: Potential QFZP tax note 2 | I15: If qualifies for QFZP and hold the investment >= 12m, income/loss from the investee supposed to suject to 0% Corporate tax rate for Investing Entity | J15: Registered Capital | L15: link | M15: link | N15: PRC | O15: 0.1438 | Q15: 7
C16: Jysan Technologies | D16: Realized | E16: Sushil | F16: Mozn aa | G16: QAZ42 Investment SPV RSC Ltd | H16: Realized | I16: Realized | J16: A (Ordinary Shares) | L16: link | M16: n/a | N16: UK | O16: 0.03 | Q16: 8
C17: Cerebras Systems Inc | D17: Unrealized | E17: Ignasi | F17: Mozn | G17: Mozn Holding RSC Ltd | H17: Potential QFZP tax note 2 | I17: If qualifies for QFZP and hold the investment >= 12m, income/loss from the investee supposed to suject to 0% Corporate tax rate for Investing Entity | J17: F Prefs | L17: link | M17: link | N17: Delaware Corporation | O17: 0.0091172068 | Q17: 9
C18: Endless Studios LLC | D18: Unrealized | E18: Sushil | F18: Mozn | G18: Mozn Holding RSC Ltd | H18: Potential QFZP tax note 2 | I18: To be monitored (see Note 0) | J18: A Pref Units | L18: link | M18: link | N18: Delaware Corporation | O18: 0.16080402 | Q18: 10
C19: Instadeep Limited | D19: Realized | E19: Ignasi | F19: Mozn | G19: Mozn Holding RSC Ltd | H19: Potential QFZP tax note 2 | I19: If qualifies for QFZP and hold the investment >= 12m, income/loss from the investee supposed to suject to 0% Corporate tax rate for Investing Entity | J19: B Prefs | L19: link | M19: link | N19: UK | O19: 0.011489406 | Q19: 11
C20: X-fusion | D20: Realized | E20: Elaine | F20: Mozn bb | G20: Enterprise Connection Holding RSC Ltd | H20: Non-QFZP | I20: pending | J20: Equity-TBC | L20: link | M20: link | N20: PRC | O20: 0.051 | Q20: 12
C21: DriveNets | D21: Unrealized | E21: Anton | F21: G42 | G21: D2 Investments RSC Ltd | H21: Non-QFZP | I21: Should qualify for Participation interest | J21: Equity-TBC | L21: link | M21: link | N21: Israeli Pvt Company | O21: 0.11141914 | P21: DN Warrants b | Q21: 13
C22: vTv Therapeutics Inc. | D22: Unrealized | E22: Divyesh | F22: G42 | G22: G42 Investments AI Holdings RSC Ltd | H22: Potential QFZP tax note 2 | I22: To be monitored (see Note 0) | J22: Ordinary Shares | K22: Listed | L22: link | M22: link | N22: Delaware Corporation | O22: 0.0022129091 | P22: vTv $30m milestn payment c | Q22: 14
C23: Honor Device Co Ltd | D23: Realized | E23: Elaine | F23: G42 cc | G23: Smart Interaction1 Holding SPV RSC LTD | H23: pending | I23: pending | J23: Equity-TBC | L23: link | M23: link | N23: PRC | O23: 0.018823528 | Q23: 15
C24: Applied AI Corporation Limited | D24: Unrealized | E24: Divyesh | F24: Mozn | G24: Mozn Holding RSC Ltd | H24: Potential QFZP tax note 2 | I24: To be monitored (see Note 0) | J24: Convertible Note | L24: link | M24: link | N24: ADGM | O24: n/a | Q24: 16
C25: eSpace | D25: Unrealized | E25: Anton | F25: Mozn dd | G25: Constellation Investments SPV RSC Ltd (previously Smart Interaction5 Holding SPV RSC Ltd) | H25: Non-QFZP | I25: Taxable for only hold 2.8% of SAFE note in eSpace. | J25: B Prefs | L25: link | M25: link | N25: Delaware Corporation | O25: 0.027864956 | Q25: 17
C26: Tools for Humanity Corporation | D26: Unrealized | E26: Divyesh | F26: Mozn | G26: Mozn Holding RSC Ltd | H26: Potential QFZP tax note 2 | I26: To be monitored (see Note 0) | J26: C Prefs | L26: link | M26: link | N26: Delaware Corporation | O26: 0.0062621983 | Q26: 24
C27: WLD Tokens | D27: Unrealized | E27: Divyesh | F27: Mozn | G27: Mozn Holding RSC Ltd | H27: Potential QFZP tax note 2 | I27: To be monitored (see Note 0) | J27: Tokens | L27: link | M27: Coinbase | N27: DAO | Cayman Islands | O27: 0.00625 | Q27: 25 | T27: Preferred Shares
C28: E-line Ventures LLC | D28: Unrealized | E28: Sushil | F28: Mozn | G28: Mozn Holding RSC Ltd | H28: Potential QFZP tax note 2 | I28: To be monitored (see Note 0) | J28: B Prefs | L28: link | M28: link | N28: New Jersey, USA | O28: ='6. %'!F28 -> 0.11483736 | Q28: 26 | T28: B Prefs
C29: School Hack (AIREV Holding Limited) | D29: Unrealized | E29: Camillo | F29: Core42 | G29: Core42 Investments 1 SPV RSC LTD | H29: Potential QFZP tax note 2 | I29: To be monitored (see Note 0) | J29: Preferred Shares | L29: link | M29: NA | N29: ADGM | O29: 0.25 | Q29: 27
C30: Life Biosciences LLC | D30: Unrealized | E30: Divyesh | F30: ='S | 01 '!F30 -> G42 Capital | G30: Expansion Project Technologies Holding 7 SPV RSC Ltd | H30: Potential QFZP tax note 2 | I30: To be monitored (see Note 0) | J30: Convertible Note | L30: link | M30: link | N30: Delaware Corporation | O30: n/a | Q30: 28
C31: Verses AI Inc | D31: Unrealized | E31: Divyesh | F31: ='S | 01 '!F31 -> G42 Capital | G31: Expansion Project Technologies Holding 8 SPV RSC Ltd | H31: Potential QFZP tax note 2 | I31: To be monitored (see Note 0) | J31: Convertible Debenture | L31: link | M31: link | N31: British Columbia | O31: n/a
C35: Debt Investments
C36: Glass Earth Holdings LLC | D36: In default | F36: Mozn | G36: G42 Investments AI Holdings RSC Ltd | H36: Potential QFZP tax note 2 | I36: not equity investment, taxable | J36: Promissory Note | L36: n/a | M36: n/a | N36: n/a | Q36: 16
C37: Mena Mobile Inc (Debt) | D37: In default | E37: Elaine | F37: Mozn | G37: Mozn Holding RSC Ltd | H37: Potential QFZP tax note 2 | I37: not equity investment, taxable | J37: Loan | L37: link | M37: link | N37: =N10 -> Cayman Islands | Q37: 17
C38: Esyasoft Holding (Debt) | D38: Unrealized | E38: Sushil | F38: Mozn | G38: Mozn Holding RSC Ltd | H38: Potential QFZP tax note 2 | I38: not equity investment, taxable | J38: Loan | L38: link | M38: n/a | N38: =N12 -> DIFC | Q38: 18
C41: Funds Investments
C42: New Space Capital Fund I | D42: Unrealized | E42: Sushil | F42: G42 | G42: G42 Investments AI Holdings RSC Ltd | H42: Potential QFZP tax note 2 | I42: If qualifies for QFZP and hold the investment >= 12m, income/loss from the investee supposed to suject to 0% Corporate tax rate for Investing Entity | J42: LP | L42: link | M42: link | N42: Luxembourg | O42: 0.22044082 | Q42: 19
C43: New Space Capital GP Com SCSp | D43: Unrealized | E43: Sushil | F43: G42 | G43: G42 Investments AI Holdings RSC Ltd | H43: Potential QFZP tax note 2 | I43: If qualifies for QFZP and hold the investment >= 12m, income/loss from the investee supposed to suject to 0% Corporate tax rate for Investing Entity | J43: GP | L43: link | M43: link | N43: Luxembourg | O43: 0.02016129 | Q43: 20
C44: North Summit Capital Fund | D44: Unrealized | E44: Elaine | F44: G42 | G44: Galbot Holding RSC Ltd | H44: Non-QFZP | I44: pending | J44: LP | L44: n/a | M44: link | N44: Cayman Islands | O44: 0.995 | Q44: 21
C45: Sinovation Disrupt Fund, L.P. | D45: Unrealized | E45: Elaine | F45: G42 | G45: G42 Investments AI Holdings RSC Ltd | H45: Potential QFZP tax note 2 | I45: If qualifies for QFZP and hold the investment >= 12m, income/loss from the investee supposed to suject to 0% Corporate tax rate for Investing Entity | J45: LP | L45: link | M45: link | N45: Cayman Islands | O45: 0.1006609 | Q45: 22
C46: Acies Investments Fund I, L.P. | D46: Unrealized | E46: Divyesh | F46: G42 | G46: G42 Investments AI Holdings RSC Ltd | H46: Potential QFZP tax note 2 | I46: If qualifies for QFZP and hold the investment >= 12m, income/loss from the investee supposed to suject to 0% Corporate tax rate for Investing Entity | J46: LP | L46: link | M46: link | N46: Delaware LLC | O46: 0.33333333 | P46: 9.9% GP | Anchor e | Q46: 23
B50: Notes:
B51: 0 | C51: General | D51: If qualifies for QFZP and hold the investment >= 12m, income/loss from the investee supposed to suject to 0% Corporate tax rate for Investing Entity. Currently we have the contribution made in June 2023 need to be monitored
B52: 1 | C52: Jollychic | D52: During 2021, Jollychic Holding Ltd has filed for its liquidation. Therefore, investment is considered to be fully impaired in Dec 21.
...

Sheet NAV
B2: NAV Date | C2: ='S | 01 '!D2 -> 45473
B5: Investments | C5: Investing Entity | D5: Instrument | E5: Carrying Value | F5: Current Shares/Units | H5: Comment | J5: Date of Update | K5: 14 Apr 2024
E6: USD, Million | F6: # | G6: USD | J6: N A V R E P O R T I N G M A R 2 0 2 4 | N6: A R D E N T E S T I M A T E S M A R 2 0 2 4
E7: ="NAV | "& TEXT(C2,"dd")&" "&TEXT(C2,"mmm")&" "&TEXT(C2,"yyyy") -> NAV | 30 Jun 2024 | G7: ="PPS |" & TEXT(C2,"dd")&" "&TEXT(C2,"mmm")&" "&TEXT(C2,"yyyy") -> PPS |30 Jun 2024 | J7: Name | K7: Carrying Value, Reporting Feb 23 | L7: Carrying Value, Revised Mar 23 | M7: Delta | N7: Carrying Value as per Ardent (as of Dec 23) | O7: Low | P7: High | Q7: Average | R7: Change | S7: Rationale for Price Change
B9: Direct Investments | J9: Drive Nets | K9: 300 | L9: =Q9 -> 204.6 | M9: =L9-K9 -> -95.4 | N9: 300 | O9: 187.6 | P9: 221.6 | Q9: =AVERAGE(O9:P9) -> 204.6 | R9: =Q9-N9 -> -95.4 | S9: marked down
B10: ='S | 01 '!C9 -> Jollychic Holding Limited | C10: ='S | 01 '!F9 -> Mozn | D10: ='S | 01 '!H9 -> C+ Prefs | E10: =F10*G10*10^-6 -> 0 | F10: =VLOOKUP(B10,'6. %'!$C$6:$I$40,2,0) -> 13458655 | H10: In liquidation | J10: Flyr | K10: 78.1 | L10: =Q10 -> 62.9 | M10: =L10-K10 -> -15.2 | N10: 80.3 | O10: 56.9 | P10: 68.9 | Q10: =AVERAGE(O10:P10) -> 62.9 | R10: =Q10-N10 -> -17.4 | S10: marked down
B11: ='S | 01 '!C10 -> Mena Mobile Inc | C11: ='S | 01 '!F10 -> Mozn | D11: ='S | 01 '!H10 -> B Prefs | E11: 0 | F11: =VLOOKUP(B11,'6. %'!$C$6:$I$40,2,0) -> 21419829 | H11: As per 3rd Party | Ardent Estimates | Equity written off | J11: Beyond Limits | K11: 91 | L11: =Q11 -> 73.8 | M11: =L11-K11 -> -17.2 | N11: 102.1 | O11: 66.2 | P11: 81.4 | Q11: =AVERAGE(O11:P11) -> 73.8 | R11: =Q11-N11 -> -28.3 | S11: marked down
B12: ='S | 01 '!C11 -> Flyr Inc | C12: ='S | 01 '!F11 -> Mozn | D12: ='S | 01 '!H11 -> B-1,2 Prefs | E12: =F12*G12*10^-6 -> 37.11873 | F12: =VLOOKUP(B12,'6. %'!$C$6:$I$40,2,0) -> 5205482 | G12: 7.1307 | H12: As per the recent fund raise completed in Dec 23 | J12: Worldcoin | K12: 15 | L12: =Q12 -> 161.9 | M12: =L12-K12 -> 146.9 | N12: =5.9*10^-3 -> 0.0059 | Q12: 161.9 | R12: =Q12-N12 -> 161.8941 | S12: marked up
B13: ='S | 01 '!C12 -> Esyasoft Holding | C13: ='S | 01 '!F12 -> Mozn | D13: ='S | 01 '!H12 -> Convertible Note | E13: 0 | F13: =VLOOKUP(B13,'6. %'!$C$6:$I$40,2,0) -> n/a | H13: Exited at $5m (10th May) | Residual value = 0
B14: ='S | 01 '!C13 -> Beyond Limits | C14: ='S | 01 '!F13 -> Mozn | D14: ='S | 01 '!H13 -> C Prefs | E14: =L11 -> 73.8 | F14: =VLOOKUP(B14,'6. %'!$C$6:$I$40,2,0) -> 17670202 | G14: 5.15 | H14: Marked down as per Ardent Estimates as of Dec 23
B15: ='S | 01 '!C14 -> ONT plc | C15: ='S | 01 '!F14 -> Mozn | D15: ='S | 01 '!H14 -> Ordinary Shares | E15: =F15*G15*10^-6 -> 53.000051 | F15: =VLOOKUP(B15,'6. %'!$C$6:$I$40,2,0) -> 44328120 | G15: =K18*K20 -> 1.1956305 | H15: Listed & marked to market
B16: ='S | 01 '!C15 -> Heygears | C16: ='S | 01 '!F15 -> Mozn | D16: ='S | 01 '!H15 -> Registered Capital | E16: =K34/1000000 -> 149.39859 | F16: ='CF (Equity, Debt)'!J20 -> 3565017.2 | H16: Adjusted for currency. Valued at the recent round | J16: Updated as on: | K16: =C2 -> 45473
B17: ='S | 01 '!C16 -> Jysan Technologies | C17: ='S | 01 '!F16 -> Mozn 1 | D17: ='S | 01 '!H16 -> A (Ordinary Shares) | E17: 0 | F17: =VLOOKUP(B17,'6. %'!$C$6:$I$40,2,0) -> 7959497 | G17: =E17*10^6/F17 -> 0 | H17: Exited at $24.5m | L17: source
B18: ='S | 01 '!C17 -> Cerebras Systems Inc | C18: ='S | 01 '!F17 -> Mozn | D18: ='S | 01 '!H17 -> F Prefs | E18: =F18*G18*10^-6 -> 21.135483 | F18: =VLOOKUP(B18,'6. %'!$C$6:$I$40,2,0) -> 1441711 | G18: 14.66 | H18: Held at cost | J18: ONT Share price | K18: 0.946 | L18: link
B19: ='S | 01 '!C18 -> Endless Studios LLC | C19: ='S | 01 '!F18 -> Mozn | D19: ='S | 01 '!H18 -> A Pref Units | E19: =-'CF (Equity, Debt)'!E23-'CF (Equity, Debt)'!E41 -> 8 | F19: =VLOOKUP(B19,'6. %'!$C$6:$I$40,2,0) -> 8000000 | H19: Held at cost | J19: VTVT Share price | K19: 17.66 | L19: link
B20: ='S | 01 '!C19 -> Instadeep Limited | C20: ='S | 01 '!F19 -> Mozn | D20: ='S | 01 '!H19 -> B Prefs | E20: =-'CF (Equity, Debt)'!E24*G20 -> 0 | F20: =VLOOKUP(B20,'6. %'!$C$6:$I$40,2,0) -> 33267 | G20: 0 | H20: Exited at 1.56X | Residual Value = 0 | J20: GBP USD | K20: 1.26388 | L20: xe.com
B21: ='S | 01 '!C20 -> X-fusion | C21: ='S | 01 '!F20 -> Mozn 2 | D21: ='S | 01 '!H20 -> Equity-TBC | E21: 0 | F21: =VLOOKUP(B21,'6. %'!$C$6:$I$40,2,0) -> n/a | H21: Exited at 0.82X | J21: EUR USD | K21: 1.0711 | L21: xe.com
B22: ='S | 01 '!C21 -> DriveNets | C22: ='S | 01 '!F21 -> G42 | D22: ='S | 01 '!H21 -> Equity-TBC | E22: =L9 -> 204.6 | F22: =VLOOKUP(B22,'6. %'!$C$6:$I$40,2,0) -> 86882669 | H22: Held at cost
B23: ='S | 01 '!C22 -> vTv Therapeutics Inc. | C23: ='S | 01 '!F22 -> G42 | D23: ='S | 01 '!H22 -> Ordinary Shares | E23: =(F23*G23)*10^-6 -> 4.5855426 | F23: =VLOOKUP(B23,'6. %'!$C$6:$I$40,2,0) -> 259657 | G23: =K19 -> 17.66 | H23: Listed & marked to market
B24: ='S | 01 '!C23 -> Honor Device Co Ltd | C24: ='S | 01 '!F23 -> G42 3 | D24: ='S | 01 '!H23 -> Equity-TBC | E24: 0 | F24: =VLOOKUP(B24,'6. %'!$C$6:$I$40,2,0) -> 6.0685078e+08 | H24: Exited at 1.0X | J24: Heygears Oct 22
B25: ='S | 01 '!C24 -> Applied AI Corporation Limited | C25: ='S | 01 '!F24 -> Mozn | D25: ='S | 01 '!H24 -> Convertible Note | E25: =-'CF (Equity, Debt)'!E32-'CF (Equity, Debt)'!E38-'CF (Equity, Debt)'!E47 -> 11.5 | F25: =VLOOKUP(B25,'6. %'!$C$6:$I$40,2,0) -> n/a | H25: Held at cost | J25: USD RMB | K25: 7.22055 | L25: xe.com
B26: ='S | 01 '!C25 -> eSpace | C26: ='S | 01 '!F25 -> Mozn 4 | D26: ='S | 01 '!H25 -> B Prefs | E26: =F26*G26*10^-6 -> 20.888122 | F26: =VLOOKUP(B26,'6. %'!$C$6:$I$40,2,0) -> 417846 | G26: 49.99 | H26: Marked up, as converted as per the latest priced round | J26: Post Valuation closed in June 2021 (RMB) | K26: 7500000000
B27: ='S | 01 '!C26 -> Tools for Humanity Corporation | C27: ='S | 01 '!F26 -> Mozn | D27: ='S | 01 '!H26 -> C Prefs | E27: ='S | 01 '!K26 -> 14.999999 | F27: =VLOOKUP(B27,'6. %'!$C$6:$I$40,2,0) -> 65413 | H27: Held at cost | J27: G42 Stake | K27: 0.143832
B28: ='S | 01 '!C27 -> WLD Tokens | C28: ='S | 01 '!F27 -> Mozn | D28: ='S | 01 '!H27 -> Tokens | E28: =F28*G28*10^-6 -> 120.19231 | F28: =VLOOKUP(B28,'6. %'!$C$6:$I$40,2,0) -> 62500000 | G28: =50/26 -> 1.9230769 | H28: Tokens valued at $50m/26m (Inveniam), $2.59 (Ardent) | J28: G42 Valuation before Discount (RMB) | K28: 1078740000
B29: ='S | 01 '!C28 -> E-line Ventures LLC | C29: ='S | 01 '!F28 -> Mozn | D29: ='S | 01 '!H28 -> B Prefs | E29: =MAX('S | 01 '!K28,F29*G29*10^-6) -> 6 | F29: =VLOOKUP(B29,'6. %'!$C$6:$I$40,2,0) -> 4477612 | H29: Held at cost | J29: Liquidity Discount | K29: 0
B30: ='S | 01 '!C29 -> School Hack (AIREV Holding Limited) | C30: ='S | 01 '!F29 -> Core42 5 | D30: ='S | 01 '!H29 -> Preferred Shares | E30: =MAX('S | 01 '!K29,F30*G30*10^-6) -> 2.5 | F30: =VLOOKUP(B30,'6. %'!$C$6:$I$40,2,0) -> 25000 | H30: Held at cost | J30: Minority Holding Discount | K30: 0
B31: ='S | 01 '!C30 -> Life Biosciences LLC | C31: ='S | 01 '!F30 -> G42 Capital | D31: ='S | 01 '!H30 -> Convertible Note | E31: =-'CF (Equity, Debt)'!E49 -> 20 | F31: =VLOOKUP(B31,'6. %'!$C$6:$I$40,2,0) -> n/a | H31: Held at cost | J31: G42 Valuation (RMB) | K31: =K28*(1-K29)*(1-K30) -> 1078740000
B32: ='S | 01 '!C31 -> Verses AI Inc | C32: ='S | 01 '!F31 -> G42 Capital | D32: ='S | 01 '!H31 -> Convertible Debenture | E32: =-'CF (Equity, Debt)'!E50 -> 10 | F32: =VLOOKUP(B32,'6. %'!$C$6:$I$40,2,0) -> n/a | H32: Held at cost
J33: Exchange Rate (RMB/USD) | K33: =K25 -> 7.22055
B34: Debt Investments | J34: G42 Valuation (USD) | K34: =K31/K33 -> 1.4939859e+08
B35: Glass Earth Holdings LLC | C35: Mozn | D35: Promissory Note | E35: ='S | 01 '!N36 -> 0 | H35: In default | J35: Investment Cost of G42 (USD) | K35: 60000000
B36: Mena Mobile Inc (Debt) | C36: Mozn | D36: Loan | E36: 0 | H36: In liquidation | J36: Investment Multiple | K36: 1.9039182
B37: Esyasoft Holding (Debt) | C37: Mozn | D37: Loan | E37: 0 | H37: Exited. Received payment of $470,784.65 ($411K+$59K)
B39: Funds Investments | J39: Checks
B40: New Space Capital Fund I | C40: G42 | D40: LP | E40: ='8. NewSpace'!H38*10^-6*K21-'CF (Funds)'!F49 -> 19.274963 | H40: Q3'23 capital account statement
B41: New Space Capital GP Com SCSp | C41: G42 | D41: GP | E41: =E40*'S | 02'!L38/'S | 02'!L37 -> 3.2756152 | H41: Q3'23 pro-rated | J41: =SUM(E10:E32) -> 757.71883 | K41: =J41='S | 01 '!N33 -> TRUE
B42: North Summit Capital Fund | C42: G42 | D42: LP | E42: =81.513771 -'CF (Funds)'!F36 -> 74.725861 | H42: Q3'23 capital account statement | J42: =SUM(E35:E37) -> 0 | K42: =J42='S | 01 '!N39 -> TRUE
B43: Sinovation Disrupt Fund, L.P. | C43: G42 | D43: LP | E43: 0 | H43: Exited | J43: =SUM(E40:E44) -> 108.15165 | K43: =J43='S | 01 '!N47 -> TRUE
B44: Acies Investments Fund I, L.P. | C44: G42 | D44: LP | E44: 10.875212 | H44: Q1'24 capital account statement
B45: Note:
...

Sheet CF (Equity, Debt)
B2: E Q U I T Y
B3: Accounting entity | C3: Investment | D3: Payment date | E3: Contributions (in USD, Mn) | F3: Distributions (in USD, Mn) | G3: Currency | H3: Investment / Exit Amt (investee currency) | I3: Investment / Exit Amount (USD) | J3: Consideration (shares) | K3: Comment | N3: NOTES
B4: =VLOOKUP(C4,'S | 01 '!$C$9:$F$46,4,0) -> Mozn | C4: Jollychic Holding Limited | D4: 43470 | E4: =-I4*10^-6 -> -30 | G4: USD | H4: 30000000 | I4: =H4 -> 30000000 | J4: 6100312 | N4: USD AED | O4: 3.678
B5: =VLOOKUP(C5,'S | 01 '!$C$9:$F$46,4,0) -> Mozn | C5: Jollychic Holding Limited | D5: 43724 | E5: =-I5*10^-6 -> -20 | G5: USD | H5: 20000000 | I5: =H5 -> 20000000 | J5: 4204767.4
B6: =VLOOKUP(C6,'S | 01 '!$C$9:$F$46,4,0) -> Mozn | C6: Jollychic Holding Limited | D6: 43724 | E6: =-I6*10^-6 -> -15 | G6: USD | H6: 15000000 | I6: =H6 -> 15000000 | J6: 3153575.6
B7: =VLOOKUP(C7,'S | 01 '!$C$9:$F$46,4,0) -> Mozn | C7: Mena Mobile Inc | D7: 43563 | E7: =-I7*10^-6 -> -8 | G7: USD | H7: 8000000 | I7: =H7 -> 8000000 | J7: 21419829
B8: =VLOOKUP(C8,'S | 01 '!$C$9:$F$46,4,0) -> Mozn | C8: Flyr Inc | D8: 43570 | E8: =-I8*10^-6 -> -4.9999981 | G8: USD | H8: 4999998.1 | I8: =H8 -> 4999998.1 | J8: 2625467
