Workbook
Name Company: #REF!
Name Dates: #REF!
Name DetailedCapShares: #REF!
Name FAGroup: #REF!
Name IQ_CH: 110000
Name IQ_CQ: 5000
Name IQ_CY: 10000
Name IQ_DAILY: 500000
Name IQ_FH: 100000
Name IQ_FQ: 500
Name IQ_FY: 1000
Name IQ_LTM: 2000
Name IQ_MONTH: 15000
Name IQ_NTM: 6000
Name IQ_WEEK: 50000
Name IQ_YTD: 3000
Name UNLOCKED_PERCENT_FAST: _xludf.LAMBDA(start_date, date, IF(start_date="",0,MIN(1,MAX(0,(date-EDATE(start_date,12)+1)/(EDATE(start_date,36)-EDATE(start_date,12))))))
Name UNLOCKED_PERCENT_SLOW: _xludf.LAMBDA(start_date, date, IF(start_date="",0, MIN(1,MAX(0,(date-EDATE(start_date,12)+1)/(EDATE(start_date,60)-EDATE(start_date,12))))))

Sheet D1
B2: Date of NAV | D2: 45900 | E2: =TEXT(D2,"dddddd") -> Sunday
H4: D A S H B O A R D
B6: L I V E D E A L S (includes unrealized or partially realized investments)
E8: # Investments | F8: Committed | G8: Invested | H8: Remaining | I8: Distributions | J8: Residual Value | K8: Gain | L8: TVPI | M8: DPI
E9: # | F9: USD, Mn | G9: USD, Mn | H9: USD, Mn | I9: USD, Mn | J9: USD, Mn | K9: USD, Mn | L9: X | M9: X
C11: EQUITY* | D11: Direct Investment | E11: =COUNTIF('1. Live'!$D$1:D25,$D11) -> 12 | F11: =SUMIF('1. Live'!$D$1:$D$110,$D11,'1. Live'!K$1:K$110) -> 1106.018 | G11: =SUMIF('1. Live'!$D$1:$D$110,$D11,'1. Live'!L$1:L$110) -> 947.50137 | H11: =SUMIF('1. Live'!$D$1:$D$110,$D11,'1. Live'!M$1:M$110) -> 158.51663 | I11: =SUMIF('1. Live'!$D$1:$D$110,$D11,'1. Live'!N$1:N$110) -> 85.304451 | J11: =SUMIF('1. Live'!$D$1:$D$110,$D11,'1. Live'!O$1:O$110) -> 878.23664 | K11: =SUMIF('1. Live'!$D$1:$D$110,$D11,'1. Live'!P$1:P$110) -> 16.039713 | L11: =IFERROR((I11+J11)/G11,"") -> 1.0169284 | M11: =IFERROR(I11/G11,"") -> 0.090030952
C13: DEBT | D13: Debt Investment | E13: =COUNTIF('1. Live'!$D$1:D27,$D13) -> 0 | F13: =SUMIF('1. Live'!$D$1:$D$110,$D13,'1. Live'!K$1:K$110) -> 0 | G13: =SUMIF('1. Live'!$D$1:$D$110,$D13,'1. Live'!L$1:L$110) -> 0 | H13: =SUMIF('1. Live'!$D$1:$D$110,$D13,'1. Live'!M$1:M$110) -> 0 | I13: =SUMIF('1. Live'!$D$1:$D$110,$D13,'1. Live'!N$1:N$110) -> 0 | J13: =SUMIF('1. Live'!$D$1:$D$110,$D13,'1. Live'!O$1:O$110) -> 0 | K13: =SUMIF('1. Live'!$D$1:$D$110,$D13,'1. Live'!P$1:P$110) -> 0 | L13: =IFERROR((I13+J13)/G13,"") | M13: =IFERROR(I13/G13,"")
C15: FUNDS | D15: Fund Investment | E15: =COUNTIF('1. Live'!$D$1:D29,$D15) -> 4 | F15: =SUMIF('1. Live'!$D$1:$D$110,$D15,'1. Live'!K$1:K$110) -> 132.83985 | G15: =SUMIF('1. Live'!$D$1:$D$110,$D15,'1. Live'!L$1:L$110) -> 120.90243 | H15: =SUMIF('1. Live'!$D$1:$D$110,$D15,'1. Live'!M$1:M$110) -> 11.937429 | I15: =SUMIF('1. Live'!$D$1:$D$110,$D15,'1. Live'!N$1:N$110) -> 11.668277 | J15: =SUMIF('1. Live'!$D$1:$D$110,$D15,'1. Live'!O$1:O$110) -> 106.52706 | K15: =SUMIF('1. Live'!$D$1:$D$110,$D15,'1. Live'!P$1:P$110) -> -2.7070901 | L15: =IFERROR((I15+J15)/G15,"") -> 0.9776093 | M15: =IFERROR(I15/G15,"") -> 0.096509869
C17: MGX | D17: MGX related | E17: 4 | F17: ='1. Live'!K52 -> 2000 | G17: ='1. Live'!L52 -> 547.72831 | H17: ='1. Live'!M52 -> 1452.2717 | I17: ='1. Live'!N52 -> 0 | J17: ='1. Live'!O52 -> 747.273 | K17: ='1. Live'!P52 -> 199.5447 | L17: =IFERROR((I17+J17)/G17,"") -> 1.3643133 | M17: =IFERROR(I17/G17,"") -> 0
C19: TOTAL | E19: =E11+E13+E15 -> 16 | F19: =F11+F13+F15+F17 -> 3238.8579 | G19: =G11+G13+G15+G17 -> 1616.1321 | H19: =H11+H13+H15+H17 -> 1622.7258 | I19: =I11+I13+I15+I17 -> 96.972728 | J19: =J11+J13+J15+J17 -> 1732.0367 | K19: =K11+K13+K15+K17 -> 212.87732 | L19: =IFERROR((I19+J19)/G19,"") -> 1.1317202 | M19: =IFERROR(I19/G19,"") -> 0.060002971
B22: E X I T E D D E A L S (includes liquidated, written-off or completely exited investments)
E24: # Investments | F24: Committed | G24: Invested | H24: Remaining | I24: Distributions | J24: Residual Value | K24: Gain | L24: TVPI | M24: DPI
E25: # | F25: USD, Mn | G25: USD, Mn | H25: USD, Mn | I25: USD, Mn | J25: USD, Mn | K25: USD, Mn | L25: X | M25: X
C27: EQUITY* | D27: Direct Investment | E27: =COUNTIF('2. Exited'!$D$1:D41,$D27) -> 8 | F27: =SUMIF('2. Exited'!$D$1:$D$41,$D27,'2. Exited'!K$1:K$41) -> 1394.0316 | G27: =SUMIF('2. Exited'!$D$1:$D$41,$D27,'2. Exited'!L$1:L$41) -> 1394.0316 | H27: =SUMIF('2. Exited'!$D$1:$D$41,$D27,'2. Exited'!M$1:M$41) -> 0 | I27: =SUMIF('2. Exited'!$D$1:$D$41,$D27,'2. Exited'!N$1:N$41) -> 1343.2422 | J27: =SUMIF('2. Exited'!$D$1:$D$41,$D27,'2. Exited'!O$1:O$41) -> 0 | K27: =SUMIF('2. Exited'!$D$1:$D$41,$D27,'2. Exited'!P$1:P$41) -> -50.789359 | L27: =IFERROR((I27+J27)/G27,"") -> 0.96356656 | M27: =IFERROR(I27/G27,"") -> 0.96356656
C29: DEBT | D29: Debt Investment | E29: =COUNTIF('2. Exited'!$D$1:D43,$D29) -> 3 | F29: =SUMIF('2. Exited'!$D$1:$D$41,$D29,'2. Exited'!K$1:K$41) -> 10.765747 | G29: =SUMIF('2. Exited'!$D$1:$D$41,$D29,'2. Exited'!L$1:L$41) -> 10.765747 | H29: =SUMIF('2. Exited'!$D$1:$D$41,$D29,'2. Exited'!M$1:M$41) -> 0 | I29: =SUMIF('2. Exited'!$D$1:$D$41,$D29,'2. Exited'!N$1:N$41) -> 0.47078465 | J29: =SUMIF('2. Exited'!$D$1:$D$41,$D29,'2. Exited'!O$1:O$41) -> 0 | K29: =SUMIF('2. Exited'!$D$1:$D$41,$D29,'2. Exited'!P$1:P$41) -> -10.294962 | L29: =IFERROR((I29+J29)/G29,"") -> 0.043729864 | M29: =IFERROR(I29/G29,"") -> 0.043729864
C31: FUNDS | D31: Fund Investment | E31: =COUNTIF('2. Exited'!$D$1:D45,$D31) -> 1 | F31: =SUMIF('2. Exited'!$D$1:$D$41,$D31,'2. Exited'!K$1:K$41) -> 50 | G31: =SUMIF('2. Exited'!$D$1:$D$41,$D31,'2. Exited'!L$1:L$41) -> 24.959693 | H31: =SUMIF('2. Exited'!$D$1:$D$41,$D31,'2. Exited'!M$1:M$41) -> 0 | I31: =SUMIF('2. Exited'!$D$1:$D$41,$D31,'2. Exited'!N$1:N$41) -> 25.403521 | J31: =SUMIF('2. Exited'!$D$1:$D$41,$D31,'2. Exited'!O$1:O$41) -> 0 | K31: =SUMIF('2. Exited'!$D$1:$D$41,$D31,'2. Exited'!P$1:P$41) -> 0.44382835 | L31: =IFERROR((I31+J31)/G31,"") -> 1.0177818 | M31: =IFERROR(I31/G31,"") -> 1.0177818
C33: TOTAL | E33: =E27+E29+E31 -> 12 | F33: =F27+F29+F31 -> 1454.7973 | G33: =G27+G29+G31 -> 1429.757 | H33: =H27+H29+H31 -> 0 | I33: =I27+I29+I31 -> 1369.1165 | J33: =J27+J29+J31 -> 0 | K33: =K27+K29+K31 -> -60.640493 | L33: =IFERROR((I33+J33)/G33,"") -> 0.95758685 | M33: =IFERROR(I33/G33,"") -> 0.95758685
B36: * Includes Convertibles
E38: CHECKS | F38: =ROUND(F19,5)=ROUND('1. Live'!K54,5) -> TRUE | G38: =ROUND(G19,5)=ROUND('1. Live'!L54,5) -> TRUE | H38: =ROUND(H19,5)=ROUND('1. Live'!M54,5) -> TRUE | I38: =ROUND(I19,5)=ROUND('1. Live'!N54,5) -> TRUE | J38: =ROUND(J19,5)=ROUND('1. Live'!O54,5) -> TRUE | K38: =ROUND(K19,5)=ROUND('1. Live'!P54,5) -> TRUE
F39: =F33='2. Exited'!K36 -> TRUE | G39: =G33='2. Exited'!L36 -> TRUE | H39: =H33='2. Exited'!M36 -> TRUE | I39: =I33='2. Exited'!N36 -> TRUE | J39: =J33='2. Exited'!O36 -> TRUE | K39: =K33='2. Exited'!P36 -> TRUE
F40: TRUE | G40: TRUE | H40: TRUE | I40: TRUE | J40: TRUE | K40: TRUE

Sheet 1. Live
C2: As of date | D2: ='D1'!D2 -> 45900
E5: 2 | F5: 3 | G5: 4 | H5: 5 | I5: 6 | J5: 7 | K5: 8 | L5: 9 | M5: 10 | N5: 11 | O5: 12 | P5: 13 | R5: 14 | S5: 15
C6: Deals | D6: Type | E6: Status | F6: Lead | G6: Investing Entity | H6: Vintageἀ | I6: Instrument | J6: % | K6: Committed | L6: Invested | M6: Remaining Commitment | N6: Distributions | O6: Carrying Value | P6: Gain | Q6: Gain till FY22 | R6: TVPI | S6: Additonal Upside/Downside
I7: # | J7: % | K7: $,m | L7: $,m | M7: $,m | N7: $,m | O7: $,m | P7: $,m | R7: X
C8: MOZN Holding RSC Ltd
C9: E-line Ventures LLC | D9: Direct Investment | E9: =VLOOKUP($C9,'A. All deals (a)'!$C$6:$Q$58,E$5,0) -> Unrealized | F9: =VLOOKUP($C9,'A. All deals (a)'!$C$6:$Q$58,F$5,0) -> 0 | G9: =VLOOKUP($C9,'A. All deals (a)'!$C$6:$Q$58,G$5,0) -> Mozn | H9: =VLOOKUP($C9,'A. All deals (a)'!$C$6:$Q$58,H$5,0) -> 2023 | I9: =VLOOKUP($C9,'A. All deals (a)'!$C$6:$Q$58,I$5,0) -> B Prefs | J9: =VLOOKUP($C9,'A. All deals (a)'!$C$6:$Q$58,J$5,0) -> 0.11483736 | K9: =VLOOKUP($C9,'A. All deals (a)'!$C$6:$Q$58,K$5,0) -> 6 | L9: =VLOOKUP($C9,'A. All deals (a)'!$C$6:$Q$58,L$5,0) -> 6 | ... P9: =VLOOKUP($C9,'A. All deals (a)'!$C$6:$Q$58,P$5,0) -> 9.3 | Q9: n/a | R9: =VLOOKUP($C9,'A. All deals (a)'!$C$6:$Q$58,R$5,0) -> 2.55 | S9: Optionse
C10: Tools for Humanity Corporation | D10: Direct Investment | E10: =VLOOKUP($C10,'A. All deals (a)'!$C$6:$Q$58,E$5,0) -> Unrealized | F10: =VLOOKUP($C10,'A. All deals (a)'!$C$6:$Q$58,F$5,0) -> 0 | G10: =VLOOKUP($C10,'A. All deals (a)'!$C$6:$Q$58,G$5,0) -> Mozn | H10: =VLOOKUP($C10,'A. All deals (a)'!$C$6:$Q$58,H$5,0) -> 2023 | I10: =VLOOKUP($C10,'A. All deals (a)'!$C$6:$Q$58,I$5,0) -> C Prefs | J10: =VLOOKUP($C10,'A. All deals (a)'!$C$6:$Q$58,J$5,0) -> 0.00626608 | K10: =VLOOKUP($C10,'A. All deals (a)'!$C$6:$Q$58,K$5,0) -> 14.999999 | L10: =VLOOKUP($C10,'A. All deals (a)'!$C$6:$Q$58,L$5,0) -> 14.999999 | ... P10: =VLOOKUP($C10,'A. All deals (a)'!$C$6:$Q$58,P$5,0) -> -12.599999 | Q10: n/a | R10: =VLOOKUP($C10,'A. All deals (a)'!$C$6:$Q$58,R$5,0) -> 0.16000001
C11: eSpace | D11: Direct Investment | E11: =VLOOKUP($C11,'A. All deals (a)'!$C$6:$Q$58,E$5,0) -> Unrealized | F11: =VLOOKUP($C11,'A. All deals (a)'!$C$6:$Q$58,F$5,0) -> 0 | G11: =VLOOKUP($C11,'A. All deals (a)'!$C$6:$Q$58,G$5,0) -> Mozn 4 | H11: =VLOOKUP($C11,'A. All deals (a)'!$C$6:$Q$58,H$5,0) -> 2022 | I11: =VLOOKUP($C11,'A. All deals (a)'!$C$6:$Q$58,I$5,0) -> B Prefs | J11: =VLOOKUP($C11,'A. All deals (a)'!$C$6:$Q$58,J$5,0) -> 0.026056201 | K11: =VLOOKUP($C11,'A. All deals (a)'!$C$6:$Q$58,K$5,0) -> 15 | L11: =VLOOKUP($C11,'A. All deals (a)'!$C$6:$Q$58,L$5,0) -> 15 | ... P11: =VLOOKUP($C11,'A. All deals (a)'!$C$6:$Q$58,P$5,0) -> 17.34128 | Q11: 0 | R11: =VLOOKUP($C11,'A. All deals (a)'!$C$6:$Q$58,R$5,0) -> 2.1560854
C12: Applied AI Corporation Limited | D12: Direct Investment | E12: =VLOOKUP($C12,'A. All deals (a)'!$C$6:$Q$58,E$5,0) -> Unrealized | F12: =VLOOKUP($C12,'A. All deals (a)'!$C$6:$Q$58,F$5,0) -> 0 | G12: =VLOOKUP($C12,'A. All deals (a)'!$C$6:$Q$58,G$5,0) -> Mozn | H12: =VLOOKUP($C12,'A. All deals (a)'!$C$6:$Q$58,H$5,0) -> 2022 | I12: =VLOOKUP($C12,'A. All deals (a)'!$C$6:$Q$58,I$5,0) -> A Prefs | J12: =VLOOKUP($C12,'A. All deals (a)'!$C$6:$Q$58,J$5,0) -> 0.12121516 | K12: =VLOOKUP($C12,'A. All deals (a)'!$C$6:$Q$58,K$5,0) -> 15 | L12: =VLOOKUP($C12,'A. All deals (a)'!$C$6:$Q$58,L$5,0) -> 15 | ... P12: =VLOOKUP($C12,'A. All deals (a)'!$C$6:$Q$58,P$5,0) -> 23.46473 | Q12: 0 | R12: =VLOOKUP($C12,'A. All deals (a)'!$C$6:$Q$58,R$5,0) -> 2.5643153
C13: Cerebras Systems Inc | D13: Direct Investment | E13: =VLOOKUP($C13,'A. All deals (a)'!$C$6:$Q$58,E$5,0) -> Unrealized | F13: =VLOOKUP($C13,'A. All deals (a)'!$C$6:$Q$58,F$5,0) -> 0 | G13: =VLOOKUP($C13,'A. All deals (a)'!$C$6:$Q$58,G$5,0) -> Mozn | H13: =VLOOKUP($C13,'A. All deals (a)'!$C$6:$Q$58,H$5,0) -> 2021 | I13: =VLOOKUP($C13,'A. All deals (a)'!$C$6:$Q$58,I$5,0) -> F Prefs | J13: =VLOOKUP($C13,'A. All deals (a)'!$C$6:$Q$58,J$5,0) -> 0.0081 | K13: =VLOOKUP($C13,'A. All deals (a)'!$C$6:$Q$58,K$5,0) -> 39.999983 | L13: =VLOOKUP($C13,'A. All deals (a)'!$C$6:$Q$58,L$5,0) -> 39.999983 | ... P13: =VLOOKUP($C13,'A. All deals (a)'!$C$6:$Q$58,P$5,0) -> -18.8645 | Q13: 0 | R13: =VLOOKUP($C13,'A. All deals (a)'!$C$6:$Q$58,R$5,0) -> 0.5283873
C14: Endless Studios LLC | D14: Direct Investment | E14: =VLOOKUP($C14,'A. All deals (a)'!$C$6:$Q$58,E$5,0) -> Unrealized | F14: =VLOOKUP($C14,'A. All deals (a)'!$C$6:$Q$58,F$5,0) -> 0 | G14: =VLOOKUP($C14,'A. All deals (a)'!$C$6:$Q$58,G$5,0) -> Mozn | H14: =VLOOKUP($C14,'A. All deals (a)'!$C$6:$Q$58,H$5,0) -> 2021 | I14: =VLOOKUP($C14,'A. All deals (a)'!$C$6:$Q$58,I$5,0) -> A Pref Units | J14: =VLOOKUP($C14,'A. All deals (a)'!$C$6:$Q$58,J$5,0) -> 0.15458937 | K14: =VLOOKUP($C14,'A. All deals (a)'!$C$6:$Q$58,K$5,0) -> 8 | L14: =VLOOKUP($C14,'A. All deals (a)'!$C$6:$Q$58,L$5,0) -> 8 | ... P14: =VLOOKUP($C14,'A. All deals (a)'!$C$6:$Q$58,P$5,0) -> -3.3 | Q14: 0 | R14: =VLOOKUP($C14,'A. All deals (a)'!$C$6:$Q$58,R$5,0) -> 0.5875
C15: Heygears | D15: Direct Investment | E15: =VLOOKUP($C15,'A. All deals (a)'!$C$6:$Q$58,E$5,0) -> Unrealized | F15: =VLOOKUP($C15,'A. All deals (a)'!$C$6:$Q$58,F$5,0) -> 0 | G15: =VLOOKUP($C15,'A. All deals (a)'!$C$6:$Q$58,G$5,0) -> Mozn | H15: =VLOOKUP($C15,'A. All deals (a)'!$C$6:$Q$58,H$5,0) -> 2020 | I15: =VLOOKUP($C15,'A. All deals (a)'!$C$6:$Q$58,I$5,0) -> Registered Capital | J15: =VLOOKUP($C15,'A. All deals (a)'!$C$6:$Q$58,J$5,0) -> 0.14383199 | K15: =VLOOKUP($C15,'A. All deals (a)'!$C$6:$Q$58,K$5,0) -> 60 | L15: =VLOOKUP($C15,'A. All deals (a)'!$C$6:$Q$58,L$5,0) -> 60 | ... P15: =VLOOKUP($C15,'A. All deals (a)'!$C$6:$Q$58,P$5,0) -> -19.7 | Q15: 96.4 | R15: =VLOOKUP($C15,'A. All deals (a)'!$C$6:$Q$58,R$5,0) -> 0.67166667
C16: Beyond Limits | D16: Direct Investment | E16: =VLOOKUP($C16,'A. All deals (a)'!$C$6:$Q$58,E$5,0) -> Unrealized | F16: =VLOOKUP($C16,'A. All deals (a)'!$C$6:$Q$58,F$5,0) -> 0 | G16: =VLOOKUP($C16,'A. All deals (a)'!$C$6:$Q$58,G$5,0) -> Mozn | H16: =VLOOKUP($C16,'A. All deals (a)'!$C$6:$Q$58,H$5,0) -> 2020 | I16: =VLOOKUP($C16,'A. All deals (a)'!$C$6:$Q$58,I$5,0) -> C Prefs | J16: =VLOOKUP($C16,'A. All deals (a)'!$C$6:$Q$58,J$5,0) -> 0.094347728 | K16: =VLOOKUP($C16,'A. All deals (a)'!$C$6:$Q$58,K$5,0) -> 90 | L16: =VLOOKUP($C16,'A. All deals (a)'!$C$6:$Q$58,L$5,0) -> 90 | ... P16: =VLOOKUP($C16,'A. All deals (a)'!$C$6:$Q$58,P$5,0) -> -48.996296 | Q16: 1.042 | R16: =VLOOKUP($C16,'A. All deals (a)'!$C$6:$Q$58,R$5,0) -> 0.45559671
C17: ONT plc | D17: Direct Investment | E17: =VLOOKUP($C17,'A. All deals (a)'!$C$6:$Q$58,E$5,0) -> Unrealized | F17: =VLOOKUP($C17,'A. All deals (a)'!$C$6:$Q$58,F$5,0) -> 0 | G17: =VLOOKUP($C17,'A. All deals (a)'!$C$6:$Q$58,G$5,0) -> Mozn | H17: =VLOOKUP($C17,'A. All deals (a)'!$C$6:$Q$58,H$5,0) -> 2020 | I17: =VLOOKUP($C17,'A. All deals (a)'!$C$6:$Q$58,I$5,0) -> Ordinary Shares | J17: =VLOOKUP($C17,'A. All deals (a)'!$C$6:$Q$58,J$5,0) -> 0.046395018 | K17: =VLOOKUP($C17,'A. All deals (a)'!$C$6:$Q$58,K$5,0) -> 141.47026 | L17: =VLOOKUP($C17,'A. All deals (a)'!$C$6:$Q$58,L$5,0) -> 141.47026 | ... P17: =VLOOKUP($C17,'A. All deals (a)'!$C$6:$Q$58,P$5,0) -> -33.190285 | Q17: -9.845 | R17: =VLOOKUP($C17,'A. All deals (a)'!$C$6:$Q$58,R$5,0) -> 0.76539038
C18: Flyr Inc | D18: Direct Investment | E18: =VLOOKUP($C18,'A. All deals (a)'!$C$6:$Q$58,E$5,0) -> Unrealized | F18: =VLOOKUP($C18,'A. All deals (a)'!$C$6:$Q$58,F$5,0) -> 0 | G18: =VLOOKUP($C18,'A. All deals (a)'!$C$6:$Q$58,G$5,0) -> Mozn | H18: =VLOOKUP($C18,'A. All deals (a)'!$C$6:$Q$58,H$5,0) -> 2019 | I18: =VLOOKUP($C18,'A. All deals (a)'!$C$6:$Q$58,I$5,0) -> B-1,2 Prefs | J18: =VLOOKUP($C18,'A. All deals (a)'!$C$6:$Q$58,J$5,0) -> 0.035329982 | K18: =VLOOKUP($C18,'A. All deals (a)'!$C$6:$Q$58,K$5,0) -> 10 | L18: =VLOOKUP($C18,'A. All deals (a)'!$C$6:$Q$58,L$5,0) -> 10 | ... P18: =VLOOKUP($C18,'A. All deals (a)'!$C$6:$Q$58,P$5,0) -> 18.213712 | Q18: 68.1 | R18: =VLOOKUP($C18,'A. All deals (a)'!$C$6:$Q$58,R$5,0) -> 2.8213712 | S18: Flyr Warrantsa
K20: =SUM(K9:K18) -> 400.47024 | L20: =SUM(L9:L18) -> 400.47024 | M20: =SUM(M9:M18) -> 0 | N20: =SUM(N9:N18) -> 0 | O20: =SUM(O9:O18) -> 332.13889 | P20: =O20+N20-L20 -> -68.331357 | Q20: =SUM(Q9:Q18) -> 155.697 | R20: =(N20+O20)/L20 -> 0.8293722
C22: G42 Investments AI Holding RSC Ltd
C23: DriveNets | D23: Direct Investment | E23: =VLOOKUP($C23,'A. All deals (a)'!$C$6:$Q$58,E$5,0) -> Partially Realized | F23: =VLOOKUP($C23,'A. All deals (a)'!$C$6:$Q$58,F$5,0) -> 0 | G23: =VLOOKUP($C23,'A. All deals (a)'!$C$6:$Q$58,G$5,0) -> G42 Investments | H23: =VLOOKUP($C23,'A. All deals (a)'!$C$6:$Q$58,H$5,0) -> 2022 | I23: =VLOOKUP($C23,'A. All deals (a)'!$C$6:$Q$58,I$5,0) -> Equity-TBC | J23: =VLOOKUP($C23,'A. All deals (a)'!$C$6:$Q$58,J$5,0) -> 0.0878 | K23: =VLOOKUP($C23,'A. All deals (a)'!$C$6:$Q$58,K$5,0) -> 300 | L23: =VLOOKUP($C23,'A. All deals (a)'!$C$6:$Q$58,L$5,0) -> 300 | ... P23: =VLOOKUP($C23,'A. All deals (a)'!$C$6:$Q$58,P$5,0) -> 110.59541 | Q23: 0 | R23: =VLOOKUP($C23,'A. All deals (a)'!$C$6:$Q$58,R$5,0) -> 1.3686514 | S23: DN Warrants b
C24: vTv Therapeutics Inc. | D24: Direct Investment | E24: =VLOOKUP($C24,'A. All deals (a)'!$C$6:$Q$58,E$5,0) -> Unrealized | F24: =VLOOKUP($C24,'A. All deals (a)'!$C$6:$Q$58,F$5,0) -> 0 | G24: =VLOOKUP($C24,'A. All deals (a)'!$C$6:$Q$58,G$5,0) -> G42 Investments | H24: =VLOOKUP($C24,'A. All deals (a)'!$C$6:$Q$58,H$5,0) -> 2022 | I24: =VLOOKUP($C24,'A. All deals (a)'!$C$6:$Q$58,I$5,0) -> Ordinary Shares | J24: =VLOOKUP($C24,'A. All deals (a)'!$C$6:$Q$58,J$5,0) -> 0.081407233 | K24: =VLOOKUP($C24,'A. All deals (a)'!$C$6:$Q$58,K$5,0) -> 24.53125 | L24: =VLOOKUP($C24,'A. All deals (a)'!$C$6:$Q$58,L$5,0) -> 24.53125 | ... P24: =VLOOKUP($C24,'A. All deals (a)'!$C$6:$Q$58,P$5,0) -> -20.584464 | Q24: -1.348 | R24: =VLOOKUP($C24,'A. All deals (a)'!$C$6:$Q$58,R$5,0) -> 0.16088811 | S24: vTv $30m milestn payment c
C25: North Summit Capital Fund | D25: Fund Investment | E25: =VLOOKUP($C25,'A. All deals (a)'!$C$6:$Q$58,E$5,0) -> Unrealized | F25: =VLOOKUP($C25,'A. All deals (a)'!$C$6:$Q$58,F$5,0) -> 0 | G25: =VLOOKUP($C25,'A. All deals (a)'!$C$6:$Q$58,G$5,0) -> G42 Investments | H25: =VLOOKUP($C25,'A. All deals (a)'!$C$6:$Q$58,H$5,0) -> 2020 | I25: =VLOOKUP($C25,'A. All deals (a)'!$C$6:$Q$58,I$5,0) -> LP | J25: =VLOOKUP($C25,'A. All deals (a)'!$C$6:$Q$58,J$5,0) -> n/a | K25: =VLOOKUP($C25,'A. All deals (a)'!$C$6:$Q$58,K$5,0) -> 83.361611 | L25: =VLOOKUP($C25,'A. All deals (a)'!$C$6:$Q$58,L$5,0) -> 83.361611 | ... P25: =VLOOKUP($C25,'A. All deals (a)'!$C$6:$Q$58,P$5,0) -> -11.257966 | Q25: -0.306 | R25: =VLOOKUP($C25,'A. All deals (a)'!$C$6:$Q$58,R$5,0) -> 0.86495023
C26: New Space Capital Fund I | D26: Fund Investment | E26: =VLOOKUP($C26,'A. All deals (a)'!$C$6:$Q$58,E$5,0) -> Unrealized | F26: =VLOOKUP($C26,'A. All deals (a)'!$C$6:$Q$58,F$5,0) -> 0 | G26: =VLOOKUP($C26,'A. All deals (a)'!$C$6:$Q$58,G$5,0) -> G42 Investments | H26: =VLOOKUP($C26,'A. All deals (a)'!$C$6:$Q$58,H$5,0) -> 2020 | I26: =VLOOKUP($C26,'A. All deals (a)'!$C$6:$Q$58,I$5,0) -> LP | J26: =VLOOKUP($C26,'A. All deals (a)'!$C$6:$Q$58,J$5,0) -> n/a | K26: =VLOOKUP($C26,'A. All deals (a)'!$C$6:$Q$58,K$5,0) -> 29.659861 | L26: =VLOOKUP($C26,'A. All deals (a)'!$C$6:$Q$58,L$5,0) -> 19.108545 | ... P26: =VLOOKUP($C26,'A. All deals (a)'!$C$6:$Q$58,P$5,0) -> 10.299548 | Q26: 5.445 | R26: =VLOOKUP($C26,'A. All deals (a)'!$C$6:$Q$58,R$5,0) -> 1.5390022
C27: New Space Capital GP Com SCSp | D27: Fund Investment | E27: =VLOOKUP($C27,'A. All deals (a)'!$C$6:$Q$58,E$5,0) -> Unrealized | F27: =VLOOKUP($C27,'A. All deals (a)'!$C$6:$Q$58,F$5,0) -> 0 | G27: =VLOOKUP($C27,'A. All deals (a)'!$C$6:$Q$58,G$5,0) -> G42 Investments | H27: =VLOOKUP($C27,'A. All deals (a)'!$C$6:$Q$58,H$5,0) -> 2023 | I27: =VLOOKUP($C27,'A. All deals (a)'!$C$6:$Q$58,I$5,0) -> LP | J27: =VLOOKUP($C27,'A. All deals (a)'!$C$6:$Q$58,J$5,0) -> n/a | K27: =VLOOKUP($C27,'A. All deals (a)'!$C$6:$Q$58,K$5,0) -> 2.7058824 | L27: =VLOOKUP($C27,'A. All deals (a)'!$C$6:$Q$58,L$5,0) -> 2.7058824 | ... P27: =VLOOKUP($C27,'A. All deals (a)'!$C$6:$Q$58,P$5,0) -> 0.9214071 | Q27: 0 | R27: =VLOOKUP($C27,'A. All deals (a)'!$C$6:$Q$58,R$5,0) -> 1.34052
C28: Acies Investments Fund I, L.P. | D28: Fund Investment | E28: =VLOOKUP($C28,'A. All deals (a)'!$C$6:$Q$58,E$5,0) -> Unrealized | F28: =VLOOKUP($C28,'A. All deals (a)'!$C$6:$Q$58,F$5,0) -> 0 | G28: =VLOOKUP($C28,'A. All deals (a)'!$C$6:$Q$58,G$5,0) -> G42 Investments | H28: =VLOOKUP($C28,'A. All deals (a)'!$C$6:$Q$58,H$5,0) -> 2021 | I28: =VLOOKUP($C28,'A. All deals (a)'!$C$6:$Q$58,I$5,0) -> LP | J28: =VLOOKUP($C28,'A. All deals (a)'!$C$6:$Q$58,J$5,0) -> 0.33 | K28: =VLOOKUP($C28,'A. All deals (a)'!$C$6:$Q$58,K$5,0) -> 17.1125 | L28: =VLOOKUP($C28,'A. All deals (a)'!$C$6:$Q$58,L$5,0) -> 15.726387 | ... P28: =VLOOKUP($C28,'A. All deals (a)'!$C$6:$Q$58,P$5,0) -> -2.6700795 | Q28: -0.306 | R28: =VLOOKUP($C28,'A. All deals (a)'!$C$6:$Q$58,R$5,0) -> 0.8302166 | S28: 9.9% GP | Anchorf
K30: =SUM(K23:K28) -> 457.3711 | L30: =SUM(L23:L28) -> 445.43368 | M30: =SUM(M23:M28) -> 11.937429 | N30: =SUM(N23:N28) -> 96.472763 | O30: =SUM(O23:O28) -> 436.26476 | P30: =O30+N30-L30 -> 87.303852 | Q30: =SUM(Q23:Q28) -> 3.485 | R30: =(N30+O30)/L30 -> 1.1959974
C32: G42 Capital SPV RSC Ltd
C33: Life Biosciences LLC | D33: Direct Investment | E33: =VLOOKUP($C33,'A. All deals (a)'!$C$6:$Q$58,E$5,0) -> Unrealized | F33: =VLOOKUP($C33,'A. All deals (a)'!$C$6:$Q$58,F$5,0) -> 0 | G33: =VLOOKUP($C33,'A. All deals (a)'!$C$6:$Q$58,G$5,0) -> G42 Capital | H33: =VLOOKUP($C33,'A. All deals (a)'!$C$6:$Q$58,H$5,0) -> 2024 | I33: =VLOOKUP($C33,'A. All deals (a)'!$C$6:$Q$58,I$5,0) -> D Prefs | J33: =VLOOKUP($C33,'A. All deals (a)'!$C$6:$Q$58,J$5,0) -> 0.072996903 | K33: =VLOOKUP($C33,'A. All deals (a)'!$C$6:$Q$58,K$5,0) -> 40 | L33: =VLOOKUP($C33,'A. All deals (a)'!$C$6:$Q$58,L$5,0) -> 40 | ... P33: =VLOOKUP($C33,'A. All deals (a)'!$C$6:$Q$58,P$5,0) -> 0.94739371 | Q33: 0 | R33: =VLOOKUP($C33,'A. All deals (a)'!$C$6:$Q$58,R$5,0) -> 1.0236848 | S33: EPTH7
C34: Cerebras Systems Inc F1 | D34: Direct Investment | E34: =VLOOKUP($C34,'A. All deals (a)'!$C$6:$Q$58,E$5,0) -> Not Completed | F34: =VLOOKUP($C34,'A. All deals (a)'!$C$6:$Q$58,F$5,0) -> 0 | G34: =VLOOKUP($C34,'A. All deals (a)'!$C$6:$Q$58,G$5,0) -> G42 Capital | H34: =VLOOKUP($C34,'A. All deals (a)'!$C$6:$Q$58,H$5,0) -> 2025 | I34: =VLOOKUP($C34,'A. All deals (a)'!$C$6:$Q$58,I$5,0) -> Series F-1 | J34: =VLOOKUP($C34,'A. All deals (a)'!$C$6:$Q$58,J$5,0) -> TBD | K34: =VLOOKUP($C34,'A. All deals (a)'!$C$6:$Q$58,K$5,0) -> 111.66667 | L34: =VLOOKUP($C34,'A. All deals (a)'!$C$6:$Q$58,L$5,0) -> 0 | ... P34: =VLOOKUP($C34,'A. All deals (a)'!$C$6:$Q$58,P$5,0) -> 0 | Q34: 0 | R34: =VLOOKUP($C34,'A. All deals (a)'!$C$6:$Q$58,R$5,0) -> NM | S34: EPTH8; option to buy more
C35: Verses AI Inc | D35: Direct Investment | E35: =VLOOKUP($C35,'A. All deals (a)'!$C$6:$Q$58,E$5,0) -> Unrealized | F35: =VLOOKUP($C35,'A. All deals (a)'!$C$6:$Q$58,F$5,0) -> 0 | G35: =VLOOKUP($C35,'A. All deals (a)'!$C$6:$Q$58,G$5,0) -> G42 Capital | H35: =VLOOKUP($C35,'A. All deals (a)'!$C$6:$Q$58,H$5,0) -> 2024 | I35: Ordinary Shares | J35: =VLOOKUP($C35,'A. All deals (a)'!$C$6:$Q$58,J$5,0) -> 0.0523 | K35: =VLOOKUP($C35,'A. All deals (a)'!$C$6:$Q$58,K$5,0) -> 10 | L35: =VLOOKUP($C35,'A. All deals (a)'!$C$6:$Q$58,L$5,0) -> 10 | M35: =VLOOKUP($C35,'A. All deals (a)'!$C$6:$Q$58,M$5,0) -> 0 | N35: =VLOOKUP($C35,'A. All deals (a)'!$C$6:$Q$58,N$5,0) -> 0 | O35: =VLOOKUP($C35,'A. All deals (a)'!$C$6:$Q$58,O$5,0) -> 2.9127687 | P35: =VLOOKUP($C35,'A. All deals (a)'!$C$6:$Q$58,P$5,0) -> -7.0872313 | Q35: 0 | R35: =VLOOKUP($C35,'A. All deals (a)'!$C$6:$Q$58,R$5,0) -> 0.29127687 | S35: ="EPTH9 "& VLOOKUP($C35,'A. All deals (a)'!$C$6:$Q$58,S$5,0) -> EPTH9 Revenue linked RSUs
C36: Inveniam Ltd | D36: Direct Investment | E36: =VLOOKUP($C36,'A. All deals (a)'!$C$6:$Q$58,E$5,0) -> Unrealized | F36: =VLOOKUP($C36,'A. All deals (a)'!$C$6:$Q$58,F$5,0) -> 0 | G36: =VLOOKUP($C36,'A. All deals (a)'!$C$6:$Q$58,G$5,0) -> G42 Capital | H36: =VLOOKUP($C36,'A. All deals (a)'!$C$6:$Q$58,H$5,0) -> 2024 | I36: =VLOOKUP($C36,'A. All deals (a)'!$C$6:$Q$58,I$5,0) -> SAR | J36: =VLOOKUP($C36,'A. All deals (a)'!$C$6:$Q$58,J$5,0) -> 20% Eq | K36: =VLOOKUP($C36,'A. All deals (a)'!$C$6:$Q$58,K$5,0) -> 100 | L36: =VLOOKUP($C36,'A. All deals (a)'!$C$6:$Q$58,L$5,0) -> 100 | ... P36: =VLOOKUP($C36,'A. All deals (a)'!$C$6:$Q$58,P$5,0) -> 0.499965 | Q36: 0 | R36: =VLOOKUP($C36,'A. All deals (a)'!$C$6:$Q$58,R$5,0) -> 1.0049997 | S36: ="EPTH10 "& VLOOKUP($C36,'A. All deals (a)'!$C$6:$Q$58,S$5,0) -> EPTH10 Upside if Tokens sold > $2.5 per token
C37: Liquid AI | D37: Direct Investment | E37: =VLOOKUP($C37,'A. All deals (a)'!$C$6:$Q$58,E$5,0) -> Unrealized | F37: =VLOOKUP($C37,'A. All deals (a)'!$C$6:$Q$58,F$5,0) -> 0 | G37: =VLOOKUP($C37,'A. All deals (a)'!$C$6:$Q$58,G$5,0) -> G42 Capital | H37: =VLOOKUP($C37,'A. All deals (a)'!$C$6:$Q$58,H$5,0) -> 2024 | I37: =VLOOKUP($C37,'A. All deals (a)'!$C$6:$Q$58,I$5,0) -> Series A | J37: =VLOOKUP($C37,'A. All deals (a)'!$C$6:$Q$58,J$5,0) -> 0.006278547 | K37: =VLOOKUP($C37,'A. All deals (a)'!$C$6:$Q$58,K$5,0) -> 66.599843 | L37: =VLOOKUP($C37,'A. All deals (a)'!$C$6:$Q$58,L$5,0) -> 19.999882 | ... P37: =VLOOKUP($C37,'A. All deals (a)'!$C$6:$Q$58,P$5,0) -> 0 | Q37: 0 | R37: =VLOOKUP($C37,'A. All deals (a)'!$C$6:$Q$58,R$5,0) -> 1 | S37: EPTH11 option to buy $45m more
C38: Neuralink | D38: Direct Investment | E38: =VLOOKUP($C38,'A. All deals (a)'!$C$6:$Q$58,E$5,0) -> Unrealized | F38: =VLOOKUP($C38,'A. All deals (a)'!$C$6:$Q$58,F$5,0) -> 0 | G38: =VLOOKUP($C38,'A. All deals (a)'!$C$6:$Q$58,G$5,0) -> G42 Capital | H38: =VLOOKUP($C38,'A. All deals (a)'!$C$6:$Q$58,H$5,0) -> 2025 | I38: =VLOOKUP($C38,'A. All deals (a)'!$C$6:$Q$58,I$5,0) -> Series E | J38: =VLOOKUP($C38,'A. All deals (a)'!$C$6:$Q$58,J$5,0) -> 0.0051805228 | K38: =VLOOKUP($C38,'A. All deals (a)'!$C$6:$Q$58,K$5,0) -> 50 | L38: =VLOOKUP($C38,'A. All deals (a)'!$C$6:$Q$58,L$5,0) -> 50 | ... P38: =VLOOKUP($C38,'A. All deals (a)'!$C$6:$Q$58,P$5,0) -> 5e-07 | Q38: 0 | R38: =VLOOKUP($C38,'A. All deals (a)'!$C$6:$Q$58,R$5,0) -> 1 | S38: EPTH12
K40: =SUM(K33:K38) -> 378.26651 | L40: =SUM(L33:L38) -> 219.99988 | M40: =SUM(M33:M38) -> 158.26663 | N40: =SUM(N33:N38) -> 0.499965 | O40: =SUM(O33:O38) -> 213.86004 | P40: =SUM(P33:P37) -> -5.6398726 | Q40: =SUM(Q33:Q35) -> 0 | R40: =(N40+O40)/L40 -> 0.9743642
C42: Core42 Holding RSC Ltd
C43: School Hack (AIREV Holding Limited) | D43: Direct Investment | E43: =VLOOKUP($C43,'A. All deals (a)'!$C$6:$Q$58,E$5,0) -> Unrealized | F43: =VLOOKUP($C43,'A. All deals (a)'!$C$6:$Q$58,F$5,0) -> 0 | G43: =VLOOKUP($C43,'A. All deals (a)'!$C$6:$Q$58,G$5,0) -> Core42 5 | H43: =VLOOKUP($C43,'A. All deals (a)'!$C$6:$Q$58,H$5,0) -> 2024 | I43: =VLOOKUP($C43,'A. All deals (a)'!$C$6:$Q$58,I$5,0) -> Preferred Shares | J43: =VLOOKUP($C43,'A. All deals (a)'!$C$6:$Q$58,J$5,0) -> 0.25 | K43: =VLOOKUP($C43,'A. All deals (a)'!$C$6:$Q$58,K$5,0) -> 2.75 | L43: =VLOOKUP($C43,'A. All deals (a)'!$C$6:$Q$58,L$5,0) -> 2.5 | ... P43: =VLOOKUP($C43,'A. All deals (a)'!$C$6:$Q$58,P$5,0) -> 0 | Q43: 0 | R43: =VLOOKUP($C43,'A. All deals (a)'!$C$6:$Q$58,R$5,0) -> 1 | S43: Cloud Creditg
K45: =SUM(K43) -> 2.75 | L45: =SUM(L43) -> 2.5 | M45: =SUM(M43) -> 0.25 | N45: =SUM(N43) -> 0 | O45: =SUM(O43) -> 2.5 | P45: =SUM(P43) -> 0 | Q45: =SUM(Q43) -> 0 | R45: =(N45+O45)/L45 -> 1
C47: GX Investments Ltd : MGX and Related Investments
C48: MGX I LP | D48: MGX LP | E48: =VLOOKUP($C48,'A. All deals (a)'!$C$6:$Q$58,E$5,0) -> Unrealized | F48: =VLOOKUP($C48,'A. All deals (a)'!$C$6:$Q$58,F$5,0) -> 0 | G48: =VLOOKUP($C48,'A. All deals (a)'!$C$6:$Q$58,G$5,0) -> G42 Holding | H48: =VLOOKUP($C48,'A. All deals (a)'!$C$6:$Q$58,H$5,0) -> 2024 | I48: =VLOOKUP($C48,'A. All deals (a)'!$C$6:$Q$58,I$5,0) -> LP | J48: =VLOOKUP($C48,'A. All deals (a)'!$C$6:$Q$58,J$5,0) -> 0.03125 | K48: =VLOOKUP($C48,'A. All deals (a)'!$C$6:$Q$58,K$5,0) -> 1200 | L48: =VLOOKUP($C48,'A. All deals (a)'!$C$6:$Q$58,L$5,0) -> 210.22875 | ... P48: =VLOOKUP($C48,'A. All deals (a)'!$C$6:$Q$58,P$5,0) -> 115.98065 | Q48: 0 | R48: =VLOOKUP($C48,'A. All deals (a)'!$C$6:$Q$58,R$5,0) -> 1.5516879
C49: MGX 1 Strategic Co-invest | D49: MGX Co-Invest LP | E49: =VLOOKUP($C49,'A. All deals (a)'!$C$6:$Q$58,E$5,0) -> Unrealized | F49: =VLOOKUP($C49,'A. All deals (a)'!$C$6:$Q$58,F$5,0) -> 0 | G49: =VLOOKUP($C49,'A. All deals (a)'!$C$6:$Q$58,G$5,0) -> G42 Holding | H49: =VLOOKUP($C49,'A. All deals (a)'!$C$6:$Q$58,H$5,0) -> 2024 | I49: =VLOOKUP($C49,'A. All deals (a)'!$C$6:$Q$58,I$5,0) -> LP | J49: =VLOOKUP($C49,'A. All deals (a)'!$C$6:$Q$58,J$5,0) -> 0.5 | K49: =VLOOKUP($C49,'A. All deals (a)'!$C$6:$Q$58,K$5,0) -> 775 | L49: =VLOOKUP($C49,'A. All deals (a)'!$C$6:$Q$58,L$5,0) -> 312.49956 | ... P49: =VLOOKUP($C49,'A. All deals (a)'!$C$6:$Q$58,P$5,0) -> 83.564042 | Q49: 0 | R49: =VLOOKUP($C49,'A. All deals (a)'!$C$6:$Q$58,R$5,0) -> 1.2674053
C50: MGX Group Holding 1 Ltd (GP) | D50: MGX GP | E50: =VLOOKUP($C50,'A. All deals (a)'!$C$6:$Q$58,E$5,0) -> Unrealized | F50: =VLOOKUP($C50,'A. All deals (a)'!$C$6:$Q$58,F$5,0) -> 0 | G50: =VLOOKUP($C50,'A. All deals (a)'!$C$6:$Q$58,G$5,0) -> G42 Holding | H50: =VLOOKUP($C50,'A. All deals (a)'!$C$6:$Q$58,H$5,0) -> 2024 | I50: =VLOOKUP($C50,'A. All deals (a)'!$C$6:$Q$58,I$5,0) -> Equity | J50: =VLOOKUP($C50,'A. All deals (a)'!$C$6:$Q$58,J$5,0) -> 0 | K50: =VLOOKUP($C50,'A. All deals (a)'!$C$6:$Q$58,K$5,0) -> 25 | L50: =VLOOKUP($C50,'A. All deals (a)'!$C$6:$Q$58,L$5,0) -> 25 | ... P50: =VLOOKUP($C50,'A. All deals (a)'!$C$6:$Q$58,P$5,0) -> 0 | Q50: 0 | R50: =VLOOKUP($C50,'A. All deals (a)'!$C$6:$Q$58,R$5,0) -> 1
K52: =SUM(K48:K50) -> 2000 | L52: =SUM(L48:L50) -> 547.72831 | M52: =SUM(M48:M50) -> 1452.2717 | N52: =SUM(N48:N50) -> 0 | O52: =SUM(O48:O50) -> 747.273 | P52: =SUM(P48:P50) -> 199.5447 | Q52: =SUM(Q48:Q48) -> 0 | R52: =(N52+O52)/L52 -> 1.3643133
...

Sheet 2. Exited
C2: As of date | D2: ='D1'!D2 -> 45900
C3: EXITED INVESTMENTS
E5: 2 | F5: 3 | G5: 4 | H5: 5 | I5: 6 | J5: 7 | K5: 8 | L5: 9 | M5: 10 | N5: 11 | O5: 12 | P5: 13 | R5: 14 | S5: 15
C6: Deals | D6: Type | E6: Status | F6: Lead | G6: Investing Entity | H6: Vintageἀ | I6: Instrument | J6: % | K6: Committed | L6: Invested | M6: Remaining Commitment | N6: Distributions | O6: Carrying Value | P6: Gain | Q6: Gain till FY22 | R6: TVPI | S6: Additonal Upside/Downside
I7: # | J7: % | K7: $,m | L7: $,m | M7: $,m | N7: $,m | O7: $,m | P7: $,m | R7: X
C8: MOZN Holding RSC Ltd
C9: WLD Tokens | D9: Direct Investment | E9: =VLOOKUP($C9,'A. All deals (a)'!$C$6:$Q$58,E$5,0) -> Unrealized | F9: =VLOOKUP($C9,'A. All deals (a)'!$C$6:$Q$58,F$5,0) -> 0 | G9: =VLOOKUP($C9,'A. All deals (a)'!$C$6:$Q$58,G$5,0) -> Mozn | H9: =VLOOKUP($C9,'A. All deals (a)'!$C$6:$Q$58,H$5,0) -> 2023 | I9: =VLOOKUP($C9,'A. All deals (a)'!$C$6:$Q$58,I$5,0) -> Tokens | J9: =VLOOKUP($C9,'A. All deals (a)'!$C$6:$Q$58,J$5,0) -> 0.00625 | K9: =VLOOKUP($C9,'A. All deals (a)'!$C$6:$Q$58,K$5,0) -> 0.006875 | L9: =VLOOKUP($C9,'A. All deals (a)'!$C$6:$Q$58,L$5,0) -> 0.006875 | ... P9: =VLOOKUP($C9,'A. All deals (a)'!$C$6:$Q$58,P$5,0) -> 99.993125 | Q9: n/a | R9: =VLOOKUP($C9,'A. All deals (a)'!$C$6:$Q$58,R$5,0) -> NM | S9: Full Exit for Inveniam SAR
C10: X-fusion | D10: Direct Investment | E10: =VLOOKUP($C10,'A. All deals (a)'!$C$6:$Q$58,E$5,0) -> Realized | F10: =VLOOKUP($C10,'A. All deals (a)'!$C$6:$Q$58,F$5,0) -> 0 | G10: =VLOOKUP($C10,'A. All deals (a)'!$C$6:$Q$58,G$5,0) -> Mozn 2 | H10: =VLOOKUP($C10,'A. All deals (a)'!$C$6:$Q$58,H$5,0) -> 2022 | I10: =VLOOKUP($C10,'A. All deals (a)'!$C$6:$Q$58,I$5,0) -> Equity-TBC | J10: =VLOOKUP($C10,'A. All deals (a)'!$C$6:$Q$58,J$5,0) -> 0.051 | K10: =VLOOKUP($C10,'A. All deals (a)'!$C$6:$Q$58,K$5,0) -> 493.50096 | L10: =VLOOKUP($C10,'A. All deals (a)'!$C$6:$Q$58,L$5,0) -> 493.50096 | ... P10: =VLOOKUP($C10,'A. All deals (a)'!$C$6:$Q$58,P$5,0) -> -90.500956 | Q10: -64.391 | R10: =VLOOKUP($C10,'A. All deals (a)'!$C$6:$Q$58,R$5,0) -> 0.81661443 | S10: Full Exit
C11: Mena Mobile Inc (Debt) | D11: Debt Investment | E11: =VLOOKUP($C11,'A. All deals (a)'!$C$6:$Q$58,E$5,0) -> Written-off | F11: =VLOOKUP($C11,'A. All deals (a)'!$C$6:$Q$58,F$5,0) -> 0 | G11: =VLOOKUP($C11,'A. All deals (a)'!$C$6:$Q$58,G$5,0) -> Mozn | H11: =VLOOKUP($C11,'A. All deals (a)'!$C$6:$Q$58,H$5,0) -> 2021 | I11: =VLOOKUP($C11,'A. All deals (a)'!$C$6:$Q$58,I$5,0) -> Loan | J11: =VLOOKUP($C11,'A. All deals (a)'!$C$6:$Q$58,J$5,0) -> n/a | K11: =VLOOKUP($C11,'A. All deals (a)'!$C$6:$Q$58,K$5,0) -> 2.353982 | L11: =VLOOKUP($C11,'A. All deals (a)'!$C$6:$Q$58,L$5,0) -> 2.353982 | ... P11: =VLOOKUP($C11,'A. All deals (a)'!$C$6:$Q$58,P$5,0) -> -2.353982 | Q11: 0 | R11: =VLOOKUP($C11,'A. All deals (a)'!$C$6:$Q$58,R$5,0) -> 0 | S11: Written Off
C12: Esyasoft Holding (Debt) | D12: Debt Investment | E12: =VLOOKUP($C12,'A. All deals (a)'!$C$6:$Q$58,E$5,0) -> Realized | F12: =VLOOKUP($C12,'A. All deals (a)'!$C$6:$Q$58,F$5,0) -> 0 | G12: =VLOOKUP($C12,'A. All deals (a)'!$C$6:$Q$58,G$5,0) -> Mozn | H12: =VLOOKUP($C12,'A. All deals (a)'!$C$6:$Q$58,H$5,0) -> 2021 | I12: =VLOOKUP($C12,'A. All deals (a)'!$C$6:$Q$58,I$5,0) -> Loan | J12: =VLOOKUP($C12,'A. All deals (a)'!$C$6:$Q$58,J$5,0) -> n/a | K12: =VLOOKUP($C12,'A. All deals (a)'!$C$6:$Q$58,K$5,0) -> 0.411765 | L12: =VLOOKUP($C12,'A. All deals (a)'!$C$6:$Q$58,L$5,0) -> 0.411765 | ... P12: =VLOOKUP($C12,'A. All deals (a)'!$C$6:$Q$58,P$5,0) -> 0.05901965 | Q12: 0.05901965 | R12: =VLOOKUP($C12,'A. All deals (a)'!$C$6:$Q$58,R$5,0) -> 1.1433333 | S12: Full Exit
C13: Jysan Technologies | D13: Direct Investment | E13: =VLOOKUP($C13,'A. All deals (a)'!$C$6:$Q$58,E$5,0) -> Realized | F13: =VLOOKUP($C13,'A. All deals (a)'!$C$6:$Q$58,F$5,0) -> 0 | G13: =VLOOKUP($C13,'A. All deals (a)'!$C$6:$Q$58,G$5,0) -> Mozn 1 | H13: =VLOOKUP($C13,'A. All deals (a)'!$C$6:$Q$58,H$5,0) -> 2021 | I13: =VLOOKUP($C13,'A. All deals (a)'!$C$6:$Q$58,I$5,0) -> A (Ordinary Shares) | J13: =VLOOKUP($C13,'A. All deals (a)'!$C$6:$Q$58,J$5,0) -> 0.03 | K13: =VLOOKUP($C13,'A. All deals (a)'!$C$6:$Q$58,K$5,0) -> 20 | L13: =VLOOKUP($C13,'A. All deals (a)'!$C$6:$Q$58,L$5,0) -> 20 | ... P13: =VLOOKUP($C13,'A. All deals (a)'!$C$6:$Q$58,P$5,0) -> 4.5 | Q13: 0 | R13: =VLOOKUP($C13,'A. All deals (a)'!$C$6:$Q$58,R$5,0) -> 1.225 | S13: Full Exit
C14: Instadeep Limited | D14: Direct Investment | E14: =VLOOKUP($C14,'A. All deals (a)'!$C$6:$Q$58,E$5,0) -> Realized | F14: =VLOOKUP($C14,'A. All deals (a)'!$C$6:$Q$58,F$5,0) -> 0 | G14: =VLOOKUP($C14,'A. All deals (a)'!$C$6:$Q$58,G$5,0) -> Mozn | H14: =VLOOKUP($C14,'A. All deals (a)'!$C$6:$Q$58,H$5,0) -> 2021 | I14: =VLOOKUP($C14,'A. All deals (a)'!$C$6:$Q$58,I$5,0) -> B Prefs | J14: =VLOOKUP($C14,'A. All deals (a)'!$C$6:$Q$58,J$5,0) -> 0.011489406 | K14: =VLOOKUP($C14,'A. All deals (a)'!$C$6:$Q$58,K$5,0) -> 5.0237202 | L14: =VLOOKUP($C14,'A. All deals (a)'!$C$6:$Q$58,L$5,0) -> 5.0237202 | ... P14: =VLOOKUP($C14,'A. All deals (a)'!$C$6:$Q$58,P$5,0) -> 2.9184723 | Q14: 1.6721788 | R14: =VLOOKUP($C14,'A. All deals (a)'!$C$6:$Q$58,R$5,0) -> 1.5809385 | S14: Full Exit
C15: Esyasoft Holding | D15: Direct Investment | E15: =VLOOKUP($C15,'A. All deals (a)'!$C$6:$Q$58,E$5,0) -> Realized | F15: =VLOOKUP($C15,'A. All deals (a)'!$C$6:$Q$58,F$5,0) -> 0 | G15: =VLOOKUP($C15,'A. All deals (a)'!$C$6:$Q$58,G$5,0) -> Mozn | H15: =VLOOKUP($C15,'A. All deals (a)'!$C$6:$Q$58,H$5,0) -> 2020 | I15: =VLOOKUP($C15,'A. All deals (a)'!$C$6:$Q$58,I$5,0) -> Convertible Note | J15: =VLOOKUP($C15,'A. All deals (a)'!$C$6:$Q$58,J$5,0) -> n/a | K15: =VLOOKUP($C15,'A. All deals (a)'!$C$6:$Q$58,K$5,0) -> 2.5 | L15: =VLOOKUP($C15,'A. All deals (a)'!$C$6:$Q$58,L$5,0) -> 2.5 | ... P15: =VLOOKUP($C15,'A. All deals (a)'!$C$6:$Q$58,P$5,0) -> 2.5 | Q15: 2.5 | R15: =VLOOKUP($C15,'A. All deals (a)'!$C$6:$Q$58,R$5,0) -> 2 | S15: Full Exit
C16: Mena Mobile Inc | D16: Direct Investment | E16: =VLOOKUP($C16,'A. All deals (a)'!$C$6:$Q$58,E$5,0) -> Written-off | F16: =VLOOKUP($C16,'A. All deals (a)'!$C$6:$Q$58,F$5,0) -> 0 | G16: =VLOOKUP($C16,'A. All deals (a)'!$C$6:$Q$58,G$5,0) -> Mozn | H16: =VLOOKUP($C16,'A. All deals (a)'!$C$6:$Q$58,H$5,0) -> 2019 | I16: =VLOOKUP($C16,'A. All deals (a)'!$C$6:$Q$58,I$5,0) -> B Prefs | J16: =VLOOKUP($C16,'A. All deals (a)'!$C$6:$Q$58,J$5,0) -> 0.14 | K16: =VLOOKUP($C16,'A. All deals (a)'!$C$6:$Q$58,K$5,0) -> 8 | L16: =VLOOKUP($C16,'A. All deals (a)'!$C$6:$Q$58,L$5,0) -> 8 | ... P16: =VLOOKUP($C16,'A. All deals (a)'!$C$6:$Q$58,P$5,0) -> -8 | Q16: -8 | R16: =VLOOKUP($C16,'A. All deals (a)'!$C$6:$Q$58,R$5,0) -> 0 | S16: Written Off
C17: Glass Earth Holdings LLC | D17: Debt Investment | E17: =VLOOKUP($C17,'A. All deals (a)'!$C$6:$Q$58,E$5,0) -> Written-off | F17: =VLOOKUP($C17,'A. All deals (a)'!$C$6:$Q$58,F$5,0) -> 0 | G17: =VLOOKUP($C17,'A. All deals (a)'!$C$6:$Q$58,G$5,0) -> Mozn | H17: =VLOOKUP($C17,'A. All deals (a)'!$C$6:$Q$58,H$5,0) -> 2019 | I17: =VLOOKUP($C17,'A. All deals (a)'!$C$6:$Q$58,I$5,0) -> Promissory Note | J17: =VLOOKUP($C17,'A. All deals (a)'!$C$6:$Q$58,J$5,0) -> n/a | K17: =VLOOKUP($C17,'A. All deals (a)'!$C$6:$Q$58,K$5,0) -> 8 | L17: =VLOOKUP($C17,'A. All deals (a)'!$C$6:$Q$58,L$5,0) -> 8 | ... P17: =VLOOKUP($C17,'A. All deals (a)'!$C$6:$Q$58,P$5,0) -> -8 | Q17: -8 | R17: =VLOOKUP($C17,'A. All deals (a)'!$C$6:$Q$58,R$5,0) -> 0 | S17: =VLOOKUP($C17,'A. All deals (a)'!$C$6:$Q$58,S$5,0) -> In Default
C18: Jollychic Holding Limited | D18: Direct Investment | E18: =VLOOKUP($C18,'A. All deals (a)'!$C$6:$Q$58,E$5,0) -> Written-off | F18: =VLOOKUP($C18,'A. All deals (a)'!$C$6:$Q$58,F$5,0) -> 0 | G18: =VLOOKUP($C18,'A. All deals (a)'!$C$6:$Q$58,G$5,0) -> Mozn | H18: =VLOOKUP($C18,'A. All deals (a)'!$C$6:$Q$58,H$5,0) -> 2019 | I18: =VLOOKUP($C18,'A. All deals (a)'!$C$6:$Q$58,I$5,0) -> C+ Prefs | J18: =VLOOKUP($C18,'A. All deals (a)'!$C$6:$Q$58,J$5,0) -> 0.056999998 | K18: =VLOOKUP($C18,'A. All deals (a)'!$C$6:$Q$58,K$5,0) -> 65 | L18: =VLOOKUP($C18,'A. All deals (a)'!$C$6:$Q$58,L$5,0) -> 65 | ... P18: =VLOOKUP($C18,'A. All deals (a)'!$C$6:$Q$58,P$5,0) -> -65 | Q18: -65 | R18: =VLOOKUP($C18,'A. All deals (a)'!$C$6:$Q$58,R$5,0) -> 0 | S18: =VLOOKUP($C18,'A. All deals (a)'!$C$6:$Q$58,S$5,0) -> In Liquidation
K20: =SUM(K9:K18) -> 604.7973 | L20: =SUM(L9:L18) -> 604.7973 | M20: =SUM(M9:M18) -> 0 | N20: =SUM(N9:N18) -> 540.91298 | O20: =SUM(O9:O18) -> 0 | P20: =SUM(P9:P18) -> -63.884321 | Q20: =SUM(Q10:Q18) -> -141.1598 | R20: =(N20+O20)/L20 -> 0.89437069
C22: G42 Investments AI Holding RSC Ltd
C23: Honor Device Co Ltd | D23: Direct Investment | E23: =VLOOKUP($C23,'A. All deals (a)'!$C$6:$Q$58,E$5,0) -> Realized | F23: =VLOOKUP($C23,'A. All deals (a)'!$C$6:$Q$58,F$5,0) -> 0 | G23: =VLOOKUP($C23,'A. All deals (a)'!$C$6:$Q$58,G$5,0) -> G42 3 | H23: =VLOOKUP($C23,'A. All deals (a)'!$C$6:$Q$58,H$5,0) -> 2022 | I23: =VLOOKUP($C23,'A. All deals (a)'!$C$6:$Q$58,I$5,0) -> Equity-TBC | J23: =VLOOKUP($C23,'A. All deals (a)'!$C$6:$Q$58,J$5,0) -> 0.018823528 | K23: =VLOOKUP($C23,'A. All deals (a)'!$C$6:$Q$58,K$5,0) -> 800 | L23: =VLOOKUP($C23,'A. All deals (a)'!$C$6:$Q$58,L$5,0) -> 800 | ... P23: =VLOOKUP($C23,'A. All deals (a)'!$C$6:$Q$58,P$5,0) -> 2.8 | Q23: 54.67 | R23: =VLOOKUP($C23,'A. All deals (a)'!$C$6:$Q$58,R$5,0) -> 1.0035
C24: Sinovation Disrupt Fund, L.P. | D24: Fund Investment | E24: =VLOOKUP($C24,'A. All deals (a)'!$C$6:$Q$58,E$5,0) -> Realized | F24: =VLOOKUP($C24,'A. All deals (a)'!$C$6:$Q$58,F$5,0) -> 0 | G24: =VLOOKUP($C24,'A. All deals (a)'!$C$6:$Q$58,G$5,0) -> G42 Investments | H24: =VLOOKUP($C24,'A. All deals (a)'!$C$6:$Q$58,H$5,0) -> 2020 | I24: =VLOOKUP($C24,'A. All deals (a)'!$C$6:$Q$58,I$5,0) -> LP | J24: =VLOOKUP($C24,'A. All deals (a)'!$C$6:$Q$58,J$5,0) -> n/a | K24: =VLOOKUP($C24,'A. All deals (a)'!$C$6:$Q$58,K$5,0) -> 50 | L24: =VLOOKUP($C24,'A. All deals (a)'!$C$6:$Q$58,L$5,0) -> 24.959693 | ... P24: =VLOOKUP($C24,'A. All deals (a)'!$C$6:$Q$58,P$5,0) -> 0.44382835 | Q24: -1.265 | R24: =VLOOKUP($C24,'A. All deals (a)'!$C$6:$Q$58,R$5,0) -> 1.0177818
K26: =SUM(K23:K24) -> 850 | L26: =SUM(L23:L24) -> 824.95969 | M26: =SUM(M23:M24) -> 0 | N26: =SUM(N23:N24) -> 828.20352 | O26: =SUM(O23:O24) -> 0 | P26: =SUM(P23:P24) -> 3.2438283 | Q26: =SUM(Q23:Q24) -> 53.405 | R26: =(N26+O26)/L26 -> 1.0039321 | S26: =O26+N26-L26 -> 3.2438283
C28: G42 Capital SPV RSC Ltd
C32: Core42 Holding RSC Ltd
K36: =K20+K26+K30+K34 -> 1454.7973 | L36: =L20+L26+L30+L34 -> 1429.757 | M36: =M20+M26+M30+M34 -> 0 | N36: =N20+N26+N30+N34 -> 1369.1165 | O36: =O20+O26+O30+O34 -> 0 | P36: =P20+P26+P30+P34 -> -60.640493 | Q36: =Q20+Q26+Q30+Q34 -> -87.754802 | R36: =(N36+O36)/L36 -> 0.95758685
C40: For Notes, refer to 9. All deals (a)
C41: Position Exited or written off are highlighted

Sheet CF (Equity, Debt)
B2: E Q U I T Y
B3: Accounting entity | C3: Investment | D3: Payment date | E3: Contributions (in USD, Mn) | F3: Distributions (in USD, Mn) | G3: Currency | H3: Investment / Exit Amt (investee currency) | I3: Investment / Exit Amount (USD) | J3: Consideration (shares) | K3: Comment | N3: NOTES
B4: =VLOOKUP(C4,'A. All deals (a)'!$C$9:$F$49,4,0) -> Mozn | C4: Jollychic Holding Limited | D4: 43470 | E4: =-I4*10^-6 -> -30 | G4: USD | H4: 30000000 | I4: =H4 -> 30000000 | J4: 6100312 | N4: USD AED | O4: 3.678
B5: =VLOOKUP(C5,'A. All deals (a)'!$C$9:$F$49,4,0) -> Mozn | C5: Jollychic Holding Limited | D5: 43724 | E5: =-I5*10^-6 -> -20 | G5: USD | H5: 20000000 | I5: =H5 -> 20000000 | J5: 4204767.4
B6: =VLOOKUP(C6,'A. All deals (a)'!$C$9:$F$49,4,0) -> Mozn | C6: Jollychic Holding Limited | D6: 43724 | E6: =-I6*10^-6 -> -15 | G6: USD | H6: 15000000 | I6: =H6 -> 15000000 | J6: 3153575.6
B7: =VLOOKUP(C7,'A. All deals (a)'!$C$9:$F$49,4,0) -> Mozn | C7: Mena Mobile Inc | D7: 43563 | E7: =-I7*10^-6 -> -8 | G7: USD | H7: 8000000 | I7: =H7 -> 8000000 | J7: 21419829
B8: =VLOOKUP(C8,'A. All deals (a)'!$C$9:$F$49,4,0) -> Mozn | C8: Flyr Inc | D8: 43570 | E8: =-I8*10^-6 -> -4.9999981 | G8: USD | H8: 4999998.1 | I8: =H8 -> 4999998.1 | J8: 2625467
B9: =VLOOKUP(C9,'A. All deals (a)'!$C$9:$F$49,4,0) -> Mozn | C9: Flyr Inc | D9: 43915 | E9: =-I9*10^-6 -> -5.0000019 | G9: USD | H9: =10000000-H8 -> 5000001.9 | I9: =H9 -> 5000001.9 | J9: 2580015
B10: =VLOOKUP(C10,'A. All deals (a)'!$C$9:$F$49,4,0) -> Mozn | C10: Esyasoft Holding | D10: 43870 | E10: =-I10*10^-6 -> -2.5 | G10: USD | H10: 2500000 | I10: =H10 -> 2500000 | J10: N/A
B11: =VLOOKUP(C11,'A. All deals (a)'!$C$9:$F$49,4,0) -> Mozn | C11: Beyond Limits | D11: 43879 | E11: =-I11*10^-6 -> -20 | G11: USD | H11: 20000000 | I11: =H11 -> 20000000 | J11: 4084038
B12: =VLOOKUP(C12,'A. All deals (a)'!$C$9:$F$49,4,0) -> Mozn | C12: Beyond Limits | D12: 43921 | E12: =-I12*10^-6 -> -30 | G12: USD | H12: 30000000 | I12: =H12 -> 30000000 | J12: 5822642
B13: =VLOOKUP(C13,'A. All deals (a)'!$C$9:$F$49,4,0) -> Mozn | C13: Beyond Limits | D13: 43989 | E13: =-I13*10^-6 -> -30 | G13: USD | H13: 30000000 | I13: =H13 -> 30000000 | J13: 5822642
B14: =VLOOKUP(C14,'A. All deals (a)'!$C$9:$F$49,4,0) -> Mozn | C14: Beyond Limits | D14: 44103 | E14: =-I14*10^-6 -> -10 | G14: USD | H14: 10000000 | I14: =H14 -> 10000000 | J14: 1940880
B15: =VLOOKUP(C15,'A. All deals (a)'!$C$9:$F$49,4,0) -> Mozn | C15: ONT plc | D15: 43968 | E15: =-I15*10^-6 -> -50 | G15: USD | H15: 50000000 | I15: 50000000 | J15: 15277680
B16: =VLOOKUP(C16,'A. All deals (a)'!$C$9:$F$49,4,0) -> Mozn | C16: ONT plc | D16: 44006 | E16: =-I16*10^-6 -> -27.268351 | G16: GBP | H16: 21029625 | I16: 27268351 | J16: 9000000
B17: =VLOOKUP(C17,'A. All deals (a)'!$C$9:$F$49,4,0) -> Mozn | C17: ONT plc | D17: 43837 | E17: =-I17*10^-6 -> -18.109441 | G17: GBP | H17: 14386480 | I17: 18109441 | J17: 6362180
B18: =VLOOKUP(C18,'A. All deals (a)'!$C$9:$F$49,4,0) -> Mozn | C18: ONT plc | D18: 43990 | E18: =-I18*10^-6 -> -34.851687 | G18: GBP | H18: 26085573 | I18: 34851687 | J18: 11381140
B19: =VLOOKUP(C19,'A. All deals (a)'!$C$9:$F$49,4,0) -> Mozn | C19: ONT plc | D19: 44315 | E19: =-I19*10^-6 -> -11.24078 | G19: GBP | H19: 8074920 | I19: 11240780 | J19: 2307120
B20: =VLOOKUP(C20,'A. All deals (a)'!$C$9:$F$49,4,0) -> Mozn | C20: Heygears | D20: 44166 | E20: =-I20*10^-6 -> -60 | G20: USD | H20: 60000000 | I20: =H20 -> 60000000 | J20: 3565017.2
B21: =VLOOKUP(C21,'A. All deals (a)'!$C$9:$F$49,4,0) -> Mozn 1 | C21: Jysan Technologies | D21: 44363 | E21: =-I21*10^-6 -> -20 | G21: USD | H21: 20000000 | I21: =H21 -> 20000000 | J21: 7959497
B22: =VLOOKUP(C22,'A. All deals (a)'!$C$9:$F$49,4,0) -> Mozn | C22: Cerebras Systems Inc | D22: 44488 | E22: =-I22*10^-6 -> -39.999983 | G22: USD | H22: 39999983 | I22: =H22 -> 39999983 | J22: 1441711
B23: =VLOOKUP(C23,'A. All deals (a)'!$C$9:$F$49,4,0) -> Mozn | C23: Endless Studios LLC | D23: 44494 | E23: =-I23*10^-6 -> -3 | G23: USD | H23: 3000000 | I23: =H23 -> 3000000 | J23: 3000000
B24: =VLOOKUP(C24,'A. All deals (a)'!$C$9:$F$49,4,0) -> Mozn | C24: Instadeep Limited | D24: 44550 | E24: =-I24*10^-6 -> -5.0237202 | G24: GBP | H24: 3679995.5 | I24: 5023720.2 | J24: 33267
B25: =VLOOKUP(C25,'A. All deals (a)'!$C$9:$F$49,4,0) -> Mozn 2 | C25: X-fusion | D25: 44574 | E25: =-I25*10^-6 -> -493.50096 | G25: USD | H25: 8.9350096e+08 | I25: 4.9350096e+08
B26: =VLOOKUP(C26,'A. All deals (a)'!$C$9:$F$49,4,0) -> G42 Investments | C26: DriveNets | D26: 44643 | E26: =-I26*10^-6 -> -200 | G26: USD | H26: 200000000 | I26: =H26 -> 200000000
B27: =VLOOKUP(C27,'A. All deals (a)'!$C$9:$F$49,4,0) -> G42 Investments | C27: DriveNets | D27: 44680 | E27: =-I27*10^-6 -> -100 | G27: USD | H27: 100000000 | I27: =H27 -> 100000000
B28: =VLOOKUP(C28,'A. All deals (a)'!$C$9:$F$49,4,0) -> Mozn | C28: Esyasoft Holding | D28: 44691 | F28: 5 | G28: USD
B29: =VLOOKUP(C29,'A. All deals (a)'!$C$9:$F$49,4,0) -> G42 Investments | C29: vTv Therapeutics Inc. | D29: 44712 | E29: =-I29*10^-6 -> -12.5 | G29: USD | H29: 12500000 | I29: =H29 -> 12500000 | J29: ='B. %'!D22 -> 259657
B30: =VLOOKUP(C30,'A. All deals (a)'!$C$9:$F$49,4,0) -> G42 3 | C30: Honor Device Co Ltd | D30: 44769 | E30: =-I30*10^-6 -> -600 | G30: USD | H30: 600000000 | I30: =H30 -> 600000000
B31: =VLOOKUP(C31,'A. All deals (a)'!$C$9:$F$49,4,0) -> G42 3 | C31: Honor Device Co Ltd | D31: 44849 | E31: =-I31*10^-6 -> -200 | G31: USD | H31: 200000000 | I31: =H31 -> 200000000
B32: =VLOOKUP(C32,'A. All deals (a)'!$C$9:$F$49,4,0) -> Mozn | C32: Applied AI Corporation Limited | D32: 44861 | E32: =-I32*10^-6 -> -4.75 | G32: USD | H32: 4750000 | I32: =H32 -> 4750000
B33: =VLOOKUP(C33,'A. All deals (a)'!$C$9:$F$49,4,0) -> Mozn 4 | C33: eSpace | D33: 44892 | E33: =-I33*10^-6 -> -15 | G33: USD | H33: 15000000 | I33: =H33 -> 15000000
B34: =VLOOKUP(C34,'A. All deals (a)'!$C$9:$F$49,4,0) -> G42 Investments | C34: vTv Therapeutics Inc. | D34: 44985 | E34: =-I34*10^-6 -> -12.03125 | G34: USD | H34: 12031250 | I34: =H34 -> 12031250 | J34: 10386274
B35: =VLOOKUP(C35,'A. All deals (a)'!$C$9:$F$49,4,0) -> Mozn | C35: Tools for Humanity Corporation | D35: 45075 | E35: =-I35*10^-6 -> -14.999999 | G35: USD | H35: 14999999 | I35: =H35 -> 14999999
B36: =VLOOKUP(C36,'A. All deals (a)'!$C$9:$F$49,4,0) -> Mozn | C36: WLD Tokens | D36: 45075 | E36: =-I36*10^-6 -> -0.005875 | G36: USD | I36: 5875
B37: =VLOOKUP(C37,'A. All deals (a)'!$C$9:$F$49,4,0) -> Mozn | C37: WLD Tokens | D37: 45114 | E37: =-I37*10^-6 -> -0.001 | G37: USD | I37: 1000
B38: =VLOOKUP(C38,'A. All deals (a)'!$C$9:$F$49,4,0) -> Mozn | C38: Applied AI Corporation Limited | D38: 45121 | E38: =-I38*10^-6 -> -2.75 | G38: USD | I38: 2750000
B39: =VLOOKUP(C39,'A. All deals (a)'!$C$9:$F$49,4,0) -> Mozn | C39: Instadeep Limited | D39: 45138 | F39: =I39*10^-6 -> 7.8207761 | G39: USD | H39: 6090345.2 | I39: 7820776.1
B40: =VLOOKUP(C40,'A. All deals (a)'!$C$9:$F$49,4,0) -> Mozn 1 | C40: Jysan Technologies | D40: 45149 | F40: 24.5 | G40: USD | I40: 24500000 | J40: 7959497
B41: =VLOOKUP(C41,'A. All deals (a)'!$C$9:$F$49,4,0) -> Mozn | C41: Endless Studios LLC | D41: 45167 | E41: =-I41*10^-6 -> -5 | G41: USD | I41: 5000000 | J41: 5000000
...

Sheet CF (Funds)
B2: F U N D S
B3: Entity | C3: Investment | D3: Payment date | E3: Contributions (USD, Mn) | F3: Distributions (USD, Mn) | G3: Currency | H3: Cashflows | I3: Description | J3: TEST
B4: G42 | C4: Sinovation Disrupt Fund, L.P. | D4: 44153 | E4: =H4 -> -10.5 | G4: USD | H4: -10.5 | I4: 1st Capital Call | J4: =SUM(E4:E65) -> -148.74911
B5: G42 | C5: Sinovation Disrupt Fund, L.P. | D5: 44238 | E5: =H5 -> 4.214027 | G5: USD | H5: 4.214027 | I5: Partial return of the 1st Capital Call | J5: ='A. All deals (a)'!K50 -> 145.86212
B6: G42 | C6: Sinovation Disrupt Fund, L.P. | D6: 44238 | F6: =H6 -> 0.05044835 | G6: USD | H6: 0.05044835 | I6: Interest Catchup | J6: =ROUND(J5,5)=-ROUND(J4,5) -> FALSE
B7: G42 | C7: Sinovation Disrupt Fund, L.P. | D7: 44285 | E7: =H7 -> -6.433746 | G7: USD | H7: -6.433746 | I7: 2nd Capital Calll
B8: G42 | C8: Sinovation Disrupt Fund, L.P. | D8: 44269 | E8: =H8 -> 1.1352074 | G8: USD | H8: 1.1352074 | I8: Return of Capital fund
B9: G42 | C9: Sinovation Disrupt Fund, L.P. | D9: 44269 | F9: =H9 -> 0.0259 | G9: USD | H9: 0.0259 | I9: Interest Catchup
B10: G42 | C10: Sinovation Disrupt Fund, L.P. | D10: 44483 | E10: =H10 -> -7.567138 | G10: USD | H10: -7.567138 | I10: 3rd Capital Call
B11: G42 | C11: Sinovation Disrupt Fund, L.P. | D11: 44554 | E11: =H11 -> -7.385016 | G11: USD | H11: -7.385016 | I11: 4th Capital Call
B12: G42 | C12: Sinovation Disrupt Fund, L.P. | D12: 44554 | E12: =H12 -> 4.0733456 | G12: USD | H12: 4.0733456 | I12: Return of Capital fund
B13: G42 | C13: Sinovation Disrupt Fund, L.P. | D13: 44554 | F13: =H13 -> 0.139694 | G13: USD | H13: 0.139694 | I13: Interest Catchup
B14: G42 | C14: Sinovation Disrupt Fund, L.P. | D14: 44703 | E14: =H14 -> 5.673074 | G14: USD | H14: 5.673074 | I14: Return of Capital fund
B15: G42 | C15: Sinovation Disrupt Fund, L.P. | D15: 44703 | F15: =H15 -> 0.227786 | G15: USD | H15: 0.227786 | I15: Interest Catchup
B16: G42 | C16: Sinovation Disrupt Fund, L.P. | D16: 44776 | E16: =H16 -> -3.235493 | G16: USD | H16: -3.235493 | I16: 5th Capital Call
B17: G42 | C17: Sinovation Disrupt Fund, L.P. | D17: 44960 | E17: =H17 -> -2.631528 | G17: USD | H17: -2.631528 | I17: 6th Capital Call
B18: G42 | C18: Sinovation Disrupt Fund, L.P. | D18: 45085 | E18: =H18 -> 1.912557 | G18: USD | H18: 1.912557 | I18: Return of Capital fund
B19: G42 | C19: Sinovation Disrupt Fund, L.P. | D19: 45166 | E19: -1.799122 | G19: USD | H19: -1.799122 | I19: 7th Capital Call
B20: G42 | C20: Sinovation Disrupt Fund, L.P. | D20: 45218 | E20: -2.415861 | G20: USD | H20: -2.415861 | I20: 8th Capital Call
B21: G42 | C21: Sinovation Disrupt Fund, L.P. | D21: 45323 | F21: =24.959693 -> 24.959693 | G21: USD | H21: =F21 -> 24.959693 | I21: Exit Proceeds (full and final)
B22: G42 | C22: North Summit Capital Fund | D22: 43665 | E22: =H22 -> -3 | G22: USD | H22: -3 | I22: 1st Capital Call
B23: G42 | C23: North Summit Capital Fund | D23: 43983 | E23: =H23 -> -4.485 | G23: USD | H23: -4.485 | I23: 2nd Capital Calll
B24: G42 | C24: North Summit Capital Fund | D24: 43879 | E24: =H24 -> -9.50975 | G24: USD | H24: -9.50975 | I24: 3rd Capital Call
B25: G42 | C25: North Summit Capital Fund | D25: 43934 | E25: =H25 -> -41.3 | G25: USD | H25: -41.3 | I25: 4th Capital Call
B26: G42 | C26: North Summit Capital Fund | D26: 44151 | E26: =H26 -> 9.95 | G26: USD | H26: 9.95 | I26: 5th Capital Call-Partial return of the 4th Capital Call
B27: G42 | C27: North Summit Capital Fund | D27: 44151 | E27: =H27 -> -10.455 | G27: USD | H27: -10.455 | I27: 5th Capital Call
B28: G42 | C28: North Summit Capital Fund | D28: 44196 | E28: =H28 -> 4.975 | G28: USD | H28: 4.975 | I28: 6th Capital Call-Partial return of the 4th Capital Call
B29: G42 | C29: North Summit Capital Fund | D29: 44196 | E29: =H29 -> -3.452293 | G29: USD | H29: -3.452293 | I29: 6th Capital Call
B30: G42 | C30: North Summit Capital Fund | D30: 44196 | F30: =H30 -> 0.582902 | G30: USD | H30: 0.582902 | I30: 6th Capital Call-Dividends from Project Topscore
B31: G42 | C31: North Summit Capital Fund | D31: 44370 | E31: =H31 -> -5.97 | G31: USD | H31: -5.97 | I31: 7th Capital Call
B32: G42 | C32: North Summit Capital Fund | D32: 44400 | E32: =H32 -> -0.75 | G32: USD | H32: -0.75 | I32: 8th Capital Call
B33: G42 | C33: North Summit Capital Fund | D33: 44400 | F33: =H33 -> 0.445059 | G33: USD | H33: 0.445059 | I33: 8th Capital Call-Dividends from Project Topscore
B34: G42 | C34: North Summit Capital Fund | D34: 44554 | E34: =H34 -> 1.78239 | G34: USD | H34: 1.78239 | I34: 9th Capital Call-Return of Capital Fund
B35: G42 | C35: North Summit Capital Fund | D35: 44676 | E35: =H35 -> -21 | G35: USD | H35: -21 | I35: 12th Capital Call
B36: G42 | C36: North Summit Capital Fund | D36: 45243 | F36: =H36 -> 6.78791 | G36: USD | H36: 6.78791 | I36: 13th Capital Call & Distribution #4
B37: G42 | C37: North Summit Capital Fund | D37: 45470 | E37: =H37 -> -0.055697 | G37: USD | H37: =-55697*10^-6 -> -0.055697 | I37: 14th Capital Call
B38: G42 | C38: North Summit Capital Fund | D38: 45611 | E38: =H38 -> -0.031561 | G38: USD | H38: =-31561*10^-6 -> -0.031561 | I38: 15th Capital Call
B39: G42 | C39: New Space Capital Fund I | D39: 44087 | E39: =H39*1.1 -> -20.917553 | G39: EUR | H39: -19.015957 | I39: Drawdown1
B40: G42 | C40: New Space Capital Fund I | D40: 44287 | E40: -0.21103182 | G40: EUR | H40: -0.21103182 | I40: Drawdown2
B41: G42 | C41: New Space Capital Fund I | D41: 44442 | E41: =1.18*H41 -> -0.23965473 | G41: EUR | H41: =-203097.23*10^-6 -> -0.20309723 | I41: Drawdown3
...

Sheet NAV
B2: NAV Date | C2: ='A. All deals (a)'!D2 -> 45900
B5: Investments | C5: Investing Entity | D5: Instrument | E5: Carrying Value | F5: Current Shares/Units | H5: Comment
E6: USD, Million | F6: # | G6: USD
E7: ="NAV | "& TEXT(C2,"dd")&" "&TEXT(C2,"mmm")&" "&TEXT(C2,"yyyy") -> NAV | 31 Aug 2025 | G7: ="PPS |" & TEXT(C2,"dd")&" "&TEXT(C2,"mmm")&" "&TEXT(C2,"yyyy") -> PPS |31 Aug 2025
B9: Direct Investments
B10: ='A. All deals (a)'!C9 -> Jollychic Holding Limited | C10: ='A. All deals (a)'!F9 -> Mozn | D10: ='A. All deals (a)'!H9 -> C+ Prefs | E10: =F10*G10*10^-6 -> 0 | F10: =VLOOKUP(B10,'B. %'!$C$6:$I$42,2,0) -> 13458655 | H10: In liquidation
B11: ='A. All deals (a)'!C10 -> Mena Mobile Inc | C11: ='A. All deals (a)'!F10 -> Mozn | D11: ='A. All deals (a)'!H10 -> B Prefs | E11: 0 | F11: =VLOOKUP(B11,'B. %'!$C$6:$I$42,2,0) -> 21419829 | H11: As per 3rd Party | Ardent Estimates | Equity written off | K11: =STOCKHISTORY(J18,$K$16,$K$16,0,0)
B12: ='A. All deals (a)'!C11 -> Flyr Inc | C12: ='A. All deals (a)'!F11 -> Mozn | D12: ='A. All deals (a)'!H11 -> B-1,2 Prefs | E12: =F12*G12*10^-6 -> 28.213712 | F12: =VLOOKUP(B12,'B. %'!$C$6:$I$42,2,0) -> 5205482 | G12: 5.42 | H12: As per the recent fund raise for Series D
B13: ='A. All deals (a)'!C12 -> Esyasoft Holding | C13: ='A. All deals (a)'!F12 -> Mozn | D13: ='A. All deals (a)'!H12 -> Convertible Note | E13: 0 | F13: =VLOOKUP(B13,'B. %'!$C$6:$I$42,2,0) -> n/a | H13: Exited at $5m (10th May) | Residual value = 0
B14: ='A. All deals (a)'!C13 -> Beyond Limits | C14: ='A. All deals (a)'!F13 -> Mozn | D14: ='A. All deals (a)'!H13 -> C Prefs | E14: =F14*G14/2/1000000 -> 41.003704 | F14: =VLOOKUP(B14,'B. %'!$C$6:$I$42,2,0) -> 17670202 | G14: 4.641 | H14: Marked down as per new round discussion Aug'24
B15: ='A. All deals (a)'!C14 -> ONT plc | C15: ='A. All deals (a)'!F14 -> Mozn | D15: ='A. All deals (a)'!H14 -> Ordinary Shares | E15: =F15*G15*10^-6 -> 108.27998 | F15: =VLOOKUP(B15,'B. %'!$C$6:$I$42,2,0) -> 44328120 | G15: =L18*L21/100 -> 2.4426927 | H15: Listed & marked to market | K15: =TEXT(K16,"ddd") -> Sun | R15: Heygears Oct 22
B16: ='A. All deals (a)'!C15 -> Heygears | C16: ='A. All deals (a)'!F15 -> Mozn | D16: ='A. All deals (a)'!H15 -> Registered Capital | E16: 40.3 | F16: ='CF (Equity, Debt)'!J20 -> 3565017.2 | H16: As per 3rd Party Ardent Estimates | Equity marked down | J16: Updated as on: | K16: =C2 -> 45900 | L16: source | R16: Post Valuation closed in June 2021 (RMB) | S16: 7500000000
B17: ='A. All deals (a)'!C16 -> Jysan Technologies | C17: ='A. All deals (a)'!F16 -> Mozn 1 | D17: ='A. All deals (a)'!H16 -> A (Ordinary Shares) | E17: 0 | F17: =VLOOKUP(B17,'B. %'!$C$6:$I$42,2,0) -> 7959497 | G17: =E17*10^6/F17 -> 0 | H17: Exited at $24.5m | R17: G42 Stake | S17: 0.143832
B18: ='A. All deals (a)'!C17 -> Cerebras Systems Inc | C18: ='A. All deals (a)'!F17 -> Mozn | D18: ='A. All deals (a)'!H17 -> F Prefs | E18: =F18*G18*10^-6 -> 21.135483 | F18: =VLOOKUP(B18,'B. %'!$C$6:$I$42,2,0) -> 1441711 | G18: 14.66 | H18: Marked down to the latest round | J18: ONT | K18: 45898 | L18: 180.9 | R18: G42 Valuation before Discount (RMB) | S18: 1078740000
B19: ='A. All deals (a)'!C18 -> Endless Studios LLC | C19: ='A. All deals (a)'!F18 -> Mozn | D19: ='A. All deals (a)'!H18 -> A Pref Units | E19: 4.7 | F19: =VLOOKUP(B19,'B. %'!$C$6:$I$42,2,0) -> 8000000 | H19: Ardent Valuation as of 31 Dec 24 | J19: VTVT | K19: 45898 | L19: 15.2 | R19: Liquidity Discount | S19: 0
B20: ='A. All deals (a)'!C19 -> Instadeep Limited | C20: ='A. All deals (a)'!F19 -> Mozn | D20: ='A. All deals (a)'!H19 -> B Prefs | E20: =-'CF (Equity, Debt)'!E24*G20 -> 0 | F20: =VLOOKUP(B20,'B. %'!$C$6:$I$42,2,0) -> 33267 | G20: 0 | H20: Exited at 1.56X | Residual Value = 0 | J20: VRSSF | K20: 45898 | L20: 5.66 | R20: Minority Holding Discount | S20: 0
B21: ='A. All deals (a)'!C20 -> X-fusion | C21: ='A. All deals (a)'!F20 -> Mozn 2 | D21: ='A. All deals (a)'!H20 -> Equity-TBC | E21: 0 | F21: =VLOOKUP(B21,'B. %'!$C$6:$I$42,2,0) -> n/a | H21: Exited at 0.82X | J21: GBPUSD | K21: 45898 | L21: 1.3503 | R21: G42 Valuation (RMB) | S21: =S18*(1-S19)*(1-S20) -> 1078740000
B22: ='A. All deals (a)'!C21 -> DriveNets | C22: ='A. All deals (a)'!F21 -> G42 Investments | D22: ='A. All deals (a)'!H21 -> Equity-TBC | E22: =(24403771*4.5712+44523131*4.8118)*10^-6 -> 325.79092 | F22: =VLOOKUP(B22,'B. %'!$C$6:$I$42,2,0) -> 68926902 | H22: New round/Secondary sale Q1 25 | J22: USDCNY | K22: 45898 | L22: 7.1304 | R22: Exchange Rate (RMB/USD) | S22: =K22 -> 45898
B23: ='A. All deals (a)'!C22 -> vTv Therapeutics Inc. | C23: ='A. All deals (a)'!F22 -> G42 Investments | D23: ='A. All deals (a)'!H22 -> Ordinary Shares | E23: =(F23*G23)*10^-6 -> 3.9467864 | F23: =VLOOKUP(B23,'B. %'!$C$6:$I$42,2,0) -> 259657 | G23: =L19 -> 15.2 | H23: Listed & marked to market | J23: EURUSD | K23: 45898 | L23: 1.1684 | R23: G42 Valuation (USD) | S23: =S21/S22 -> 23502.985
B24: ='A. All deals (a)'!C23 -> Honor Device Co Ltd | C24: ='A. All deals (a)'!F23 -> G42 3 | D24: ='A. All deals (a)'!H23 -> Equity-TBC | E24: 0 | F24: =VLOOKUP(B24,'B. %'!$C$6:$I$42,2,0) -> 6.0685078e+08 | H24: Exited at 1.0X | R24: Investment Cost of G42 (USD) | S24: 60000000
B25: ='A. All deals (a)'!C24 -> Applied AI Corporation Limited | C25: ='A. All deals (a)'!F24 -> Mozn | D25: ='A. All deals (a)'!H24 -> A Prefs | E25: 38.46473 | F25: =VLOOKUP(B25,'B. %'!$C$6:$I$42,2,0) -> 211519 | H25: Held at 2.27X
B26: ='A. All deals (a)'!C25 -> eSpace | C26: ='A. All deals (a)'!F25 -> Mozn 4 | D26: ='A. All deals (a)'!H25 -> B Prefs | E26: =F26*G26*10^-6 -> 32.34128 | F26: =VLOOKUP(B26,'B. %'!$C$6:$I$42,2,0) -> 417846 | G26: 77.4 | H26: Marked up, as converted as per the latest priced round | J26: Checks
B27: ='A. All deals (a)'!C26 -> Tools for Humanity Corporation | C27: ='A. All deals (a)'!F26 -> Mozn | D27: ='A. All deals (a)'!H26 -> C Prefs | E27: 2.4 | F27: =VLOOKUP(B27,'B. %'!$C$6:$I$42,2,0) -> 65413 | H27: Ardent Valuation as of 31 Dec 24
B28: ='A. All deals (a)'!C27 -> WLD Tokens | C28: ='A. All deals (a)'!F27 -> Mozn | D28: ='A. All deals (a)'!H27 -> Tokens | E28: =F28*G28*10^-6 -> 0 | F28: 0 | G28: =K17 -> 0 | H28: source: coinmarket cap | J28: =SUM(E10:E35) -> 878.23664 | K28: =J28='A. All deals (a)'!N36 -> TRUE
B29: ='A. All deals (a)'!C28 -> E-line Ventures LLC | C29: ='A. All deals (a)'!F28 -> Mozn | D29: ='A. All deals (a)'!H28 -> B Prefs | E29: 15.3 | F29: =VLOOKUP(B29,'B. %'!$C$6:$I$42,2,0) -> 4477612 | H29: Ardent Valuation as of 31 Dec 24 | J29: =SUM(E38:E40) -> 0 | K29: =J29='A. All deals (a)'!N42 -> TRUE
B30: ='A. All deals (a)'!C29 -> School Hack (AIREV Holding Limited) | C30: ='A. All deals (a)'!F29 -> Core42 5 | D30: ='A. All deals (a)'!H29 -> Preferred Shares | E30: =MAX('A. All deals (a)'!K29,F30*G30*10^-6) -> 2.5 | F30: =VLOOKUP(B30,'B. %'!$C$6:$I$42,2,0) -> 25000 | H30: Held at cost | J30: =SUM(E43:E47) -> 106.52706 | K30: =J30='A. All deals (a)'!N50 -> TRUE
B31: ='A. All deals (a)'!C30 -> Life Biosciences LLC | C31: ='A. All deals (a)'!F30 -> G42 Capital | D31: ='A. All deals (a)'!H30 -> D Prefs | E31: =(F31*G31*10^-6) -> 40.947394 | F31: =VLOOKUP(B31,'B. %'!$C$6:$I$42,2,0) -> 14178755 | G31: 2.88794 | H31: Held at cost
B32: ='A. All deals (a)'!C31 -> Verses AI Inc | C32: ='A. All deals (a)'!F31 -> G42 Capital | D32: ='A. All deals (a)'!H31 -> Ordinary Shares | E32: =F32*L20*10^-6 -> 2.9127687 | F32: =VLOOKUP(B32,'B. %'!$C$6:$I$42,2,0) -> 514623.44 | H32: Listed & marked to market
B33: ='A. All deals (a)'!C32 -> Inveniam Ltd | C33: G42 Capital | D33: SAR | E33: 100 | F33: =VLOOKUP(B33,'B. %'!$C$6:$I$42,2,0) -> n/a | H33: Held at cost
B34: Liquid AI | C34: G42 Capital | D34: Series A | E34: ='CF (Equity, Debt)'!I56*10^-6 -> 19.999882 | F34: n/a | H34: Held at cost
B35: Neuralink | C35: G42 Capital | D35: Series E | E35: =50 -> 50 | F35: n/a | H35: Held at cost
B37: Debt Investments
