Workbook
Name Company: #REF!
Name Dates: #REF!
Name DetailedCapShares: #REF!
Name FAGroup: #REF!
Name IQ_CH: 110000
Name IQ_CQ: 5000
Name IQ_CY: 10000
Name IQ_DAILY: 500000
Name IQ_FH: 100000
Name IQ_FQ: 500
Name IQ_FY: 1000
Name IQ_LTM: 2000
Name IQ_MONTH: 15000
Name IQ_NTM: 6000
Name IQ_WEEK: 50000
Name IQ_YTD: 3000
Name UNLOCKED_PERCENT_FAST: _xludf.LAMBDA(start_date, date, IF(start_date="",0,MIN(1,MAX(0,(date-EDATE(start_date,12)+1)/(EDATE(start_date,36)-EDATE(start_date,12))))))
Name UNLOCKED_PERCENT_SLOW: _xludf.LAMBDA(start_date, date, IF(start_date="",0, MIN(1,MAX(0,(date-EDATE(start_date,12)+1)/(EDATE(start_date,60)-EDATE(start_date,12))))))

Sheet D1
B2: Date of NAV | D2: 46265 | E2: =TEXT(D2,"dddddd") -> Monday
H4: D A S H B O A R D
B6: L I V E D E A L S (includes unrealized or partially realized investments)
E8: # Investments | F8: Committed | G8: Invested | H8: Remaining | I8: Distributions | J8: Residual Value | K8: Gain | L8: TVPI | M8: DPI
E9: # | F9: USD, Mn | G9: USD, Mn | H9: USD, Mn | I9: USD, Mn | J9: USD, Mn | K9: USD, Mn | L9: X | M9: X
C11: EQUITY* | D11: Direct Investment | E11: =COUNTIF('1. Live'!$I$1:I110,$D11) -> 19 | F11: =SUMIF('1. Live'!$I$1:$I$110,$D11,'1. Live'!O$1:O$110) -> 988.60649 | G11: =SUMIF('1. Live'!$I$1:$I$110,$D11,'1. Live'!P$1:P$110) -> 988.35649 | H11: =SUMIF('1. Live'!$I$1:$I$110,$D11,'1. Live'!Q$1:Q$110) -> 0.25 | I11: =SUMIF('1. Live'!$I$1:$I$110,$D11,'1. Live'!R$1:R$110) -> 85.304451 | J11: =SUMIF('1. Live'!$I$1:$I$110,$D11,'1. Live'!S$1:S$110) -> 2175.5555 | K11: =SUMIF('1. Live'!$I$1:$I$110,$D11,'1. Live'!T$1:T$110) -> 1272.5035 | L11: =IFERROR((I11+J11)/G11,"") -> 2.2874944 | M11: =IFERROR(I11/G11,"") -> 0.086309396
C13: DEBT | D13: Debt Investment | E13: =COUNTIF('1. Live'!$I$1:I110,$D13) -> 0 | F13: =SUMIF('1. Live'!$I$1:$I$110,$D13,'1. Live'!O$1:O$110) -> 0 | G13: =SUMIF('1. Live'!$I$1:$I$110,$D13,'1. Live'!P$1:P$110) -> 0 | H13: =SUMIF('1. Live'!$I$1:$I$110,$D13,'1. Live'!Q$1:Q$110) -> 0 | I13: =SUMIF('1. Live'!$I$1:$I$110,$D13,'1. Live'!R$1:R$110) -> 0 | J13: =SUMIF('1. Live'!$I$1:$I$110,$D13,'1. Live'!S$1:S$110) -> 0 | K13: =SUMIF('1. Live'!$I$1:$I$110,$D13,'1. Live'!T$1:T$110) -> 0 | L13: =IFERROR((I13+J13)/G13,"") | M13: =IFERROR(I13/G13,"")
C15: FUNDS | D15: Fund Investment | E15: =COUNTIF('1. Live'!$I$1:I110,$D15) -> 4 | F15: =SUMIF('1. Live'!$I$1:$I$110,$D15,'1. Live'!O$1:O$110) -> 130.17124 | G15: =SUMIF('1. Live'!$I$1:$I$110,$D15,'1. Live'!P$1:P$110) -> 118.80356 | H15: =SUMIF('1. Live'!$I$1:$I$110,$D15,'1. Live'!Q$1:Q$110) -> 11.367673 | I15: =SUMIF('1. Live'!$I$1:$I$110,$D15,'1. Live'!R$1:R$110) -> 14.653505 | J15: =SUMIF('1. Live'!$I$1:$I$110,$D15,'1. Live'!S$1:S$110) -> 150.49907 | K15: =SUMIF('1. Live'!$I$1:$I$110,$D15,'1. Live'!T$1:T$110) -> 46.349013 | L15: =IFERROR((I15+J15)/G15,"") -> 1.3901315 | M15: =IFERROR(I15/G15,"") -> 0.1233423
C17: MGX | D17: MGX related | E17: 4 | F17: ='1. Live'!O52 -> 1881.4 | G17: ='1. Live'!P52 -> 705.75142 | H17: ='1. Live'!Q52 -> 1175.6486 | I17: ='1. Live'!R52 -> 14.688852 | J17: ='1. Live'!S52 -> 2216.6516 | K17: ='1. Live'!T52 -> 1510.9002 | L17: =IFERROR((I17+J17)/G17,"") -> 3.1616521 | M17: =IFERROR(I17/G17,"") -> 0.020813068
C19: TOTAL | E19: =E11+E13+E15 -> 23 | F19: =F11+F13+F15+F17 -> 3000.1777 | G19: =G11+G13+G15+G17 -> 1812.9115 | H19: =H11+H13+H15+H17 -> 1187.2663 | I19: =I11+I13+I15+I17 -> 114.64681 | J19: =J11+J13+J15+J17 -> 4542.7062 | K19: =K11+K13+K15+K17 -> 2829.7527 | L19: =IFERROR((I19+J19)/G19,"") -> 2.5689909 | M19: =IFERROR(I19/G19,"") -> 0.063239055
B22: E X I T E D D E A L S (includes liquidated, written-off or completely exited investments)
E24: # Investments | F24: Committed | G24: Invested | H24: Remaining | I24: Distributions | J24: Residual Value | K24: Gain | L24: TVPI | M24: DPI
E25: # | F25: USD, Mn | G25: USD, Mn | H25: USD, Mn | I25: USD, Mn | J25: USD, Mn | K25: USD, Mn | L25: X | M25: X
C27: EQUITY* | D27: Direct Investment | E27: =COUNTIF('2. Exited'!$D$1:D41,$D27) -> 8 | F27: =SUMIF('2. Exited'!$D$1:$D$41,$D27,'2. Exited'!K$1:K$41) -> 1394.0316 | G27: =SUMIF('2. Exited'!$D$1:$D$41,$D27,'2. Exited'!L$1:L$41) -> 1394.0316 | H27: =SUMIF('2. Exited'!$D$1:$D$41,$D27,'2. Exited'!M$1:M$41) -> 0 | I27: =SUMIF('2. Exited'!$D$1:$D$41,$D27,'2. Exited'!N$1:N$41) -> 1343.2422 | J27: =SUMIF('2. Exited'!$D$1:$D$41,$D27,'2. Exited'!O$1:O$41) -> 0 | K27: =SUMIF('2. Exited'!$D$1:$D$41,$D27,'2. Exited'!P$1:P$41) -> -50.789359 | L27: =IFERROR((I27+J27)/G27,"") -> 0.96356656 | M27: =IFERROR(I27/G27,"") -> 0.96356656
C29: DEBT | D29: Debt Investment | E29: =COUNTIF('2. Exited'!$D$1:D43,$D29) -> 3 | F29: =SUMIF('2. Exited'!$D$1:$D$41,$D29,'2. Exited'!K$1:K$41) -> 10.765747 | G29: =SUMIF('2. Exited'!$D$1:$D$41,$D29,'2. Exited'!L$1:L$41) -> 10.765747 | H29: =SUMIF('2. Exited'!$D$1:$D$41,$D29,'2. Exited'!M$1:M$41) -> 0 | I29: =SUMIF('2. Exited'!$D$1:$D$41,$D29,'2. Exited'!N$1:N$41) -> 0.47078465 | J29: =SUMIF('2. Exited'!$D$1:$D$41,$D29,'2. Exited'!O$1:O$41) -> 0 | K29: =SUMIF('2. Exited'!$D$1:$D$41,$D29,'2. Exited'!P$1:P$41) -> -10.294962 | L29: =IFERROR((I29+J29)/G29,"") -> 0.043729864 | M29: =IFERROR(I29/G29,"") -> 0.043729864
C31: FUNDS | D31: Fund Investment | E31: =COUNTIF('2. Exited'!$D$1:D45,$D31) -> 1 | F31: =SUMIF('2. Exited'!$D$1:$D$41,$D31,'2. Exited'!K$1:K$41) -> 50 | G31: =SUMIF('2. Exited'!$D$1:$D$41,$D31,'2. Exited'!L$1:L$41) -> 24.959693 | H31: =SUMIF('2. Exited'!$D$1:$D$41,$D31,'2. Exited'!M$1:M$41) -> 0 | I31: =SUMIF('2. Exited'!$D$1:$D$41,$D31,'2. Exited'!N$1:N$41) -> 25.403521 | J31: =SUMIF('2. Exited'!$D$1:$D$41,$D31,'2. Exited'!O$1:O$41) -> 0 | K31: =SUMIF('2. Exited'!$D$1:$D$41,$D31,'2. Exited'!P$1:P$41) -> 0.44382835 | L31: =IFERROR((I31+J31)/G31,"") -> 1.0177818 | M31: =IFERROR(I31/G31,"") -> 1.0177818
C33: TOTAL | E33: =E27+E29+E31 -> 12 | F33: =F27+F29+F31 -> 1454.7973 | G33: =G27+G29+G31 -> 1429.757 | H33: =H27+H29+H31 -> 0 | I33: =I27+I29+I31 -> 1369.1165 | J33: =J27+J29+J31 -> 0 | K33: =K27+K29+K31 -> -60.640493 | L33: =IFERROR((I33+J33)/G33,"") -> 0.95758685 | M33: =IFERROR(I33/G33,"") -> 0.95758685
B36: * Includes Convertibles
E38: CHECKS | F38: =ROUND(F19,5)=ROUND('1. Live'!O54,5) -> TRUE | G38: =ROUND(G19,5)=ROUND('1. Live'!P54,5) -> TRUE | H38: =ROUND(H19,5)=ROUND('1. Live'!Q54,5) -> TRUE | I38: =ROUND(I19,5)=ROUND('1. Live'!R54,5) -> TRUE | J38: =ROUND(J19,5)=ROUND('1. Live'!S54,5) -> TRUE | K38: =ROUND(K19,5)=ROUND('1. Live'!T54,5) -> TRUE
F39: =F33='2. Exited'!K36 -> TRUE | G39: =G33='2. Exited'!L36 -> TRUE | H39: =H33='2. Exited'!M36 -> TRUE | I39: =I33='2. Exited'!N36 -> TRUE | J39: =J33='2. Exited'!O36 -> TRUE | K39: =K33='2. Exited'!P36 -> TRUE
F40: TRUE | G40: TRUE | H40: TRUE | I40: TRUE | J40: TRUE | K40: TRUE

Sheet 1. Live
C2: As of date
C3: ='D1'!D2 -> 46265
J5: 2 | K5: 4 | L5: 5 | M5: 6 | N5: 7 | O5: 8 | P5: 9 | Q5: 10 | R5: 11 | S5: 12 | T5: 13 | U5: 14 | V5: 15
C6: Deals | D6: Key Person | E6: G42 Sponsor | F6: Geography | G6: Sector | H6: Last Series | I6: Type | J6: Status | K6: Investing Entity | L6: Vintageἀ | M6: Instrument | N6: % | O6: Committed | P6: Invested | Q6: Remaining Commitment | R6: Distributions | S6: Carrying Value | T6: Gain | U6: TVPI | V6: Additonal Upside/Downside
M7: # | N7: % | O7: $,m | P7: $,m | Q7: $,m | R7: $,m | S7: $,m | T7: $,m | U7: X
C8: MOZN Holding RSC Ltd
C9: E-line Ventures LLC | D9: Sushil | E9: Peng | F9: USA | G9: Education | H9: B Prefs | I9: Direct Investment | J9: =VLOOKUP($C9,'A. All deals (a)'!$C$6:$Q$58,J$5,0) -> Unrealized | K9: =VLOOKUP($C9,'A. All deals (a)'!$C$6:$Q$58,K$5,0) -> Mozn | L9: =VLOOKUP($C9,'A. All deals (a)'!$C$6:$Q$58,L$5,0) -> 2023 | M9: =VLOOKUP($C9,'A. All deals (a)'!$C$6:$Q$58,M$5,0) -> B Prefs | N9: =VLOOKUP($C9,'A. All deals (a)'!$C$6:$Q$58,N$5,0) -> 0.1163 | O9: =VLOOKUP($C9,'A. All deals (a)'!$C$6:$Q$58,O$5,0) -> 6 | P9: =VLOOKUP($C9,'A. All deals (a)'!$C$6:$Q$58,P$5,0) -> 6 | Q9: =VLOOKUP($C9,'A. All deals (a)'!$C$6:$Q$58,Q$5,0) -> 0 | ... U9: =VLOOKUP($C9,'A. All deals (a)'!$C$6:$Q$58,U$5,0) -> 1.1833333 | V9: Optionse
C10: Tools for Humanity Corporation | D10: Divyesh | E10: Peng | F10: USA | G10: Biometrics | H10: C Prefs | I10: Direct Investment | J10: =VLOOKUP($C10,'A. All deals (a)'!$C$6:$Q$58,J$5,0) -> Unrealized | K10: =VLOOKUP($C10,'A. All deals (a)'!$C$6:$Q$58,K$5,0) -> Mozn | L10: =VLOOKUP($C10,'A. All deals (a)'!$C$6:$Q$58,L$5,0) -> 2023 | M10: =VLOOKUP($C10,'A. All deals (a)'!$C$6:$Q$58,M$5,0) -> C Prefs | N10: =VLOOKUP($C10,'A. All deals (a)'!$C$6:$Q$58,N$5,0) -> 0.00626608 | O10: =VLOOKUP($C10,'A. All deals (a)'!$C$6:$Q$58,O$5,0) -> 14.999999 | P10: =VLOOKUP($C10,'A. All deals (a)'!$C$6:$Q$58,P$5,0) -> 14.999999 | Q10: =VLOOKUP($C10,'A. All deals (a)'!$C$6:$Q$58,Q$5,0) -> 0 | ... U10: =VLOOKUP($C10,'A. All deals (a)'!$C$6:$Q$58,U$5,0) -> 0.080000006
C11: eSpace | D11: Sushil | E11: Peng | F11: USA | G11: Space | H11: C Prefs | I11: Direct Investment | J11: =VLOOKUP($C11,'A. All deals (a)'!$C$6:$Q$58,J$5,0) -> Unrealized | K11: =VLOOKUP($C11,'A. All deals (a)'!$C$6:$Q$58,K$5,0) -> Mozn 4 | L11: =VLOOKUP($C11,'A. All deals (a)'!$C$6:$Q$58,L$5,0) -> 2022 | M11: =VLOOKUP($C11,'A. All deals (a)'!$C$6:$Q$58,M$5,0) -> B Prefs | N11: =VLOOKUP($C11,'A. All deals (a)'!$C$6:$Q$58,N$5,0) -> 0.02481 | O11: =VLOOKUP($C11,'A. All deals (a)'!$C$6:$Q$58,O$5,0) -> 15 | P11: =VLOOKUP($C11,'A. All deals (a)'!$C$6:$Q$58,P$5,0) -> 15 | Q11: =VLOOKUP($C11,'A. All deals (a)'!$C$6:$Q$58,Q$5,0) -> 0 | ... U11: =VLOOKUP($C11,'A. All deals (a)'!$C$6:$Q$58,U$5,0) -> 15.333834
C12: Applied AI Corporation Limited | D12: Divyesh | E12: HE Tariq | F12: UAE/UK | G12: AI Software | H12: Convertible | I12: Direct Investment | J12: =VLOOKUP($C12,'A. All deals (a)'!$C$6:$Q$58,J$5,0) -> Unrealized | K12: =VLOOKUP($C12,'A. All deals (a)'!$C$6:$Q$58,K$5,0) -> Mozn | L12: =VLOOKUP($C12,'A. All deals (a)'!$C$6:$Q$58,L$5,0) -> 2022 | M12: =VLOOKUP($C12,'A. All deals (a)'!$C$6:$Q$58,M$5,0) -> A Prefs | N12: =VLOOKUP($C12,'A. All deals (a)'!$C$6:$Q$58,N$5,0) -> 0.12121516 | O12: =VLOOKUP($C12,'A. All deals (a)'!$C$6:$Q$58,O$5,0) -> 15 | P12: =VLOOKUP($C12,'A. All deals (a)'!$C$6:$Q$58,P$5,0) -> 15 | Q12: =VLOOKUP($C12,'A. All deals (a)'!$C$6:$Q$58,Q$5,0) -> 0 | ... U12: =VLOOKUP($C12,'A. All deals (a)'!$C$6:$Q$58,U$5,0) -> 2.5643153
C13: Cerebras Systems Inc (1) | D13: Divyesh | E13: Peng | F13: USA | G13: Semiconductors | H13: Listed | I13: Direct Investment | J13: =VLOOKUP($C13,'A. All deals (a)'!$C$6:$Q$58,J$5,0) -> Unrealized | K13: =VLOOKUP($C13,'A. All deals (a)'!$C$6:$Q$58,K$5,0) -> Mozn | L13: =VLOOKUP($C13,'A. All deals (a)'!$C$6:$Q$58,L$5,0) -> 2021 | M13: Class A/B | N13: =VLOOKUP($C13,'A. All deals (a)'!$C$6:$Q$58,N$5,0) -> 0.0065613279 | O13: =VLOOKUP($C13,'A. All deals (a)'!$C$6:$Q$58,O$5,0) -> 39.999983 | P13: =VLOOKUP($C13,'A. All deals (a)'!$C$6:$Q$58,P$5,0) -> 39.999983 | Q13: =VLOOKUP($C13,'A. All deals (a)'!$C$6:$Q$58,Q$5,0) -> 0 | R13: =VLOOKUP($C13,'A. All deals (a)'!$C$6:$Q$58,R$5,0) -> 0 | S13: =VLOOKUP($C13,'A. All deals (a)'!$C$6:$Q$58,S$5,0) -> 265.62083 | T13: =VLOOKUP($C13,'A. All deals (a)'!$C$6:$Q$58,T$5,0) -> 225.62085 | U13: =VLOOKUP($C13,'A. All deals (a)'!$C$6:$Q$58,U$5,0) -> 6.6405236
C14: Endless Studios LLC | D14: Sushil | E14: Peng | F14: USA | G14: Gaming | H14: A Pref Units | I14: Direct Investment | J14: =VLOOKUP($C14,'A. All deals (a)'!$C$6:$Q$58,J$5,0) -> Unrealized | K14: =VLOOKUP($C14,'A. All deals (a)'!$C$6:$Q$58,K$5,0) -> Mozn | L14: =VLOOKUP($C14,'A. All deals (a)'!$C$6:$Q$58,L$5,0) -> 2021 | M14: =VLOOKUP($C14,'A. All deals (a)'!$C$6:$Q$58,M$5,0) -> A Pref Units | N14: =VLOOKUP($C14,'A. All deals (a)'!$C$6:$Q$58,N$5,0) -> 0.16016016 | O14: =VLOOKUP($C14,'A. All deals (a)'!$C$6:$Q$58,O$5,0) -> 8 | P14: =VLOOKUP($C14,'A. All deals (a)'!$C$6:$Q$58,P$5,0) -> 8 | Q14: =VLOOKUP($C14,'A. All deals (a)'!$C$6:$Q$58,Q$5,0) -> 0 | ... U14: =VLOOKUP($C14,'A. All deals (a)'!$C$6:$Q$58,U$5,0) -> 0.8125
C15: Heygears | D15: Divyesh | E15: Peng | F15: PRC | G15: 3D Printing | H15: Series D | I15: Direct Investment | J15: =VLOOKUP($C15,'A. All deals (a)'!$C$6:$Q$58,J$5,0) -> Unrealized | K15: =VLOOKUP($C15,'A. All deals (a)'!$C$6:$Q$58,K$5,0) -> Mozn | L15: =VLOOKUP($C15,'A. All deals (a)'!$C$6:$Q$58,L$5,0) -> 2020 | M15: =VLOOKUP($C15,'A. All deals (a)'!$C$6:$Q$58,M$5,0) -> Registered Capital | N15: =VLOOKUP($C15,'A. All deals (a)'!$C$6:$Q$58,N$5,0) -> 0.14383199 | O15: =VLOOKUP($C15,'A. All deals (a)'!$C$6:$Q$58,O$5,0) -> 60 | P15: =VLOOKUP($C15,'A. All deals (a)'!$C$6:$Q$58,P$5,0) -> 60 | Q15: =VLOOKUP($C15,'A. All deals (a)'!$C$6:$Q$58,Q$5,0) -> 0 | ... U15: =VLOOKUP($C15,'A. All deals (a)'!$C$6:$Q$58,U$5,0) -> 1.1986474
C16: Beyond Limits | D16: Sushil | E16: Peng | F16: USA | G16: AI Software | H16: C Prefs | I16: Direct Investment | J16: =VLOOKUP($C16,'A. All deals (a)'!$C$6:$Q$58,J$5,0) -> Unrealized | K16: =VLOOKUP($C16,'A. All deals (a)'!$C$6:$Q$58,K$5,0) -> Mozn | L16: =VLOOKUP($C16,'A. All deals (a)'!$C$6:$Q$58,L$5,0) -> 2020 | M16: =VLOOKUP($C16,'A. All deals (a)'!$C$6:$Q$58,M$5,0) -> C Prefs | N16: =VLOOKUP($C16,'A. All deals (a)'!$C$6:$Q$58,N$5,0) -> 0.065 | O16: =VLOOKUP($C16,'A. All deals (a)'!$C$6:$Q$58,O$5,0) -> 90 | P16: =VLOOKUP($C16,'A. All deals (a)'!$C$6:$Q$58,P$5,0) -> 90 | Q16: =VLOOKUP($C16,'A. All deals (a)'!$C$6:$Q$58,Q$5,0) -> 0 | ... U16: =VLOOKUP($C16,'A. All deals (a)'!$C$6:$Q$58,U$5,0) -> 0.24111111
C17: ONT plc | D17: Divyesh | E17: Peng | F17: UK | G17: Genome Sequencing | H17: Ordinary Shares | I17: Direct Investment | J17: =VLOOKUP($C17,'A. All deals (a)'!$C$6:$Q$58,J$5,0) -> Unrealized | K17: =VLOOKUP($C17,'A. All deals (a)'!$C$6:$Q$58,K$5,0) -> Mozn | L17: =VLOOKUP($C17,'A. All deals (a)'!$C$6:$Q$58,L$5,0) -> 2020 | M17: =VLOOKUP($C17,'A. All deals (a)'!$C$6:$Q$58,M$5,0) -> Ordinary Shares | N17: =VLOOKUP($C17,'A. All deals (a)'!$C$6:$Q$58,N$5,0) -> 0.045562985 | O17: =VLOOKUP($C17,'A. All deals (a)'!$C$6:$Q$58,O$5,0) -> 141.47026 | P17: =VLOOKUP($C17,'A. All deals (a)'!$C$6:$Q$58,P$5,0) -> 141.47026 | Q17: =VLOOKUP($C17,'A. All deals (a)'!$C$6:$Q$58,Q$5,0) -> 0 | ... U17: =VLOOKUP($C17,'A. All deals (a)'!$C$6:$Q$58,U$5,0) -> 0.74381239
C18: Flyr Inc | D18: Divyesh | E18: Peng | F18: USA | G18: Aviation | H18: B-1,2 Prefs | I18: Direct Investment | J18: =VLOOKUP($C18,'A. All deals (a)'!$C$6:$Q$58,J$5,0) -> Unrealized | K18: =VLOOKUP($C18,'A. All deals (a)'!$C$6:$Q$58,K$5,0) -> Mozn | L18: =VLOOKUP($C18,'A. All deals (a)'!$C$6:$Q$58,L$5,0) -> 2019 | M18: =VLOOKUP($C18,'A. All deals (a)'!$C$6:$Q$58,M$5,0) -> B-1,2 Prefs | N18: =VLOOKUP($C18,'A. All deals (a)'!$C$6:$Q$58,N$5,0) -> 0.0334 | O18: =VLOOKUP($C18,'A. All deals (a)'!$C$6:$Q$58,O$5,0) -> 10 | P18: =VLOOKUP($C18,'A. All deals (a)'!$C$6:$Q$58,P$5,0) -> 10 | Q18: =VLOOKUP($C18,'A. All deals (a)'!$C$6:$Q$58,Q$5,0) -> 0 | ... U18: =VLOOKUP($C18,'A. All deals (a)'!$C$6:$Q$58,U$5,0) -> 1.46 | V18: Flyr Warrantsa
O20: =SUM(O9:O18) -> 400.47024 | P20: =SUM(P9:P18) -> 400.47024 | Q20: =SUM(Q9:Q18) -> 0 | R20: =SUM(R9:R18) -> 0 | S20: =SUM(S9:S18) -> 762.33925 | T20: =S20+R20-P20 -> 361.86901 | U20: =(R20+S20)/P20 -> 1.9036102
C22: G42 Investments AI Holding RSC Ltd
C23: DriveNets | D23: Sushil | E23: HE Tariq | F23: Israel | G23: Networking | I23: Direct Investment | J23: =VLOOKUP($C23,'A. All deals (a)'!$C$6:$Q$58,J$5,0) -> Partially Realized | K23: =VLOOKUP($C23,'A. All deals (a)'!$C$6:$Q$58,K$5,0) -> G42 Investments | L23: =VLOOKUP($C23,'A. All deals (a)'!$C$6:$Q$58,L$5,0) -> 2022 | M23: =VLOOKUP($C23,'A. All deals (a)'!$C$6:$Q$58,M$5,0) -> Equity-TBC | N23: =VLOOKUP($C23,'A. All deals (a)'!$C$6:$Q$58,N$5,0) -> 0.0655 | O23: =VLOOKUP($C23,'A. All deals (a)'!$C$6:$Q$58,O$5,0) -> 300 | P23: =VLOOKUP($C23,'A. All deals (a)'!$C$6:$Q$58,P$5,0) -> 300 | Q23: =VLOOKUP($C23,'A. All deals (a)'!$C$6:$Q$58,Q$5,0) -> 0 | ... U23: =VLOOKUP($C23,'A. All deals (a)'!$C$6:$Q$58,U$5,0) -> 1.9411318 | V23: DN Warrants b
C24: vTv Therapeutics Inc. | D24: Divyesh | E24: Dr. Fahed, M42 | F24: USA | G24: Healthcare | I24: Direct Investment | J24: =VLOOKUP($C24,'A. All deals (a)'!$C$6:$Q$58,J$5,0) -> Unrealized | K24: =VLOOKUP($C24,'A. All deals (a)'!$C$6:$Q$58,K$5,0) -> G42 Investments | L24: =VLOOKUP($C24,'A. All deals (a)'!$C$6:$Q$58,L$5,0) -> 2022 | M24: =VLOOKUP($C24,'A. All deals (a)'!$C$6:$Q$58,M$5,0) -> Ordinary Shares | N24: =VLOOKUP($C24,'A. All deals (a)'!$C$6:$Q$58,N$5,0) -> 0.020924424 | O24: =VLOOKUP($C24,'A. All deals (a)'!$C$6:$Q$58,O$5,0) -> 24.53125 | P24: =VLOOKUP($C24,'A. All deals (a)'!$C$6:$Q$58,P$5,0) -> 24.53125 | Q24: =VLOOKUP($C24,'A. All deals (a)'!$C$6:$Q$58,Q$5,0) -> 0 | ... U24: =VLOOKUP($C24,'A. All deals (a)'!$C$6:$Q$58,U$5,0) -> 0.33871181 | V24: vTv $30m milestn payment c
C25: North Summit Capital Fund | D25: Divyesh | E25: Peng | F25: Cayman | G25: Fund | I25: Fund Investment | J25: =VLOOKUP($C25,'A. All deals (a)'!$C$6:$Q$58,J$5,0) -> Unrealized | K25: =VLOOKUP($C25,'A. All deals (a)'!$C$6:$Q$58,K$5,0) -> G42 Investments | L25: =VLOOKUP($C25,'A. All deals (a)'!$C$6:$Q$58,L$5,0) -> 2020 | M25: =VLOOKUP($C25,'A. All deals (a)'!$C$6:$Q$58,M$5,0) -> LP | N25: =VLOOKUP($C25,'A. All deals (a)'!$C$6:$Q$58,N$5,0) -> n/a | O25: =VLOOKUP($C25,'A. All deals (a)'!$C$6:$Q$58,O$5,0) -> 83.361611 | P25: =VLOOKUP($C25,'A. All deals (a)'!$C$6:$Q$58,P$5,0) -> 83.361611 | Q25: =VLOOKUP($C25,'A. All deals (a)'!$C$6:$Q$58,Q$5,0) -> 0 | ... U25: =VLOOKUP($C25,'A. All deals (a)'!$C$6:$Q$58,U$5,0) -> 0.96497411
C26: New Space Capital Fund I | D26: Sushil | E26: Peng | F26: Luxembourg | G26: Fund | I26: Fund Investment | J26: =VLOOKUP($C26,'A. All deals (a)'!$C$6:$Q$58,J$5,0) -> Unrealized | K26: =VLOOKUP($C26,'A. All deals (a)'!$C$6:$Q$58,K$5,0) -> G42 Investments | L26: =VLOOKUP($C26,'A. All deals (a)'!$C$6:$Q$58,L$5,0) -> 2020 | M26: =VLOOKUP($C26,'A. All deals (a)'!$C$6:$Q$58,M$5,0) -> LP | N26: =VLOOKUP($C26,'A. All deals (a)'!$C$6:$Q$58,N$5,0) -> n/a | O26: =VLOOKUP($C26,'A. All deals (a)'!$C$6:$Q$58,O$5,0) -> 26.991242 | P26: =VLOOKUP($C26,'A. All deals (a)'!$C$6:$Q$58,P$5,0) -> 17.009681 | Q26: =VLOOKUP($C26,'A. All deals (a)'!$C$6:$Q$58,Q$5,0) -> 9.9815607 | ... U26: =VLOOKUP($C26,'A. All deals (a)'!$C$6:$Q$58,U$5,0) -> 3.7586897
C27: New Space Capital GP Com SCSp | D27: Sushil | E27: Peng | F27: Luxembourg | G27: Fund | I27: Fund Investment | J27: =VLOOKUP($C27,'A. All deals (a)'!$C$6:$Q$58,J$5,0) -> Unrealized | K27: =VLOOKUP($C27,'A. All deals (a)'!$C$6:$Q$58,K$5,0) -> G42 Investments | L27: =VLOOKUP($C27,'A. All deals (a)'!$C$6:$Q$58,L$5,0) -> 2023 | M27: =VLOOKUP($C27,'A. All deals (a)'!$C$6:$Q$58,M$5,0) -> LP | N27: =VLOOKUP($C27,'A. All deals (a)'!$C$6:$Q$58,N$5,0) -> n/a | O27: =VLOOKUP($C27,'A. All deals (a)'!$C$6:$Q$58,O$5,0) -> 2.7058824 | P27: =VLOOKUP($C27,'A. All deals (a)'!$C$6:$Q$58,P$5,0) -> 2.7058824 | Q27: =VLOOKUP($C27,'A. All deals (a)'!$C$6:$Q$58,Q$5,0) -> 0 | ... U27: =VLOOKUP($C27,'A. All deals (a)'!$C$6:$Q$58,U$5,0) -> 2.4915204
C28: Acies Investments Fund I, L.P. | D28: Divyesh | E28: Peng | F28: USA | G28: Fund | I28: Fund Investment | J28: =VLOOKUP($C28,'A. All deals (a)'!$C$6:$Q$58,J$5,0) -> Unrealized | K28: =VLOOKUP($C28,'A. All deals (a)'!$C$6:$Q$58,K$5,0) -> G42 Investments | L28: =VLOOKUP($C28,'A. All deals (a)'!$C$6:$Q$58,L$5,0) -> 2021 | M28: =VLOOKUP($C28,'A. All deals (a)'!$C$6:$Q$58,M$5,0) -> LP | N28: =VLOOKUP($C28,'A. All deals (a)'!$C$6:$Q$58,N$5,0) -> 0.33 | O28: =VLOOKUP($C28,'A. All deals (a)'!$C$6:$Q$58,O$5,0) -> 17.1125 | P28: =VLOOKUP($C28,'A. All deals (a)'!$C$6:$Q$58,P$5,0) -> 15.726387 | Q28: =VLOOKUP($C28,'A. All deals (a)'!$C$6:$Q$58,Q$5,0) -> 1.3861125 | ... U28: =VLOOKUP($C28,'A. All deals (a)'!$C$6:$Q$58,U$5,0) -> 0.89244291 | V28: 9.9% GP | Anchorf
O30: =SUM(O23:O28) -> 454.70249 | P30: =SUM(P23:P28) -> 443.33481 | Q30: =SUM(Q23:Q28) -> 11.367673 | R30: =SUM(R23:R28) -> 99.457991 | S30: =SUM(S23:S28) -> 656.34315 | T30: =S30+R30-P30 -> 312.46633 | U30: =(R30+S30)/P30 -> 1.7048089
C32: G42 Capital SPV RSC Ltd
C33: Life Biosciences LLC | D33: Divyesh | E33: Peng/XP | F33: USA | G33: Healthcare | I33: Direct Investment | J33: =VLOOKUP($C33,'A. All deals (a)'!$C$6:$Q$58,J$5,0) -> Unrealized | K33: =VLOOKUP($C33,'A. All deals (a)'!$C$6:$Q$58,K$5,0) -> G42 Capital | L33: =VLOOKUP($C33,'A. All deals (a)'!$C$6:$Q$58,L$5,0) -> 2024 | M33: =VLOOKUP($C33,'A. All deals (a)'!$C$6:$Q$58,M$5,0) -> D Prefs | N33: =VLOOKUP($C33,'A. All deals (a)'!$C$6:$Q$58,N$5,0) -> 0.0639 | O33: =VLOOKUP($C33,'A. All deals (a)'!$C$6:$Q$58,O$5,0) -> 40 | P33: =VLOOKUP($C33,'A. All deals (a)'!$C$6:$Q$58,P$5,0) -> 40 | Q33: =VLOOKUP($C33,'A. All deals (a)'!$C$6:$Q$58,Q$5,0) -> 0 | ... U33: =VLOOKUP($C33,'A. All deals (a)'!$C$6:$Q$58,U$5,0) -> 1.0236848 | V33: EPTH7
C34: Verses AI Inc | D34: Divyesh | E34: Peng/XP | F34: Canada | G34: AI Software | I34: Direct Investment | J34: =VLOOKUP($C34,'A. All deals (a)'!$C$6:$Q$58,J$5,0) -> Unrealized | K34: =VLOOKUP($C34,'A. All deals (a)'!$C$6:$Q$58,K$5,0) -> G42 Capital | L34: =VLOOKUP($C34,'A. All deals (a)'!$C$6:$Q$58,L$5,0) -> 2024 | M34: Ordinary Shares | N34: =VLOOKUP($C34,'A. All deals (a)'!$C$6:$Q$58,N$5,0) -> 0.035972427 | O34: =VLOOKUP($C34,'A. All deals (a)'!$C$6:$Q$58,O$5,0) -> 10 | P34: =VLOOKUP($C34,'A. All deals (a)'!$C$6:$Q$58,P$5,0) -> 10 | Q34: =VLOOKUP($C34,'A. All deals (a)'!$C$6:$Q$58,Q$5,0) -> 0 | R34: =VLOOKUP($C34,'A. All deals (a)'!$C$6:$Q$58,R$5,0) -> 0 | S34: =VLOOKUP($C34,'A. All deals (a)'!$C$6:$Q$58,S$5,0) -> 0 | T34: =VLOOKUP($C34,'A. All deals (a)'!$C$6:$Q$58,T$5,0) -> -10 | U34: =VLOOKUP($C34,'A. All deals (a)'!$C$6:$Q$58,U$5,0) -> 0 | V34: ="EPTH9 "& VLOOKUP($C34,'A. All deals (a)'!$C$6:$Q$58,V$5,0) -> EPTH9 Revenue linked RSUs
C35: Inveniam Ltd | D35: Divyesh | E35: Jon Nieman | F35: USA | G35: AI Software | I35: Direct Investment | J35: =VLOOKUP($C35,'A. All deals (a)'!$C$6:$Q$58,J$5,0) -> Unrealized | K35: =VLOOKUP($C35,'A. All deals (a)'!$C$6:$Q$58,K$5,0) -> G42 Capital | L35: =VLOOKUP($C35,'A. All deals (a)'!$C$6:$Q$58,L$5,0) -> 2024 | M35: =VLOOKUP($C35,'A. All deals (a)'!$C$6:$Q$58,M$5,0) -> SAR | N35: =VLOOKUP($C35,'A. All deals (a)'!$C$6:$Q$58,N$5,0) -> NA | O35: =VLOOKUP($C35,'A. All deals (a)'!$C$6:$Q$58,O$5,0) -> 100 | P35: =VLOOKUP($C35,'A. All deals (a)'!$C$6:$Q$58,P$5,0) -> 100 | Q35: =VLOOKUP($C35,'A. All deals (a)'!$C$6:$Q$58,Q$5,0) -> 0 | ... U35: =VLOOKUP($C35,'A. All deals (a)'!$C$6:$Q$58,U$5,0) -> 1.0049997 | V35: ="EPTH10 "& VLOOKUP($C35,'A. All deals (a)'!$C$6:$Q$58,V$5,0) -> EPTH10 Upside if Tokens sold > $2.5 per token
C36: Liquid AI | D36: Divyesh | E36: Peng | F36: USA | G36: Foundation Model | I36: Direct Investment | J36: =VLOOKUP($C36,'A. All deals (a)'!$C$6:$Q$58,J$5,0) -> Unrealized | K36: =VLOOKUP($C36,'A. All deals (a)'!$C$6:$Q$58,K$5,0) -> G42 Capital | L36: =VLOOKUP($C36,'A. All deals (a)'!$C$6:$Q$58,L$5,0) -> 2025 | M36: =VLOOKUP($C36,'A. All deals (a)'!$C$6:$Q$58,M$5,0) -> Series A | N36: =VLOOKUP($C36,'A. All deals (a)'!$C$6:$Q$58,N$5,0) -> 0.030216555 | O36: =VLOOKUP($C36,'A. All deals (a)'!$C$6:$Q$58,O$5,0) -> 60.819863 | P36: =VLOOKUP($C36,'A. All deals (a)'!$C$6:$Q$58,P$5,0) -> 60.819863 | Q36: =VLOOKUP($C36,'A. All deals (a)'!$C$6:$Q$58,Q$5,0) -> 0 | ... U36: =VLOOKUP($C36,'A. All deals (a)'!$C$6:$Q$58,U$5,0) -> 1.0950236 | V36: EPTH11
C37: Neuralink | D37: Divyesh | E37: Peng | F37: USA | G37: Healthcare | I37: Direct Investment | J37: =VLOOKUP($C37,'A. All deals (a)'!$C$6:$Q$58,J$5,0) -> Unrealized | K37: =VLOOKUP($C37,'A. All deals (a)'!$C$6:$Q$58,K$5,0) -> G42 Capital | L37: =VLOOKUP($C37,'A. All deals (a)'!$C$6:$Q$58,L$5,0) -> 2025 | M37: =VLOOKUP($C37,'A. All deals (a)'!$C$6:$Q$58,M$5,0) -> Series E | N37: =VLOOKUP($C37,'A. All deals (a)'!$C$6:$Q$58,N$5,0) -> 0.0051805228 | O37: =VLOOKUP($C37,'A. All deals (a)'!$C$6:$Q$58,O$5,0) -> 50 | P37: =VLOOKUP($C37,'A. All deals (a)'!$C$6:$Q$58,P$5,0) -> 50 | Q37: =VLOOKUP($C37,'A. All deals (a)'!$C$6:$Q$58,Q$5,0) -> 0 | ... U37: =VLOOKUP($C37,'A. All deals (a)'!$C$6:$Q$58,U$5,0) -> 1 | V37: EPTH12
C38: Cerebras Systems Inc (2) | D38: Divyesh | E38: Peng | F38: USA | G38: Semiconductors | I38: Direct Investment | J38: =VLOOKUP($C38,'A. All deals (a)'!$C$6:$Q$58,J$5,0) -> Unrealized | K38: =VLOOKUP($C38,'A. All deals (a)'!$C$6:$Q$58,K$5,0) -> G42 Capital | L38: =VLOOKUP($C38,'A. All deals (a)'!$C$6:$Q$58,L$5,0) -> 2026 | M38: Class A/B | N38: =VLOOKUP($C38,'A. All deals (a)'!$C$6:$Q$58,N$5,0) -> 0.015990144 | O38: =VLOOKUP($C38,'A. All deals (a)'!$C$6:$Q$58,O$5,0) -> 0.03513491 | P38: =VLOOKUP($C38,'A. All deals (a)'!$C$6:$Q$58,P$5,0) -> 0.03513491 | Q38: =VLOOKUP($C38,'A. All deals (a)'!$C$6:$Q$58,Q$5,0) -> 0 | R38: =VLOOKUP($C38,'A. All deals (a)'!$C$6:$Q$58,R$5,0) -> 0 | S38: =VLOOKUP($C38,'A. All deals (a)'!$C$6:$Q$58,S$5,0) -> 647.32558 | T38: =VLOOKUP($C38,'A. All deals (a)'!$C$6:$Q$58,T$5,0) -> 647.29045 | U38: =IF(VLOOKUP($C38,'A. All deals (a)'!$C$6:$Q$58,U$5,0)>10,">10x",VLOOKUP($C38,'A. All deals (a)'!$C$6:$Q$58,U$5,0)) -> >10x | V38: EPTH8 (1.86m shares W1 plus 1.66m shares W2)
O40: =SUM(O33:O38) -> 260.855 | P40: =SUM(P33:P38) -> 260.855 | Q40: =SUM(Q33:Q38) -> 0 | R40: =SUM(R33:R38) -> 0.499965 | S40: =SUM(S33:S38) -> 904.87216 | T40: =SUM(T33:T38) -> 644.51713 | U40: =(R40+S40)/P40 -> 3.470787
C42: Core42 Holding RSC Ltd
C43: School Hack (AIREV Holding Limited) | D43: Divyesh | E43: Peng | F43: UAE | G43: AI Software | I43: Direct Investment | J43: =VLOOKUP($C43,'A. All deals (a)'!$C$6:$Q$58,J$5,0) -> Unrealized | K43: =VLOOKUP($C43,'A. All deals (a)'!$C$6:$Q$58,K$5,0) -> Core42 5 | L43: =VLOOKUP($C43,'A. All deals (a)'!$C$6:$Q$58,L$5,0) -> 2024 | M43: =VLOOKUP($C43,'A. All deals (a)'!$C$6:$Q$58,M$5,0) -> Preferred Shares | N43: =VLOOKUP($C43,'A. All deals (a)'!$C$6:$Q$58,N$5,0) -> 0.23 | O43: =VLOOKUP($C43,'A. All deals (a)'!$C$6:$Q$58,O$5,0) -> 2.75 | P43: =VLOOKUP($C43,'A. All deals (a)'!$C$6:$Q$58,P$5,0) -> 2.5 | Q43: =VLOOKUP($C43,'A. All deals (a)'!$C$6:$Q$58,Q$5,0) -> 0.25 | ... U43: =VLOOKUP($C43,'A. All deals (a)'!$C$6:$Q$58,U$5,0) -> 1 | V43: Cloud Creditg
O45: =SUM(O43) -> 2.75 | P45: =SUM(P43) -> 2.5 | Q45: =SUM(Q43) -> 0.25 | R45: =SUM(R43) -> 0 | S45: =SUM(S43) -> 2.5 | T45: =SUM(T43) -> 0 | U45: =(R45+S45)/P45 -> 1
C47: GX Investments Ltd : MGX and Related Investments
C48: MGX I LP + Denali | D48: Nitesh/Gino | E48: Peng | F48: UAE | G48: Fund | I48: MGX LP | J48: =VLOOKUP($C48,'A. All deals (a)'!$C$6:$Q$58,J$5,0) -> Unrealized | K48: =VLOOKUP($C48,'A. All deals (a)'!$C$6:$Q$58,K$5,0) -> G42 Holding | L48: =VLOOKUP($C48,'A. All deals (a)'!$C$6:$Q$58,L$5,0) -> 2024 | M48: =VLOOKUP($C48,'A. All deals (a)'!$C$6:$Q$58,M$5,0) -> LP | N48: =VLOOKUP($C48,'A. All deals (a)'!$C$6:$Q$58,N$5,0) -> 0.03125 | O48: =VLOOKUP($C48,'A. All deals (a)'!$C$6:$Q$58,O$5,0) -> 1559.798 | P48: =VLOOKUP($C48,'A. All deals (a)'!$C$6:$Q$58,P$5,0) -> 386.49987 | Q48: =VLOOKUP($C48,'A. All deals (a)'!$C$6:$Q$58,Q$5,0) -> 1173.2982 | ... U48: =VLOOKUP($C48,'A. All deals (a)'!$C$6:$Q$58,U$5,0) -> 2.6545083
C49: MGX 1 Strategic Co-invest | D49: Nitesh/Gino | E49: Peng | F49: UAE | G49: Fund | I49: MGX Co-Invest LP | J49: =VLOOKUP($C49,'A. All deals (a)'!$C$6:$Q$58,J$5,0) -> Unrealized | K49: =VLOOKUP($C49,'A. All deals (a)'!$C$6:$Q$58,K$5,0) -> G42 Holding | L49: =VLOOKUP($C49,'A. All deals (a)'!$C$6:$Q$58,L$5,0) -> 2024 | M49: =VLOOKUP($C49,'A. All deals (a)'!$C$6:$Q$58,M$5,0) -> LP | N49: =VLOOKUP($C49,'A. All deals (a)'!$C$6:$Q$58,N$5,0) -> 0.5 | O49: =VLOOKUP($C49,'A. All deals (a)'!$C$6:$Q$58,O$5,0) -> 296.60196 | P49: =VLOOKUP($C49,'A. All deals (a)'!$C$6:$Q$58,P$5,0) -> 294.25155 | Q49: =VLOOKUP($C49,'A. All deals (a)'!$C$6:$Q$58,Q$5,0) -> 2.350415 | ... U49: =VLOOKUP($C49,'A. All deals (a)'!$C$6:$Q$58,U$5,0) -> 4.0114431
C50: MGX Group Holding 1 Ltd (GP) | D50: Nitesh/Gino | E50: Peng | F50: UAE | G50: Fund | I50: MGX GP | J50: =VLOOKUP($C50,'A. All deals (a)'!$C$6:$Q$58,J$5,0) -> Unrealized | K50: =VLOOKUP($C50,'A. All deals (a)'!$C$6:$Q$58,K$5,0) -> G42 Holding | L50: =VLOOKUP($C50,'A. All deals (a)'!$C$6:$Q$58,L$5,0) -> 2024 | M50: =VLOOKUP($C50,'A. All deals (a)'!$C$6:$Q$58,M$5,0) -> Equity | N50: =VLOOKUP($C50,'A. All deals (a)'!$C$6:$Q$58,N$5,0) -> 0 | O50: =VLOOKUP($C50,'A. All deals (a)'!$C$6:$Q$58,O$5,0) -> 25 | P50: =VLOOKUP($C50,'A. All deals (a)'!$C$6:$Q$58,P$5,0) -> 25 | Q50: =VLOOKUP($C50,'A. All deals (a)'!$C$6:$Q$58,Q$5,0) -> 0 | ... U50: =VLOOKUP($C50,'A. All deals (a)'!$C$6:$Q$58,U$5,0) -> 1
...

Sheet 2. Exited
C2: As of date | D2: ='D1'!D2 -> 46265
C3: EXITED INVESTMENTS
E5: 2 | G5: 4 | H5: 5 | I5: 6 | J5: 7 | K5: 8 | L5: 9 | M5: 10 | N5: 11 | O5: 12 | P5: 13 | R5: 14 | S5: 15
C6: Deals | D6: Type | E6: Status | G6: Investing Entity | H6: Vintageἀ | I6: Instrument | J6: % | K6: Committed | L6: Invested | M6: Remaining Commitment | N6: Distributions | O6: Carrying Value | P6: Gain | Q6: Gain till FY22 | R6: TVPI | S6: Additonal Upside/Downside
I7: # | J7: % | K7: $,m | L7: $,m | M7: $,m | N7: $,m | O7: $,m | P7: $,m | R7: X
C8: MOZN Holding RSC Ltd
C9: WLD Tokens | D9: Direct Investment | E9: =VLOOKUP($C9,'A. All deals (a)'!$C$6:$Q$58,E$5,0) -> Unrealized | G9: =VLOOKUP($C9,'A. All deals (a)'!$C$6:$Q$58,G$5,0) -> Mozn | H9: =VLOOKUP($C9,'A. All deals (a)'!$C$6:$Q$58,H$5,0) -> 2023 | I9: =VLOOKUP($C9,'A. All deals (a)'!$C$6:$Q$58,I$5,0) -> Tokens | J9: =VLOOKUP($C9,'A. All deals (a)'!$C$6:$Q$58,J$5,0) -> NA | K9: =VLOOKUP($C9,'A. All deals (a)'!$C$6:$Q$58,K$5,0) -> 0.006875 | L9: =VLOOKUP($C9,'A. All deals (a)'!$C$6:$Q$58,L$5,0) -> 0.006875 | M9: =VLOOKUP($C9,'A. All deals (a)'!$C$6:$Q$58,M$5,0) -> 0 | N9: =VLOOKUP($C9,'A. All deals (a)'!$C$6:$Q$58,N$5,0) -> 100 | ... P9: =VLOOKUP($C9,'A. All deals (a)'!$C$6:$Q$58,P$5,0) -> 99.993125 | Q9: n/a | R9: =VLOOKUP($C9,'A. All deals (a)'!$C$6:$Q$58,R$5,0) -> NM | S9: Full Exit for Inveniam SAR
C10: X-fusion | D10: Direct Investment | E10: =VLOOKUP($C10,'A. All deals (a)'!$C$6:$Q$58,E$5,0) -> Realized | G10: =VLOOKUP($C10,'A. All deals (a)'!$C$6:$Q$58,G$5,0) -> Mozn 2 | H10: =VLOOKUP($C10,'A. All deals (a)'!$C$6:$Q$58,H$5,0) -> 2022 | I10: =VLOOKUP($C10,'A. All deals (a)'!$C$6:$Q$58,I$5,0) -> Equity-TBC | J10: =VLOOKUP($C10,'A. All deals (a)'!$C$6:$Q$58,J$5,0) -> NA | K10: =VLOOKUP($C10,'A. All deals (a)'!$C$6:$Q$58,K$5,0) -> 493.50096 | L10: =VLOOKUP($C10,'A. All deals (a)'!$C$6:$Q$58,L$5,0) -> 493.50096 | M10: =VLOOKUP($C10,'A. All deals (a)'!$C$6:$Q$58,M$5,0) -> 0 | N10: =VLOOKUP($C10,'A. All deals (a)'!$C$6:$Q$58,N$5,0) -> 403 | ... P10: =VLOOKUP($C10,'A. All deals (a)'!$C$6:$Q$58,P$5,0) -> -90.500956 | Q10: -64.391 | R10: =VLOOKUP($C10,'A. All deals (a)'!$C$6:$Q$58,R$5,0) -> 0.81661443 | S10: Full Exit
C11: Mena Mobile Inc (Debt) | D11: Debt Investment | E11: =VLOOKUP($C11,'A. All deals (a)'!$C$6:$Q$58,E$5,0) -> Written-off | G11: =VLOOKUP($C11,'A. All deals (a)'!$C$6:$Q$58,G$5,0) -> Mozn | H11: =VLOOKUP($C11,'A. All deals (a)'!$C$6:$Q$58,H$5,0) -> 2021 | I11: =VLOOKUP($C11,'A. All deals (a)'!$C$6:$Q$58,I$5,0) -> Loan | J11: =VLOOKUP($C11,'A. All deals (a)'!$C$6:$Q$58,J$5,0) -> n/a | K11: =VLOOKUP($C11,'A. All deals (a)'!$C$6:$Q$58,K$5,0) -> 2.353982 | L11: =VLOOKUP($C11,'A. All deals (a)'!$C$6:$Q$58,L$5,0) -> 2.353982 | M11: =VLOOKUP($C11,'A. All deals (a)'!$C$6:$Q$58,M$5,0) -> 0 | N11: =VLOOKUP($C11,'A. All deals (a)'!$C$6:$Q$58,N$5,0) -> 0 | ... P11: =VLOOKUP($C11,'A. All deals (a)'!$C$6:$Q$58,P$5,0) -> -2.353982 | Q11: 0 | R11: =VLOOKUP($C11,'A. All deals (a)'!$C$6:$Q$58,R$5,0) -> 0 | S11: Written Off
C12: Esyasoft Holding (Debt) | D12: Debt Investment | E12: =VLOOKUP($C12,'A. All deals (a)'!$C$6:$Q$58,E$5,0) -> Realized | G12: =VLOOKUP($C12,'A. All deals (a)'!$C$6:$Q$58,G$5,0) -> Mozn | H12: =VLOOKUP($C12,'A. All deals (a)'!$C$6:$Q$58,H$5,0) -> 2021 | I12: =VLOOKUP($C12,'A. All deals (a)'!$C$6:$Q$58,I$5,0) -> Loan | J12: =VLOOKUP($C12,'A. All deals (a)'!$C$6:$Q$58,J$5,0) -> n/a | K12: =VLOOKUP($C12,'A. All deals (a)'!$C$6:$Q$58,K$5,0) -> 0.411765 | L12: =VLOOKUP($C12,'A. All deals (a)'!$C$6:$Q$58,L$5,0) -> 0.411765 | M12: =VLOOKUP($C12,'A. All deals (a)'!$C$6:$Q$58,M$5,0) -> 0 | N12: =VLOOKUP($C12,'A. All deals (a)'!$C$6:$Q$58,N$5,0) -> 0.47078465 | ... P12: =VLOOKUP($C12,'A. All deals (a)'!$C$6:$Q$58,P$5,0) -> 0.05901965 | Q12: 0.05901965 | R12: =VLOOKUP($C12,'A. All deals (a)'!$C$6:$Q$58,R$5,0) -> 1.1433333 | S12: Full Exit
C13: Jysan Technologies | D13: Direct Investment | E13: =VLOOKUP($C13,'A. All deals (a)'!$C$6:$Q$58,E$5,0) -> Realized | G13: =VLOOKUP($C13,'A. All deals (a)'!$C$6:$Q$58,G$5,0) -> Mozn 1 | H13: =VLOOKUP($C13,'A. All deals (a)'!$C$6:$Q$58,H$5,0) -> 2021 | I13: =VLOOKUP($C13,'A. All deals (a)'!$C$6:$Q$58,I$5,0) -> A (Ordinary Shares) | J13: =VLOOKUP($C13,'A. All deals (a)'!$C$6:$Q$58,J$5,0) -> 0.03 | K13: =VLOOKUP($C13,'A. All deals (a)'!$C$6:$Q$58,K$5,0) -> 20 | L13: =VLOOKUP($C13,'A. All deals (a)'!$C$6:$Q$58,L$5,0) -> 20 | M13: =VLOOKUP($C13,'A. All deals (a)'!$C$6:$Q$58,M$5,0) -> 0 | N13: =VLOOKUP($C13,'A. All deals (a)'!$C$6:$Q$58,N$5,0) -> 24.5 | ... P13: =VLOOKUP($C13,'A. All deals (a)'!$C$6:$Q$58,P$5,0) -> 4.5 | Q13: 0 | R13: =VLOOKUP($C13,'A. All deals (a)'!$C$6:$Q$58,R$5,0) -> 1.225 | S13: Full Exit
C14: Instadeep Limited | D14: Direct Investment | E14: =VLOOKUP($C14,'A. All deals (a)'!$C$6:$Q$58,E$5,0) -> Realized | G14: =VLOOKUP($C14,'A. All deals (a)'!$C$6:$Q$58,G$5,0) -> Mozn | H14: =VLOOKUP($C14,'A. All deals (a)'!$C$6:$Q$58,H$5,0) -> 2021 | I14: =VLOOKUP($C14,'A. All deals (a)'!$C$6:$Q$58,I$5,0) -> B Prefs | J14: =VLOOKUP($C14,'A. All deals (a)'!$C$6:$Q$58,J$5,0) -> NA | K14: =VLOOKUP($C14,'A. All deals (a)'!$C$6:$Q$58,K$5,0) -> 5.0237202 | L14: =VLOOKUP($C14,'A. All deals (a)'!$C$6:$Q$58,L$5,0) -> 5.0237202 | M14: =VLOOKUP($C14,'A. All deals (a)'!$C$6:$Q$58,M$5,0) -> 0 | N14: =VLOOKUP($C14,'A. All deals (a)'!$C$6:$Q$58,N$5,0) -> 7.9421925 | ... P14: =VLOOKUP($C14,'A. All deals (a)'!$C$6:$Q$58,P$5,0) -> 2.9184723 | Q14: 1.6721788 | R14: =VLOOKUP($C14,'A. All deals (a)'!$C$6:$Q$58,R$5,0) -> 1.5809385 | S14: Full Exit
C15: Esyasoft Holding | D15: Direct Investment | E15: =VLOOKUP($C15,'A. All deals (a)'!$C$6:$Q$58,E$5,0) -> Realized | G15: =VLOOKUP($C15,'A. All deals (a)'!$C$6:$Q$58,G$5,0) -> Mozn | H15: =VLOOKUP($C15,'A. All deals (a)'!$C$6:$Q$58,H$5,0) -> 2020 | I15: =VLOOKUP($C15,'A. All deals (a)'!$C$6:$Q$58,I$5,0) -> Convertible Note | J15: =VLOOKUP($C15,'A. All deals (a)'!$C$6:$Q$58,J$5,0) -> NA | K15: =VLOOKUP($C15,'A. All deals (a)'!$C$6:$Q$58,K$5,0) -> 2.5 | L15: =VLOOKUP($C15,'A. All deals (a)'!$C$6:$Q$58,L$5,0) -> 2.5 | M15: =VLOOKUP($C15,'A. All deals (a)'!$C$6:$Q$58,M$5,0) -> 0 | N15: =VLOOKUP($C15,'A. All deals (a)'!$C$6:$Q$58,N$5,0) -> 5 | ... P15: =VLOOKUP($C15,'A. All deals (a)'!$C$6:$Q$58,P$5,0) -> 2.5 | Q15: 2.5 | R15: =VLOOKUP($C15,'A. All deals (a)'!$C$6:$Q$58,R$5,0) -> 2 | S15: Full Exit
C16: Mena Mobile Inc | D16: Direct Investment | E16: =VLOOKUP($C16,'A. All deals (a)'!$C$6:$Q$58,E$5,0) -> Written-off | G16: =VLOOKUP($C16,'A. All deals (a)'!$C$6:$Q$58,G$5,0) -> Mozn | H16: =VLOOKUP($C16,'A. All deals (a)'!$C$6:$Q$58,H$5,0) -> 2019 | I16: =VLOOKUP($C16,'A. All deals (a)'!$C$6:$Q$58,I$5,0) -> B Prefs | J16: =VLOOKUP($C16,'A. All deals (a)'!$C$6:$Q$58,J$5,0) -> 0.14 | K16: =VLOOKUP($C16,'A. All deals (a)'!$C$6:$Q$58,K$5,0) -> 8 | L16: =VLOOKUP($C16,'A. All deals (a)'!$C$6:$Q$58,L$5,0) -> 8 | M16: =VLOOKUP($C16,'A. All deals (a)'!$C$6:$Q$58,M$5,0) -> 0 | N16: =VLOOKUP($C16,'A. All deals (a)'!$C$6:$Q$58,N$5,0) -> 0 | ... P16: =VLOOKUP($C16,'A. All deals (a)'!$C$6:$Q$58,P$5,0) -> -8 | Q16: -8 | R16: =VLOOKUP($C16,'A. All deals (a)'!$C$6:$Q$58,R$5,0) -> 0 | S16: Written Off
C17: Glass Earth Holdings LLC | D17: Debt Investment | E17: =VLOOKUP($C17,'A. All deals (a)'!$C$6:$Q$58,E$5,0) -> Written-off | G17: =VLOOKUP($C17,'A. All deals (a)'!$C$6:$Q$58,G$5,0) -> Mozn | H17: =VLOOKUP($C17,'A. All deals (a)'!$C$6:$Q$58,H$5,0) -> 2019 | I17: =VLOOKUP($C17,'A. All deals (a)'!$C$6:$Q$58,I$5,0) -> Promissory Note | J17: =VLOOKUP($C17,'A. All deals (a)'!$C$6:$Q$58,J$5,0) -> n/a | K17: =VLOOKUP($C17,'A. All deals (a)'!$C$6:$Q$58,K$5,0) -> 8 | L17: =VLOOKUP($C17,'A. All deals (a)'!$C$6:$Q$58,L$5,0) -> 8 | M17: =VLOOKUP($C17,'A. All deals (a)'!$C$6:$Q$58,M$5,0) -> 0 | N17: =VLOOKUP($C17,'A. All deals (a)'!$C$6:$Q$58,N$5,0) -> 0 | ... P17: =VLOOKUP($C17,'A. All deals (a)'!$C$6:$Q$58,P$5,0) -> -8 | Q17: -8 | R17: =VLOOKUP($C17,'A. All deals (a)'!$C$6:$Q$58,R$5,0) -> 0 | S17: =VLOOKUP($C17,'A. All deals (a)'!$C$6:$Q$58,S$5,0) -> In Default
C18: Jollychic Holding Limited | D18: Direct Investment | E18: =VLOOKUP($C18,'A. All deals (a)'!$C$6:$Q$58,E$5,0) -> Written-off | G18: =VLOOKUP($C18,'A. All deals (a)'!$C$6:$Q$58,G$5,0) -> Mozn | H18: =VLOOKUP($C18,'A. All deals (a)'!$C$6:$Q$58,H$5,0) -> 2019 | I18: =VLOOKUP($C18,'A. All deals (a)'!$C$6:$Q$58,I$5,0) -> C+ Prefs | J18: =VLOOKUP($C18,'A. All deals (a)'!$C$6:$Q$58,J$5,0) -> 0.056999998 | K18: =VLOOKUP($C18,'A. All deals (a)'!$C$6:$Q$58,K$5,0) -> 65 | L18: =VLOOKUP($C18,'A. All deals (a)'!$C$6:$Q$58,L$5,0) -> 65 | M18: =VLOOKUP($C18,'A. All deals (a)'!$C$6:$Q$58,M$5,0) -> 0 | N18: =VLOOKUP($C18,'A. All deals (a)'!$C$6:$Q$58,N$5,0) -> 0 | ... P18: =VLOOKUP($C18,'A. All deals (a)'!$C$6:$Q$58,P$5,0) -> -65 | Q18: -65 | R18: =VLOOKUP($C18,'A. All deals (a)'!$C$6:$Q$58,R$5,0) -> 0 | S18: =VLOOKUP($C18,'A. All deals (a)'!$C$6:$Q$58,S$5,0) -> In Liquidation
K20: =SUM(K9:K18) -> 604.7973 | L20: =SUM(L9:L18) -> 604.7973 | M20: =SUM(M9:M18) -> 0 | N20: =SUM(N9:N18) -> 540.91298 | O20: =SUM(O9:O18) -> 0 | P20: =SUM(P9:P18) -> -63.884321 | Q20: =SUM(Q10:Q18) -> -141.1598 | R20: =(N20+O20)/L20 -> 0.89437069
C22: G42 Investments AI Holding RSC Ltd
C23: Honor Device Co Ltd | D23: Direct Investment | E23: =VLOOKUP($C23,'A. All deals (a)'!$C$6:$Q$58,E$5,0) -> Realized | G23: =VLOOKUP($C23,'A. All deals (a)'!$C$6:$Q$58,G$5,0) -> G42 3 | H23: =VLOOKUP($C23,'A. All deals (a)'!$C$6:$Q$58,H$5,0) -> 2022 | I23: =VLOOKUP($C23,'A. All deals (a)'!$C$6:$Q$58,I$5,0) -> Equity-TBC | J23: =VLOOKUP($C23,'A. All deals (a)'!$C$6:$Q$58,J$5,0) -> NA | K23: =VLOOKUP($C23,'A. All deals (a)'!$C$6:$Q$58,K$5,0) -> 800 | L23: =VLOOKUP($C23,'A. All deals (a)'!$C$6:$Q$58,L$5,0) -> 800 | M23: =VLOOKUP($C23,'A. All deals (a)'!$C$6:$Q$58,M$5,0) -> 0 | N23: =VLOOKUP($C23,'A. All deals (a)'!$C$6:$Q$58,N$5,0) -> 802.8 | ... P23: =VLOOKUP($C23,'A. All deals (a)'!$C$6:$Q$58,P$5,0) -> 2.8 | Q23: 54.67 | R23: =VLOOKUP($C23,'A. All deals (a)'!$C$6:$Q$58,R$5,0) -> 1.0035
C24: Sinovation Disrupt Fund, L.P. | D24: Fund Investment | E24: =VLOOKUP($C24,'A. All deals (a)'!$C$6:$Q$58,E$5,0) -> Realized | G24: =VLOOKUP($C24,'A. All deals (a)'!$C$6:$Q$58,G$5,0) -> G42 Investments | H24: =VLOOKUP($C24,'A. All deals (a)'!$C$6:$Q$58,H$5,0) -> 2020 | I24: =VLOOKUP($C24,'A. All deals (a)'!$C$6:$Q$58,I$5,0) -> LP | J24: =VLOOKUP($C24,'A. All deals (a)'!$C$6:$Q$58,J$5,0) -> n/a | K24: =VLOOKUP($C24,'A. All deals (a)'!$C$6:$Q$58,K$5,0) -> 50 | L24: =VLOOKUP($C24,'A. All deals (a)'!$C$6:$Q$58,L$5,0) -> 24.959693 | M24: =VLOOKUP($C24,'A. All deals (a)'!$C$6:$Q$58,M$5,0) -> 0 | N24: =VLOOKUP($C24,'A. All deals (a)'!$C$6:$Q$58,N$5,0) -> 25.403521 | ... P24: =VLOOKUP($C24,'A. All deals (a)'!$C$6:$Q$58,P$5,0) -> 0.44382835 | Q24: -1.265 | R24: =VLOOKUP($C24,'A. All deals (a)'!$C$6:$Q$58,R$5,0) -> 1.0177818
K26: =SUM(K23:K24) -> 850 | L26: =SUM(L23:L24) -> 824.95969 | M26: =SUM(M23:M24) -> 0 | N26: =SUM(N23:N24) -> 828.20352 | O26: =SUM(O23:O24) -> 0 | P26: =SUM(P23:P24) -> 3.2438283 | Q26: =SUM(Q23:Q24) -> 53.405 | R26: =(N26+O26)/L26 -> 1.0039321 | S26: =O26+N26-L26 -> 3.2438283
C28: G42 Capital SPV RSC Ltd
C32: Core42 Holding RSC Ltd
K36: =K20+K26+K30+K34 -> 1454.7973 | L36: =L20+L26+L30+L34 -> 1429.757 | M36: =M20+M26+M30+M34 -> 0 | N36: =N20+N26+N30+N34 -> 1369.1165 | O36: =O20+O26+O30+O34 -> 0 | P36: =P20+P26+P30+P34 -> -60.640493 | Q36: =Q20+Q26+Q30+Q34 -> -87.754802 | R36: =(N36+O36)/L36 -> 0.95758685
C40: For Notes, refer to 9. All deals (a)
C41: Position Exited or written off are highlighted

Sheet CF (Equity, Debt)
B2: E Q U I T Y
B3: Accounting entity | C3: Investment | D3: Payment date | E3: Contributions (in USD, Mn) | F3: Distributions (in USD, Mn) | G3: Currency | H3: Investment / Exit Amt (investee currency) | I3: Investment / Exit Amount (USD) | J3: Consideration (shares) | K3: Comment
B4: =VLOOKUP(C4,'A. All deals (a)'!$C$9:$F$49,4,0) -> Mozn | C4: Jollychic Holding Limited | D4: 43470 | E4: =-I4*10^-6 -> -30 | G4: USD | H4: 30000000 | I4: =H4 -> 30000000 | J4: 6100312
B5: =VLOOKUP(C5,'A. All deals (a)'!$C$9:$F$49,4,0) -> Mozn | C5: Jollychic Holding Limited | D5: 43724 | E5: =-I5*10^-6 -> -20 | G5: USD | H5: 20000000 | I5: =H5 -> 20000000 | J5: 4204767.4
B6: =VLOOKUP(C6,'A. All deals (a)'!$C$9:$F$49,4,0) -> Mozn | C6: Jollychic Holding Limited | D6: 43724 | E6: =-I6*10^-6 -> -15 | G6: USD | H6: 15000000 | I6: =H6 -> 15000000 | J6: 3153575.6
B7: =VLOOKUP(C7,'A. All deals (a)'!$C$9:$F$49,4,0) -> Mozn | C7: Mena Mobile Inc | D7: 43563 | E7: =-I7*10^-6 -> -8 | G7: USD | H7: 8000000 | I7: =H7 -> 8000000 | J7: 21419829
B8: =VLOOKUP(C8,'A. All deals (a)'!$C$9:$F$49,4,0) -> Mozn | C8: Flyr Inc | D8: 43570 | E8: =-I8*10^-6 -> -4.9999981 | G8: USD | H8: 4999998.1 | I8: =H8 -> 4999998.1 | J8: 2625467
B9: =VLOOKUP(C9,'A. All deals (a)'!$C$9:$F$49,4,0) -> Mozn | C9: Flyr Inc | D9: 43915 | E9: =-I9*10^-6 -> -5.0000019 | G9: USD | H9: =10000000-H8 -> 5000001.9 | I9: =H9 -> 5000001.9 | J9: 2580015
B10: =VLOOKUP(C10,'A. All deals (a)'!$C$9:$F$49,4,0) -> Mozn | C10: Esyasoft Holding | D10: 43870 | E10: =-I10*10^-6 -> -2.5 | G10: USD | H10: 2500000 | I10: =H10 -> 2500000 | J10: N/A
B11: =VLOOKUP(C11,'A. All deals (a)'!$C$9:$F$49,4,0) -> Mozn | C11: Beyond Limits | D11: 43879 | E11: =-I11*10^-6 -> -20 | G11: USD | H11: 20000000 | I11: =H11 -> 20000000 | J11: 4084038
B12: =VLOOKUP(C12,'A. All deals (a)'!$C$9:$F$49,4,0) -> Mozn | C12: Beyond Limits | D12: 43921 | E12: =-I12*10^-6 -> -30 | G12: USD | H12: 30000000 | I12: =H12 -> 30000000 | J12: 5822642
B13: =VLOOKUP(C13,'A. All deals (a)'!$C$9:$F$49,4,0) -> Mozn | C13: Beyond Limits | D13: 43989 | E13: =-I13*10^-6 -> -30 | G13: USD | H13: 30000000 | I13: =H13 -> 30000000 | J13: 5822642
B14: =VLOOKUP(C14,'A. All deals (a)'!$C$9:$F$49,4,0) -> Mozn | C14: Beyond Limits | D14: 44103 | E14: =-I14*10^-6 -> -10 | G14: USD | H14: 10000000 | I14: =H14 -> 10000000 | J14: 1940880
B15: =VLOOKUP(C15,'A. All deals (a)'!$C$9:$F$49,4,0) -> Mozn | C15: ONT plc | D15: 43968 | E15: =-I15*10^-6 -> -50 | G15: USD | H15: 50000000 | I15: 50000000 | J15: 15277680
B16: =VLOOKUP(C16,'A. All deals (a)'!$C$9:$F$49,4,0) -> Mozn | C16: ONT plc | D16: 44006 | E16: =-I16*10^-6 -> -27.268351 | G16: GBP | H16: 21029625 | I16: 27268351 | J16: 9000000
B17: =VLOOKUP(C17,'A. All deals (a)'!$C$9:$F$49,4,0) -> Mozn | C17: ONT plc | D17: 43837 | E17: =-I17*10^-6 -> -18.109441 | G17: GBP | H17: 14386480 | I17: 18109441 | J17: 6362180
B18: =VLOOKUP(C18,'A. All deals (a)'!$C$9:$F$49,4,0) -> Mozn | C18: ONT plc | D18: 43990 | E18: =-I18*10^-6 -> -34.851687 | G18: GBP | H18: 26085573 | I18: 34851687 | J18: 11381140
B19: =VLOOKUP(C19,'A. All deals (a)'!$C$9:$F$49,4,0) -> Mozn | C19: ONT plc | D19: 44315 | E19: =-I19*10^-6 -> -11.24078 | G19: GBP | H19: 8074920 | I19: 11240780 | J19: 2307120
B20: =VLOOKUP(C20,'A. All deals (a)'!$C$9:$F$49,4,0) -> Mozn | C20: Heygears | D20: 44166 | E20: =-I20*10^-6 -> -60 | G20: USD | H20: 60000000 | I20: =H20 -> 60000000 | J20: 3565017.2
B21: =VLOOKUP(C21,'A. All deals (a)'!$C$9:$F$49,4,0) -> Mozn 1 | C21: Jysan Technologies | D21: 44363 | E21: =-I21*10^-6 -> -20 | G21: USD | H21: 20000000 | I21: =H21 -> 20000000 | J21: 7959497
B22: =VLOOKUP(C22,'A. All deals (a)'!$C$9:$F$49,4,0) -> Mozn | C22: Cerebras Systems Inc (1) | D22: 44488 | E22: =-I22*10^-6 -> -39.999983 | G22: USD | H22: 39999983 | I22: =H22 -> 39999983 | J22: 1441711
B23: =VLOOKUP(C23,'A. All deals (a)'!$C$9:$F$49,4,0) -> Mozn | C23: Endless Studios LLC | D23: 44494 | E23: =-I23*10^-6 -> -3 | G23: USD | H23: 3000000 | I23: =H23 -> 3000000 | J23: 3000000
B24: =VLOOKUP(C24,'A. All deals (a)'!$C$9:$F$49,4,0) -> Mozn | C24: Instadeep Limited | D24: 44550 | E24: =-I24*10^-6 -> -5.0237202 | G24: GBP | H24: 3679995.5 | I24: 5023720.2 | J24: 33267
B25: =VLOOKUP(C25,'A. All deals (a)'!$C$9:$F$49,4,0) -> Mozn 2 | C25: X-fusion | D25: 44574 | E25: =-I25*10^-6 -> -493.50096 | G25: USD | H25: 8.9350096e+08 | I25: 4.9350096e+08
B26: =VLOOKUP(C26,'A. All deals (a)'!$C$9:$F$49,4,0) -> G42 Investments | C26: DriveNets | D26: 44643 | E26: =-I26*10^-6 -> -200 | G26: USD | H26: 200000000 | I26: =H26 -> 200000000
B27: =VLOOKUP(C27,'A. All deals (a)'!$C$9:$F$49,4,0) -> G42 Investments | C27: DriveNets | D27: 44680 | E27: =-I27*10^-6 -> -100 | G27: USD | H27: 100000000 | I27: =H27 -> 100000000
B28: =VLOOKUP(C28,'A. All deals (a)'!$C$9:$F$49,4,0) -> Mozn | C28: Esyasoft Holding | D28: 44691 | F28: 5 | G28: USD
B29: =VLOOKUP(C29,'A. All deals (a)'!$C$9:$F$49,4,0) -> G42 Investments | C29: vTv Therapeutics Inc. | D29: 44712 | E29: =-I29*10^-6 -> -12.5 | G29: USD | H29: 12500000 | I29: =H29 -> 12500000 | J29: ='%'!D22 -> 259657
B30: =VLOOKUP(C30,'A. All deals (a)'!$C$9:$F$49,4,0) -> G42 3 | C30: Honor Device Co Ltd | D30: 44769 | E30: =-I30*10^-6 -> -600 | G30: USD | H30: 600000000 | I30: =H30 -> 600000000
B31: =VLOOKUP(C31,'A. All deals (a)'!$C$9:$F$49,4,0) -> G42 3 | C31: Honor Device Co Ltd | D31: 44849 | E31: =-I31*10^-6 -> -200 | G31: USD | H31: 200000000 | I31: =H31 -> 200000000
B32: =VLOOKUP(C32,'A. All deals (a)'!$C$9:$F$49,4,0) -> Mozn | C32: Applied AI Corporation Limited | D32: 44861 | E32: =-I32*10^-6 -> -4.75 | G32: USD | H32: 4750000 | I32: =H32 -> 4750000
B33: =VLOOKUP(C33,'A. All deals (a)'!$C$9:$F$49,4,0) -> Mozn 4 | C33: eSpace | D33: 44892 | E33: =-I33*10^-6 -> -15 | G33: USD | H33: 15000000 | I33: =H33 -> 15000000
B34: =VLOOKUP(C34,'A. All deals (a)'!$C$9:$F$49,4,0) -> G42 Investments | C34: vTv Therapeutics Inc. | D34: 44985 | E34: =-I34*10^-6 -> -12.03125 | G34: USD | H34: 12031250 | I34: =H34 -> 12031250 | J34: 10386274
B35: =VLOOKUP(C35,'A. All deals (a)'!$C$9:$F$49,4,0) -> Mozn | C35: Tools for Humanity Corporation | D35: 45075 | E35: =-I35*10^-6 -> -14.999999 | G35: USD | H35: 14999999 | I35: =H35 -> 14999999
B36: =VLOOKUP(C36,'A. All deals (a)'!$C$9:$F$49,4,0) -> Mozn | C36: WLD Tokens | D36: 45075 | E36: =-I36*10^-6 -> -0.005875 | G36: USD | I36: 5875
B37: =VLOOKUP(C37,'A. All deals (a)'!$C$9:$F$49,4,0) -> Mozn | C37: WLD Tokens | D37: 45114 | E37: =-I37*10^-6 -> -0.001 | G37: USD | I37: 1000
B38: =VLOOKUP(C38,'A. All deals (a)'!$C$9:$F$49,4,0) -> Mozn | C38: Applied AI Corporation Limited | D38: 45121 | E38: =-I38*10^-6 -> -2.75 | G38: USD | I38: 2750000
B39: =VLOOKUP(C39,'A. All deals (a)'!$C$9:$F$49,4,0) -> Mozn | C39: Instadeep Limited | D39: 45138 | F39: =I39*10^-6 -> 7.8207761 | G39: USD | H39: 6090345.2 | I39: 7820776.1
B40: =VLOOKUP(C40,'A. All deals (a)'!$C$9:$F$49,4,0) -> Mozn 1 | C40: Jysan Technologies | D40: 45149 | F40: 24.5 | G40: USD | I40: 24500000 | J40: 7959497
B41: =VLOOKUP(C41,'A. All deals (a)'!$C$9:$F$49,4,0) -> Mozn | C41: Endless Studios LLC | D41: 45167 | E41: =-I41*10^-6 -> -5 | G41: USD | I41: 5000000 | J41: 5000000
...

Sheet CF (Funds)
B2: F U N D S
B3: Entity | C3: Investment | D3: Payment date | E3: Contributions (USD, Mn) | F3: Distributions (USD, Mn) | G3: Currency | H3: Cashflows | I3: Description
B4: G42 | C4: Sinovation Disrupt Fund, L.P. | D4: 44153 | E4: =H4 -> -10.5 | G4: USD | H4: -10.5 | I4: 1st Capital Call
B5: G42 | C5: Sinovation Disrupt Fund, L.P. | D5: 44238 | E5: =H5 -> 4.214027 | G5: USD | H5: 4.214027 | I5: Partial return of the 1st Capital Call
B6: G42 | C6: Sinovation Disrupt Fund, L.P. | D6: 44238 | F6: =H6 -> 0.05044835 | G6: USD | H6: 0.05044835 | I6: Interest Catchup
B7: G42 | C7: Sinovation Disrupt Fund, L.P. | D7: 44285 | E7: =H7 -> -6.433746 | G7: USD | H7: -6.433746 | I7: 2nd Capital Calll
B8: G42 | C8: Sinovation Disrupt Fund, L.P. | D8: 44269 | E8: =H8 -> 1.1352074 | G8: USD | H8: 1.1352074 | I8: Return of Capital fund
B9: G42 | C9: Sinovation Disrupt Fund, L.P. | D9: 44269 | F9: =H9 -> 0.0259 | G9: USD | H9: 0.0259 | I9: Interest Catchup
B10: G42 | C10: Sinovation Disrupt Fund, L.P. | D10: 44483 | E10: =H10 -> -7.567138 | G10: USD | H10: -7.567138 | I10: 3rd Capital Call
B11: G42 | C11: Sinovation Disrupt Fund, L.P. | D11: 44554 | E11: =H11 -> -7.385016 | G11: USD | H11: -7.385016 | I11: 4th Capital Call
B12: G42 | C12: Sinovation Disrupt Fund, L.P. | D12: 44554 | E12: =H12 -> 4.0733456 | G12: USD | H12: 4.0733456 | I12: Return of Capital fund
B13: G42 | C13: Sinovation Disrupt Fund, L.P. | D13: 44554 | F13: =H13 -> 0.139694 | G13: USD | H13: 0.139694 | I13: Interest Catchup
B14: G42 | C14: Sinovation Disrupt Fund, L.P. | D14: 44703 | E14: =H14 -> 5.673074 | G14: USD | H14: 5.673074 | I14: Return of Capital fund
B15: G42 | C15: Sinovation Disrupt Fund, L.P. | D15: 44703 | F15: =H15 -> 0.227786 | G15: USD | H15: 0.227786 | I15: Interest Catchup
B16: G42 | C16: Sinovation Disrupt Fund, L.P. | D16: 44776 | E16: =H16 -> -3.235493 | G16: USD | H16: -3.235493 | I16: 5th Capital Call
B17: G42 | C17: Sinovation Disrupt Fund, L.P. | D17: 44960 | E17: =H17 -> -2.631528 | G17: USD | H17: -2.631528 | I17: 6th Capital Call
B18: G42 | C18: Sinovation Disrupt Fund, L.P. | D18: 45085 | E18: =H18 -> 1.912557 | G18: USD | H18: 1.912557 | I18: Return of Capital fund
B19: G42 | C19: Sinovation Disrupt Fund, L.P. | D19: 45166 | E19: -1.799122 | G19: USD | H19: -1.799122 | I19: 7th Capital Call
B20: G42 | C20: Sinovation Disrupt Fund, L.P. | D20: 45218 | E20: -2.415861 | G20: USD | H20: -2.415861 | I20: 8th Capital Call
B21: G42 | C21: Sinovation Disrupt Fund, L.P. | D21: 45323 | F21: =24.959693 -> 24.959693 | G21: USD | H21: =F21 -> 24.959693 | I21: Exit Proceeds (full and final)
B22: G42 | C22: North Summit Capital Fund | D22: 43665 | E22: =H22 -> -3 | G22: USD | H22: -3 | I22: 1st Capital Call
B23: G42 | C23: North Summit Capital Fund | D23: 43983 | E23: =H23 -> -4.485 | G23: USD | H23: -4.485 | I23: 2nd Capital Calll
B24: G42 | C24: North Summit Capital Fund | D24: 43879 | E24: =H24 -> -9.50975 | G24: USD | H24: -9.50975 | I24: 3rd Capital Call
B25: G42 | C25: North Summit Capital Fund | D25: 43934 | E25: =H25 -> -41.3 | G25: USD | H25: -41.3 | I25: 4th Capital Call
B26: G42 | C26: North Summit Capital Fund | D26: 44151 | E26: =H26 -> 9.95 | G26: USD | H26: 9.95 | I26: 5th Capital Call-Partial return of the 4th Capital Call
B27: G42 | C27: North Summit Capital Fund | D27: 44151 | E27: =H27 -> -10.455 | G27: USD | H27: -10.455 | I27: 5th Capital Call
B28: G42 | C28: North Summit Capital Fund | D28: 44196 | E28: =H28 -> 4.975 | G28: USD | H28: 4.975 | I28: 6th Capital Call-Partial return of the 4th Capital Call
B29: G42 | C29: North Summit Capital Fund | D29: 44196 | E29: =H29 -> -3.452293 | G29: USD | H29: -3.452293 | I29: 6th Capital Call
B30: G42 | C30: North Summit Capital Fund | D30: 44196 | F30: =H30 -> 0.582902 | G30: USD | H30: 0.582902 | I30: 6th Capital Call-Dividends from Project Topscore
B31: G42 | C31: North Summit Capital Fund | D31: 44370 | E31: =H31 -> -5.97 | G31: USD | H31: -5.97 | I31: 7th Capital Call
B32: G42 | C32: North Summit Capital Fund | D32: 44400 | E32: =H32 -> -0.75 | G32: USD | H32: -0.75 | I32: 8th Capital Call
B33: G42 | C33: North Summit Capital Fund | D33: 44400 | F33: =H33 -> 0.445059 | G33: USD | H33: 0.445059 | I33: 8th Capital Call-Dividends from Project Topscore
B34: G42 | C34: North Summit Capital Fund | D34: 44554 | E34: =H34 -> 1.78239 | G34: USD | H34: 1.78239 | I34: 9th Capital Call-Return of Capital Fund
B35: G42 | C35: North Summit Capital Fund | D35: 44676 | E35: =H35 -> -21 | G35: USD | H35: -21 | I35: 12th Capital Call
B36: G42 | C36: North Summit Capital Fund | D36: 45243 | F36: =H36 -> 6.78791 | G36: USD | H36: 6.78791 | I36: 13th Capital Call & Distribution #4
B37: G42 | C37: North Summit Capital Fund | D37: 45470 | E37: =H37 -> -0.055697 | G37: USD | H37: =-55697*10^-6 -> -0.055697 | I37: 14th Capital Call
B38: G42 | C38: North Summit Capital Fund | D38: 45611 | E38: =H38 -> -0.031561 | G38: USD | H38: =-31561*10^-6 -> -0.031561 | I38: 15th Capital Call
B39: G42 | C39: New Space Capital Fund I | D39: 44087 | E39: =H39*1.1 -> -20.917553 | G39: EUR | H39: -19.015957 | I39: Drawdown1
B40: G42 | C40: New Space Capital Fund I | D40: 44287 | E40: -0.21103182 | G40: EUR | H40: -0.21103182 | I40: Drawdown2
B41: G42 | C41: New Space Capital Fund I | D41: 44442 | E41: =1.18*H41 -> -0.23965473 | G41: EUR | H41: =-203097.23*10^-6 -> -0.20309723 | I41: Drawdown3
...

Sheet NAV
B2: NAV Date | C2: ='A. All deals (a)'!D2 -> 46265 | D2: =TEXT(C2,"ddd") -> Mon
B5: Investments | C5: Investing Entity | D5: Instrument | E5: Carrying Value | F5: Current Shares/Units | H5: Comment
E6: USD, Million | F6: # | G6: USD
E7: ="NAV | "& TEXT(C2,"dd")&" "&TEXT(C2,"mmm")&" "&TEXT(C2,"yyyy") -> NAV | 31 Aug 2026 | G7: ="PPS |" & TEXT(C2,"dd")&" "&TEXT(C2,"mmm")&" "&TEXT(C2,"yyyy") -> PPS |31 Aug 2026
B9: Direct Investments
B10: ='A. All deals (a)'!C9 -> Jollychic Holding Limited | C10: ='A. All deals (a)'!F9 -> Mozn | D10: ='A. All deals (a)'!H9 -> C+ Prefs | E10: =F10*G10*10^-6 -> 0 | F10: =VLOOKUP(B10,'%'!$C$6:$I$43,2,0) -> 13458655 | H10: Exited/Liquidated
B11: ='A. All deals (a)'!C10 -> Mena Mobile Inc | C11: ='A. All deals (a)'!F10 -> Mozn | D11: ='A. All deals (a)'!H10 -> B Prefs | E11: 0 | F11: =VLOOKUP(B11,'%'!$C$6:$I$43,2,0) -> 21419829 | H11: As per 3rd Party | Ardent Estimates | Equity written off | K11: =STOCKHISTORY(J18,$K$16,$K$16,0,0)
B12: ='A. All deals (a)'!C12 -> Esyasoft Holding | C12: ='A. All deals (a)'!F12 -> Mozn | D12: ='A. All deals (a)'!H12 -> Convertible Note | E12: 0 | F12: =VLOOKUP(B12,'%'!$C$6:$I$43,2,0) -> n/a | H12: Exited at $5m (10th May) | Residual value = 0
B13: ='A. All deals (a)'!C16 -> Jysan Technologies | C13: ='A. All deals (a)'!F16 -> Mozn 1 | D13: ='A. All deals (a)'!H16 -> A (Ordinary Shares) | E13: 0 | F13: =VLOOKUP(B13,'%'!$C$6:$I$43,2,0) -> 7959497 | G13: =E13*10^6/F13 -> 0 | H13: Exited at $24.5m
B14: ='A. All deals (a)'!C19 -> Instadeep Limited | C14: ='A. All deals (a)'!F19 -> Mozn | D14: ='A. All deals (a)'!H19 -> B Prefs | E14: =-'CF (Equity, Debt)'!E24*G14 -> 0 | F14: =VLOOKUP(B14,'%'!$C$6:$I$43,2,0) -> 33267 | G14: 0 | H14: Exited at 1.56X | Residual Value = 0
B15: ='A. All deals (a)'!C20 -> X-fusion | C15: ='A. All deals (a)'!F20 -> Mozn 2 | D15: ='A. All deals (a)'!H20 -> Equity-TBC | E15: 0 | F15: =VLOOKUP(B15,'%'!$C$6:$I$43,2,0) -> n/a | H15: Exited at 0.82X | K15: =TEXT(K16,"ddd") -> Mon | S15: Heygears Oct 22
B16: ='A. All deals (a)'!C23 -> Honor Device Co Ltd | C16: ='A. All deals (a)'!F23 -> G42 3 | D16: ='A. All deals (a)'!H23 -> Equity-TBC | E16: 0 | F16: =VLOOKUP(B16,'%'!$C$6:$I$43,2,0) -> 6.0685078e+08 | H16: Exited at 1.0X | J16: Updated as on: | K16: =C2 -> 46265 | M16: source | S16: Post Valuation closed in June 2021 (RMB) | T16: 7500000000
B17: ='A. All deals (a)'!C27 -> WLD Tokens | C17: ='A. All deals (a)'!F27 -> Mozn | D17: ='A. All deals (a)'!H27 -> Tokens | E17: =F17*G17*10^-6 -> 0 | F17: 0 | G17: =K17 -> 0 | H17: source: coinmarket cap | S17: G42 Stake | T17: 0.143832
B18: ='A. All deals (a)'!C14 -> ONT plc | C18: ='A. All deals (a)'!F14 -> Mozn | D18: ='A. All deals (a)'!H14 -> Ordinary Shares | E18: =F18*G18*10^-6 -> 105.22733 | F18: =VLOOKUP(B18,'%'!$C$6:$I$43,2,0) -> 44328120 | G18: =M18*M22/100 -> 2.373828 | H18: Listed & marked to market | J18: ONT | K18: {=_xlfn.STOCKHISTORY(J18,$K$16,$K$16,0,0)} -> 46265 | L18: 16.72 | M18: 176.1 | S18: G42 Valuation before Discount (RMB) | T18: 1078740000
B19: ='A. All deals (a)'!C22 -> vTv Therapeutics Inc. | C19: ='A. All deals (a)'!F22 -> G42 Investments | D19: ='A. All deals (a)'!H22 -> Ordinary Shares | E19: =(F19*G19)*10^-6 -> 8.309024 | F19: =VLOOKUP(B19,'%'!$C$6:$I$43,2,0) -> 259657 | G19: =M19 -> 32 | H19: Listed & marked to market | J19: VTVT | K19: {=_xlfn.STOCKHISTORY(J19,$K$16,$K$16,0,0)} -> 46265 | L19: 32 | M19: 32 | S19: Liquidity Discount | T19: 0
B20: ='A. All deals (a)'!C31 -> Verses AI Inc | C20: ='A. All deals (a)'!F31 -> G42 Capital | D20: ='A. All deals (a)'!H31 -> Ordinary Shares | E20: =(F20*G20)*10^-6 -> 0 | F20: =VLOOKUP(B20,'%'!$C$6:$I$43,2,0) -> 514623.44 | G20: =M21 -> 0 | H20: Listed & marked to market | J20: CBRS | K20: {=_xlfn.STOCKHISTORY(J20,$K$16,$K$16,0,0)} -> 46265 | L20: 184.24 | M20: 184.24 | S20: Minority Holding Discount | T20: 0
B21: ='A. All deals (a)'!C17 -> Cerebras Systems Inc (1) | C21: ='A. All deals (a)'!F17 -> Mozn | D21: ='A. All deals (a)'!H17 -> F Prefs | E21: =F21*G21*10^-6 -> 265.62083 | F21: =VLOOKUP(B21,'%'!$C$6:$I$43,2,0) -> 1441711 | G21: =M20 -> 184.24 | H21: Listed & marked to market | J21: VRSSF | K21: {=_xlfn.STOCKHISTORY(J21,$K$16,$K$16,0,0)} -> 46265 | L21: #N/A | M21: 0 | S21: G42 Valuation (RMB) | T21: =T18*(1-T19)*(1-T20) -> 1078740000
B22: ='A. All deals (a)'!C35 -> Cerebras Systems Inc (2) | C22: G42 Capital | D22: ='A. All deals (a)'!H29 -> Preferred Shares | E22: =F22*G22*10^-6 -> 647.32558 | F22: =1857516+1655975 -> 3513491 | G22: =M20 -> 184.24 | H22: Listed & marked to market | J22: GBPUSD | K22: {=_xlfn.STOCKHISTORY(J22,$K$16,$K$16,0,0)} -> 46265 | L22: 1.3547 | M22: 1.348 | S22: Exchange Rate (RMB/USD) | T22: =K23 -> 46265
B23: ='A. All deals (a)'!C11 -> Flyr Inc | C23: ='A. All deals (a)'!F11 -> Mozn | D23: ='A. All deals (a)'!H11 -> B-1,2 Prefs | E23: 14.6 | F23: =VLOOKUP(B23,'%'!$C$6:$I$43,2,0) -> 5205482 | H23: As per the recent fund raise for Series D | J23: USDCNY | K23: {=_xlfn.STOCKHISTORY(J23,$K$16,$K$16,0,0)} -> 46265 | L23: 6.7197 | M23: 6.7237 | S23: G42 Valuation (USD) | T23: =T21/T22 -> 23316.546
B24: ='A. All deals (a)'!C13 -> Beyond Limits | C24: ='A. All deals (a)'!F13 -> Mozn | D24: ='A. All deals (a)'!H13 -> C Prefs | E24: 21.7 | F24: =VLOOKUP(B24,'%'!$C$6:$I$43,2,0) -> 17670202 | G24: =5.152 * 50% -> 2.576 | H24: Ardent Dec'25 | 50% haircut recent convertible price during Q4'25 | J24: EURUSD | K24: {=_xlfn.STOCKHISTORY(J24,$K$16,$K$16,0,0)} -> 46265 | L24: 1.1616 | M24: 1.16169 | S24: Investment Cost of G42 (USD) | T24: 60000000
B25: ='A. All deals (a)'!C15 -> Heygears | C25: ='A. All deals (a)'!F15 -> Mozn | D25: ='A. All deals (a)'!H15 -> Registered Capital | E25: =F25*G25*10^-6 -> 71.918846 | F25: ='CF (Equity, Debt)'!J20 -> 3565017.2 | G25: =141.2/$K$44 -> 20.173492 | H25: Priced round at RMB 141.2 per share | Mar'26
B26: ='A. All deals (a)'!C18 -> Endless Studios LLC | C26: ='A. All deals (a)'!F18 -> Mozn | D26: ='A. All deals (a)'!H18 -> A Pref Units | E26: 6.5 | F26: =VLOOKUP(B26,'%'!$C$6:$I$43,2,0) -> 8000000 | H26: Ardent Valuation as of 31 Dec 25
B27: ='A. All deals (a)'!C28 -> E-line Ventures LLC | C27: ='A. All deals (a)'!F28 -> Mozn | D27: ='A. All deals (a)'!H28 -> B Prefs | E27: 7.1 | F27: =VLOOKUP(B27,'%'!$C$6:$I$43,2,0) -> 4477612 | H27: Ardent Valuation as of 31 Dec 25 | J27: Checks
B28: ='A. All deals (a)'!C21 -> DriveNets | C28: ='A. All deals (a)'!F21 -> G42 Investments | D28: ='A. All deals (a)'!H21 -> Equity-TBC | E28: =F28*G28*10^-6 -> 497.53506 | F28: =VLOOKUP(B28,'%'!$C$6:$I$43,2,0) -> 68926902 | G28: 7.2183 | H28: Priced round at US$7.35 per share | Mar'26
B29: ='A. All deals (a)'!C24 -> Applied AI Corporation Limited | C29: ='A. All deals (a)'!F24 -> Mozn | D29: ='A. All deals (a)'!H24 -> A Prefs | E29: 38.46473 | F29: =VLOOKUP(B29,'%'!$C$6:$I$43,2,0) -> 211519 | H29: Marked up, being held at 2.27X as per the last round | J29: =SUM(E10:E36) -> 2175.5555 | K29: =J29='A. All deals (a)'!N36 -> TRUE
B30: ='A. All deals (a)'!C25 -> eSpace | C30: ='A. All deals (a)'!F25 -> Mozn 4 | D30: ='A. All deals (a)'!H25 -> B Prefs | E30: =F30*G30*10^-6 -> 230.00751 | F30: =VLOOKUP(B30,'%'!$C$6:$I$43,2,0) -> 417846 | G30: 550.46 | H30: Marked up, as converted as per the latest priced round | J30: =SUM(E41:E43) -> 0 | K30: =J30='A. All deals (a)'!N42 -> TRUE
